Workbook

Sheet Assumptions
A1: 3325 Banks Rd - Investor Return Model | C1: Editable inputs are in column B. Outputs update through formulas.
A3: Project Timing
A4: Stabilization / Refinance Year | B4: 2 | C4: Year when refinance proceeds are modeled
A5: Sale / Exit Year | B5: 4 | C5: Model uses annual periods 0 through this year
A7: Rental Program
A8: First Floor Premium Suites | B8: 4 | C8: Private bed/bath/kitchenette suites
A9: Monthly Rent per Premium Suite | B9: 1600 | C9: Editable rent assumption
A10: Second Floor Co-Living Suites | B10: 4 | C10: Private bed/bath with shared amenities
A11: Monthly Rent per Co-Living Suite | B11: 1100 | C11: Editable rent assumption
A12: Other Monthly Income | B12: 0 | C12: Parking, utility fees, laundry, etc.
A13: Stabilized Occupancy | B13: 0.93 | C13: Before operating expense load
A14: Year 1 Lease-Up Occupancy | B14: 0.5 | C14: First partial operating year
A15: Operating Expense Ratio | B15: 0.4 | C15: Percent of effective gross income
A16: NOI Growth | B16: 0.03 | C16: Annual growth after stabilization
A17: Stabilized Monthly Gross Rent | B17: =B8*B9+B10*B11+B12 -> 10800 | C17: Calculated
A19: Debt / Refinance / Exit
A20: Project Debt Payoff at Refi | B20: =MIN(INDEX('Annual Model'!$L$4:$L$14,MATCH($B$4,'Annual Model'!$A$4:$A$14,0))*70%,$B$28+$B$30) -> 744863.04 | C20: Construction/existing debt repaid from refinance
A21: Permanent Loan Amount | B21: 650000 | C21: New loan proceeds at refinance
A22: Permanent Loan Interest Rate | B22: 0.065 | C22: Annual fixed rate
A23: Permanent Loan Amortization Years | B23: 30 | C23: Used for annual debt service
A24: Exit Cap Rate | B24: 0.07 | C24: Sale value = following year NOI / cap rate
A25: Selling Costs | B25: 0.02 | C25: Percent deducted from gross sale value
A27: Capital Stack / Waterfall
A28: Class A Capital | B28: 300000 | C28: Preferred capital raise
A29: Class A Preferred Return | B29: 0.08 | C29: Cumulative annual preferred return
A30: Class B Capital | B30: =MAX(0,'Cost Analysis'!$C$17-$B$28) -> 1200000 | C30: Subordinate beneficiary capital; edit as needed
A31: Class B Capital Return Priority | B31: 1 | C31: 1 = return Class B capital before residual split
A32: Class B Residual Share | B32: 0.4 | C32: Residual cash flow / sale proceeds after priority payments
A33: Sponsor Residual Share | B33: =1-B32 -> 0.6 | C33: Default aligns with ~60% sponsor residual participation
A34: Sponsor Basis / Deemed Investment | B34: 150000 | C34: Land/control/origination value used for sponsor ROI
A36: Model Note | B36: This is a planning model, not tax, legal, securities, or investment advice.

Sheet Annual Model
A1: Annual Project Model
A3: Year | B3: Phase | C3: Gross Potential Rent | D3: Effective Gross Income | E3: Operating Expenses | F3: NOI | G3: Debt Service | H3: Cash Before Refi/Sale | I3: Net Refi/Sale Proceeds | J3: Total Cash Available | K3: Loan Balance | L3: Property Value / Refi Value
A4: 0 | B4: Capitalization / Entitlement | C4: =IF(A4=0,0,Assumptions!$B$17*12*(1+Assumptions!$B$16)^MAX(0,A4-Assumptions!$B$4)) -> 0 | D4: =IF(A4=0,0,C4*IF(A4=1,Assumptions!$B$14,Assumptions!$B$13)) -> 0 | E4: =D4*Assumptions!$B$15 -> 0 | F4: =D4-E4 -> 0 | G4: =IF(AND(A4>=Assumptions!$B$4,A4<=Assumptions!$B$5),-PMT(Assumptions!$B$22/12,Assumptions!$B$23*12,Assumptions!$B$21)*12,0) -> 0 | H4: =F4-G4 -> 0 | I4: =IF(A4=Assumptions!$B$4,MAX(0,Assumptions!$B$21-Assumptions!$B$20),IF(A4=Assumptions!$B$5,MAX(0,L4*(1-Assumptions!$B$25)-K4),0)) -> 0 | J4: =H4+I4 -> 0 | K4: =IF(A4<Assumptions!$B$4,0,IF(A4=Assumptions!$B$5,0,-FV(Assumptions!$B$22/12,(A4-Assumptions!$B$4)*12,PMT(Assumptions!$B$22/12,Assumptions!$B$23*12,Assumptions!$B$21),Assumptions!$B$21))) -> 0 | L4: =IF(A4<Assumptions!$B$4,0,F4*(1+Assumptions!$B$16)/Assumptions!$B$24) -> 0
A5: 1 | B5: Lease-Up | C5: =IF(A5=0,0,Assumptions!$B$17*12*(1+Assumptions!$B$16)^MAX(0,A5-Assumptions!$B$4)) -> 129600 | D5: =IF(A5=0,0,C5*IF(A5=1,Assumptions!$B$14,Assumptions!$B$13)) -> 64800 | E5: =D5*Assumptions!$B$15 -> 25920 | F5: =D5-E5 -> 38880 | G5: =IF(AND(A5>=Assumptions!$B$4,A5<=Assumptions!$B$5),-PMT(Assumptions!$B$22/12,Assumptions!$B$23*12,Assumptions!$B$21)*12,0) -> 0 | H5: =F5-G5 -> 38880 | I5: =IF(A5=Assumptions!$B$4,MAX(0,Assumptions!$B$21-Assumptions!$B$20),IF(A5=Assumptions!$B$5,MAX(0,L5*(1-Assumptions!$B$25)-K5),0)) -> 0 | J5: =H5+I5 -> 38880 | K5: =IF(A5<Assumptions!$B$4,0,IF(A5=Assumptions!$B$5,0,-FV(Assumptions!$B$22/12,(A5-Assumptions!$B$4)*12,PMT(Assumptions!$B$22/12,Assumptions!$B$23*12,Assumptions!$B$21),Assumptions!$B$21))) -> 0 | L5: =IF(A5<Assumptions!$B$4,0,F5*(1+Assumptions!$B$16)/Assumptions!$B$24) -> 0
A6: 2 | B6: Stabilization / Refi | C6: =IF(A6=0,0,Assumptions!$B$17*12*(1+Assumptions!$B$16)^MAX(0,A6-Assumptions!$B$4)) -> 129600 | D6: =IF(A6=0,0,C6*IF(A6=1,Assumptions!$B$14,Assumptions!$B$13)) -> 120528 | E6: =D6*Assumptions!$B$15 -> 48211.2 | F6: =D6-E6 -> 72316.8 | G6: =IF(AND(A6>=Assumptions!$B$4,A6<=Assumptions!$B$5),-PMT(Assumptions!$B$22/12,Assumptions!$B$23*12,Assumptions!$B$21)*12,0) -> 49301.306 | H6: =F6-G6 -> 23015.494 | I6: =IF(A6=Assumptions!$B$4,MAX(0,Assumptions!$B$21-Assumptions!$B$20),IF(A6=Assumptions!$B$5,MAX(0,L6*(1-Assumptions!$B$25)-K6),0)) -> 0 | J6: =H6+I6 -> 23015.494 | K6: =IF(A6<Assumptions!$B$4,0,IF(A6=Assumptions!$B$5,0,-FV(Assumptions!$B$22/12,(A6-Assumptions!$B$4)*12,PMT(Assumptions!$B$22/12,Assumptions!$B$23*12,Assumptions!$B$21),Assumptions!$B$21))) -> 650000 | L6: =IF(A6<Assumptions!$B$4,0,F6*(1+Assumptions!$B$16)/Assumptions!$B$24) -> 1064090.1
A7: 3 | B7: Operations | C7: =IF(A7=0,0,Assumptions!$B$17*12*(1+Assumptions!$B$16)^MAX(0,A7-Assumptions!$B$4)) -> 133488 | D7: =IF(A7=0,0,C7*IF(A7=1,Assumptions!$B$14,Assumptions!$B$13)) -> 124143.84 | E7: =D7*Assumptions!$B$15 -> 49657.536 | F7: =D7-E7 -> 74486.304 | G7: =IF(AND(A7>=Assumptions!$B$4,A7<=Assumptions!$B$5),-PMT(Assumptions!$B$22/12,Assumptions!$B$23*12,Assumptions!$B$21)*12,0) -> 49301.306 | H7: =F7-G7 -> 25184.998 | I7: =IF(A7=Assumptions!$B$4,MAX(0,Assumptions!$B$21-Assumptions!$B$20),IF(A7=Assumptions!$B$5,MAX(0,L7*(1-Assumptions!$B$25)-K7),0)) -> 0 | J7: =H7+I7 -> 25184.998 | K7: =IF(A7<Assumptions!$B$4,0,IF(A7=Assumptions!$B$5,0,-FV(Assumptions!$B$22/12,(A7-Assumptions!$B$4)*12,PMT(Assumptions!$B$22/12,Assumptions!$B$23*12,Assumptions!$B$21),Assumptions!$B$21))) -> 642734.78 | L7: =IF(A7<Assumptions!$B$4,0,F7*(1+Assumptions!$B$16)/Assumptions!$B$24) -> 1096012.8
A8: 4 | B8: Operations | C8: =IF(A8=0,0,Assumptions!$B$17*12*(1+Assumptions!$B$16)^MAX(0,A8-Assumptions!$B$4)) -> 137492.64 | D8: =IF(A8=0,0,C8*IF(A8=1,Assumptions!$B$14,Assumptions!$B$13)) -> 127868.16 | E8: =D8*Assumptions!$B$15 -> 51147.262 | F8: =D8-E8 -> 76720.893 | G8: =IF(AND(A8>=Assumptions!$B$4,A8<=Assumptions!$B$5),-PMT(Assumptions!$B$22/12,Assumptions!$B$23*12,Assumptions!$B$21)*12,0) -> 49301.306 | H8: =F8-G8 -> 27419.587 | I8: =IF(A8=Assumptions!$B$4,MAX(0,Assumptions!$B$21-Assumptions!$B$20),IF(A8=Assumptions!$B$5,MAX(0,L8*(1-Assumptions!$B$25)-K8),0)) -> 1106315.3 | J8: =H8+I8 -> 1133734.9 | K8: =IF(A8<Assumptions!$B$4,0,IF(A8=Assumptions!$B$5,0,-FV(Assumptions!$B$22/12,(A8-Assumptions!$B$4)*12,PMT(Assumptions!$B$22/12,Assumptions!$B$23*12,Assumptions!$B$21),Assumptions!$B$21))) -> 0 | L8: =IF(A8<Assumptions!$B$4,0,F8*(1+Assumptions!$B$16)/Assumptions!$B$24) -> 1128893.1
A9: 5 | B9: Operations | C9: =IF(A9=0,0,Assumptions!$B$17*12*(1+Assumptions!$B$16)^MAX(0,A9-Assumptions!$B$4)) -> 141617.42 | D9: =IF(A9=0,0,C9*IF(A9=1,Assumptions!$B$14,Assumptions!$B$13)) -> 131704.2 | E9: =D9*Assumptions!$B$15 -> 52681.68 | F9: =D9-E9 -> 79022.52 | G9: =IF(AND(A9>=Assumptions!$B$4,A9<=Assumptions!$B$5),-PMT(Assumptions!$B$22/12,Assumptions!$B$23*12,Assumptions!$B$21)*12,0) -> 0 | H9: =F9-G9 -> 79022.52 | I9: =IF(A9=Assumptions!$B$4,MAX(0,Assumptions!$B$21-Assumptions!$B$20),IF(A9=Assumptions!$B$5,MAX(0,L9*(1-Assumptions!$B$25)-K9),0)) -> 0 | J9: =H9+I9 -> 79022.52 | K9: =IF(A9<Assumptions!$B$4,0,IF(A9=Assumptions!$B$5,0,-FV(Assumptions!$B$22/12,(A9-Assumptions!$B$4)*12,PMT(Assumptions!$B$22/12,Assumptions!$B$23*12,Assumptions!$B$21),Assumptions!$B$21))) -> 626712.07 | L9: =IF(A9<Assumptions!$B$4,0,F9*(1+Assumptions!$B$16)/Assumptions!$B$24) -> 1162759.9
A10: 6 | B10: Operations | C10: =IF(A10=0,0,Assumptions!$B$17*12*(1+Assumptions!$B$16)^MAX(0,A10-Assumptions!$B$4)) -> 145865.94 | D10: =IF(A10=0,0,C10*IF(A10=1,Assumptions!$B$14,Assumptions!$B$13)) -> 135655.33 | E10: =D10*Assumptions!$B$15 -> 54262.13 | F10: =D10-E10 -> 81393.196 | G10: =IF(AND(A10>=Assumptions!$B$4,A10<=Assumptions!$B$5),-PMT(Assumptions!$B$22/12,Assumptions!$B$23*12,Assumptions!$B$21)*12,0) -> 0 | H10: =F10-G10 -> 81393.196 | I10: =IF(A10=Assumptions!$B$4,MAX(0,Assumptions!$B$21-Assumptions!$B$20),IF(A10=Assumptions!$B$5,MAX(0,L10*(1-Assumptions!$B$25)-K10),0)) -> 0 | J10: =H10+I10 -> 81393.196 | K10: =IF(A10<Assumptions!$B$4,0,IF(A10=Assumptions!$B$5,0,-FV(Assumptions!$B$22/12,(A10-Assumptions!$B$4)*12,PMT(Assumptions!$B$22/12,Assumptions!$B$23*12,Assumptions!$B$21),Assumptions!$B$21))) -> 617887.22 | L10: =IF(A10<Assumptions!$B$4,0,F10*(1+Assumptions!$B$16)/Assumptions!$B$24) -> 1197642.7
A11: 7 | B11: Operations | C11: =IF(A11=0,0,Assumptions!$B$17*12*(1+Assumptions!$B$16)^MAX(0,A11-Assumptions!$B$4)) -> 150241.92 | D11: =IF(A11=0,0,C11*IF(A11=1,Assumptions!$B$14,Assumptions!$B$13)) -> 139724.99 | E11: =D11*Assumptions!$B$15 -> 55889.994 | F11: =D11-E11 -> 83834.991 | G11: =IF(AND(A11>=Assumptions!$B$4,A11<=Assumptions!$B$5),-PMT(Assumptions!$B$22/12,Assumptions!$B$23*12,Assumptions!$B$21)*12,0) -> 0 | H11: =F11-G11 -> 83834.991 | I11: =IF(A11=Assumptions!$B$4,MAX(0,Assumptions!$B$21-Assumptions!$B$20),IF(A11=Assumptions!$B$5,MAX(0,L11*(1-Assumptions!$B$25)-K11),0)) -> 0 | J11: =H11+I11 -> 83834.991 | K11: =IF(A11<Assumptions!$B$4,0,IF(A11=Assumptions!$B$5,0,-FV(Assumptions!$B$22/12,(A11-Assumptions!$B$4)*12,PMT(Assumptions!$B$22/12,Assumptions!$B$23*12,Assumptions!$B$21),Assumptions!$B$21))) -> 608471.35 | L11: =IF(A11<Assumptions!$B$4,0,F11*(1+Assumptions!$B$16)/Assumptions!$B$24) -> 1233572
A12: 8 | B12: Operations | C12: =IF(A12=0,0,Assumptions!$B$17*12*(1+Assumptions!$B$16)^MAX(0,A12-Assumptions!$B$4)) -> 154749.18 | D12: =IF(A12=0,0,C12*IF(A12=1,Assumptions!$B$14,Assumptions!$B$13)) -> 143916.74 | E12: =D12*Assumptions!$B$15 -> 57566.694 | F12: =D12-E12 -> 86350.041 | G12: =IF(AND(A12>=Assumptions!$B$4,A12<=Assumptions!$B$5),-PMT(Assumptions!$B$22/12,Assumptions!$B$23*12,Assumptions!$B$21)*12,0) -> 0 | H12: =F12-G12 -> 86350.041 | I12: =IF(A12=Assumptions!$B$4,MAX(0,Assumptions!$B$21-Assumptions!$B$20),IF(A12=Assumptions!$B$5,MAX(0,L12*(1-Assumptions!$B$25)-K12),0)) -> 0 | J12: =H12+I12 -> 86350.041 | K12: =IF(A12<Assumptions!$B$4,0,IF(A12=Assumptions!$B$5,0,-FV(Assumptions!$B$22/12,(A12-Assumptions!$B$4)*12,PMT(Assumptions!$B$22/12,Assumptions!$B$23*12,Assumptions!$B$21),Assumptions!$B$21))) -> 598424.89 | L12: =IF(A12<Assumptions!$B$4,0,F12*(1+Assumptions!$B$16)/Assumptions!$B$24) -> 1270579.2
A13: 9 | B13: Operations | C13: =IF(A13=0,0,Assumptions!$B$17*12*(1+Assumptions!$B$16)^MAX(0,A13-Assumptions!$B$4)) -> 159391.65 | D13: =IF(A13=0,0,C13*IF(A13=1,Assumptions!$B$14,Assumptions!$B$13)) -> 148234.24 | E13: =D13*Assumptions!$B$15 -> 59293.695 | F13: =D13-E13 -> 88940.542 | G13: =IF(AND(A13>=Assumptions!$B$4,A13<=Assumptions!$B$5),-PMT(Assumptions!$B$22/12,Assumptions!$B$23*12,Assumptions!$B$21)*12,0) -> 0 | H13: =F13-G13 -> 88940.542 | I13: =IF(A13=Assumptions!$B$4,MAX(0,Assumptions!$B$21-Assumptions!$B$20),IF(A13=Assumptions!$B$5,MAX(0,L13*(1-Assumptions!$B$25)-K13),0)) -> 0 | J13: =H13+I13 -> 88940.542 | K13: =IF(A13<Assumptions!$B$4,0,IF(A13=Assumptions!$B$5,0,-FV(Assumptions!$B$22/12,(A13-Assumptions!$B$4)*12,PMT(Assumptions!$B$22/12,Assumptions!$B$23*12,Assumptions!$B$21),Assumptions!$B$21))) -> 587705.59 | L13: =IF(A13<Assumptions!$B$4,0,F13*(1+Assumptions!$B$16)/Assumptions!$B$24) -> 1308696.6
A14: 10 | B14: Exit | C14: =IF(A14=0,0,Assumptions!$B$17*12*(1+Assumptions!$B$16)^MAX(0,A14-Assumptions!$B$4)) -> 164173.4 | D14: =IF(A14=0,0,C14*IF(A14=1,Assumptions!$B$14,Assumptions!$B$13)) -> 152681.26 | E14: =D14*Assumptions!$B$15 -> 61072.506 | F14: =D14-E14 -> 91608.759 | G14: =IF(AND(A14>=Assumptions!$B$4,A14<=Assumptions!$B$5),-PMT(Assumptions!$B$22/12,Assumptions!$B$23*12,Assumptions!$B$21)*12,0) -> 0 | H14: =F14-G14 -> 91608.759 | I14: =IF(A14=Assumptions!$B$4,MAX(0,Assumptions!$B$21-Assumptions!$B$20),IF(A14=Assumptions!$B$5,MAX(0,L14*(1-Assumptions!$B$25)-K14),0)) -> 0 | J14: =H14+I14 -> 91608.759 | K14: =IF(A14<Assumptions!$B$4,0,IF(A14=Assumptions!$B$5,0,-FV(Assumptions!$B$22/12,(A14-Assumptions!$B$4)*12,PMT(Assumptions!$B$22/12,Assumptions!$B$23*12,Assumptions!$B$21),Assumptions!$B$21))) -> 576268.4 | L14: =IF(A14<Assumptions!$B$4,0,F14*(1+Assumptions!$B$16)/Assumptions!$B$24) -> 1347957.4

Sheet Waterfall
A1: Annual Waterfall
A3: Year | B3: Cash Available | C3: Class A Beg. Accrued Pref | D3: Class A Pref Accrued | E3: Class A Pref Paid | F3: Class A Beg. Capital | G3: Class A Capital Returned | H3: Class A End Accrued Pref | I3: Class A End Capital | J3: Cash After Class A | K3: Class B Beg. Capital | L3: Class B Capital Returned | M3: Class B End Capital | N3: Residual to Class B | O3: Residual to Sponsor | P3: Total Class A Dist. | Q3: Total Class B Dist. | R3: Total Sponsor Dist.
A4: 0 | B4: ='Annual Model'!J4 -> 0 | C4: =0 -> 0 | D4: =F4*Assumptions!$B$29 -> 24000 | E4: =MIN(B4,C4+D4) -> 0 | F4: =Assumptions!$B$28 -> 300000 | G4: =MIN(MAX(0,B4-E4),F4) -> 0 | H4: =C4+D4-E4 -> 24000 | I4: =F4-G4 -> 300000 | J4: =MAX(0,B4-E4-G4) -> 0 | K4: =Assumptions!$B$30 -> 1200000 | L4: =IF(Assumptions!$B$31=1,MIN(J4,K4),0) -> 0 | M4: =K4-L4 -> 1200000 | N4: =MAX(0,J4-L4)*Assumptions!$B$32 -> 0 | O4: =MAX(0,J4-L4)*Assumptions!$B$33 -> 0 | P4: =E4+G4 -> 0 | Q4: =L4+N4 -> 0 | R4: =O4 -> 0
A5: 1 | B5: ='Annual Model'!J5 -> 38880 | C5: =H4 -> 24000 | D5: =F5*Assumptions!$B$29 -> 24000 | E5: =MIN(B5,C5+D5) -> 38880 | F5: =I4 -> 300000 | G5: =MIN(MAX(0,B5-E5),F5) -> 0 | H5: =C5+D5-E5 -> 9120 | I5: =F5-G5 -> 300000 | J5: =MAX(0,B5-E5-G5) -> 0 | K5: =M4 -> 1200000 | L5: =IF(Assumptions!$B$31=1,MIN(J5,K5),0) -> 0 | M5: =K5-L5 -> 1200000 | N5: =MAX(0,J5-L5)*Assumptions!$B$32 -> 0 | O5: =MAX(0,J5-L5)*Assumptions!$B$33 -> 0 | P5: =E5+G5 -> 38880 | Q5: =L5+N5 -> 0 | R5: =O5 -> 0
A6: 2 | B6: ='Annual Model'!J6 -> 23015.494 | C6: =H5 -> 9120 | D6: =F6*Assumptions!$B$29 -> 24000 | E6: =MIN(B6,C6+D6) -> 23015.494 | F6: =I5 -> 300000 | G6: =MIN(MAX(0,B6-E6),F6) -> 0 | H6: =C6+D6-E6 -> 10104.506 | I6: =F6-G6 -> 300000 | J6: =MAX(0,B6-E6-G6) -> 0 | K6: =M5 -> 1200000 | L6: =IF(Assumptions!$B$31=1,MIN(J6,K6),0) -> 0 | M6: =K6-L6 -> 1200000 | N6: =MAX(0,J6-L6)*Assumptions!$B$32 -> 0 | O6: =MAX(0,J6-L6)*Assumptions!$B$33 -> 0 | P6: =E6+G6 -> 23015.494 | Q6: =L6+N6 -> 0 | R6: =O6 -> 0
A7: 3 | B7: ='Annual Model'!J7 -> 25184.998 | C7: =H6 -> 10104.506 | D7: =F7*Assumptions!$B$29 -> 24000 | E7: =MIN(B7,C7+D7) -> 25184.998 | F7: =I6 -> 300000 | G7: =MIN(MAX(0,B7-E7),F7) -> 0 | H7: =C7+D7-E7 -> 8919.5077 | I7: =F7-G7 -> 300000 | J7: =MAX(0,B7-E7-G7) -> 0 | K7: =M6 -> 1200000 | L7: =IF(Assumptions!$B$31=1,MIN(J7,K7),0) -> 0 | M7: =K7-L7 -> 1200000 | N7: =MAX(0,J7-L7)*Assumptions!$B$32 -> 0 | O7: =MAX(0,J7-L7)*Assumptions!$B$33 -> 0 | P7: =E7+G7 -> 25184.998 | Q7: =L7+N7 -> 0 | R7: =O7 -> 0
A8: 4 | B8: ='Annual Model'!J8 -> 1133734.9 | C8: =H7 -> 8919.5077 | D8: =F8*Assumptions!$B$29 -> 24000 | E8: =MIN(B8,C8+D8) -> 32919.508 | F8: =I7 -> 300000 | G8: =MIN(MAX(0,B8-E8),F8) -> 300000 | H8: =C8+D8-E8 -> 0 | I8: =F8-G8 -> 0 | J8: =MAX(0,B8-E8-G8) -> 800815.36 | K8: =M7 -> 1200000 | L8: =IF(Assumptions!$B$31=1,MIN(J8,K8),0) -> 800815.36 | M8: =K8-L8 -> 399184.64 | N8: =MAX(0,J8-L8)*Assumptions!$B$32 -> 0 | O8: =MAX(0,J8-L8)*Assumptions!$B$33 -> 0 | P8: =E8+G8 -> 332919.51 | Q8: =L8+N8 -> 800815.36 | R8: =O8 -> 0
A9: 5 | B9: ='Annual Model'!J9 -> 79022.52 | C9: =H8 -> 0 | D9: =F9*Assumptions!$B$29 -> 0 | E9: =MIN(B9,C9+D9) -> 0 | F9: =I8 -> 0 | G9: =MIN(MAX(0,B9-E9),F9) -> 0 | H9: =C9+D9-E9 -> 0 | I9: =F9-G9 -> 0 | J9: =MAX(0,B9-E9-G9) -> 79022.52 | K9: =M8 -> 399184.64 | L9: =IF(Assumptions!$B$31=1,MIN(J9,K9),0) -> 79022.52 | M9: =K9-L9 -> 320162.12 | N9: =MAX(0,J9-L9)*Assumptions!$B$32 -> 0 | O9: =MAX(0,J9-L9)*Assumptions!$B$33 -> 0 | P9: =E9+G9 -> 0 | Q9: =L9+N9 -> 79022.52 | R9: =O9 -> 0
A10: 6 | B10: ='Annual Model'!J10 -> 81393.196 | C10: =H9 -> 0 | D10: =F10*Assumptions!$B$29 -> 0 | E10: =MIN(B10,C10+D10) -> 0 | F10: =I9 -> 0 | G10: =MIN(MAX(0,B10-E10),F10) -> 0 | H10: =C10+D10-E10 -> 0 | I10: =F10-G10 -> 0 | J10: =MAX(0,B10-E10-G10) -> 81393.196 | K10: =M9 -> 320162.12 | L10: =IF(Assumptions!$B$31=1,MIN(J10,K10),0) -> 81393.196 | M10: =K10-L10 -> 238768.93 | N10: =MAX(0,J10-L10)*Assumptions!$B$32 -> 0 | O10: =MAX(0,J10-L10)*Assumptions!$B$33 -> 0 | P10: =E10+G10 -> 0 | Q10: =L10+N10 -> 81393.196 | R10: =O10 -> 0
A11: 7 | B11: ='Annual Model'!J11 -> 83834.991 | C11: =H10 -> 0 | D11: =F11*Assumptions!$B$29 -> 0 | E11: =MIN(B11,C11+D11) -> 0 | F11: =I10 -> 0 | G11: =MIN(MAX(0,B11-E11),F11) -> 0 | H11: =C11+D11-E11 -> 0 | I11: =F11-G11 -> 0 | J11: =MAX(0,B11-E11-G11) -> 83834.991 | K11: =M10 -> 238768.93 | L11: =IF(Assumptions!$B$31=1,MIN(J11,K11),0) -> 83834.991 | M11: =K11-L11 -> 154933.93 | N11: =MAX(0,J11-L11)*Assumptions!$B$32 -> 0 | O11: =MAX(0,J11-L11)*Assumptions!$B$33 -> 0 | P11: =E11+G11 -> 0 | Q11: =L11+N11 -> 83834.991 | R11: =O11 -> 0
A12: 8 | B12: ='Annual Model'!J12 -> 86350.041 | C12: =H11 -> 0 | D12: =F12*Assumptions!$B$29 -> 0 | E12: =MIN(B12,C12+D12) -> 0 | F12: =I11 -> 0 | G12: =MIN(MAX(0,B12-E12),F12) -> 0 | H12: =C12+D12-E12 -> 0 | I12: =F12-G12 -> 0 | J12: =MAX(0,B12-E12-G12) -> 86350.041 | K12: =M11 -> 154933.93 | L12: =IF(Assumptions!$B$31=1,MIN(J12,K12),0) -> 86350.041 | M12: =K12-L12 -> 68583.894 | N12: =MAX(0,J12-L12)*Assumptions!$B$32 -> 0 | O12: =MAX(0,J12-L12)*Assumptions!$B$33 -> 0 | P12: =E12+G12 -> 0 | Q12: =L12+N12 -> 86350.041 | R12: =O12 -> 0
A13: 9 | B13: ='Annual Model'!J13 -> 88940.542 | C13: =H12 -> 0 | D13: =F13*Assumptions!$B$29 -> 0 | E13: =MIN(B13,C13+D13) -> 0 | F13: =I12 -> 0 | G13: =MIN(MAX(0,B13-E13),F13) -> 0 | H13: =C13+D13-E13 -> 0 | I13: =F13-G13 -> 0 | J13: =MAX(0,B13-E13-G13) -> 88940.542 | K13: =M12 -> 68583.894 | L13: =IF(Assumptions!$B$31=1,MIN(J13,K13),0) -> 68583.894 | M13: =K13-L13 -> 0 | N13: =MAX(0,J13-L13)*Assumptions!$B$32 -> 8142.6595 | O13: =MAX(0,J13-L13)*Assumptions!$B$33 -> 12213.989 | P13: =E13+G13 -> 0 | Q13: =L13+N13 -> 76726.553 | R13: =O13 -> 12213.989
A14: 10 | B14: ='Annual Model'!J14 -> 91608.759 | C14: =H13 -> 0 | D14: =F14*Assumptions!$B$29 -> 0 | E14: =MIN(B14,C14+D14) -> 0 | F14: =I13 -> 0 | G14: =MIN(MAX(0,B14-E14),F14) -> 0 | H14: =C14+D14-E14 -> 0 | I14: =F14-G14 -> 0 | J14: =MAX(0,B14-E14-G14) -> 91608.759 | K14: =M13 -> 0 | L14: =IF(Assumptions!$B$31=1,MIN(J14,K14),0) -> 0 | M14: =K14-L14 -> 0 | N14: =MAX(0,J14-L14)*Assumptions!$B$32 -> 36643.503 | O14: =MAX(0,J14-L14)*Assumptions!$B$33 -> 54965.255 | P14: =E14+G14 -> 0 | Q14: =L14+N14 -> 36643.503 | R14: =O14 -> 54965.255

Sheet Returns
A1: Investor / Sponsor Return Summary
A3: Participant | B3: Capital / Basis | C3: Total Distributions | D3: Net Profit | E3: Equity Multiple | F3: ROI % | G3: IRR | H3: Year 0 | I3: Year 1 | J3: Year 2 | K3: Year 3 | L3: Year 4 | M3: Year 5 | N3: Year 6 | O3: Year 7 | P3: Year 8 | Q3: Year 9 | R3: Year 10
A4: Class A | B4: =Assumptions!$B$28 -> 300000 | C4: =SUM(Waterfall!P4:P14) -> 420000 | D4: =C4-B4 -> 120000 | E4: =C4/B4 -> 1.4 | F4: =D4/B4 -> 0.4 | G4: =IRR(H4:R4) -> 0.10071726 | H4: =-B4 -> -300000 | I4: =Waterfall!P5 -> 38880 | J4: =Waterfall!P6 -> 23015.494 | K4: =Waterfall!P7 -> 25184.998 | L4: =Waterfall!P8 -> 332919.51 | M4: =Waterfall!P9 -> 0 | N4: =Waterfall!P10 -> 0 | O4: =Waterfall!P11 -> 0 | P4: =Waterfall!P12 -> 0 | Q4: =Waterfall!P13 -> 0 | R4: =Waterfall!P14 -> 0
A5: Class B | B5: =Assumptions!$B$30 -> 1200000 | C5: =SUM(Waterfall!Q4:Q14) -> 1244786.2 | D5: =C5-B5 -> 44786.163 | E5: =IFERROR(C5/B5,0) -> 1.0373218 | F5: =IFERROR(D5/B5,0) -> 0.037321802 | G5: =IFERROR(IRR(H5:R5),0) -> 0.0071446495 | H5: =-B5 -> -1200000 | I5: =Waterfall!Q5 -> 0 | J5: =Waterfall!Q6 -> 0 | K5: =Waterfall!Q7 -> 0 | L5: =Waterfall!Q8 -> 800815.36 | M5: =Waterfall!Q9 -> 79022.52 | N5: =Waterfall!Q10 -> 81393.196 | O5: =Waterfall!Q11 -> 83834.991 | P5: =Waterfall!Q12 -> 86350.041 | Q5: =Waterfall!Q13 -> 76726.553 | R5: =Waterfall!Q14 -> 36643.503
A6: Sponsor | B6: =Assumptions!$B$34 -> 150000 | C6: =SUM(Waterfall!R4:R14) -> 67179.244 | D6: =C6-B6 -> -82820.756 | E6: =IFERROR(C6/B6,0) -> 0.44786163 | F6: =IFERROR(D6/B6,0) -> -0.55213837 | G6: =IFERROR(IRR(H6:R6),0) -> -0.078511343 | H6: =-B6 -> -150000 | I6: =Waterfall!R5 -> 0 | J6: =Waterfall!R6 -> 0 | K6: =Waterfall!R7 -> 0 | L6: =Waterfall!R8 -> 0 | M6: =Waterfall!R9 -> 0 | N6: =Waterfall!R10 -> 0 | O6: =Waterfall!R11 -> 0 | P6: =Waterfall!R12 -> 0 | Q6: =Waterfall!R13 -> 12213.989 | R6: =Waterfall!R14 -> 54965.255
A9: Important | B9: Class A preferred return is modeled as cumulative simple annual accrual on unrecovered Class A capital. Class B capital is returned before residual splits when the Assumptions toggle is set to 1.

Sheet Notes
A1: Model Notes
A3: Purpose | B3: Calculates project-level cash available, then allocates distributions to Class A, Class B, and Sponsor through a simplified waterfall.
A4: Key editable cells | B4: Use the Assumptions tab, column B.
A5: Class A | B5: Modeled with 8% cumulative annual preferred return by default, then return of capital, then no residual share unless you revise the waterfall.
A6: Class B | B6: Modeled as subordinate capital that can receive capital back before residual distributions, plus residual participation.
A7: Sponsor | B7: Modeled using sponsor basis / deemed investment as the return denominator and sponsor residual share as the distribution source.
A8: Caution | B8: This workbook is for planning and discussion only. It is not legal, tax, securities, appraisal, or investment advice. Have counsel and CPA review before investor use.

Sheet Cost Analysis
A1: 3325 Banks Rd - Design, Development & Build Cost Analysis
A2: Status | B2: Planning estimate added 2026-05-11
A3: Source Markdown | B3: 04_Design_Development_and_Build_Cost_Analysis.md
A5: Workbook-Backed Capital Assumptions | B5: Amount | C5: Notes
A6: Project debt payoff at refinance | B6: =Assumptions!$B$20 -> 744863.04 | C6: Existing assumption
A7: Permanent loan amount | B7: =Assumptions!$B$21 -> 650000 | C7: Existing assumption
A8: Class A capital | B8: =Assumptions!$B$28 -> 300000 | C8: Existing assumption
A9: Class B capital | B9: =Assumptions!$B$30 -> 1200000 | C9: Existing assumption
A10: Sponsor basis / deemed investment | B10: =Assumptions!$B$34 -> 150000 | C10: Existing assumption
A11: Total Class A + Class B capitalization | B11: =B8+B9 -> 1500000 | C11: Completion capital
A13: Sponsor-Controlled Working Case | B13: Low | C13: High
A14: Risk-adjusted sponsor-controlled total package | B14: 750000 | C14: 1500000
A15: Outside-market benchmark total | B15: 1880000 | C15: 4160000
A16: Outside-market benchmark note | B16: Not controlling case | C16: Stress benchmark
A17: Selected risk-adjusted sponsor-controlled total project cost | B17: =B14 -> 750000 | C17: =C14 -> 1500000
A19: Funding Gap Analysis | B19: Low | C19: High
A20: Estimated total project cost | B20: =B17 -> 750000 | C20: =C17 -> 1500000
A21: Class A + Class B capitalization | B21: =B11 -> 1500000 | C21: =B11 -> 1500000
A22: Potential unfunded development gap | B22: =MAX(0,B20-B21) -> 0 | C22: =MAX(0,C20-C21) -> 0
A24: Design & Entitlement Detail | B24: Low | C24: High
A25: Architecture and building design | B25: 35000 | C25: 90000
A26: Civil engineering and site planning | B26: 20000 | C26: 60000
A27: Septic, soil, and wastewater engineering | B27: 20000 | C27: 90000
A28: Survey, testing, environmental, and due diligence | B28: 10000 | C28: 30000
A29: Permitting, review, and municipal/county coordination | B29: 15000 | C29: 50000
A30: Legal, accounting, and trust structuring | B30: 15000 | C30: 40000
A31: Design/entitlement contingency | B31: 15000 | C31: 45000
A32: Design & entitlement total | B32: =SUM(B25:B31) -> 130000 | C32: =SUM(C25:C31) -> 405000
A34: Development & Pre-Construction Detail | B34: Low | C34: High
A35: Development management / sponsor fee | B35: 50000 | C35: 150000
A36: Financing, lender, appraisal, and closing costs | B36: 40000 | C36: 120000
A37: Insurance, taxes, utilities, and carrying costs | B37: 25000 | C37: 75000
A38: Accounting, administration, and reporting | B38: 10000 | C38: 30000
A39: Leasing, operations setup, and launch costs | B39: 20000 | C39: 60000
A40: Development contingency / liquidity reserve | B40: 40000 | C40: 125000
A41: Development & pre-construction total | B41: =SUM(B35:B40) -> 185000 | C41: =SUM(C35:C40) -> 560000
A43: Build & Delivery Detail | B43: Low | C43: High
A44: Building construction, 5,000-6,000 SF | B44: 1125000 | C44: 1950000
A45: Sitework, grading, access, parking, and drainage | B45: 125000 | C45: 350000
A46: Private utilities and well infrastructure | B46: 35000 | C46: 125000
...
