Workbook
Name baseCost: #REF!
Name BaseFlagOf: _xlfn.LAMBDA(_xlpm.i,_xlpm.baseIdxTxt,_xlpm.baseCost, --ISNUMBER(SEARCH("BASE PARENT", UPPER(_xlfn.XLOOKUP(TEXT(_xlpm.i,"0"), _xlpm.baseIdxTxt, _xlpm.baseCost, "")))) )
Name baseIdxTxt: TEXT(#REF!,"0")
Name cfdContractDate: [1]Amortization!$J$13
Name cfdContractMonths: [1]Amortization!$P$14
Name cfdEndDate: [1]Amortization!$S$14
Name cfdFirstRateMonths: [1]Amortization!$P$13
Name cfdRate1: [1]Amortization!$O$8
Name cfdRate1Payment: [1]Amortization!$V$8
Name cfdRate2: [1]Amortization!$O$11
Name cfdRate2Payment: [1]Amortization!$V$11
Name cfdRateChangeDate: [1]Amortization!$S$13
Name DepTitlesUsed: _xlfn.ANCHORARRAY(#REF!)
Name downPaymentRefinancedFirstMortgage: [1]Amortization!$AH$5
Name editsIdxTxt: TEXT(#REF!,"0")
Name editsParentKeyTxt: TEXT(#REF!,"0")
Name Milestone_Marker: '[1]Gnatt Chart'!$G$4
Name Milestone_Marker: 'Gnatt Chart'!$G$4
Name Project_Start: '[1]Gnatt Chart'!$F$2
Name Project_Start: 'Gnatt Chart'!$F$2
Name Scrolling_Increment: '[1]Gnatt Chart'!$AB$24
Name Scrolling_Increment: 'Gnatt Chart'!$AB$26
Name subjectInterestRate: [1]Amortization!$D$4
Name subjectKnownBalance: [1]Amortization!$D$3
Name subjectKnownBalanceDate: [1]Amortization!$D$7
Name subjectMortgageEndDate: [1]Amortization!$D$8
Name subjectPayment: [1]Amortization!$D$6
Name subjectRemainingMonths: [1]Amortization!$E$5
Name Today: TODAY()
Name tradeMonthlyNetSpread: 'Trade Properties'!$T$13
Name tradeNetCreditIncluded: 'Trade Properties'!$T$10
Name tradePropertyConditionsForDocs: 'Trade Properties'!$T$21
Name tradePropertyListForDocs: 'Trade Properties'!$T$20

Sheet Profit
A1: Flip, Hold or Wholetale: | B1: hold | E1: Buy | F1: Your Home LLC
B2: 1426 Pleasant Garden Ln, Raleigh, NC 27604 | H2: Monthly Cash Flow | J2: Hearing Date: | N2: Use Template Estimate | O2: no
A3: Income | D3: Immediate | F3: Upon Sale
A4: CMA: | B4: 341700 | J4: Finalized: | K4: yes
A5: % Above/Below Market Sale: | B5: -0.15 | C5: 0.1 | N5: Zillow: | O5: 45194 | P5: 344600
A6: Sale Price: | B6: =+B4 + IF(B1="Hold",B4*C5,0) + IF(B1="wholetale",B4*B5,0) -> 375870 | G6: =IF($B$1="hold",$B$6,$B$4) -> 375870 | J6: Anuual Growth: | K6: 0.03 | O6: 45217 | P6: 342200
A7: NonRefundable Deposit: | D7: =+B7 -> 0 | F7: =-B7 -> 0 | G7: =+IF($B$1="hold",$K$6,0)*$C$47/12*B4 -> 41004 | H7: =+IF($B$1="hold","<-- Apprication -----------","") -> <-- Apprication ----------- | O7: 45363 | P7: 336800
A8: Rent: | B8: 2225 | I8: =IF(B1="Hold",+B8,"") -> 2225 | J8: Sq Footage | K8: 1898 | O8: 45691 | P8: 341700
C9: Net Income: | D9: Net Income: | E9: =SUM(D4:D8) -> 0 | F9: =+SUM(F4:G8) -> 416874 | H9: =SUM(H4:I8) -> 2225 | O9: 45792 | P9: 343400
A11: Expenses
A12: Reinstatment Cost 1st: | B12: 15392.15 | D12: =-B12 -> -15392.15 | H12: <-- Approx Pay-Down | J12: If the Subject To Value is finalized, zero-out the Pay-Down savings
A13: Subject To 1st:Truist | B13: 0.03375 | C13: 131630 | F13: =-C13 -> -131630
A14: Reinstatment Cost 2st: | F14: =-+(120-C46)*(C14/120) -> 0 | H14: =-(C14*B14/12) -> 0 | R14: loan Balance | S14: Rate | T14: Annual Payment
A15: Subject To 2st:Notes | B15: 0.1 | F15: =-C15 -> 0 | H15: =-C15/120-(C15*B15/12) -> 0 | Q15: liens | R15: 31154 | S15: 0
A16: Liens - IRS & HOA | C16: =5946+7709+17499 -> 31154 | F16: =-C16 -> -31154 | Q16: Private money | R16: 119000 | S16: 0.1 | T16: =+R16*S16 -> 11900
A17: Partners Share % | B17: 0 | Q17: Wells Fargo | R17: 131630 | S17: 0.03375 | T17: =+R17*S17 -> 4442.5125
A18: or Seller Payout: | B18: 20000 | D18: =-B18 -> -20000 | R18: Total Debt | S18: Effect Rate | T18: Total Payments
A19: HOA Fees(Catch Up) | C19: 0 | D19: =-B19 -> 0 | J19: Yellow cells can be edited | R19: =SUM(R15:R17) -> 281784 | S19: =+T19/R19 -> 0.057996595 | T19: =SUM(T16:T17) -> 16342.513
A20: Months Carried | B20: =+F69/30 -> 33.333333
A21: Mortgage Payment: | B21: =+Carrying!E$47/$B$20 -> 1077.4881 | H21: =IF($B$1="Hold",-B21,"") -> -1077.4881 | J21: Do not edit Green cells. They are highlighted only to show profit
A22: Private Money | B22: =+Carrying!H$47/$B$20 -> 888 | H22: =IF($B$1="Hold",-B22,"") -> -888
A23: Property Insurance | B23: =+Carrying!K$47/$B$20 -> 0 | H23: =IF($B$1="Hold",-B23,"") -> 0
A24: Property Tax: | B24: =+Carrying!W$47/$B$20 -> 41.2125 | H24: =IF($B$1="Hold",-B24,"") -> -41.2125
A35: HOA Fees (monthly) | B35: =+Carrying!T$47/$B$20 -> 2.6316 | H35: =IF($B$1="Hold",-B35,"") -> -2.6316
A36: Electric | B36: =+Carrying!B$47/$B$20 -> 10.7658 | H36: =IF($B$1="Hold",-B36,"") -> -10.7658
A37: Gas | B37: =+Carrying!Q$47/$B$20 -> 12.4227 | H37: =IF($B$1="Hold",-B37,"") -> -12.4227
A38: water | B38: =+Carrying!N$47/$B$20 -> 99.5298 | H38: =IF($B$1="Hold",-B38,"") -> -99.5298
A39: Carrying Cost | B39: =SUM(B21:B38) -> 2132.0505 | D39: =-IF(B1="flip",B39*B20,0) -> 0
A40: Private Lender Rate: | B40: 0.1 | C40: yes
A41: Duke Electric | B41: =+Carrying!B47/Profit!$B$38 -> 3.6055533 | E41: =36000+75000 -> 111000 | F41: =IF(C40="No","",-E41) -> -111000 | J41: Carrying Cost | K41: =+B39/B20 -> 63.961515 | Q41: =+E41*0.1/12 -> 925
A42: Mortgage Payment | B42: =+Carrying!E47/Profit!$B$38 -> 360.85946 | D42: =-B42 -> -360.85946
A43: Private Money | B43: =+Carrying!H47/Profit!$B$38 -> 297.39837 | D43: =-B43 -> -297.39837
A44: Casa Lending | B44: =+Carrying!K47/Profit!$B$38 -> 0 | C44: =+B44*399 -> 0 | F44: =-C44 -> 0 | J44: Total Debt: | K44: =+SUM(C13:C17)+E41 -> 273784
A45: Insurance Payments | B45: =+Carrying!N47/Profit!$B$38 -> 33.333333 | C45: 0.026 | F45: =-B45*C45*$F$9 -> -361290.8
A46: Water | B46: =+Carrying!Q47/Profit!$B$38 -> 4.1604625 | C46: 0.024 | F46: =-B46*C46*$F$9 -> -41625.327
A47: Natural Gas | B47: =+Carrying!T47/Profit!$B$38 -> 0.88134408 | C47: 48 | J47: Purchase Cost | K47: =+SUM(C12:C16)+B18 -> 182784
A48: HOA | B48: =+Carrying!W47/Profit!$B$38 -> 13.802399 | F48: =-C48 -> 0
A49: Property Taxes | B49: =+Carrying!Z47/Profit!$B$38 -> 23.455588 | D49: =-B49 -> -23.455588 | J49: Out of Pocket | K49: =-E51 -> 36073.863
A50: Excavator Rental | B50: =+Carrying!AC47/Profit!$B$38 -> 0 | F50: =-B50 -> 0
A51: Lawn | B51: =+Carrying!AF47/Profit!$B$38 -> 0 | C51: Net Expenses: | E51: =+SUM(D12:D50) -> -36073.863 | F51: =+SUM(F12:F50) -> -676700.13 | H51: =+SUM(H9:I50) -> 92.9495 | J51: PL Balance +Interest
...

Sheet Trade Properties
A2: Property | B2: Home Type | C2: Est. Property Value | D2: Lot Rent / Mo | E2: Tenant Payment / Mo | F2: Property Tax / Mo | G2: Insurance / Mo | H2: Monthly Net Spread | I2: Annual Net Spread | J2: Expense % of Payment | K2: Net Spread Margin | L2: Net Yield on Value | M2: Max Value @ 10% | N2: Max Value @ 12% | O2: Max Value @ 15% | P2: Notes | R2: Summary / Document Outputs
H3: =IF(OR(D3="",E3=""),"",E3-SUM(D3,F3:G3)) | I3: =IF(H3="","",H3*12) | J3: =IFERROR(SUM(D3,F3:G3)/E3,"") | K3: =IFERROR(H3/E3,"") | L3: =IFERROR(I3/C3,"") | M3: =IF(I3="","",I3/10%) | N3: =IF(I3="","",I3/12%) | O3: =IF(I3="","",I3/15%) | R3: Total Trade Property Value Proposed | S3: =SUM(I14:I16) -> 0
H4: =IF(OR(D4="",E4=""),"",E4-SUM(D4,F4:G4)) | I4: =IF(H4="","",H4*12) | J4: =IFERROR(SUM(D4,F4:G4)/E4,"") | K4: =IFERROR(H4/E4,"") | L4: =IFERROR(I4/C4,"") | M4: =IF(I4="","",I4/10%) | N4: =IF(I4="","",I4/12%) | O4: =IF(I4="","",I4/15%) | R4: Total Liens or Deductions | S4: =SUM(J14:J16) -> 0
H5: =IF(OR(D5="",E5=""),"",E5-SUM(D5,F5:G5)) | I5: =IF(H5="","",H5*12) | J5: =IFERROR(SUM(D5,F5:G5)/E5,"") | K5: =IFERROR(H5/E5,"") | L5: =IFERROR(I5/C5,"") | M5: =IF(I5="","",I5/10%) | N5: =IF(I5="","",I5/12%) | O5: =IF(I5="","",I5/15%) | R5: Total Net Trade Credit Included | S5: =K17 -> 0
A6: Total | C6: =SUM(C3:C5) -> 0 | D6: =SUM(D3:D5) -> 0 | E6: =SUM(E3:E5) -> 0 | F6: =SUM(F3:F5) -> 0 | G6: =SUM(G3:G5) -> 0 | H6: =SUM(H3:H5) -> 0 | I6: =SUM(I3:I5) -> 0 | J6: =IFERROR(SUM(D6,F6:G6)/E6,"") | K6: =IFERROR(H6/E6,"") | L6: =IFERROR(I6/C6,"") | M6: =IF(I6="","",I6/10%) -> 0 | N6: =IF(I6="","",I6/12%) -> 0 | O6: =IF(I6="","",I6/15%) -> 0 | R6: Total Tenant Rent | S6: =D17 -> 0
R7: Total Monthly Expenses | S7: =C17 -> 0
A8: Trade Properties - Manufactured Home Credit Analysis | R8: Total Monthly Net Spread: | S8: =E17 -> 0
A9: Use this tab for valuation and support detail only. Contract generators should read only the final document fields exposed on Replacement Docs. Proposed values are analysis inputs until titles/bills of sale, lien releases, possession/keys, tenant/rent information, and park/lot approvals are delivered and accepted. | R9: Total Annual Net Spread: | S9: =F17 -> 0
I11: 0.1 | J11: 2 | R11: Implied Value at 10% Yield | S11: =S9/10% -> 0
C12: Expected monthly net spread from future Contract for Deed/resale payments after lot rent, property tax, and insurance | R12: Implied Value at 12% Yield | S12: =S9/12% -> 0
A13: Property Address | B13: Home Type | C13: Monthly Expenses | D13: Tenant Rent | E13: Monthly Net Spread | F13: Annual Net Spread | G13: Cap Based Value | H13: CMA Based Value | I13: Proposed Value / Agreed Credit | J13: Liens or Deductions | K13: Net Trade Credit | L13: Include in Contract? | M13: Title/Bill-of-Sale Status | N13: Park/Lot Approval Status | O13: Tenant/Lease Verification Status | R13: Implied Value at 15% Yield | S13: =S9/15% -> 0
A14: =+A3 -> 0 | B14: =+B3 -> 0 | C14: =SUM(D3,F3:G3) -> 0 | D14: =E3 -> 0 | E14: =D14-C14 -> 0 | F14: =E14*12 -> 0 | G14: =+O3 | H14: =C3 -> 0 | I14: =IF($J$11=2,H14,G14)*(1-$I$11) -> 0 | J14: 0 | K14: =IF($L14,MAX(0,I14-J14),0) -> 0 | L14: FALSE
A15: =+A4 -> 0 | B15: =+B4 -> 0 | C15: =SUM(D4,F4:G4) -> 0 | D15: =E4 -> 0 | E15: =D15-C15 -> 0 | F15: =E15*12 -> 0 | G15: =+O4 | H15: =C4 -> 0 | I15: =IF($J$11=2,H15,G15)*(1-$I$11) -> 0 | J15: 0 | K15: =IF($L15,MAX(0,I15-J15),0) -> 0 | L15: FALSE | R15: Trade Property List for Docs | S15: =_xlfn.TEXTJOIN("; ",TRUE,IF($L$14,$A$14&" - "&$B$14,""),IF($L$15,$A$15&" - "&$B$15,""),IF($L$16,$A$16&" - "&$B$16,""))
A16: =+A5 -> 0 | B16: =+B5 -> 0 | C16: =SUM(D5,F5:G5) -> 0 | D16: =E5 -> 0 | E16: =D16-C16 -> 0 | F16: =E16*12 -> 0 | G16: =+O5 | H16: =C5 -> 0 | I16: =IF($J$11=2,H16,G16)*(1-$I$11) -> 0 | J16: 0 | K16: =IF($L16,MAX(0,I16-J16),0) -> 0 | L16: FALSE | R16: Trade Property Conditions for Docs | S16: Trade credit is not final until titles/bills of sale, lien releases or payoff documentation, possession/keys, tenant and rent information, and park/lot approvals are delivered and accepted.
A17: Totals / Included Credit | C17: =SUMPRODUCT(--($L$14:$L$16=TRUE),C14:C16) -> 0 | D17: =SUMPRODUCT(--($L$14:$L$16=TRUE),D14:D16) -> 0 | E17: =SUMPRODUCT(--($L$14:$L$16=TRUE),E14:E16) -> 0 | F17: =SUMPRODUCT(--($L$14:$L$16=TRUE),F14:F16) -> 0 | G17: =SUMPRODUCT(--($L$14:$L$16=TRUE),G14:G16) -> 0 | H17: =SUMPRODUCT(--($L$14:$L$16=TRUE),H14:H16) -> 0 | I17: =SUMPRODUCT(--($L$14:$L$16=TRUE),I14:I16) -> 0 | J17: =SUM(J14:J16) -> 0 | K17: =SUM(K14:K16) -> 0
R18: Addendum Requirement | S18: A trade-property addendum should control title, possession, park approval, liens, tenant rents, verification, condition, and remedies if conditions are not met.
T20: =_xlfn.TEXTJOIN("; ",TRUE,IF(AND($L$14,$A$14<>""),$A$14&" - "&$B$14,""),IF(AND($L$15,$A$15<>""),$A$15&" - "&$B$15,""),IF(AND($L$16,$A$16<>""),$A$16&" - "&$B$16,""))

Sheet MOG
C1: Multiple Offer Generator | I1: ="Hi "&B3 & IF(B4 ="",""," and ") &B4&", Thank you for the opportunity to make an offer on your property at "&Profit!B2&". I have several options I would like for you to consider. I also want to give you several very good reasons for you to work with us here at Buy Your Home LLC. "&REPT(" ",6)&"1. If you sell your home to us, you will incur no expense from the transaction. We will pay all: "&REPT(" ",20)&"Closing Cost "&REPT(" ",20)&"Attorney's Fees "&REPT(" ",20)&"Realtor Commissions "&REPT(" ",6) &" 2. We can close fast. It will be a matter of days, probably less than two weeks, when we can "&REPT(" ",11) &"close at our attorney's office and get you your cash. "&REPT(" ",6) &"3. We cover the cost, time, and effort of paying any money due to any lender or HOA "&REPT(" ",11) &"involved." -> Hi Nikki, Thank you for the opportunity to make an offer on your property at 1426 Pleasant Garden Ln, Raleigh, NC 27604. I have several options I would like for you to consider. I also want to give you several very good reasons for you to work with us here at Buy Your Home LLC. 1. If you sell your home to us, you will incur no expense from the transaction. We will pay all: Closing Cost Attorney's Fees Realtor Commissions 2. We can close fast. It will be a matter of days, probably less than two weeks, when we can close at our attorney's office and get you your cash. 3. We cover the cost, time, and effort of paying any money due to any lender or HOA involved. | J1: Buyers Copy | K1: =+I1&IF(N14="X",O14,"")&" "& IF(H15="X",I15,"") &" "& IF(H16="X",I16,"") &" "& IF(H20="X",I20,"") &" "& IF(H26="X",I26,"") &" "& IF(H33="X",I33,"") & " "& IF(H42="X",I42,"") & " "& IF(H52="X",I52,"") & " "& IF(H61="X",I61,"") & " "& IF(H74="X",I74,"") & " "& IF(H81="X",I81,"") & " "& IF(H82="X",I82,"") & " "& "" -> Hi Nikki, Thank you for the opportunity to make an offer on your property at 1426 Pleasant Garden Ln, Raleigh, NC 27604. I have several options I would like for you to consider. I also want to give you several very good reasons for you to work with us here at Buy Your Home LLC. 1. If you sell your home to us, you will incur no expense from the transaction. We will pay all: Closing Cost Attorney's Fees Realtor Commissions 2. We can close fast. It will be a matter of days, probably less than two weeks, when we can close at our attorney's office and get you your cash. 3. We cover the cost, time, and effort of paying any money due to any lender or HOA involved. Here are some purchase options for your consideration. They are presented in summary form and I am sure you will have some questions that I will be happy to take time needed to answer. Each option below will have more value than the one above it. Option 1: Cash plus Assumption of Mortgage This is a cash payment, at closing. We will take responsibility for the existing mortgage, HOA fees, and any liens that may be discovered until we are able to resell the property. This offer is: Cash: $20,000.00 Total Value: $20,000.00 Option 2: Cash plus Promissory Note The explanation for the cash component is the same as for option 1. However, 20.% of the value of the offer will be cash and 80.% will be in the form of a promissory note, complete with a Deed of Trust. The note will have a 24-month term that will pay simple interest at the rate of 4% per year. Cash: $4,000.00 12 Month Note: $36,000.00 Interest Earned: $2,880.00 $120.00 per month Total Value: $42,880.00 Option 3: Cash plus Beneficial Interest in Trust The explanation for the cash component is the same as for option 2. Instead of a note as in Option 2, you will share in the profit earned when the property is resold. The property will be placed into a trust that you will share a beneficial interest in. The advantage here is you will benefit from the appreciated value of the property, over time. You will receive quarterly reports on the financial status of the property. Cash: $10,000.00 Interest in Trust: 70.% Expected Sellers Profit: -$72,469.20 * Expected 3% appreciation per year Expected Value: -$62,469.20 ** After 24 months. Nikki, this offer is contingent upon a normal due diligence period. The values of each option are predicated on some assumptions that may need to be altered upon further discovery. The more we can learn from you, in advance, the more reliable these options may be considered. When you decide which offer you prefer, I will email you a contract along with an earnest money payment. We are ready to be of service in any way we can. This offer is based on Zillow's Zestimate of $341,700.00. We will clean and prepare the property for a quick resale. There is also an assumption that the property will need no rehab. If that turns out to not be true, an allowance will need to be made. In any case, that will be decided in the due diligence period of the contract. Sincerely, Wes Browning (919) 899-2104
A3: Seller 1: | B3: Nikki | C3: Kulas | J3: no
A4: Seller 2:
A5: email:
A6: Phone #:
A9: Offer 1 | B9: Traditional, All Cash
B10: This is an all cash payment, at closing with no other allowances considered. Seller pays all Mortgages, liens, HOA expenses out of closings proceedings.
F12: Seller's Equity
B13: Sales Price | C13: ARV | D13: Debt | G13: BYH's Profit
B14: =+D14+F14 -> 180784 | C14: =+Profit!B4 -> 341700 | D14: =+Profit!K47-Profit!B18 -> 162784 | F14: =+B24-(B24*F16) -> 18000 | G14: =+C14-D14-F14+Profit!E51+Profit!B18 -> 144842.14
D15: BYH Out of Pocket: | E15: =+Profit!$K$49 -> 36073.863
D16: BYH Profit/Out of Pocket: | E16: =+G14/E15 -> 4.0151545 | F16: 0.1 | H16: X | I16: ="Here are some purchase options for your consideration. They are presented in summary form and I am sure you will have some questions that I will be happy to take time needed to answer. Each option below will have more value than the one above it." -> Here are some purchase options for your consideration. They are presented in summary form and I am sure you will have some questions that I will be happy to take time needed to answer. Each option below will have more value than the one above it.
D17: Buy Your Home's % of Profit: | E17: =+G14/(F14+G14) -> 0.8894635 | F17: less than Opt 2
A19: Offer 2 | B19: Cash plus Assumption of Mortgage | D19: *This is the default values from the Profit Sheet. | H19: =IF(H20="X",1,0) -> 0
B20: Cash payment in conjunction with taking the existing mortgage subject to: | I20: ="Option "&H19&": "&""&B9&" "&REPT(" ",6)&"This is a, traditional, all cash purchase, at closing with no other allowances considered. Seller "&REPT(" ",6)&"pays all mortgages, liens, HOA expenses, etc., out of closings disbursements. This option has " & REPT(" ",6) & "the smallest value for the seller. Our cash offer is: "&REPT(" ",43) &"Cash:"&REPT(" ",21)&+TEXT(B14,"$#,##0.00") & IF(J3="yes",REPT(" ",10) & "Profit = "& TEXT(G14,"$#,##0.00"),"" )& " "&REPT(" ",32) & "Total Value:"&REPT(" ",21)&TEXT(F14,"$#,##0.00") -> Option 0: Traditional, All Cash This is a, traditional, all cash purchase, at closing with no other allowances considered. Seller pays all mortgages, liens, HOA expenses, etc., out of closings disbursements. This option has the smallest value for the seller. Our cash offer is: Cash: $180,784.00 Total Value: $18,000.00
B21: After reinstating existing loans and HOA fees
F22: Seller's Total Value
B23: Cash | G23: BYH's Profit
B24: =+Profit!B18 -> 20000 | C24: <- The default value form profit sheet | F24: =+B24 -> 20000 | G24: =+Profit!K57+Profit!B18-B24 -> -154531.42
D25: BYH Out of Pocket: | E25: =+Profit!$K$49 -> 36073.863 | H25: =IF(H26="X",1+H19,H19) -> 1
D26: BYH Profit/Out of Pocket: | E26: =+G24/E25 -> -4.2837503 | H26: x | I26: ="Option " & H25 & ": "&""&B19&" "&REPT(" ",6) & "This is a cash payment, at closing. We will take responsibility for the existing mortgage, HOA "&REPT(" ",6) & "fees, and any liens that may be discovered until we are able to resell the property. This offer is: "&REPT(" ",43)&"Cash:"&REPT(" ",22) & TEXT(F24,"$#,##0.00") & IF(J3="yes",REPT(" ",10) & "Profit = "& TEXT(G24,"$#,##0.00"),"" ) & " "&REPT(" ",32)&"Total Value:"&REPT(" ",22) & TEXT(F24,"$#,##0.00") -> Option 1: Cash plus Assumption of Mortgage This is a cash payment, at closing. We will take responsibility for the existing mortgage, HOA fees, and any liens that may be discovered until we are able to resell the property. This offer is: Cash: $20,000.00 Total Value: $20,000.00
D27: Buy Your Home's % of Profit: | E27: =+G24/(F24+G24) -> 1.1486642
A30: Offer 3 | B30: Cash plus Promissory Note | D30: - this is the one to stear seller to:
B31: Cash payment in conjunction with taking the existing mortgage subject to: | I31: ="This is a cash payment, at closing, in conjunction with reinstating the existing mortgage taking responsibility for those payments, HOA fees and other liens that may be discovered. Our cash offer is:" -> This is a cash payment, at closing, in conjunction with reinstating the existing mortgage taking responsibility for those payments, HOA fees and other liens that may be discovered. Our cash offer is:
B32: After reinstating existing loans and HOA fees | H32: =IF(H33="X",H25+1,H25) -> 2
H33: x | I33: ="Option " & H32 & ": " &""&B30&" "&REPT(" ",6)&"The explanation for the cash component is the same as for option "& H25 & ". However, "&TEXT(B38,"##.#%") &" of the " & REPT(" ",6) & "value of the offer will be cash and "& TEXT(C38,"##.#%") &" will be in the form of a promissory note, complete " & REPT(" ",6) & "with a Deed of Trust. The note will have a " & D35 & "-month term that will pay simple interest at " & REPT(" ",6) & "the rate of "&E37*100&"% per year. "& REPT(" ",43) & "Cash:" & REPT(" ",23) & TEXT(B37,"$#,##0.00") & IF(J3="yes",REPT(" ",10) & "Profit = "& TEXT(G37,"$#,##0.00"),"" ) &" "& REPT(" ",24) & "12 Month Note:" & REPT(" ",24) & TEXT(C37,"$#,##0.00")&" "& REPT(" ",25) & "Interest Earned:" & REPT(" ",25) & TEXT(D37,"$#,##0.00") &REPT(" ",12)&+TEXT(D37/D35,"$#,##0.00") & " per month" & " "& REPT(" ",32) & "Total Value:" & REPT(" ",20) & TEXT(F37,"$#,##0.00") -> Option 2: Cash plus Promissory Note The explanation for the cash component is the same as for option 1. However, 20.% of the value of the offer will be cash and 80.% will be in the form of a promissory note, complete with a Deed of Trust. The note will have a 24-month term that will pay simple interest at the rate of 4% per year. Cash: $4,000.00 12 Month Note: $36,000.00 Interest Earned: $2,880.00 $120.00 per month Total Value: $42,880.00
C34: Note is a simple interest note for: | D34: Months | F34: (Based on Current Valuation)
B35: Value added to Note: | C35: 20000 | D35: 24 | F35: Seller's Total Value
B36: Cash | C36: Note | D36: Interest Earned | E36: Interest Rate | G36: BYH's Profit
B37: =+(Profit!$B$18)*B38 -> 4000 | C37: =+(Profit!$B$18)-B37+C35 -> 36000 | D37: =+C37*D35/12*E37 -> 2880 | E37: 0.04 | F37: =+SUM(B37:D37) -> 42880 | G37: =+Profit!$K$57-D37-C35 -> -177411.42
B38: 0.2 | C38: =1-B38 -> 0.8
D39: BYH Out of Pocket: | E39: =+Profit!$K$49-C37+C35 -> 20073.863
D40: BYH Profit/Out of Pocket: | E40: =+G37/E39 -> -8.8379312
D41: Buy Your Home's % of Profit: | E41: =+G37/(F37+G37) -> 1.3187359 | H41: =IF(H42="X",H32+1,H32) -> 3
A42: Offer 4 | B42: Cash plus Beneficial Interest in Trust | H42: x | I42: ="Option " & H41 & ": " & B42&" "&REPT(" ",6)&"The explanation for the cash component is the same as for option "& H32 & ". Instead of a note as in " & REPT(" ",6) & "Option "& H32 & ", you will share in the profit earned when the property is resold." &" The property will " & REPT(" ",6) & "be placed into a trust that you will share a beneficial interest in. The advantage here is you will " & REPT(" ",6) & "benefit from the appreciated value of the property, over time." &" You will receive quarterly " & REPT(" ",6) & "reports on the financial status of the property. "& REPT(" ",43) & "Cash:" & REPT(" ",23) & TEXT(B50,"$#,##0.00") & IF(J3="yes",REPT(" ",10) & "Profit = "& TEXT(G50,"$#,##0.00"),"" ) &" "& REPT(" ",24) & "Interest in Trust:" & REPT(" ",33) & TEXT(D50,"#.#%")&" "& REPT(" ",13) & "Expected Sellers Profit:" & REPT(" ",23) & TEXT(E50,"$#,##0.00") &" * Expected "&Profit!$K$6*100&"% appreciation per year" & " "& REPT(" ",26) & "Expected Value:" & REPT(" ",20) & TEXT(F50,"$#,##0.00") & " ** After " & D35 &" months." -> Option 3: Cash plus Beneficial Interest in Trust The explanation for the cash component is the same as for option 2. Instead of a note as in Option 2, you will share in the profit earned when the property is resold. The property will be placed into a trust that you will share a beneficial interest in. The advantage here is you will benefit from the appreciated value of the property, over time. You will receive quarterly reports on the financial status of the property. Cash: $10,000.00 Interest in Trust: 70.% Expected Sellers Profit: -$72,469.20 * Expected 3% appreciation per year Expected Value: -$62,469.20 ** After 24 months.
B43: Cash payment in conjunction with taking the existing mortgage subject to:
B44: After reinstating existing loans and HOA fees
B45: Profit split is a split of the profits upon the eventual sale of the pproperty.
B46: Profits will be calculated after deducting all expenses incurred from the sales price
F47: (Based on Future Valuation)
...

Sheet Contact
A1: Vendor | B1: Phone Number | C1: Contact | D1: Acct/Policy | E1: Email | F1: Purpose
A2: Sellers
A4: Estate of Sharrice Y Stagg | D4: SS#: 231 04 1014 | E4: birthday: 11/12/1971
A5: Paticai Baker - Adminstrator | D5: 936 52 3090
A6: Mortgage | B6: 800 274 7025 | E6: Wiring Instructions Acct#: 3000500412, Routing#: 121000248, Wells Fargo Bank NA, 420 Montgomery St, Sanfransico, CA 94104
A7: Wells Fargo Home Mortgage | B7: Fax: 866 278 1179 | D7: 0211198205 | F7: sent on 09/27/2023
A8: Brock & Scott | B8: 919 872 5466 x1147
B10: HOA | D10: User Name:WesBrowning PW:w3638B0@ | E10: https://www.homewisedocs.com/login
A11: Reosourch Property Management | B11: ‪(919) 240-4045‬ | C11: Meshann Chalmers | D11: www.rpmpropertypros.com | E11: User:BuyYourHome PW:w3638B0@
D12: HOA Acct #:108902341
A14: NREIG | B14: 770 734 1523 | E14: 952.79 | F14: 45323
A16: Plumber GWE Plumbing | B16: 2340 Sapphire Valley Dr Ral 27604 | C16: gweplbg@gmail.com | E16: 1905.58 | U16: To | V16: Subject | W16: Sent | X16: Size | Y16: Categories
U17: DefaultCFC@Truist.com | V17: 5008 Larchmont Dr - Loan 9015 2144 11-5998 | W17: 0.44583333 | X17: 478 KB
A20: Insurance National Real Estate Insurance Group LLC | E20: =2*E14 -> 1905.58
A21: Rani Walker | B21: 678 329 0123 | C21: RWalker@insurancehub.com
A22: Customer Care Specialist
A23: InsuranceHub Leavitt Agency
A24: Phone/SMS/Fax: 678.329.0123 | insurancehub.com
A25: Becki Miron | B25: 678.685.3277 | C25: BMiron@insurancehub.com
A26: Account Manager
A27: InsuranceHub Leavitt Agency
A28: Phone/SMS/Fax: 678.685.3277 | insurancehub.com

Sheet Carrying
A1: Duke Electric | D1: Mortgage Payment paid after Reinstatement | G1: Private Money | J1: Casa Lending | M1: Insurance Payments | P1: Water | S1: Natural Gas | V1: HOA | Y1: Property Taxes | AB1: Excavator Rental | AE1: Lawn
A2: Date | B2: payment | D2: Date | E2: payment | G2: Date | H2: payment | J2: Date | K2: payment | M2: Date | N2: payment | P2: Date | Q2: payment | S2: Date | T2: payment | V2: Date | W2: payment | Y2: Date | Z2: payment | AA2: Paid in Escrow | AB2: Date | AC2: payment | AE2: Date | AF2: payment | AL2: Include | AM2: Category | AN2: Date | AO2: Vendor | AP2: Description | AQ2: Amount | AR2: Source | AS2: Invoice # | AT2: Source File | AU2: Status | AV2: Notes
A3: {=IFERROR(INDEX(_xlfn.SORTBY(_xlfn._xlws.FILTER(tblCarryingExpenses[Date],(tblCarryingExpenses[Category]="Duke Electric")*(tblCarryingExpenses[Include]="Yes")),_xlfn._xlws.FILTER(tblCarryingExpenses[Date],(tblCarryingExpenses[Category]="Duke Electric")*(tblCarryingExpenses[Include]="Yes")),1),ROWS($A$3:A3)),"")} -> 45236 | B3: {=IFERROR(INDEX(_xlfn.SORTBY(_xlfn._xlws.FILTER(tblCarryingExpenses[Amount],(tblCarryingExpenses[Category]="Duke Electric")*(tblCarryingExpenses[Include]="Yes")),_xlfn._xlws.FILTER(tblCarryingExpenses[Date],(tblCarryingExpenses[Category]="Duke Electric")*(tblCarryingExpenses[Include]="Yes")),1),ROWS($A$3:A3)),"")} -> 50.55 | D3: {=IFERROR(INDEX(_xlfn.SORTBY(_xlfn._xlws.FILTER(tblCarryingExpenses[Date],(tblCarryingExpenses[Category]="Mortgage Payment")*(tblCarryingExpenses[Include]="Yes")),_xlfn._xlws.FILTER(tblCarryingExpenses[Date],(tblCarryingExpenses[Category]="Mortgage Payment")*(tblCarryingExpenses[Include]="Yes")),1),ROWS($D$3:D3)),"")} -> 45295 | E3: {=IFERROR(INDEX(_xlfn.SORTBY(_xlfn._xlws.FILTER(tblCarryingExpenses[Amount],(tblCarryingExpenses[Category]="Mortgage Payment")*(tblCarryingExpenses[Include]="Yes")),_xlfn._xlws.FILTER(tblCarryingExpenses[Date],(tblCarryingExpenses[Category]="Mortgage Payment")*(tblCarryingExpenses[Include]="Yes")),1),ROWS($D$3:D3)),"")} -> 2858.37 | G3: {=IFERROR(INDEX(_xlfn.SORTBY(_xlfn._xlws.FILTER(tblCarryingExpenses[Date],(tblCarryingExpenses[Category]="Private Money")*(tblCarryingExpenses[Include]="Yes")),_xlfn._xlws.FILTER(tblCarryingExpenses[Date],(tblCarryingExpenses[Category]="Private Money")*(tblCarryingExpenses[Include]="Yes")),1),ROWS($G$3:G3)),"")} -> 45231 | H3: {=IFERROR(INDEX(_xlfn.SORTBY(_xlfn._xlws.FILTER(tblCarryingExpenses[Amount],(tblCarryingExpenses[Category]="Private Money")*(tblCarryingExpenses[Include]="Yes")),_xlfn._xlws.FILTER(tblCarryingExpenses[Date],(tblCarryingExpenses[Category]="Private Money")*(tblCarryingExpenses[Include]="Yes")),1),ROWS($G$3:G3)),"")} -> 925 | J3: {=IFERROR(INDEX(_xlfn.SORTBY(_xlfn._xlws.FILTER(tblCarryingExpenses[Date],(tblCarryingExpenses[Category]="Casa Lending")*(tblCarryingExpenses[Include]="Yes")),_xlfn._xlws.FILTER(tblCarryingExpenses[Date],(tblCarryingExpenses[Category]="Casa Lending")*(tblCarryingExpenses[Include]="Yes")),1),ROWS($J$3:J3)),"")} | K3: {=IFERROR(INDEX(_xlfn.SORTBY(_xlfn._xlws.FILTER(tblCarryingExpenses[Amount],(tblCarryingExpenses[Category]="Casa Lending")*(tblCarryingExpenses[Include]="Yes")),_xlfn._xlws.FILTER(tblCarryingExpenses[Date],(tblCarryingExpenses[Category]="Casa Lending")*(tblCarryingExpenses[Include]="Yes")),1),ROWS($J$3:J3)),"")} | M3: {=IFERROR(INDEX(_xlfn.SORTBY(_xlfn._xlws.FILTER(tblCarryingExpenses[Date],(tblCarryingExpenses[Category]="Insurance Payments")*(tblCarryingExpenses[Include]="Yes")),_xlfn._xlws.FILTER(tblCarryingExpenses[Date],(tblCarryingExpenses[Category]="Insurance Payments")*(tblCarryingExpenses[Include]="Yes")),1),ROWS($M$3:M3)),"")} -> 45263 | N3: {=IFERROR(INDEX(_xlfn.SORTBY(_xlfn._xlws.FILTER(tblCarryingExpenses[Amount],(tblCarryingExpenses[Category]="Insurance Payments")*(tblCarryingExpenses[Include]="Yes")),_xlfn._xlws.FILTER(tblCarryingExpenses[Date],(tblCarryingExpenses[Category]="Insurance Payments")*(tblCarryingExpenses[Include]="Yes")),1),ROWS($M$3:M3)),"")} -> 199.39 | P3: {=IFERROR(INDEX(_xlfn.SORTBY(_xlfn._xlws.FILTER(tblCarryingExpenses[Date],(tblCarryingExpenses[Category]="Water")*(tblCarryingExpenses[Include]="Yes")),_xlfn._xlws.FILTER(tblCarryingExpenses[Date],(tblCarryingExpenses[Category]="Water")*(tblCarryingExpenses[Include]="Yes")),1),ROWS($P$3:P3)),"")} -> 45201 | Q3: {=IFERROR(INDEX(_xlfn.SORTBY(_xlfn._xlws.FILTER(tblCarryingExpenses[Amount],(tblCarryingExpenses[Category]="Water")*(tblCarryingExpenses[Include]="Yes")),_xlfn._xlws.FILTER(tblCarryingExpenses[Date],(tblCarryingExpenses[Category]="Water")*(tblCarryingExpenses[Include]="Yes")),1),ROWS($P$3:P3)),"")} -> 53.96 | S3: {=IFERROR(INDEX(_xlfn.SORTBY(_xlfn._xlws.FILTER(tblCarryingExpenses[Date],(tblCarryingExpenses[Category]="Natural Gas")*(tblCarryingExpenses[Include]="Yes")),_xlfn._xlws.FILTER(tblCarryingExpenses[Date],(tblCarryingExpenses[Category]="Natural Gas")*(tblCarryingExpenses[Include]="Yes")),1),ROWS($S$3:S3)),"")} -> 45209 | T3: {=IFERROR(INDEX(_xlfn.SORTBY(_xlfn._xlws.FILTER(tblCarryingExpenses[Amount],(tblCarryingExpenses[Category]="Natural Gas")*(tblCarryingExpenses[Include]="Yes")),_xlfn._xlws.FILTER(tblCarryingExpenses[Date],(tblCarryingExpenses[Category]="Natural Gas")*(tblCarryingExpenses[Include]="Yes")),1),ROWS($S$3:S3)),"")} -> 30.7 | V3: {=IFERROR(INDEX(_xlfn.SORTBY(_xlfn._xlws.FILTER(tblCarryingExpenses[Date],(tblCarryingExpenses[Category]="HOA")*(tblCarryingExpenses[Include]="Yes")),_xlfn._xlws.FILTER(tblCarryingExpenses[Date],(tblCarryingExpenses[Category]="HOA")*(tblCarryingExpenses[Include]="Yes")),1),ROWS($V$3:V3)),"")} -> 45446 | W3: {=IFERROR(INDEX(_xlfn.SORTBY(_xlfn._xlws.FILTER(tblCarryingExpenses[Amount],(tblCarryingExpenses[Category]="HOA")*(tblCarryingExpenses[Include]="Yes")),_xlfn._xlws.FILTER(tblCarryingExpenses[Date],(tblCarryingExpenses[Category]="HOA")*(tblCarryingExpenses[Include]="Yes")),1),ROWS($V$3:V3)),"")} -> 346.23 | Y3: {=IFERROR(INDEX(_xlfn.SORTBY(_xlfn._xlws.FILTER(tblCarryingExpenses[Date],(tblCarryingExpenses[Category]="Property Taxes")*(tblCarryingExpenses[Include]="Yes")),_xlfn._xlws.FILTER(tblCarryingExpenses[Date],(tblCarryingExpenses[Category]="Property Taxes")*(tblCarryingExpenses[Include]="Yes")),1),ROWS($Y$3:Y3)),"")} -> 45243 | Z3: {=IFERROR(IF(INDEX(_xlfn.SORTBY(_xlfn._xlws.FILTER(tblCarryingExpenses[Amount],(tblCarryingExpenses[Category]="Property Taxes")*(tblCarryingExpenses[Include]="Yes")),_xlfn._xlws.FILTER(tblCarryingExpenses[Date],(tblCarryingExpenses[Category]="Property Taxes")*(tblCarryingExpenses[Include]="Yes")),1),ROWS($Y$3:Y3))<0,"",INDEX(_xlfn.SORTBY(_xlfn._xlws.FILTER(tblCarryingExpenses[Amount],(tblCarryingExpenses[Category]="Property Taxes")*(tblCarryingExpenses[Include]="Yes")),_xlfn._xlws.FILTER(tblCarryingExpenses[Date],(tblCarryingExpenses[Category]="Property Taxes")*(tblCarryingExpenses[Include]="Yes")),1),ROWS($Y$3:Y3))),"")} -> 2334.53 | AA3: {=IFERROR(IF(ISNUMBER(SEARCH("escrow",INDEX(_xlfn.SORTBY(_xlfn._xlws.FILTER(tblCarryingExpenses[Notes],(tblCarryingExpenses[Category]="Property Taxes")*(tblCarryingExpenses[Include]="Yes")),_xlfn._xlws.FILTER(tblCarryingExpenses[Date],(tblCarryingExpenses[Category]="Property Taxes")*(tblCarryingExpenses[Include]="Yes")),1),ROWS($Y$3:Y3)))),INDEX(_xlfn.SORTBY(_xlfn._xlws.FILTER(tblCarryingExpenses[Amount],(tblCarryingExpenses[Category]="Property Taxes")*(tblCarryingExpenses[Include]="Yes")),_xlfn._xlws.FILTER(tblCarryingExpenses[Date],(tblCarryingExpenses[Category]="Property Taxes")*(tblCarryingExpenses[Include]="Yes")),1),ROWS($Y$3:Y3)),""),"")} | AB3: {=IFERROR(INDEX(_xlfn.SORTBY(_xlfn._xlws.FILTER(tblCarryingExpenses[Date],(tblCarryingExpenses[Category]="Excavator Rental")*(tblCarryingExpenses[Include]="Yes")),_xlfn._xlws.FILTER(tblCarryingExpenses[Date],(tblCarryingExpenses[Category]="Excavator Rental")*(tblCarryingExpenses[Include]="Yes")),1),ROWS($AB$3:AB3)),"")} | AC3: {=IFERROR(INDEX(_xlfn.SORTBY(_xlfn._xlws.FILTER(tblCarryingExpenses[Amount],(tblCarryingExpenses[Category]="Excavator Rental")*(tblCarryingExpenses[Include]="Yes")),_xlfn._xlws.FILTER(tblCarryingExpenses[Date],(tblCarryingExpenses[Category]="Excavator Rental")*(tblCarryingExpenses[Include]="Yes")),1),ROWS($AB$3:AB3)),"")} | AE3: {=IFERROR(INDEX(_xlfn.SORTBY(_xlfn._xlws.FILTER(tblCarryingExpenses[Date],(tblCarryingExpenses[Category]="Lawn")*(tblCarryingExpenses[Include]="Yes")),_xlfn._xlws.FILTER(tblCarryingExpenses[Date],(tblCarryingExpenses[Category]="Lawn")*(tblCarryingExpenses[Include]="Yes")),1),ROWS($AE$3:AE3)),"")} | AF3: {=IFERROR(INDEX(_xlfn.SORTBY(_xlfn._xlws.FILTER(tblCarryingExpenses[Amount],(tblCarryingExpenses[Category]="Lawn")*(tblCarryingExpenses[Include]="Yes")),_xlfn._xlws.FILTER(tblCarryingExpenses[Date],(tblCarryingExpenses[Category]="Lawn")*(tblCarryingExpenses[Include]="Yes")),1),ROWS($AE$3:AE3)),"")} | AL3: Yes | AM3: Duke Electric | AN3: 45236 | AQ3: 50.55 | AR3: Migrated Carrying Grid | AT3: 19_Project Management - 1426 Pleasant Garden Ln orignianl .xlsx | AU3: Migrated | AV3: Source Carrying!A4:B4
A4: {=IFERROR(INDEX(_xlfn.SORTBY(_xlfn._xlws.FILTER(tblCarryingExpenses[Date],(tblCarryingExpenses[Category]="Duke Electric")*(tblCarryingExpenses[Include]="Yes")),_xlfn._xlws.FILTER(tblCarryingExpenses[Date],(tblCarryingExpenses[Category]="Duke Electric")*(tblCarryingExpenses[Include]="Yes")),1),ROWS($A$3:A4)),"")} -> 45265 | B4: {=IFERROR(INDEX(_xlfn.SORTBY(_xlfn._xlws.FILTER(tblCarryingExpenses[Amount],(tblCarryingExpenses[Category]="Duke Electric")*(tblCarryingExpenses[Include]="Yes")),_xlfn._xlws.FILTER(tblCarryingExpenses[Date],(tblCarryingExpenses[Category]="Duke Electric")*(tblCarryingExpenses[Include]="Yes")),1),ROWS($A$3:A4)),"")} -> 24.66 | D4: {=IFERROR(INDEX(_xlfn.SORTBY(_xlfn._xlws.FILTER(tblCarryingExpenses[Date],(tblCarryingExpenses[Category]="Mortgage Payment")*(tblCarryingExpenses[Include]="Yes")),_xlfn._xlws.FILTER(tblCarryingExpenses[Date],(tblCarryingExpenses[Category]="Mortgage Payment")*(tblCarryingExpenses[Include]="Yes")),1),ROWS($D$3:D4)),"")} -> 45363 | E4: {=IFERROR(INDEX(_xlfn.SORTBY(_xlfn._xlws.FILTER(tblCarryingExpenses[Amount],(tblCarryingExpenses[Category]="Mortgage Payment")*(tblCarryingExpenses[Include]="Yes")),_xlfn._xlws.FILTER(tblCarryingExpenses[Date],(tblCarryingExpenses[Category]="Mortgage Payment")*(tblCarryingExpenses[Include]="Yes")),1),ROWS($D$3:D4)),"")} -> 1905.58 | G4: {=IFERROR(INDEX(_xlfn.SORTBY(_xlfn._xlws.FILTER(tblCarryingExpenses[Date],(tblCarryingExpenses[Category]="Private Money")*(tblCarryingExpenses[Include]="Yes")),_xlfn._xlws.FILTER(tblCarryingExpenses[Date],(tblCarryingExpenses[Category]="Private Money")*(tblCarryingExpenses[Include]="Yes")),1),ROWS($G$3:G4)),"")} -> 45261 | H4: {=IFERROR(INDEX(_xlfn.SORTBY(_xlfn._xlws.FILTER(tblCarryingExpenses[Amount],(tblCarryingExpenses[Category]="Private Money")*(tblCarryingExpenses[Include]="Yes")),_xlfn._xlws.FILTER(tblCarryingExpenses[Date],(tblCarryingExpenses[Category]="Private Money")*(tblCarryingExpenses[Include]="Yes")),1),ROWS($G$3:G4)),"")} -> 925 | J4: {=IFERROR(INDEX(_xlfn.SORTBY(_xlfn._xlws.FILTER(tblCarryingExpenses[Date],(tblCarryingExpenses[Category]="Casa Lending")*(tblCarryingExpenses[Include]="Yes")),_xlfn._xlws.FILTER(tblCarryingExpenses[Date],(tblCarryingExpenses[Category]="Casa Lending")*(tblCarryingExpenses[Include]="Yes")),1),ROWS($J$3:J4)),"")} | K4: {=IFERROR(INDEX(_xlfn.SORTBY(_xlfn._xlws.FILTER(tblCarryingExpenses[Amount],(tblCarryingExpenses[Category]="Casa Lending")*(tblCarryingExpenses[Include]="Yes")),_xlfn._xlws.FILTER(tblCarryingExpenses[Date],(tblCarryingExpenses[Category]="Casa Lending")*(tblCarryingExpenses[Include]="Yes")),1),ROWS($J$3:J4)),"")} | M4: {=IFERROR(INDEX(_xlfn.SORTBY(_xlfn._xlws.FILTER(tblCarryingExpenses[Date],(tblCarryingExpenses[Category]="Insurance Payments")*(tblCarryingExpenses[Include]="Yes")),_xlfn._xlws.FILTER(tblCarryingExpenses[Date],(tblCarryingExpenses[Category]="Insurance Payments")*(tblCarryingExpenses[Include]="Yes")),1),ROWS($M$3:M4)),"")} -> 45294 | N4: {=IFERROR(INDEX(_xlfn.SORTBY(_xlfn._xlws.FILTER(tblCarryingExpenses[Amount],(tblCarryingExpenses[Category]="Insurance Payments")*(tblCarryingExpenses[Include]="Yes")),_xlfn._xlws.FILTER(tblCarryingExpenses[Date],(tblCarryingExpenses[Category]="Insurance Payments")*(tblCarryingExpenses[Include]="Yes")),1),ROWS($M$3:M4)),"")} -> 199.39 | P4: {=IFERROR(INDEX(_xlfn.SORTBY(_xlfn._xlws.FILTER(tblCarryingExpenses[Date],(tblCarryingExpenses[Category]="Water")*(tblCarryingExpenses[Include]="Yes")),_xlfn._xlws.FILTER(tblCarryingExpenses[Date],(tblCarryingExpenses[Category]="Water")*(tblCarryingExpenses[Include]="Yes")),1),ROWS($P$3:P4)),"")} -> 45231 | Q4: {=IFERROR(INDEX(_xlfn.SORTBY(_xlfn._xlws.FILTER(tblCarryingExpenses[Amount],(tblCarryingExpenses[Category]="Water")*(tblCarryingExpenses[Include]="Yes")),_xlfn._xlws.FILTER(tblCarryingExpenses[Date],(tblCarryingExpenses[Category]="Water")*(tblCarryingExpenses[Include]="Yes")),1),ROWS($P$3:P4)),"")} -> 66.12 | S4: {=IFERROR(INDEX(_xlfn.SORTBY(_xlfn._xlws.FILTER(tblCarryingExpenses[Date],(tblCarryingExpenses[Category]="Natural Gas")*(tblCarryingExpenses[Include]="Yes")),_xlfn._xlws.FILTER(tblCarryingExpenses[Date],(tblCarryingExpenses[Category]="Natural Gas")*(tblCarryingExpenses[Include]="Yes")),1),ROWS($S$3:S4)),"")} -> 45237 | T4: {=IFERROR(INDEX(_xlfn.SORTBY(_xlfn._xlws.FILTER(tblCarryingExpenses[Amount],(tblCarryingExpenses[Category]="Natural Gas")*(tblCarryingExpenses[Include]="Yes")),_xlfn._xlws.FILTER(tblCarryingExpenses[Date],(tblCarryingExpenses[Category]="Natural Gas")*(tblCarryingExpenses[Include]="Yes")),1),ROWS($S$3:S4)),"")} -> 10.7 | V4: {=IFERROR(INDEX(_xlfn.SORTBY(_xlfn._xlws.FILTER(tblCarryingExpenses[Date],(tblCarryingExpenses[Category]="HOA")*(tblCarryingExpenses[Include]="Yes")),_xlfn._xlws.FILTER(tblCarryingExpenses[Date],(tblCarryingExpenses[Category]="HOA")*(tblCarryingExpenses[Include]="Yes")),1),ROWS($V$3:V4)),"")} -> 45482 | W4: {=IFERROR(INDEX(_xlfn.SORTBY(_xlfn._xlws.FILTER(tblCarryingExpenses[Amount],(tblCarryingExpenses[Category]="HOA")*(tblCarryingExpenses[Include]="Yes")),_xlfn._xlws.FILTER(tblCarryingExpenses[Date],(tblCarryingExpenses[Category]="HOA")*(tblCarryingExpenses[Include]="Yes")),1),ROWS($V$3:V4)),"")} -> 241.57 | Y4: {=IFERROR(INDEX(_xlfn.SORTBY(_xlfn._xlws.FILTER(tblCarryingExpenses[Date],(tblCarryingExpenses[Category]="Property Taxes")*(tblCarryingExpenses[Include]="Yes")),_xlfn._xlws.FILTER(tblCarryingExpenses[Date],(tblCarryingExpenses[Category]="Property Taxes")*(tblCarryingExpenses[Include]="Yes")),1),ROWS($Y$3:Y4)),"")} -> 45546 | Z4: {=IFERROR(IF(INDEX(_xlfn.SORTBY(_xlfn._xlws.FILTER(tblCarryingExpenses[Amount],(tblCarryingExpenses[Category]="Property Taxes")*(tblCarryingExpenses[Include]="Yes")),_xlfn._xlws.FILTER(tblCarryingExpenses[Date],(tblCarryingExpenses[Category]="Property Taxes")*(tblCarryingExpenses[Include]="Yes")),1),ROWS($Y$3:Y4))<0,"",INDEX(_xlfn.SORTBY(_xlfn._xlws.FILTER(tblCarryingExpenses[Amount],(tblCarryingExpenses[Category]="Property Taxes")*(tblCarryingExpenses[Include]="Yes")),_xlfn._xlws.FILTER(tblCarryingExpenses[Date],(tblCarryingExpenses[Category]="Property Taxes")*(tblCarryingExpenses[Include]="Yes")),1),ROWS($Y$3:Y4))),"")} -> 3101.83 | AA4: {=IFERROR(IF(ISNUMBER(SEARCH("escrow",INDEX(_xlfn.SORTBY(_xlfn._xlws.FILTER(tblCarryingExpenses[Notes],(tblCarryingExpenses[Category]="Property Taxes")*(tblCarryingExpenses[Include]="Yes")),_xlfn._xlws.FILTER(tblCarryingExpenses[Date],(tblCarryingExpenses[Category]="Property Taxes")*(tblCarryingExpenses[Include]="Yes")),1),ROWS($Y$3:Y4)))),INDEX(_xlfn.SORTBY(_xlfn._xlws.FILTER(tblCarryingExpenses[Amount],(tblCarryingExpenses[Category]="Property Taxes")*(tblCarryingExpenses[Include]="Yes")),_xlfn._xlws.FILTER(tblCarryingExpenses[Date],(tblCarryingExpenses[Category]="Property Taxes")*(tblCarryingExpenses[Include]="Yes")),1),ROWS($Y$3:Y4)),""),"")} | AB4: {=IFERROR(INDEX(_xlfn.SORTBY(_xlfn._xlws.FILTER(tblCarryingExpenses[Date],(tblCarryingExpenses[Category]="Excavator Rental")*(tblCarryingExpenses[Include]="Yes")),_xlfn._xlws.FILTER(tblCarryingExpenses[Date],(tblCarryingExpenses[Category]="Excavator Rental")*(tblCarryingExpenses[Include]="Yes")),1),ROWS($AB$3:AB4)),"")} | AC4: {=IFERROR(INDEX(_xlfn.SORTBY(_xlfn._xlws.FILTER(tblCarryingExpenses[Amount],(tblCarryingExpenses[Category]="Excavator Rental")*(tblCarryingExpenses[Include]="Yes")),_xlfn._xlws.FILTER(tblCarryingExpenses[Date],(tblCarryingExpenses[Category]="Excavator Rental")*(tblCarryingExpenses[Include]="Yes")),1),ROWS($AB$3:AB4)),"")} | AE4: {=IFERROR(INDEX(_xlfn.SORTBY(_xlfn._xlws.FILTER(tblCarryingExpenses[Date],(tblCarryingExpenses[Category]="Lawn")*(tblCarryingExpenses[Include]="Yes")),_xlfn._xlws.FILTER(tblCarryingExpenses[Date],(tblCarryingExpenses[Category]="Lawn")*(tblCarryingExpenses[Include]="Yes")),1),ROWS($AE$3:AE4)),"")} | AF4: {=IFERROR(INDEX(_xlfn.SORTBY(_xlfn._xlws.FILTER(tblCarryingExpenses[Amount],(tblCarryingExpenses[Category]="Lawn")*(tblCarryingExpenses[Include]="Yes")),_xlfn._xlws.FILTER(tblCarryingExpenses[Date],(tblCarryingExpenses[Category]="Lawn")*(tblCarryingExpenses[Include]="Yes")),1),ROWS($AE$3:AE4)),"")} | AL4: Yes | AM4: Duke Electric | AN4: 45265 | AQ4: 24.66 | AR4: Migrated Carrying Grid | AT4: 19_Project Management - 1426 Pleasant Garden Ln orignianl .xlsx | AU4: Migrated | AV4: Source Carrying!A5:B5
A5: {=IFERROR(INDEX(_xlfn.SORTBY(_xlfn._xlws.FILTER(tblCarryingExpenses[Date],(tblCarryingExpenses[Category]="Duke Electric")*(tblCarryingExpenses[Include]="Yes")),_xlfn._xlws.FILTER(tblCarryingExpenses[Date],(tblCarryingExpenses[Category]="Duke Electric")*(tblCarryingExpenses[Include]="Yes")),1),ROWS($A$3:A5)),"")} -> 45301 | B5: {=IFERROR(INDEX(_xlfn.SORTBY(_xlfn._xlws.FILTER(tblCarryingExpenses[Amount],(tblCarryingExpenses[Category]="Duke Electric")*(tblCarryingExpenses[Include]="Yes")),_xlfn._xlws.FILTER(tblCarryingExpenses[Date],(tblCarryingExpenses[Category]="Duke Electric")*(tblCarryingExpenses[Include]="Yes")),1),ROWS($A$3:A5)),"")} -> 30.01 | D5: {=IFERROR(INDEX(_xlfn.SORTBY(_xlfn._xlws.FILTER(tblCarryingExpenses[Date],(tblCarryingExpenses[Category]="Mortgage Payment")*(tblCarryingExpenses[Include]="Yes")),_xlfn._xlws.FILTER(tblCarryingExpenses[Date],(tblCarryingExpenses[Category]="Mortgage Payment")*(tblCarryingExpenses[Include]="Yes")),1),ROWS($D$3:D5)),"")} -> 45383 | E5: {=IFERROR(INDEX(_xlfn.SORTBY(_xlfn._xlws.FILTER(tblCarryingExpenses[Amount],(tblCarryingExpenses[Category]="Mortgage Payment")*(tblCarryingExpenses[Include]="Yes")),_xlfn._xlws.FILTER(tblCarryingExpenses[Date],(tblCarryingExpenses[Category]="Mortgage Payment")*(tblCarryingExpenses[Include]="Yes")),1),ROWS($D$3:D5)),"")} -> 952.79 | G5: {=IFERROR(INDEX(_xlfn.SORTBY(_xlfn._xlws.FILTER(tblCarryingExpenses[Date],(tblCarryingExpenses[Category]="Private Money")*(tblCarryingExpenses[Include]="Yes")),_xlfn._xlws.FILTER(tblCarryingExpenses[Date],(tblCarryingExpenses[Category]="Private Money")*(tblCarryingExpenses[Include]="Yes")),1),ROWS($G$3:G5)),"")} -> 45291 | H5: {=IFERROR(INDEX(_xlfn.SORTBY(_xlfn._xlws.FILTER(tblCarryingExpenses[Amount],(tblCarryingExpenses[Category]="Private Money")*(tblCarryingExpenses[Include]="Yes")),_xlfn._xlws.FILTER(tblCarryingExpenses[Date],(tblCarryingExpenses[Category]="Private Money")*(tblCarryingExpenses[Include]="Yes")),1),ROWS($G$3:G5)),"")} -> 925 | J5: {=IFERROR(INDEX(_xlfn.SORTBY(_xlfn._xlws.FILTER(tblCarryingExpenses[Date],(tblCarryingExpenses[Category]="Casa Lending")*(tblCarryingExpenses[Include]="Yes")),_xlfn._xlws.FILTER(tblCarryingExpenses[Date],(tblCarryingExpenses[Category]="Casa Lending")*(tblCarryingExpenses[Include]="Yes")),1),ROWS($J$3:J5)),"")} | K5: {=IFERROR(INDEX(_xlfn.SORTBY(_xlfn._xlws.FILTER(tblCarryingExpenses[Amount],(tblCarryingExpenses[Category]="Casa Lending")*(tblCarryingExpenses[Include]="Yes")),_xlfn._xlws.FILTER(tblCarryingExpenses[Date],(tblCarryingExpenses[Category]="Casa Lending")*(tblCarryingExpenses[Include]="Yes")),1),ROWS($J$3:J5)),"")} | M5: {=IFERROR(INDEX(_xlfn.SORTBY(_xlfn._xlws.FILTER(tblCarryingExpenses[Date],(tblCarryingExpenses[Category]="Insurance Payments")*(tblCarryingExpenses[Include]="Yes")),_xlfn._xlws.FILTER(tblCarryingExpenses[Date],(tblCarryingExpenses[Category]="Insurance Payments")*(tblCarryingExpenses[Include]="Yes")),1),ROWS($M$3:M5)),"")} -> 45325 | N5: {=IFERROR(INDEX(_xlfn.SORTBY(_xlfn._xlws.FILTER(tblCarryingExpenses[Amount],(tblCarryingExpenses[Category]="Insurance Payments")*(tblCarryingExpenses[Include]="Yes")),_xlfn._xlws.FILTER(tblCarryingExpenses[Date],(tblCarryingExpenses[Category]="Insurance Payments")*(tblCarryingExpenses[Include]="Yes")),1),ROWS($M$3:M5)),"")} -> 134.34 | P5: {=IFERROR(INDEX(_xlfn.SORTBY(_xlfn._xlws.FILTER(tblCarryingExpenses[Date],(tblCarryingExpenses[Category]="Water")*(tblCarryingExpenses[Include]="Yes")),_xlfn._xlws.FILTER(tblCarryingExpenses[Date],(tblCarryingExpenses[Category]="Water")*(tblCarryingExpenses[Include]="Yes")),1),ROWS($P$3:P5)),"")} -> 45261 | Q5: {=IFERROR(INDEX(_xlfn.SORTBY(_xlfn._xlws.FILTER(tblCarryingExpenses[Amount],(tblCarryingExpenses[Category]="Water")*(tblCarryingExpenses[Include]="Yes")),_xlfn._xlws.FILTER(tblCarryingExpenses[Date],(tblCarryingExpenses[Category]="Water")*(tblCarryingExpenses[Include]="Yes")),1),ROWS($P$3:P5)),"")} -> 50.62 | S5: {=IFERROR(INDEX(_xlfn.SORTBY(_xlfn._xlws.FILTER(tblCarryingExpenses[Date],(tblCarryingExpenses[Category]="Natural Gas")*(tblCarryingExpenses[Include]="Yes")),_xlfn._xlws.FILTER(tblCarryingExpenses[Date],(tblCarryingExpenses[Category]="Natural Gas")*(tblCarryingExpenses[Include]="Yes")),1),ROWS($S$3:S5)),"")} -> 45268 | T5: {=IFERROR(INDEX(_xlfn.SORTBY(_xlfn._xlws.FILTER(tblCarryingExpenses[Amount],(tblCarryingExpenses[Category]="Natural Gas")*(tblCarryingExpenses[Include]="Yes")),_xlfn._xlws.FILTER(tblCarryingExpenses[Date],(tblCarryingExpenses[Category]="Natural Gas")*(tblCarryingExpenses[Include]="Yes")),1),ROWS($S$3:S5)),"")} -> 10.7 | V5: {=IFERROR(INDEX(_xlfn.SORTBY(_xlfn._xlws.FILTER(tblCarryingExpenses[Date],(tblCarryingExpenses[Category]="HOA")*(tblCarryingExpenses[Include]="Yes")),_xlfn._xlws.FILTER(tblCarryingExpenses[Date],(tblCarryingExpenses[Category]="HOA")*(tblCarryingExpenses[Include]="Yes")),1),ROWS($V$3:V5)),"")} -> 45670 | W5: {=IFERROR(INDEX(_xlfn.SORTBY(_xlfn._xlws.FILTER(tblCarryingExpenses[Amount],(tblCarryingExpenses[Category]="HOA")*(tblCarryingExpenses[Include]="Yes")),_xlfn._xlws.FILTER(tblCarryingExpenses[Date],(tblCarryingExpenses[Category]="HOA")*(tblCarryingExpenses[Include]="Yes")),1),ROWS($V$3:V5)),"")} -> 253.65 | Y5: {=IFERROR(INDEX(_xlfn.SORTBY(_xlfn._xlws.FILTER(tblCarryingExpenses[Date],(tblCarryingExpenses[Category]="Property Taxes")*(tblCarryingExpenses[Include]="Yes")),_xlfn._xlws.FILTER(tblCarryingExpenses[Date],(tblCarryingExpenses[Category]="Property Taxes")*(tblCarryingExpenses[Include]="Yes")),1),ROWS($Y$3:Y5)),"")} -> 45911 | Z5: {=IFERROR(IF(INDEX(_xlfn.SORTBY(_xlfn._xlws.FILTER(tblCarryingExpenses[Amount],(tblCarryingExpenses[Category]="Property Taxes")*(tblCarryingExpenses[Include]="Yes")),_xlfn._xlws.FILTER(tblCarryingExpenses[Date],(tblCarryingExpenses[Category]="Property Taxes")*(tblCarryingExpenses[Include]="Yes")),1),ROWS($Y$3:Y5))<0,"",INDEX(_xlfn.SORTBY(_xlfn._xlws.FILTER(tblCarryingExpenses[Amount],(tblCarryingExpenses[Category]="Property Taxes")*(tblCarryingExpenses[Include]="Yes")),_xlfn._xlws.FILTER(tblCarryingExpenses[Date],(tblCarryingExpenses[Category]="Property Taxes")*(tblCarryingExpenses[Include]="Yes")),1),ROWS($Y$3:Y5))),"")} | AA5: {=IFERROR(IF(ISNUMBER(SEARCH("escrow",INDEX(_xlfn.SORTBY(_xlfn._xlws.FILTER(tblCarryingExpenses[Notes],(tblCarryingExpenses[Category]="Property Taxes")*(tblCarryingExpenses[Include]="Yes")),_xlfn._xlws.FILTER(tblCarryingExpenses[Date],(tblCarryingExpenses[Category]="Property Taxes")*(tblCarryingExpenses[Include]="Yes")),1),ROWS($Y$3:Y5)))),INDEX(_xlfn.SORTBY(_xlfn._xlws.FILTER(tblCarryingExpenses[Amount],(tblCarryingExpenses[Category]="Property Taxes")*(tblCarryingExpenses[Include]="Yes")),_xlfn._xlws.FILTER(tblCarryingExpenses[Date],(tblCarryingExpenses[Category]="Property Taxes")*(tblCarryingExpenses[Include]="Yes")),1),ROWS($Y$3:Y5)),""),"")} -> -3101.83 | AB5: {=IFERROR(INDEX(_xlfn.SORTBY(_xlfn._xlws.FILTER(tblCarryingExpenses[Date],(tblCarryingExpenses[Category]="Excavator Rental")*(tblCarryingExpenses[Include]="Yes")),_xlfn._xlws.FILTER(tblCarryingExpenses[Date],(tblCarryingExpenses[Category]="Excavator Rental")*(tblCarryingExpenses[Include]="Yes")),1),ROWS($AB$3:AB5)),"")} | AC5: {=IFERROR(INDEX(_xlfn.SORTBY(_xlfn._xlws.FILTER(tblCarryingExpenses[Amount],(tblCarryingExpenses[Category]="Excavator Rental")*(tblCarryingExpenses[Include]="Yes")),_xlfn._xlws.FILTER(tblCarryingExpenses[Date],(tblCarryingExpenses[Category]="Excavator Rental")*(tblCarryingExpenses[Include]="Yes")),1),ROWS($AB$3:AB5)),"")} | AE5: {=IFERROR(INDEX(_xlfn.SORTBY(_xlfn._xlws.FILTER(tblCarryingExpenses[Date],(tblCarryingExpenses[Category]="Lawn")*(tblCarryingExpenses[Include]="Yes")),_xlfn._xlws.FILTER(tblCarryingExpenses[Date],(tblCarryingExpenses[Category]="Lawn")*(tblCarryingExpenses[Include]="Yes")),1),ROWS($AE$3:AE5)),"")} | AF5: {=IFERROR(INDEX(_xlfn.SORTBY(_xlfn._xlws.FILTER(tblCarryingExpenses[Amount],(tblCarryingExpenses[Category]="Lawn")*(tblCarryingExpenses[Include]="Yes")),_xlfn._xlws.FILTER(tblCarryingExpenses[Date],(tblCarryingExpenses[Category]="Lawn")*(tblCarryingExpenses[Include]="Yes")),1),ROWS($AE$3:AE5)),"")} | AL5: Yes | AM5: Duke Electric | AN5: 45301 | AQ5: 30.01 | AR5: Migrated Carrying Grid | AT5: 19_Project Management - 1426 Pleasant Garden Ln orignianl .xlsx | AU5: Migrated | AV5: Source Carrying!A6:B6
