Workbook
Name AnnualManagementFee: 'Operating Expense Budget'!$B$15
Name AssumedOperatingExpenseRatio: 'Operating Expense Budget'!$B$5
Name CalculatedOperatingExpenseRatio: 'Operating Expense Budget'!$B$6
Name ClassACapital: Assumptions!$B$39
Name ClassAPreferredReturn: Assumptions!$B$40
Name ClassAResidualShare: Assumptions!$B$44
Name ClassBCapital: Assumptions!$B$41
Name ClassBResidualShare: Assumptions!$B$45
Name ClassBReturnPriority: Assumptions!$B$42
Name CoLivingSuiteRent: Assumptions!$B$11
Name CoLivingSuiteRentHigh: Assumptions!$G$10
Name CoLivingSuiteRentLow: Assumptions!$E$10
Name CoLivingSuiteRentMedium: Assumptions!$F$10
Name CoLivingSuites: Assumptions!$B$10
Name ExistingDebtServiceAnnual: Assumptions!$B$28
Name ExistingFirstMortgage: Assumptions!$B$20
Name ExistingFirstMortgageAnnualPayment: Assumptions!$B$26
Name ExistingFirstMortgageMonthlyPI: Assumptions!$B$25
Name ExistingFirstMortgagePrincipal: Assumptions!$B$20
Name ExistingFirstMortgageRate: Assumptions!$B$21
Name ExitCapRate: Assumptions!$B$35
Name LeaseUpOccupancy: Assumptions!$B$14
Name ManagementFeeRate: 'Operating Expense Budget'!$D$15
Name NOIGrowth: Assumptions!$B$16
Name OperatingExpenseRatio: Assumptions!$B$15
Name OtherMonthlyIncome: Assumptions!$B$12
Name PermanentLoanAmortizationYears: Assumptions!$B$34
Name PermanentLoanAmount: Assumptions!$B$30
Name PermanentLoanRate: Assumptions!$B$33
Name PremiumSuiteRent: Assumptions!$B$9
Name PremiumSuiteRentHigh: Assumptions!$G$9
Name PremiumSuiteRentLow: Assumptions!$E$9
Name PremiumSuiteRentMedium: Assumptions!$F$9
Name PremiumSuites: Assumptions!$B$8
Name PrivateDebtAnnualInterestPayment: Assumptions!$B$27
Name PrivateDebtInterestRate: Assumptions!$B$23
Name PrivateDebtPrincipal: Assumptions!$B$22
Name ProjectDebtPayoffAtRefi: Assumptions!$B$24
Name RefinanceLoanAmortizationYears: Assumptions!$B$34
Name RefinanceLoanAmount: Assumptions!$B$30
Name RefinanceLoanRate: Assumptions!$B$33
Name RefinanceLoanToValueCap: Assumptions!$B$29
Name RefinanceProceedsAfterDebtAndClassA: Assumptions!$B$32
Name RefinanceProceedsAfterExistingDebt: Assumptions!$B$31
Name RentScenarioAverageMonthlyGross: Assumptions!$H$11
Name RentScenarioHighEffectiveYear: Assumptions!$G$12
Name RentScenarioHighMonthlyGross: Assumptions!$G$11
Name RentScenarioLowEffectiveYear: Assumptions!$E$12
Name RentScenarioLowMonthlyGross: Assumptions!$E$11
Name RentScenarioMediumEffectiveYear: Assumptions!$F$12
Name RentScenarioMediumMonthlyGross: Assumptions!$F$11
Name SaleExitYear: Assumptions!$B$5
Name SelectedCostCase: 'Cost Analysis'!$E$8
Name SelectedCostCaseId: 'Cost Analysis'!$D$11
Name SelectedOperatingExpenseRatio: 'Operating Expense Budget'!$B$7
Name SelectedProjectCost: 'Cost Analysis'!$G$10
Name SelectedProjectCostHigh: 'Cost Analysis'!$C$10
Name SelectedProjectCostLow: 'Cost Analysis'!$B$10
Name SelectedScenario: 'Cost Analysis'!$C$6
Name SelectedScenarioId: 'Cost Analysis'!$D$12

Sheet Assumptions
A1: 3325 Banks Rd - Investor Return Model | C1: Editable inputs are in column B. Outputs update through formulas.
A3: Project Timing
A4: Stabilization / Refinance Year | B4: 2 | C4: Year when refinance proceeds are modeled
A5: Sale / Exit Year | B5: =+Waterfall!R3 -> 4 | C5: Model uses annual periods 0 through this year
A7: Rental Program | D7: Rent Scenario Schedule
A8: First Floor Premium Suites | B8: 4 | C8: Private bed/bath/kitchenette suites | D8: Rent Input | E8: Low | F8: Medium | G8: High | H8: Average | I8: Current Use | J8: Notes
A9: Monthly Rent per Premium Suite | B9: 1600 | C9: Mid/base reference; Annual Model uses scenario schedule at right | D9: Premium Suite Rent | E9: 1350 | F9: 1600 | G9: 1750 | H9: =AVERAGE(E9:G9) -> 1566.6667 | I9: Rent levels increase left to right
A10: Second Floor Co-Living Suites | B10: 4 | C10: Private bed/bath with shared amenities | D10: Co-Living Suite Rent | E10: 850 | F10: 1100 | G10: 1250 | H10: =AVERAGE(E10:G10) -> 1066.6667 | I10: Rent levels increase left to right
A11: Monthly Rent per Co-Living Suite | B11: 1100 | C11: Mid/base reference; Annual Model uses scenario schedule at right | D11: Monthly Gross Rent | E11: =PremiumSuites*E9+CoLivingSuites*E10+OtherMonthlyIncome -> 8800 | F11: =PremiumSuites*F9+CoLivingSuites*F10+OtherMonthlyIncome -> 10800 | G11: =PremiumSuites*G9+CoLivingSuites*G10+OtherMonthlyIncome -> 12000 | H11: =AVERAGE(E11:G11) -> 10533.333 | I11: Average feeds stabilized monthly rent
A12: Other Monthly Income | B12: 0 | C12: Parking, utility fees, laundry, etc. | D12: Effective Year | E12: 1 | F12: 2 | G12: 3 | I12: Annual Model timing | J12: Low ends after Year 1 under current schedule
A13: Stabilized Occupancy | B13: 0.93 | C13: Before operating expense load
A14: Year 1 Lease-Up Occupancy | B14: 0.5 | C14: First partial operating year
A15: Selected Operating Expense Ratio | B15: =SelectedOperatingExpenseRatio -> 0.4 | C15: From Operating Expense Budget tab; toggle between assumed ratio and calculated budget ratio
A16: NOI Growth | B16: 0.03 | C16: Annual growth after stabilization
A17: Stabilized Monthly Gross Rent | B17: =RentScenarioAverageMonthlyGross -> 10533.333 | C17: Average of low, medium, and high rent scenarios
A19: Debt / Refinance / Exit
A20: Existing First Mortgage Principal | B20: 119000 | C20: Existing first mortgage principal to be paid from refinance proceeds
A21: Existing First Mortgage Rate | B21: 0.0325 | C21: Interest rate on existing first mortgage
A22: Private Debt Principal | B22: 75000 | C22: Private debt principal; interest-only before payoff
A23: Private Debt Interest Rate | B23: 0.1 | C23: Interest-only private debt rate
A24: Total Existing Debt Payoff | B24: =_xlfn.SINGLE(ExistingFirstMortgagePrincipal)+PrivateDebtPrincipal -> 194000 | C24: Existing first mortgage principal plus private debt principal
A25: First Mortgage Monthly P&I Excl. Escrow | B25: 526 | C25: Actual monthly principal and interest payment; excludes escrow, taxes, and insurance
A26: First Mortgage Annual P&I Excl. Escrow | B26: =_xlfn.SINGLE(ExistingFirstMortgageMonthlyPI)*12 -> 6312 | C26: Annual principal and interest payment; excludes escrow, taxes, and insurance
A27: Private Debt Annual Interest Payment | B27: =PrivateDebtPrincipal*PrivateDebtInterestRate -> 7500 | C27: Interest-only payment on private debt
A28: Total Existing Annual Debt Service | B28: =ExistingFirstMortgageAnnualPayment+PrivateDebtAnnualInterestPayment -> 13812 | C28: Existing debt service before refinance; taxes and insurance remain in operating expenses
A29: Refinance Loan-to-Value Cap | B29: 0.7 | C29: Maximum refinance loan as % of stabilized value
A30: Refinance Loan Amount | B30: =MIN((StabilizedMonthlyGrossRent*12*StabilizedOccupancy*(1-OperatingExpenseRatio)*(1+NOIGrowth)/ExitCapRate)*RefinanceLoanToValueCap,TotalExistingDebt+ClassACapital+ClassBCapital) -> 726471.36 | C30: Only new loan; takeout/refinance proceeds, not development or construction debt
A31: Refi Proceeds After Existing Debt | B31: =MAX(0,RefinanceLoanAmount-TotalExistingDebt) -> 532471.36 | C31: Available to Class A first through waterfall
A32: Refi Remaining After Debt + Class A | B32: =MAX(0,RefinanceLoanAmount-TotalExistingDebt-ClassACapital) -> 232471.36 | C32: Indicative amount available to Class B before waterfall details
A33: Refinance Loan Interest Rate | B33: 0.065 | C33: Annual fixed rate on stabilization refinance loan
A34: Refinance Loan Amortization Years | B34: 30 | C34: Used for annual debt service after stabilization refinance
A35: Exit Cap Rate | B35: 0.07 | C35: Sale value = following year NOI / cap rate
A36: Selling Costs | B36: 0.02 | C36: Percent deducted from gross sale value
A38: Capital Stack / Waterfall
A39: Class A Capital | B39: 300000 | C39: Preferred capital raise
A40: Class A Preferred Return | B40: 0.08 | C40: Cumulative annual preferred return
A41: Class B Capital | B41: =MAX(0,SelectedProjectCost-ClassACapital) -> 597500 | C41: Subordinate beneficiary capital; dependent upon selected project cost in Cost Analysis
A42: Class B Capital Return Priority | B42: 1 | C42: 1 = return Class B capital before residual split
A43: Sponsor Residual Share | B43: 0.4 | C43: Editable sponsor share of residual after capital return priorities
A44: Class A Residual Share | B44: =(1-SponsorResidualShare)*(ClassACapital/(ClassACapital+ClassBCapital)) -> 0.2005571 | C44: Class A share of non-sponsor residual, proportional to Class A capital
...

Sheet Annual Model
A1: Annual Project Model
A3: Year | B3: Phase | C3: Gross Potential Rent | D3: Effective Gross Income | E3: Operating Expenses | F3: NOI | G3: Debt Service | H3: Current Year Cash Before Refi/Sale | I3: Net Refi/Sale Proceeds | J3: Cash Available Before Distributions | K3: Waterfall Distributions | L3: Ending Cash Balance | M3: Loan Balance | N3: Property Value / Refi Value
A4: 0 | B4: Capitalization / Entitlement | C4: =IF(AnnualModelTable[[#This Row],[Year]]>SaleExitYear,0,IF(AnnualModelTable[[#This Row],[Year]]=0,0,IF(AnnualModelTable[[#This Row],[Year]]>=RentScenarioHighEffectiveYear,RentScenarioHighMonthlyGross*12,IF(AnnualModelTable[[#This Row],[Year]]>=RentScenarioMediumEffectiveYear,RentScenarioMediumMonthlyGross*12,IF(AnnualModelTable[[#This Row],[Year]]>=RentScenarioLowEffectiveYear,RentScenarioLowMonthlyGross*12,0))))) -> 0 | D4: =IF(AnnualModelTable[[#This Row],[Year]]>SaleExitYear,0,IF(AnnualModelTable[[#This Row],[Year]]=0,0,AnnualModelTable[[#This Row],[Gross Potential Rent]]*IF(AnnualModelTable[[#This Row],[Year]]=1,LeaseUpOccupancy,StabilizedOccupancy))) -> 0 | E4: =IF(AnnualModelTable[[#This Row],[Year]]>SaleExitYear,0,AnnualModelTable[[#This Row],[Effective Gross Income]]*OperatingExpenseRatio) -> 0 | F4: =IF(AnnualModelTable[[#This Row],[Year]]>SaleExitYear,0,AnnualModelTable[[#This Row],[Effective Gross Income]]-AnnualModelTable[[#This Row],[Operating Expenses]]) -> 0 | G4: =IF(AnnualModelTable[[#This Row],[Year]]>SaleExitYear,0,IF(AND(AnnualModelTable[[#This Row],[Year]]>=1,AnnualModelTable[[#This Row],[Year]]<StabilizationRefiYear),ExistingDebtServiceAnnual,IF(AND(AnnualModelTable[[#This Row],[Year]]>=StabilizationRefiYear,AnnualModelTable[[#This Row],[Year]]<=SaleExitYear),-PMT(RefinanceLoanRate/12,RefinanceLoanAmortizationYears*12,RefinanceLoanAmount)*12,0))) -> 0 | H4: =IF(AnnualModelTable[[#This Row],[Year]]>SaleExitYear,0,AnnualModelTable[[#This Row],[NOI]]-AnnualModelTable[[#This Row],[Debt Service]]) -> 0 | I4: =IF(AnnualModelTable[[#This Row],[Year]]>SaleExitYear,0,IF(AnnualModelTable[[#This Row],[Year]]=0,SponsorPropertyPayment,IF(AnnualModelTable[[#This Row],[Year]]=StabilizationRefiYear,MAX(0,RefinanceLoanAmount-TotalExistingDebt),IF(AnnualModelTable[[#This Row],[Year]]=SaleExitYear,MAX(0,AnnualModelTable[[#This Row],[Property Value / Refi Value]]*(1-SellingCosts)-AnnualModelTable[[#This Row],[Loan Balance]]),0)))) -> 150000 | J4: =IF(AnnualModelTable[[#This Row],[Year]]>SaleExitYear,0,IF(AnnualModelTable[[#This Row],[Year]]=0,0,IFERROR(INDEX(AnnualModelTable[Ending Cash Balance],MATCH(AnnualModelTable[[#This Row],[Year]]-1,AnnualModelTable[Year],0)),0))+AnnualModelTable[[#This Row],[Current Year Cash Before Refi/Sale]]+AnnualModelTable[[#This Row],[Net Refi/Sale Proceeds]]) -> 150000 | K4: =IF(AnnualModelTable[[#This Row],[Year]]>SaleExitYear,0,SUM(INDEX(WaterfallTable[Total Distribution],MATCH(AnnualModelTable[[#This Row],[Year]],WaterfallTable[Year],0)),INDEX(WaterfallTable[Total Dist],MATCH(AnnualModelTable[[#This Row],[Year]],WaterfallTable[Year],0)),INDEX(WaterfallTable[Total Dist2],MATCH(AnnualModelTable[[#This Row],[Year]],WaterfallTable[Year],0)))) -> 150000 | L4: =IF(AnnualModelTable[[#This Row],[Year]]>SaleExitYear,0,MAX(0,AnnualModelTable[[#This Row],[Cash Available Before Distributions]]-AnnualModelTable[[#This Row],[Waterfall Distributions]])) -> 0 | M4: =IF(AnnualModelTable[[#This Row],[Year]]>SaleExitYear,0,IF(AnnualModelTable[[#This Row],[Year]]<StabilizationRefiYear,0,IF(AnnualModelTable[[#This Row],[Year]]=SaleExitYear,0,-FV(RefinanceLoanRate/12,(AnnualModelTable[[#This Row],[Year]]-StabilizationRefiYear)*12,PMT(RefinanceLoanRate/12,RefinanceLoanAmortizationYears*12,RefinanceLoanAmount),RefinanceLoanAmount)))) -> 0 | N4: =IF(AnnualModelTable[[#This Row],[Year]]>SaleExitYear,0,IF(AnnualModelTable[[#This Row],[Year]]<StabilizationRefiYear,0,AnnualModelTable[[#This Row],[NOI]]*(1+NOIGrowth)/ExitCapRate)) -> 0
A5: 1 | B5: Lease-Up | C5: =IF(AnnualModelTable[[#This Row],[Year]]>SaleExitYear,0,IF(AnnualModelTable[[#This Row],[Year]]=0,0,IF(AnnualModelTable[[#This Row],[Year]]>=RentScenarioHighEffectiveYear,RentScenarioHighMonthlyGross*12,IF(AnnualModelTable[[#This Row],[Year]]>=RentScenarioMediumEffectiveYear,RentScenarioMediumMonthlyGross*12,IF(AnnualModelTable[[#This Row],[Year]]>=RentScenarioLowEffectiveYear,RentScenarioLowMonthlyGross*12,0))))) -> 105600 | D5: =IF(AnnualModelTable[[#This Row],[Year]]>SaleExitYear,0,IF(AnnualModelTable[[#This Row],[Year]]=0,0,AnnualModelTable[[#This Row],[Gross Potential Rent]]*IF(AnnualModelTable[[#This Row],[Year]]=1,LeaseUpOccupancy,StabilizedOccupancy))) -> 52800 | E5: =IF(AnnualModelTable[[#This Row],[Year]]>SaleExitYear,0,AnnualModelTable[[#This Row],[Effective Gross Income]]*OperatingExpenseRatio) -> 21120 | F5: =IF(AnnualModelTable[[#This Row],[Year]]>SaleExitYear,0,AnnualModelTable[[#This Row],[Effective Gross Income]]-AnnualModelTable[[#This Row],[Operating Expenses]]) -> 31680 | G5: =IF(AnnualModelTable[[#This Row],[Year]]>SaleExitYear,0,IF(AND(AnnualModelTable[[#This Row],[Year]]>=1,AnnualModelTable[[#This Row],[Year]]<StabilizationRefiYear),ExistingDebtServiceAnnual,IF(AND(AnnualModelTable[[#This Row],[Year]]>=StabilizationRefiYear,AnnualModelTable[[#This Row],[Year]]<=SaleExitYear),-PMT(RefinanceLoanRate/12,RefinanceLoanAmortizationYears*12,RefinanceLoanAmount)*12,0))) -> 13812 | H5: =IF(AnnualModelTable[[#This Row],[Year]]>SaleExitYear,0,AnnualModelTable[[#This Row],[NOI]]-AnnualModelTable[[#This Row],[Debt Service]]) -> 17868 | I5: =IF(AnnualModelTable[[#This Row],[Year]]>SaleExitYear,0,IF(AnnualModelTable[[#This Row],[Year]]=0,SponsorPropertyPayment,IF(AnnualModelTable[[#This Row],[Year]]=StabilizationRefiYear,MAX(0,RefinanceLoanAmount-TotalExistingDebt),IF(AnnualModelTable[[#This Row],[Year]]=SaleExitYear,MAX(0,AnnualModelTable[[#This Row],[Property Value / Refi Value]]*(1-SellingCosts)-AnnualModelTable[[#This Row],[Loan Balance]]),0)))) -> 0 | J5: =IF(AnnualModelTable[[#This Row],[Year]]>SaleExitYear,0,IF(AnnualModelTable[[#This Row],[Year]]=0,0,IFERROR(INDEX(AnnualModelTable[Ending Cash Balance],MATCH(AnnualModelTable[[#This Row],[Year]]-1,AnnualModelTable[Year],0)),0))+AnnualModelTable[[#This Row],[Current Year Cash Before Refi/Sale]]+AnnualModelTable[[#This Row],[Net Refi/Sale Proceeds]]) -> 17868 | K5: =IF(AnnualModelTable[[#This Row],[Year]]>SaleExitYear,0,SUM(INDEX(WaterfallTable[Total Distribution],MATCH(AnnualModelTable[[#This Row],[Year]],WaterfallTable[Year],0)),INDEX(WaterfallTable[Total Dist],MATCH(AnnualModelTable[[#This Row],[Year]],WaterfallTable[Year],0)),INDEX(WaterfallTable[Total Dist2],MATCH(AnnualModelTable[[#This Row],[Year]],WaterfallTable[Year],0)))) -> 17868 | L5: =IF(AnnualModelTable[[#This Row],[Year]]>SaleExitYear,0,MAX(0,AnnualModelTable[[#This Row],[Cash Available Before Distributions]]-AnnualModelTable[[#This Row],[Waterfall Distributions]])) -> 0 | M5: =IF(AnnualModelTable[[#This Row],[Year]]>SaleExitYear,0,IF(AnnualModelTable[[#This Row],[Year]]<StabilizationRefiYear,0,IF(AnnualModelTable[[#This Row],[Year]]=SaleExitYear,0,-FV(RefinanceLoanRate/12,(AnnualModelTable[[#This Row],[Year]]-StabilizationRefiYear)*12,PMT(RefinanceLoanRate/12,RefinanceLoanAmortizationYears*12,RefinanceLoanAmount),RefinanceLoanAmount)))) -> 0 | N5: =IF(AnnualModelTable[[#This Row],[Year]]>SaleExitYear,0,IF(AnnualModelTable[[#This Row],[Year]]<StabilizationRefiYear,0,AnnualModelTable[[#This Row],[NOI]]*(1+NOIGrowth)/ExitCapRate)) -> 0
A6: 2 | B6: Stabilization / Refi | C6: =IF(AnnualModelTable[[#This Row],[Year]]>SaleExitYear,0,IF(AnnualModelTable[[#This Row],[Year]]=0,0,IF(AnnualModelTable[[#This Row],[Year]]>=RentScenarioHighEffectiveYear,RentScenarioHighMonthlyGross*12,IF(AnnualModelTable[[#This Row],[Year]]>=RentScenarioMediumEffectiveYear,RentScenarioMediumMonthlyGross*12,IF(AnnualModelTable[[#This Row],[Year]]>=RentScenarioLowEffectiveYear,RentScenarioLowMonthlyGross*12,0))))) -> 129600 | D6: =IF(AnnualModelTable[[#This Row],[Year]]>SaleExitYear,0,IF(AnnualModelTable[[#This Row],[Year]]=0,0,AnnualModelTable[[#This Row],[Gross Potential Rent]]*IF(AnnualModelTable[[#This Row],[Year]]=1,LeaseUpOccupancy,StabilizedOccupancy))) -> 120528 | E6: =IF(AnnualModelTable[[#This Row],[Year]]>SaleExitYear,0,AnnualModelTable[[#This Row],[Effective Gross Income]]*OperatingExpenseRatio) -> 48211.2 | F6: =IF(AnnualModelTable[[#This Row],[Year]]>SaleExitYear,0,AnnualModelTable[[#This Row],[Effective Gross Income]]-AnnualModelTable[[#This Row],[Operating Expenses]]) -> 72316.8 | G6: =IF(AnnualModelTable[[#This Row],[Year]]>SaleExitYear,0,IF(AND(AnnualModelTable[[#This Row],[Year]]>=1,AnnualModelTable[[#This Row],[Year]]<StabilizationRefiYear),ExistingDebtServiceAnnual,IF(AND(AnnualModelTable[[#This Row],[Year]]>=StabilizationRefiYear,AnnualModelTable[[#This Row],[Year]]<=SaleExitYear),-PMT(RefinanceLoanRate/12,RefinanceLoanAmortizationYears*12,RefinanceLoanAmount)*12,0))) -> 55101.518 | H6: =IF(AnnualModelTable[[#This Row],[Year]]>SaleExitYear,0,AnnualModelTable[[#This Row],[NOI]]-AnnualModelTable[[#This Row],[Debt Service]]) -> 17215.282 | I6: =IF(AnnualModelTable[[#This Row],[Year]]>SaleExitYear,0,IF(AnnualModelTable[[#This Row],[Year]]=0,SponsorPropertyPayment,IF(AnnualModelTable[[#This Row],[Year]]=StabilizationRefiYear,MAX(0,RefinanceLoanAmount-TotalExistingDebt),IF(AnnualModelTable[[#This Row],[Year]]=SaleExitYear,MAX(0,AnnualModelTable[[#This Row],[Property Value / Refi Value]]*(1-SellingCosts)-AnnualModelTable[[#This Row],[Loan Balance]]),0)))) -> 532471.36 | J6: =IF(AnnualModelTable[[#This Row],[Year]]>SaleExitYear,0,IF(AnnualModelTable[[#This Row],[Year]]=0,0,IFERROR(INDEX(AnnualModelTable[Ending Cash Balance],MATCH(AnnualModelTable[[#This Row],[Year]]-1,AnnualModelTable[Year],0)),0))+AnnualModelTable[[#This Row],[Current Year Cash Before Refi/Sale]]+AnnualModelTable[[#This Row],[Net Refi/Sale Proceeds]]) -> 549686.64 | K6: =IF(AnnualModelTable[[#This Row],[Year]]>SaleExitYear,0,SUM(INDEX(WaterfallTable[Total Distribution],MATCH(AnnualModelTable[[#This Row],[Year]],WaterfallTable[Year],0)),INDEX(WaterfallTable[Total Dist],MATCH(AnnualModelTable[[#This Row],[Year]],WaterfallTable[Year],0)),INDEX(WaterfallTable[Total Dist2],MATCH(AnnualModelTable[[#This Row],[Year]],WaterfallTable[Year],0)))) -> 549686.64 | L6: =IF(AnnualModelTable[[#This Row],[Year]]>SaleExitYear,0,MAX(0,AnnualModelTable[[#This Row],[Cash Available Before Distributions]]-AnnualModelTable[[#This Row],[Waterfall Distributions]])) -> 0 | M6: =IF(AnnualModelTable[[#This Row],[Year]]>SaleExitYear,0,IF(AnnualModelTable[[#This Row],[Year]]<StabilizationRefiYear,0,IF(AnnualModelTable[[#This Row],[Year]]=SaleExitYear,0,-FV(RefinanceLoanRate/12,(AnnualModelTable[[#This Row],[Year]]-StabilizationRefiYear)*12,PMT(RefinanceLoanRate/12,RefinanceLoanAmortizationYears*12,RefinanceLoanAmount),RefinanceLoanAmount)))) -> 726471.36 | N6: =IF(AnnualModelTable[[#This Row],[Year]]>SaleExitYear,0,IF(AnnualModelTable[[#This Row],[Year]]<StabilizationRefiYear,0,AnnualModelTable[[#This Row],[NOI]]*(1+NOIGrowth)/ExitCapRate)) -> 1064090.1
A7: 3 | B7: Operations | C7: =IF(AnnualModelTable[[#This Row],[Year]]>SaleExitYear,0,IF(AnnualModelTable[[#This Row],[Year]]=0,0,IF(AnnualModelTable[[#This Row],[Year]]>=RentScenarioHighEffectiveYear,RentScenarioHighMonthlyGross*12,IF(AnnualModelTable[[#This Row],[Year]]>=RentScenarioMediumEffectiveYear,RentScenarioMediumMonthlyGross*12,IF(AnnualModelTable[[#This Row],[Year]]>=RentScenarioLowEffectiveYear,RentScenarioLowMonthlyGross*12,0))))) -> 144000 | D7: =IF(AnnualModelTable[[#This Row],[Year]]>SaleExitYear,0,IF(AnnualModelTable[[#This Row],[Year]]=0,0,AnnualModelTable[[#This Row],[Gross Potential Rent]]*IF(AnnualModelTable[[#This Row],[Year]]=1,LeaseUpOccupancy,StabilizedOccupancy))) -> 133920 | E7: =IF(AnnualModelTable[[#This Row],[Year]]>SaleExitYear,0,AnnualModelTable[[#This Row],[Effective Gross Income]]*OperatingExpenseRatio) -> 53568 | F7: =IF(AnnualModelTable[[#This Row],[Year]]>SaleExitYear,0,AnnualModelTable[[#This Row],[Effective Gross Income]]-AnnualModelTable[[#This Row],[Operating Expenses]]) -> 80352 | G7: =IF(AnnualModelTable[[#This Row],[Year]]>SaleExitYear,0,IF(AND(AnnualModelTable[[#This Row],[Year]]>=1,AnnualModelTable[[#This Row],[Year]]<StabilizationRefiYear),ExistingDebtServiceAnnual,IF(AND(AnnualModelTable[[#This Row],[Year]]>=StabilizationRefiYear,AnnualModelTable[[#This Row],[Year]]<=SaleExitYear),-PMT(RefinanceLoanRate/12,RefinanceLoanAmortizationYears*12,RefinanceLoanAmount)*12,0))) -> 55101.518 | H7: =IF(AnnualModelTable[[#This Row],[Year]]>SaleExitYear,0,AnnualModelTable[[#This Row],[NOI]]-AnnualModelTable[[#This Row],[Debt Service]]) -> 25250.482 | I7: =IF(AnnualModelTable[[#This Row],[Year]]>SaleExitYear,0,IF(AnnualModelTable[[#This Row],[Year]]=0,SponsorPropertyPayment,IF(AnnualModelTable[[#This Row],[Year]]=StabilizationRefiYear,MAX(0,RefinanceLoanAmount-TotalExistingDebt),IF(AnnualModelTable[[#This Row],[Year]]=SaleExitYear,MAX(0,AnnualModelTable[[#This Row],[Property Value / Refi Value]]*(1-SellingCosts)-AnnualModelTable[[#This Row],[Loan Balance]]),0)))) -> 0 | J7: =IF(AnnualModelTable[[#This Row],[Year]]>SaleExitYear,0,IF(AnnualModelTable[[#This Row],[Year]]=0,0,IFERROR(INDEX(AnnualModelTable[Ending Cash Balance],MATCH(AnnualModelTable[[#This Row],[Year]]-1,AnnualModelTable[Year],0)),0))+AnnualModelTable[[#This Row],[Current Year Cash Before Refi/Sale]]+AnnualModelTable[[#This Row],[Net Refi/Sale Proceeds]]) -> 25250.482 | K7: =IF(AnnualModelTable[[#This Row],[Year]]>SaleExitYear,0,SUM(INDEX(WaterfallTable[Total Distribution],MATCH(AnnualModelTable[[#This Row],[Year]],WaterfallTable[Year],0)),INDEX(WaterfallTable[Total Dist],MATCH(AnnualModelTable[[#This Row],[Year]],WaterfallTable[Year],0)),INDEX(WaterfallTable[Total Dist2],MATCH(AnnualModelTable[[#This Row],[Year]],WaterfallTable[Year],0)))) -> 25250.482 | L7: =IF(AnnualModelTable[[#This Row],[Year]]>SaleExitYear,0,MAX(0,AnnualModelTable[[#This Row],[Cash Available Before Distributions]]-AnnualModelTable[[#This Row],[Waterfall Distributions]])) -> 0 | M7: =IF(AnnualModelTable[[#This Row],[Year]]>SaleExitYear,0,IF(AnnualModelTable[[#This Row],[Year]]<StabilizationRefiYear,0,IF(AnnualModelTable[[#This Row],[Year]]=SaleExitYear,0,-FV(RefinanceLoanRate/12,(AnnualModelTable[[#This Row],[Year]]-StabilizationRefiYear)*12,PMT(RefinanceLoanRate/12,RefinanceLoanAmortizationYears*12,RefinanceLoanAmount),RefinanceLoanAmount)))) -> 718351.4 | N7: =IF(AnnualModelTable[[#This Row],[Year]]>SaleExitYear,0,IF(AnnualModelTable[[#This Row],[Year]]<StabilizationRefiYear,0,AnnualModelTable[[#This Row],[NOI]]*(1+NOIGrowth)/ExitCapRate)) -> 1182322.3
A8: 4 | B8: Operations | C8: =IF(AnnualModelTable[[#This Row],[Year]]>SaleExitYear,0,IF(AnnualModelTable[[#This Row],[Year]]=0,0,IF(AnnualModelTable[[#This Row],[Year]]>=RentScenarioHighEffectiveYear,RentScenarioHighMonthlyGross*12,IF(AnnualModelTable[[#This Row],[Year]]>=RentScenarioMediumEffectiveYear,RentScenarioMediumMonthlyGross*12,IF(AnnualModelTable[[#This Row],[Year]]>=RentScenarioLowEffectiveYear,RentScenarioLowMonthlyGross*12,0))))) -> 144000 | D8: =IF(AnnualModelTable[[#This Row],[Year]]>SaleExitYear,0,IF(AnnualModelTable[[#This Row],[Year]]=0,0,AnnualModelTable[[#This Row],[Gross Potential Rent]]*IF(AnnualModelTable[[#This Row],[Year]]=1,LeaseUpOccupancy,StabilizedOccupancy))) -> 133920 | E8: =IF(AnnualModelTable[[#This Row],[Year]]>SaleExitYear,0,AnnualModelTable[[#This Row],[Effective Gross Income]]*OperatingExpenseRatio) -> 53568 | F8: =IF(AnnualModelTable[[#This Row],[Year]]>SaleExitYear,0,AnnualModelTable[[#This Row],[Effective Gross Income]]-AnnualModelTable[[#This Row],[Operating Expenses]]) -> 80352 | G8: =IF(AnnualModelTable[[#This Row],[Year]]>SaleExitYear,0,IF(AND(AnnualModelTable[[#This Row],[Year]]>=1,AnnualModelTable[[#This Row],[Year]]<StabilizationRefiYear),ExistingDebtServiceAnnual,IF(AND(AnnualModelTable[[#This Row],[Year]]>=StabilizationRefiYear,AnnualModelTable[[#This Row],[Year]]<=SaleExitYear),-PMT(RefinanceLoanRate/12,RefinanceLoanAmortizationYears*12,RefinanceLoanAmount)*12,0))) -> 55101.518 | H8: =IF(AnnualModelTable[[#This Row],[Year]]>SaleExitYear,0,AnnualModelTable[[#This Row],[NOI]]-AnnualModelTable[[#This Row],[Debt Service]]) -> 25250.482 | I8: =IF(AnnualModelTable[[#This Row],[Year]]>SaleExitYear,0,IF(AnnualModelTable[[#This Row],[Year]]=0,SponsorPropertyPayment,IF(AnnualModelTable[[#This Row],[Year]]=StabilizationRefiYear,MAX(0,RefinanceLoanAmount-TotalExistingDebt),IF(AnnualModelTable[[#This Row],[Year]]=SaleExitYear,MAX(0,AnnualModelTable[[#This Row],[Property Value / Refi Value]]*(1-SellingCosts)-AnnualModelTable[[#This Row],[Loan Balance]]),0)))) -> 1158675.8 | J8: =IF(AnnualModelTable[[#This Row],[Year]]>SaleExitYear,0,IF(AnnualModelTable[[#This Row],[Year]]=0,0,IFERROR(INDEX(AnnualModelTable[Ending Cash Balance],MATCH(AnnualModelTable[[#This Row],[Year]]-1,AnnualModelTable[Year],0)),0))+AnnualModelTable[[#This Row],[Current Year Cash Before Refi/Sale]]+AnnualModelTable[[#This Row],[Net Refi/Sale Proceeds]]) -> 1183926.3 | K8: =IF(AnnualModelTable[[#This Row],[Year]]>SaleExitYear,0,SUM(INDEX(WaterfallTable[Total Distribution],MATCH(AnnualModelTable[[#This Row],[Year]],WaterfallTable[Year],0)),INDEX(WaterfallTable[Total Dist],MATCH(AnnualModelTable[[#This Row],[Year]],WaterfallTable[Year],0)),INDEX(WaterfallTable[Total Dist2],MATCH(AnnualModelTable[[#This Row],[Year]],WaterfallTable[Year],0)))) -> 1183926.3 | L8: =IF(AnnualModelTable[[#This Row],[Year]]>SaleExitYear,0,MAX(0,AnnualModelTable[[#This Row],[Cash Available Before Distributions]]-AnnualModelTable[[#This Row],[Waterfall Distributions]])) -> 0 | M8: =IF(AnnualModelTable[[#This Row],[Year]]>SaleExitYear,0,IF(AnnualModelTable[[#This Row],[Year]]<StabilizationRefiYear,0,IF(AnnualModelTable[[#This Row],[Year]]=SaleExitYear,0,-FV(RefinanceLoanRate/12,(AnnualModelTable[[#This Row],[Year]]-StabilizationRefiYear)*12,PMT(RefinanceLoanRate/12,RefinanceLoanAmortizationYears*12,RefinanceLoanAmount),RefinanceLoanAmount)))) -> 0 | N8: =IF(AnnualModelTable[[#This Row],[Year]]>SaleExitYear,0,IF(AnnualModelTable[[#This Row],[Year]]<StabilizationRefiYear,0,AnnualModelTable[[#This Row],[NOI]]*(1+NOIGrowth)/ExitCapRate)) -> 1182322.3
A9: 5 | B9: Operations | C9: =IF(AnnualModelTable[[#This Row],[Year]]>SaleExitYear,0,IF(AnnualModelTable[[#This Row],[Year]]=0,0,IF(AnnualModelTable[[#This Row],[Year]]>=RentScenarioHighEffectiveYear,RentScenarioHighMonthlyGross*12,IF(AnnualModelTable[[#This Row],[Year]]>=RentScenarioMediumEffectiveYear,RentScenarioMediumMonthlyGross*12,IF(AnnualModelTable[[#This Row],[Year]]>=RentScenarioLowEffectiveYear,RentScenarioLowMonthlyGross*12,0))))) -> 0 | D9: =IF(AnnualModelTable[[#This Row],[Year]]>SaleExitYear,0,IF(AnnualModelTable[[#This Row],[Year]]=0,0,AnnualModelTable[[#This Row],[Gross Potential Rent]]*IF(AnnualModelTable[[#This Row],[Year]]=1,LeaseUpOccupancy,StabilizedOccupancy))) -> 0 | E9: =IF(AnnualModelTable[[#This Row],[Year]]>SaleExitYear,0,AnnualModelTable[[#This Row],[Effective Gross Income]]*OperatingExpenseRatio) -> 0 | F9: =IF(AnnualModelTable[[#This Row],[Year]]>SaleExitYear,0,AnnualModelTable[[#This Row],[Effective Gross Income]]-AnnualModelTable[[#This Row],[Operating Expenses]]) -> 0 | G9: =IF(AnnualModelTable[[#This Row],[Year]]>SaleExitYear,0,IF(AND(AnnualModelTable[[#This Row],[Year]]>=1,AnnualModelTable[[#This Row],[Year]]<StabilizationRefiYear),ExistingDebtServiceAnnual,IF(AND(AnnualModelTable[[#This Row],[Year]]>=StabilizationRefiYear,AnnualModelTable[[#This Row],[Year]]<=SaleExitYear),-PMT(RefinanceLoanRate/12,RefinanceLoanAmortizationYears*12,RefinanceLoanAmount)*12,0))) -> 0 | H9: =IF(AnnualModelTable[[#This Row],[Year]]>SaleExitYear,0,AnnualModelTable[[#This Row],[NOI]]-AnnualModelTable[[#This Row],[Debt Service]]) -> 0 | I9: =IF(AnnualModelTable[[#This Row],[Year]]>SaleExitYear,0,IF(AnnualModelTable[[#This Row],[Year]]=0,SponsorPropertyPayment,IF(AnnualModelTable[[#This Row],[Year]]=StabilizationRefiYear,MAX(0,RefinanceLoanAmount-TotalExistingDebt),IF(AnnualModelTable[[#This Row],[Year]]=SaleExitYear,MAX(0,AnnualModelTable[[#This Row],[Property Value / Refi Value]]*(1-SellingCosts)-AnnualModelTable[[#This Row],[Loan Balance]]),0)))) -> 0 | J9: =IF(AnnualModelTable[[#This Row],[Year]]>SaleExitYear,0,IF(AnnualModelTable[[#This Row],[Year]]=0,0,IFERROR(INDEX(AnnualModelTable[Ending Cash Balance],MATCH(AnnualModelTable[[#This Row],[Year]]-1,AnnualModelTable[Year],0)),0))+AnnualModelTable[[#This Row],[Current Year Cash Before Refi/Sale]]+AnnualModelTable[[#This Row],[Net Refi/Sale Proceeds]]) -> 0 | K9: =IF(AnnualModelTable[[#This Row],[Year]]>SaleExitYear,0,SUM(INDEX(WaterfallTable[Total Distribution],MATCH(AnnualModelTable[[#This Row],[Year]],WaterfallTable[Year],0)),INDEX(WaterfallTable[Total Dist],MATCH(AnnualModelTable[[#This Row],[Year]],WaterfallTable[Year],0)),INDEX(WaterfallTable[Total Dist2],MATCH(AnnualModelTable[[#This Row],[Year]],WaterfallTable[Year],0)))) -> 0 | L9: =IF(AnnualModelTable[[#This Row],[Year]]>SaleExitYear,0,MAX(0,AnnualModelTable[[#This Row],[Cash Available Before Distributions]]-AnnualModelTable[[#This Row],[Waterfall Distributions]])) -> 0 | M9: =IF(AnnualModelTable[[#This Row],[Year]]>SaleExitYear,0,IF(AnnualModelTable[[#This Row],[Year]]<StabilizationRefiYear,0,IF(AnnualModelTable[[#This Row],[Year]]=SaleExitYear,0,-FV(RefinanceLoanRate/12,(AnnualModelTable[[#This Row],[Year]]-StabilizationRefiYear)*12,PMT(RefinanceLoanRate/12,RefinanceLoanAmortizationYears*12,RefinanceLoanAmount),RefinanceLoanAmount)))) -> 0 | N9: =IF(AnnualModelTable[[#This Row],[Year]]>SaleExitYear,0,IF(AnnualModelTable[[#This Row],[Year]]<StabilizationRefiYear,0,AnnualModelTable[[#This Row],[NOI]]*(1+NOIGrowth)/ExitCapRate)) -> 0
A10: 6 | B10: Operations | C10: =IF(AnnualModelTable[[#This Row],[Year]]>SaleExitYear,0,IF(AnnualModelTable[[#This Row],[Year]]=0,0,IF(AnnualModelTable[[#This Row],[Year]]>=RentScenarioHighEffectiveYear,RentScenarioHighMonthlyGross*12,IF(AnnualModelTable[[#This Row],[Year]]>=RentScenarioMediumEffectiveYear,RentScenarioMediumMonthlyGross*12,IF(AnnualModelTable[[#This Row],[Year]]>=RentScenarioLowEffectiveYear,RentScenarioLowMonthlyGross*12,0))))) -> 0 | D10: =IF(AnnualModelTable[[#This Row],[Year]]>SaleExitYear,0,IF(AnnualModelTable[[#This Row],[Year]]=0,0,AnnualModelTable[[#This Row],[Gross Potential Rent]]*IF(AnnualModelTable[[#This Row],[Year]]=1,LeaseUpOccupancy,StabilizedOccupancy))) -> 0 | E10: =IF(AnnualModelTable[[#This Row],[Year]]>SaleExitYear,0,AnnualModelTable[[#This Row],[Effective Gross Income]]*OperatingExpenseRatio) -> 0 | F10: =IF(AnnualModelTable[[#This Row],[Year]]>SaleExitYear,0,AnnualModelTable[[#This Row],[Effective Gross Income]]-AnnualModelTable[[#This Row],[Operating Expenses]]) -> 0 | G10: =IF(AnnualModelTable[[#This Row],[Year]]>SaleExitYear,0,IF(AND(AnnualModelTable[[#This Row],[Year]]>=1,AnnualModelTable[[#This Row],[Year]]<StabilizationRefiYear),ExistingDebtServiceAnnual,IF(AND(AnnualModelTable[[#This Row],[Year]]>=StabilizationRefiYear,AnnualModelTable[[#This Row],[Year]]<=SaleExitYear),-PMT(RefinanceLoanRate/12,RefinanceLoanAmortizationYears*12,RefinanceLoanAmount)*12,0))) -> 0 | H10: =IF(AnnualModelTable[[#This Row],[Year]]>SaleExitYear,0,AnnualModelTable[[#This Row],[NOI]]-AnnualModelTable[[#This Row],[Debt Service]]) -> 0 | I10: =IF(AnnualModelTable[[#This Row],[Year]]>SaleExitYear,0,IF(AnnualModelTable[[#This Row],[Year]]=0,SponsorPropertyPayment,IF(AnnualModelTable[[#This Row],[Year]]=StabilizationRefiYear,MAX(0,RefinanceLoanAmount-TotalExistingDebt),IF(AnnualModelTable[[#This Row],[Year]]=SaleExitYear,MAX(0,AnnualModelTable[[#This Row],[Property Value / Refi Value]]*(1-SellingCosts)-AnnualModelTable[[#This Row],[Loan Balance]]),0)))) -> 0 | J10: =IF(AnnualModelTable[[#This Row],[Year]]>SaleExitYear,0,IF(AnnualModelTable[[#This Row],[Year]]=0,0,IFERROR(INDEX(AnnualModelTable[Ending Cash Balance],MATCH(AnnualModelTable[[#This Row],[Year]]-1,AnnualModelTable[Year],0)),0))+AnnualModelTable[[#This Row],[Current Year Cash Before Refi/Sale]]+AnnualModelTable[[#This Row],[Net Refi/Sale Proceeds]]) -> 0 | K10: =IF(AnnualModelTable[[#This Row],[Year]]>SaleExitYear,0,SUM(INDEX(WaterfallTable[Total Distribution],MATCH(AnnualModelTable[[#This Row],[Year]],WaterfallTable[Year],0)),INDEX(WaterfallTable[Total Dist],MATCH(AnnualModelTable[[#This Row],[Year]],WaterfallTable[Year],0)),INDEX(WaterfallTable[Total Dist2],MATCH(AnnualModelTable[[#This Row],[Year]],WaterfallTable[Year],0)))) -> 0 | L10: =IF(AnnualModelTable[[#This Row],[Year]]>SaleExitYear,0,MAX(0,AnnualModelTable[[#This Row],[Cash Available Before Distributions]]-AnnualModelTable[[#This Row],[Waterfall Distributions]])) -> 0 | M10: =IF(AnnualModelTable[[#This Row],[Year]]>SaleExitYear,0,IF(AnnualModelTable[[#This Row],[Year]]<StabilizationRefiYear,0,IF(AnnualModelTable[[#This Row],[Year]]=SaleExitYear,0,-FV(RefinanceLoanRate/12,(AnnualModelTable[[#This Row],[Year]]-StabilizationRefiYear)*12,PMT(RefinanceLoanRate/12,RefinanceLoanAmortizationYears*12,RefinanceLoanAmount),RefinanceLoanAmount)))) -> 0 | N10: =IF(AnnualModelTable[[#This Row],[Year]]>SaleExitYear,0,IF(AnnualModelTable[[#This Row],[Year]]<StabilizationRefiYear,0,AnnualModelTable[[#This Row],[NOI]]*(1+NOIGrowth)/ExitCapRate)) -> 0
A11: 7 | B11: Operations | C11: =IF(AnnualModelTable[[#This Row],[Year]]>SaleExitYear,0,IF(AnnualModelTable[[#This Row],[Year]]=0,0,IF(AnnualModelTable[[#This Row],[Year]]>=RentScenarioHighEffectiveYear,RentScenarioHighMonthlyGross*12,IF(AnnualModelTable[[#This Row],[Year]]>=RentScenarioMediumEffectiveYear,RentScenarioMediumMonthlyGross*12,IF(AnnualModelTable[[#This Row],[Year]]>=RentScenarioLowEffectiveYear,RentScenarioLowMonthlyGross*12,0))))) -> 0 | D11: =IF(AnnualModelTable[[#This Row],[Year]]>SaleExitYear,0,IF(AnnualModelTable[[#This Row],[Year]]=0,0,AnnualModelTable[[#This Row],[Gross Potential Rent]]*IF(AnnualModelTable[[#This Row],[Year]]=1,LeaseUpOccupancy,StabilizedOccupancy))) -> 0 | E11: =IF(AnnualModelTable[[#This Row],[Year]]>SaleExitYear,0,AnnualModelTable[[#This Row],[Effective Gross Income]]*OperatingExpenseRatio) -> 0 | F11: =IF(AnnualModelTable[[#This Row],[Year]]>SaleExitYear,0,AnnualModelTable[[#This Row],[Effective Gross Income]]-AnnualModelTable[[#This Row],[Operating Expenses]]) -> 0 | G11: =IF(AnnualModelTable[[#This Row],[Year]]>SaleExitYear,0,IF(AND(AnnualModelTable[[#This Row],[Year]]>=1,AnnualModelTable[[#This Row],[Year]]<StabilizationRefiYear),ExistingDebtServiceAnnual,IF(AND(AnnualModelTable[[#This Row],[Year]]>=StabilizationRefiYear,AnnualModelTable[[#This Row],[Year]]<=SaleExitYear),-PMT(RefinanceLoanRate/12,RefinanceLoanAmortizationYears*12,RefinanceLoanAmount)*12,0))) -> 0 | H11: =IF(AnnualModelTable[[#This Row],[Year]]>SaleExitYear,0,AnnualModelTable[[#This Row],[NOI]]-AnnualModelTable[[#This Row],[Debt Service]]) -> 0 | I11: =IF(AnnualModelTable[[#This Row],[Year]]>SaleExitYear,0,IF(AnnualModelTable[[#This Row],[Year]]=0,SponsorPropertyPayment,IF(AnnualModelTable[[#This Row],[Year]]=StabilizationRefiYear,MAX(0,RefinanceLoanAmount-TotalExistingDebt),IF(AnnualModelTable[[#This Row],[Year]]=SaleExitYear,MAX(0,AnnualModelTable[[#This Row],[Property Value / Refi Value]]*(1-SellingCosts)-AnnualModelTable[[#This Row],[Loan Balance]]),0)))) -> 0 | J11: =IF(AnnualModelTable[[#This Row],[Year]]>SaleExitYear,0,IF(AnnualModelTable[[#This Row],[Year]]=0,0,IFERROR(INDEX(AnnualModelTable[Ending Cash Balance],MATCH(AnnualModelTable[[#This Row],[Year]]-1,AnnualModelTable[Year],0)),0))+AnnualModelTable[[#This Row],[Current Year Cash Before Refi/Sale]]+AnnualModelTable[[#This Row],[Net Refi/Sale Proceeds]]) -> 0 | K11: =IF(AnnualModelTable[[#This Row],[Year]]>SaleExitYear,0,SUM(INDEX(WaterfallTable[Total Distribution],MATCH(AnnualModelTable[[#This Row],[Year]],WaterfallTable[Year],0)),INDEX(WaterfallTable[Total Dist],MATCH(AnnualModelTable[[#This Row],[Year]],WaterfallTable[Year],0)),INDEX(WaterfallTable[Total Dist2],MATCH(AnnualModelTable[[#This Row],[Year]],WaterfallTable[Year],0)))) -> 0 | L11: =IF(AnnualModelTable[[#This Row],[Year]]>SaleExitYear,0,MAX(0,AnnualModelTable[[#This Row],[Cash Available Before Distributions]]-AnnualModelTable[[#This Row],[Waterfall Distributions]])) -> 0 | M11: =IF(AnnualModelTable[[#This Row],[Year]]>SaleExitYear,0,IF(AnnualModelTable[[#This Row],[Year]]<StabilizationRefiYear,0,IF(AnnualModelTable[[#This Row],[Year]]=SaleExitYear,0,-FV(RefinanceLoanRate/12,(AnnualModelTable[[#This Row],[Year]]-StabilizationRefiYear)*12,PMT(RefinanceLoanRate/12,RefinanceLoanAmortizationYears*12,RefinanceLoanAmount),RefinanceLoanAmount)))) -> 0 | N11: =IF(AnnualModelTable[[#This Row],[Year]]>SaleExitYear,0,IF(AnnualModelTable[[#This Row],[Year]]<StabilizationRefiYear,0,AnnualModelTable[[#This Row],[NOI]]*(1+NOIGrowth)/ExitCapRate)) -> 0
A12: 8 | B12: Operations | C12: =IF(AnnualModelTable[[#This Row],[Year]]>SaleExitYear,0,IF(AnnualModelTable[[#This Row],[Year]]=0,0,IF(AnnualModelTable[[#This Row],[Year]]>=RentScenarioHighEffectiveYear,RentScenarioHighMonthlyGross*12,IF(AnnualModelTable[[#This Row],[Year]]>=RentScenarioMediumEffectiveYear,RentScenarioMediumMonthlyGross*12,IF(AnnualModelTable[[#This Row],[Year]]>=RentScenarioLowEffectiveYear,RentScenarioLowMonthlyGross*12,0))))) -> 0 | D12: =IF(AnnualModelTable[[#This Row],[Year]]>SaleExitYear,0,IF(AnnualModelTable[[#This Row],[Year]]=0,0,AnnualModelTable[[#This Row],[Gross Potential Rent]]*IF(AnnualModelTable[[#This Row],[Year]]=1,LeaseUpOccupancy,StabilizedOccupancy))) -> 0 | E12: =IF(AnnualModelTable[[#This Row],[Year]]>SaleExitYear,0,AnnualModelTable[[#This Row],[Effective Gross Income]]*OperatingExpenseRatio) -> 0 | F12: =IF(AnnualModelTable[[#This Row],[Year]]>SaleExitYear,0,AnnualModelTable[[#This Row],[Effective Gross Income]]-AnnualModelTable[[#This Row],[Operating Expenses]]) -> 0 | G12: =IF(AnnualModelTable[[#This Row],[Year]]>SaleExitYear,0,IF(AND(AnnualModelTable[[#This Row],[Year]]>=1,AnnualModelTable[[#This Row],[Year]]<StabilizationRefiYear),ExistingDebtServiceAnnual,IF(AND(AnnualModelTable[[#This Row],[Year]]>=StabilizationRefiYear,AnnualModelTable[[#This Row],[Year]]<=SaleExitYear),-PMT(RefinanceLoanRate/12,RefinanceLoanAmortizationYears*12,RefinanceLoanAmount)*12,0))) -> 0 | H12: =IF(AnnualModelTable[[#This Row],[Year]]>SaleExitYear,0,AnnualModelTable[[#This Row],[NOI]]-AnnualModelTable[[#This Row],[Debt Service]]) -> 0 | I12: =IF(AnnualModelTable[[#This Row],[Year]]>SaleExitYear,0,IF(AnnualModelTable[[#This Row],[Year]]=0,SponsorPropertyPayment,IF(AnnualModelTable[[#This Row],[Year]]=StabilizationRefiYear,MAX(0,RefinanceLoanAmount-TotalExistingDebt),IF(AnnualModelTable[[#This Row],[Year]]=SaleExitYear,MAX(0,AnnualModelTable[[#This Row],[Property Value / Refi Value]]*(1-SellingCosts)-AnnualModelTable[[#This Row],[Loan Balance]]),0)))) -> 0 | J12: =IF(AnnualModelTable[[#This Row],[Year]]>SaleExitYear,0,IF(AnnualModelTable[[#This Row],[Year]]=0,0,IFERROR(INDEX(AnnualModelTable[Ending Cash Balance],MATCH(AnnualModelTable[[#This Row],[Year]]-1,AnnualModelTable[Year],0)),0))+AnnualModelTable[[#This Row],[Current Year Cash Before Refi/Sale]]+AnnualModelTable[[#This Row],[Net Refi/Sale Proceeds]]) -> 0 | K12: =IF(AnnualModelTable[[#This Row],[Year]]>SaleExitYear,0,SUM(INDEX(WaterfallTable[Total Distribution],MATCH(AnnualModelTable[[#This Row],[Year]],WaterfallTable[Year],0)),INDEX(WaterfallTable[Total Dist],MATCH(AnnualModelTable[[#This Row],[Year]],WaterfallTable[Year],0)),INDEX(WaterfallTable[Total Dist2],MATCH(AnnualModelTable[[#This Row],[Year]],WaterfallTable[Year],0)))) -> 0 | L12: =IF(AnnualModelTable[[#This Row],[Year]]>SaleExitYear,0,MAX(0,AnnualModelTable[[#This Row],[Cash Available Before Distributions]]-AnnualModelTable[[#This Row],[Waterfall Distributions]])) -> 0 | M12: =IF(AnnualModelTable[[#This Row],[Year]]>SaleExitYear,0,IF(AnnualModelTable[[#This Row],[Year]]<StabilizationRefiYear,0,IF(AnnualModelTable[[#This Row],[Year]]=SaleExitYear,0,-FV(RefinanceLoanRate/12,(AnnualModelTable[[#This Row],[Year]]-StabilizationRefiYear)*12,PMT(RefinanceLoanRate/12,RefinanceLoanAmortizationYears*12,RefinanceLoanAmount),RefinanceLoanAmount)))) -> 0 | N12: =IF(AnnualModelTable[[#This Row],[Year]]>SaleExitYear,0,IF(AnnualModelTable[[#This Row],[Year]]<StabilizationRefiYear,0,AnnualModelTable[[#This Row],[NOI]]*(1+NOIGrowth)/ExitCapRate)) -> 0
A13: 9 | B13: Operations | C13: =IF(AnnualModelTable[[#This Row],[Year]]>SaleExitYear,0,IF(AnnualModelTable[[#This Row],[Year]]=0,0,IF(AnnualModelTable[[#This Row],[Year]]>=RentScenarioHighEffectiveYear,RentScenarioHighMonthlyGross*12,IF(AnnualModelTable[[#This Row],[Year]]>=RentScenarioMediumEffectiveYear,RentScenarioMediumMonthlyGross*12,IF(AnnualModelTable[[#This Row],[Year]]>=RentScenarioLowEffectiveYear,RentScenarioLowMonthlyGross*12,0))))) -> 0 | D13: =IF(AnnualModelTable[[#This Row],[Year]]>SaleExitYear,0,IF(AnnualModelTable[[#This Row],[Year]]=0,0,AnnualModelTable[[#This Row],[Gross Potential Rent]]*IF(AnnualModelTable[[#This Row],[Year]]=1,LeaseUpOccupancy,StabilizedOccupancy))) -> 0 | E13: =IF(AnnualModelTable[[#This Row],[Year]]>SaleExitYear,0,AnnualModelTable[[#This Row],[Effective Gross Income]]*OperatingExpenseRatio) -> 0 | F13: =IF(AnnualModelTable[[#This Row],[Year]]>SaleExitYear,0,AnnualModelTable[[#This Row],[Effective Gross Income]]-AnnualModelTable[[#This Row],[Operating Expenses]]) -> 0 | G13: =IF(AnnualModelTable[[#This Row],[Year]]>SaleExitYear,0,IF(AND(AnnualModelTable[[#This Row],[Year]]>=1,AnnualModelTable[[#This Row],[Year]]<StabilizationRefiYear),ExistingDebtServiceAnnual,IF(AND(AnnualModelTable[[#This Row],[Year]]>=StabilizationRefiYear,AnnualModelTable[[#This Row],[Year]]<=SaleExitYear),-PMT(RefinanceLoanRate/12,RefinanceLoanAmortizationYears*12,RefinanceLoanAmount)*12,0))) -> 0 | H13: =IF(AnnualModelTable[[#This Row],[Year]]>SaleExitYear,0,AnnualModelTable[[#This Row],[NOI]]-AnnualModelTable[[#This Row],[Debt Service]]) -> 0 | I13: =IF(AnnualModelTable[[#This Row],[Year]]>SaleExitYear,0,IF(AnnualModelTable[[#This Row],[Year]]=0,SponsorPropertyPayment,IF(AnnualModelTable[[#This Row],[Year]]=StabilizationRefiYear,MAX(0,RefinanceLoanAmount-TotalExistingDebt),IF(AnnualModelTable[[#This Row],[Year]]=SaleExitYear,MAX(0,AnnualModelTable[[#This Row],[Property Value / Refi Value]]*(1-SellingCosts)-AnnualModelTable[[#This Row],[Loan Balance]]),0)))) -> 0 | J13: =IF(AnnualModelTable[[#This Row],[Year]]>SaleExitYear,0,IF(AnnualModelTable[[#This Row],[Year]]=0,0,IFERROR(INDEX(AnnualModelTable[Ending Cash Balance],MATCH(AnnualModelTable[[#This Row],[Year]]-1,AnnualModelTable[Year],0)),0))+AnnualModelTable[[#This Row],[Current Year Cash Before Refi/Sale]]+AnnualModelTable[[#This Row],[Net Refi/Sale Proceeds]]) -> 0 | K13: =IF(AnnualModelTable[[#This Row],[Year]]>SaleExitYear,0,SUM(INDEX(WaterfallTable[Total Distribution],MATCH(AnnualModelTable[[#This Row],[Year]],WaterfallTable[Year],0)),INDEX(WaterfallTable[Total Dist],MATCH(AnnualModelTable[[#This Row],[Year]],WaterfallTable[Year],0)),INDEX(WaterfallTable[Total Dist2],MATCH(AnnualModelTable[[#This Row],[Year]],WaterfallTable[Year],0)))) -> 0 | L13: =IF(AnnualModelTable[[#This Row],[Year]]>SaleExitYear,0,MAX(0,AnnualModelTable[[#This Row],[Cash Available Before Distributions]]-AnnualModelTable[[#This Row],[Waterfall Distributions]])) -> 0 | M13: =IF(AnnualModelTable[[#This Row],[Year]]>SaleExitYear,0,IF(AnnualModelTable[[#This Row],[Year]]<StabilizationRefiYear,0,IF(AnnualModelTable[[#This Row],[Year]]=SaleExitYear,0,-FV(RefinanceLoanRate/12,(AnnualModelTable[[#This Row],[Year]]-StabilizationRefiYear)*12,PMT(RefinanceLoanRate/12,RefinanceLoanAmortizationYears*12,RefinanceLoanAmount),RefinanceLoanAmount)))) -> 0 | N13: =IF(AnnualModelTable[[#This Row],[Year]]>SaleExitYear,0,IF(AnnualModelTable[[#This Row],[Year]]<StabilizationRefiYear,0,AnnualModelTable[[#This Row],[NOI]]*(1+NOIGrowth)/ExitCapRate)) -> 0
A14: 10 | B14: Exit | C14: =IF(AnnualModelTable[[#This Row],[Year]]>SaleExitYear,0,IF(AnnualModelTable[[#This Row],[Year]]=0,0,IF(AnnualModelTable[[#This Row],[Year]]>=RentScenarioHighEffectiveYear,RentScenarioHighMonthlyGross*12,IF(AnnualModelTable[[#This Row],[Year]]>=RentScenarioMediumEffectiveYear,RentScenarioMediumMonthlyGross*12,IF(AnnualModelTable[[#This Row],[Year]]>=RentScenarioLowEffectiveYear,RentScenarioLowMonthlyGross*12,0))))) -> 0 | D14: =IF(AnnualModelTable[[#This Row],[Year]]>SaleExitYear,0,IF(AnnualModelTable[[#This Row],[Year]]=0,0,AnnualModelTable[[#This Row],[Gross Potential Rent]]*IF(AnnualModelTable[[#This Row],[Year]]=1,LeaseUpOccupancy,StabilizedOccupancy))) -> 0 | E14: =IF(AnnualModelTable[[#This Row],[Year]]>SaleExitYear,0,AnnualModelTable[[#This Row],[Effective Gross Income]]*OperatingExpenseRatio) -> 0 | F14: =IF(AnnualModelTable[[#This Row],[Year]]>SaleExitYear,0,AnnualModelTable[[#This Row],[Effective Gross Income]]-AnnualModelTable[[#This Row],[Operating Expenses]]) -> 0 | G14: =IF(AnnualModelTable[[#This Row],[Year]]>SaleExitYear,0,IF(AND(AnnualModelTable[[#This Row],[Year]]>=1,AnnualModelTable[[#This Row],[Year]]<StabilizationRefiYear),ExistingDebtServiceAnnual,IF(AND(AnnualModelTable[[#This Row],[Year]]>=StabilizationRefiYear,AnnualModelTable[[#This Row],[Year]]<=SaleExitYear),-PMT(RefinanceLoanRate/12,RefinanceLoanAmortizationYears*12,RefinanceLoanAmount)*12,0))) -> 0 | H14: =IF(AnnualModelTable[[#This Row],[Year]]>SaleExitYear,0,AnnualModelTable[[#This Row],[NOI]]-AnnualModelTable[[#This Row],[Debt Service]]) -> 0 | I14: =IF(AnnualModelTable[[#This Row],[Year]]>SaleExitYear,0,IF(AnnualModelTable[[#This Row],[Year]]=0,SponsorPropertyPayment,IF(AnnualModelTable[[#This Row],[Year]]=StabilizationRefiYear,MAX(0,RefinanceLoanAmount-TotalExistingDebt),IF(AnnualModelTable[[#This Row],[Year]]=SaleExitYear,MAX(0,AnnualModelTable[[#This Row],[Property Value / Refi Value]]*(1-SellingCosts)-AnnualModelTable[[#This Row],[Loan Balance]]),0)))) -> 0 | J14: =IF(AnnualModelTable[[#This Row],[Year]]>SaleExitYear,0,IF(AnnualModelTable[[#This Row],[Year]]=0,0,IFERROR(INDEX(AnnualModelTable[Ending Cash Balance],MATCH(AnnualModelTable[[#This Row],[Year]]-1,AnnualModelTable[Year],0)),0))+AnnualModelTable[[#This Row],[Current Year Cash Before Refi/Sale]]+AnnualModelTable[[#This Row],[Net Refi/Sale Proceeds]]) -> 0 | K14: =IF(AnnualModelTable[[#This Row],[Year]]>SaleExitYear,0,SUM(INDEX(WaterfallTable[Total Distribution],MATCH(AnnualModelTable[[#This Row],[Year]],WaterfallTable[Year],0)),INDEX(WaterfallTable[Total Dist],MATCH(AnnualModelTable[[#This Row],[Year]],WaterfallTable[Year],0)),INDEX(WaterfallTable[Total Dist2],MATCH(AnnualModelTable[[#This Row],[Year]],WaterfallTable[Year],0)))) -> 0 | L14: =IF(AnnualModelTable[[#This Row],[Year]]>SaleExitYear,0,MAX(0,AnnualModelTable[[#This Row],[Cash Available Before Distributions]]-AnnualModelTable[[#This Row],[Waterfall Distributions]])) -> 0 | M14: =IF(AnnualModelTable[[#This Row],[Year]]>SaleExitYear,0,IF(AnnualModelTable[[#This Row],[Year]]<StabilizationRefiYear,0,IF(AnnualModelTable[[#This Row],[Year]]=SaleExitYear,0,-FV(RefinanceLoanRate/12,(AnnualModelTable[[#This Row],[Year]]-StabilizationRefiYear)*12,PMT(RefinanceLoanRate/12,RefinanceLoanAmortizationYears*12,RefinanceLoanAmount),RefinanceLoanAmount)))) -> 0 | N14: =IF(AnnualModelTable[[#This Row],[Year]]>SaleExitYear,0,IF(AnnualModelTable[[#This Row],[Year]]<StabilizationRefiYear,0,AnnualModelTable[[#This Row],[NOI]]*(1+NOIGrowth)/ExitCapRate)) -> 0

Sheet Waterfall
A1: Annual Waterfall
C2: Class A | J2: Class B | N2: Sponsor
A3: Year | B3: Cash Available | C3: Pref Accrued | D3: Pref Paid | E3: End of Year Pref Balance | F3: A Capital Balance | G3: A Capital Returned | H3: A Residual | I3: Total Distribution | J3: B Capital Balance | K3: B Capital Returned | L3: B Residual | M3: Total Dist | N3: Property Payment | O3: Residual | P3: Total Dist2 | R3: 4
A4: 0 | B4: =IF(WaterfallTable[[#This Row],[Year]]>SaleExitYear,0,INDEX(AnnualModelTable[Cash Available Before Distributions],MATCH(WaterfallTable[[#This Row],[Year]],AnnualModelTable[Year],0))) -> 150000 | C4: =IF(WaterfallTable[[#This Row],[Year]]>SaleExitYear,0,WaterfallTable[[#This Row],[A Capital Balance]]*ClassAPreferredReturn) -> 24000 | D4: =IF(WaterfallTable[[#This Row],[Year]]>SaleExitYear,0,IF(WaterfallTable[[#This Row],[Year]]=0,0,MIN(WaterfallTable[[#This Row],[Cash Available]],0+WaterfallTable[[#This Row],[Pref Accrued]]))) -> 0 | E4: =IF(WaterfallTable[[#This Row],[Year]]>SaleExitYear,0,MAX(0,0+WaterfallTable[[#This Row],[Pref Accrued]]-WaterfallTable[[#This Row],[Pref Paid]])) -> 24000 | F4: =IF(WaterfallTable[[#This Row],[Year]]>SaleExitYear,0,ClassACapital) -> 300000 | G4: =IF(WaterfallTable[[#This Row],[Year]]>SaleExitYear,0,IF(WaterfallTable[[#This Row],[Year]]=0,0,MIN(MAX(0,WaterfallTable[[#This Row],[Cash Available]]-WaterfallTable[[#This Row],[Pref Paid]]),WaterfallTable[[#This Row],[A Capital Balance]]))) -> 0 | H4: =IF(WaterfallTable[[#This Row],[Year]]>SaleExitYear,0,IF(WaterfallTable[[#This Row],[Year]]=0,0,MAX(0,WaterfallTable[[#This Row],[Cash Available]]-WaterfallTable[[#This Row],[Pref Paid]]-WaterfallTable[[#This Row],[A Capital Returned]]-WaterfallTable[[#This Row],[B Capital Returned]])*ClassAResidualShare)) -> 0 | I4: =IF(WaterfallTable[[#This Row],[Year]]>SaleExitYear,0,WaterfallTable[[#This Row],[Pref Paid]]+WaterfallTable[[#This Row],[A Capital Returned]]+WaterfallTable[[#This Row],[A Residual]]) -> 0 | J4: =IF(WaterfallTable[[#This Row],[Year]]>SaleExitYear,0,ClassBCapital) -> 597500 | K4: =IF(WaterfallTable[[#This Row],[Year]]>SaleExitYear,0,IF(WaterfallTable[[#This Row],[Year]]=0,0,IF(ClassBReturnPriority=1,MIN(MAX(0,WaterfallTable[[#This Row],[Cash Available]]-WaterfallTable[[#This Row],[Pref Paid]]-WaterfallTable[[#This Row],[A Capital Returned]]),WaterfallTable[[#This Row],[B Capital Balance]]),0))) -> 0 | L4: =IF(WaterfallTable[[#This Row],[Year]]>SaleExitYear,0,IF(WaterfallTable[[#This Row],[Year]]=0,0,MAX(0,WaterfallTable[[#This Row],[Cash Available]]-WaterfallTable[[#This Row],[Pref Paid]]-WaterfallTable[[#This Row],[A Capital Returned]]-WaterfallTable[[#This Row],[B Capital Returned]])*ClassBResidualShare)) -> 0 | M4: =IF(WaterfallTable[[#This Row],[Year]]>SaleExitYear,0,WaterfallTable[[#This Row],[B Capital Returned]]+WaterfallTable[[#This Row],[B Residual]]) -> 0 | N4: =IF(WaterfallTable[[#This Row],[Year]]>SaleExitYear,0,IF(WaterfallTable[[#This Row],[Year]]=0,SponsorPropertyPayment,0)) -> 150000 | O4: =IF(WaterfallTable[[#This Row],[Year]]>SaleExitYear,0,IF(WaterfallTable[[#This Row],[Year]]=0,0,MAX(0,WaterfallTable[[#This Row],[Cash Available]]-WaterfallTable[[#This Row],[Pref Paid]]-WaterfallTable[[#This Row],[A Capital Returned]]-WaterfallTable[[#This Row],[B Capital Returned]])*SponsorResidualShare)) -> 0 | P4: =IF(WaterfallTable[[#This Row],[Year]]>SaleExitYear,0,WaterfallTable[[#This Row],[Property Payment]]+WaterfallTable[[#This Row],[Residual]]) -> 150000
A5: 1 | B5: =IF(WaterfallTable[[#This Row],[Year]]>SaleExitYear,0,INDEX(AnnualModelTable[Cash Available Before Distributions],MATCH(WaterfallTable[[#This Row],[Year]],AnnualModelTable[Year],0))) -> 17868 | C5: =IF(WaterfallTable[[#This Row],[Year]]>SaleExitYear,0,WaterfallTable[[#This Row],[A Capital Balance]]*ClassAPreferredReturn) -> 24000 | D5: =IF(WaterfallTable[[#This Row],[Year]]>SaleExitYear,0,IF(WaterfallTable[[#This Row],[Year]]=0,0,MIN(WaterfallTable[[#This Row],[Cash Available]],INDEX(WaterfallTable[End of Year Pref Balance],1)+WaterfallTable[[#This Row],[Pref Accrued]]))) -> 17868 | E5: =IF(WaterfallTable[[#This Row],[Year]]>SaleExitYear,0,MAX(0,INDEX(WaterfallTable[End of Year Pref Balance],1)+WaterfallTable[[#This Row],[Pref Accrued]]-WaterfallTable[[#This Row],[Pref Paid]])) -> 30132 | F5: =IF(WaterfallTable[[#This Row],[Year]]>SaleExitYear,0,MAX(0,INDEX(WaterfallTable[A Capital Balance],1)-INDEX(WaterfallTable[A Capital Returned],1))) -> 300000 | G5: =IF(WaterfallTable[[#This Row],[Year]]>SaleExitYear,0,IF(WaterfallTable[[#This Row],[Year]]=0,0,MIN(MAX(0,WaterfallTable[[#This Row],[Cash Available]]-WaterfallTable[[#This Row],[Pref Paid]]),WaterfallTable[[#This Row],[A Capital Balance]]))) -> 0 | H5: =IF(WaterfallTable[[#This Row],[Year]]>SaleExitYear,0,IF(WaterfallTable[[#This Row],[Year]]=0,0,MAX(0,WaterfallTable[[#This Row],[Cash Available]]-WaterfallTable[[#This Row],[Pref Paid]]-WaterfallTable[[#This Row],[A Capital Returned]]-WaterfallTable[[#This Row],[B Capital Returned]])*ClassAResidualShare)) -> 0 | I5: =IF(WaterfallTable[[#This Row],[Year]]>SaleExitYear,0,WaterfallTable[[#This Row],[Pref Paid]]+WaterfallTable[[#This Row],[A Capital Returned]]+WaterfallTable[[#This Row],[A Residual]]) -> 17868 | J5: =IF(WaterfallTable[[#This Row],[Year]]>SaleExitYear,0,MAX(0,INDEX(WaterfallTable[B Capital Balance],1)-INDEX(WaterfallTable[B Capital Returned],1))) -> 597500 | K5: =IF(WaterfallTable[[#This Row],[Year]]>SaleExitYear,0,IF(WaterfallTable[[#This Row],[Year]]=0,0,IF(ClassBReturnPriority=1,MIN(MAX(0,WaterfallTable[[#This Row],[Cash Available]]-WaterfallTable[[#This Row],[Pref Paid]]-WaterfallTable[[#This Row],[A Capital Returned]]),WaterfallTable[[#This Row],[B Capital Balance]]),0))) -> 0 | L5: =IF(WaterfallTable[[#This Row],[Year]]>SaleExitYear,0,IF(WaterfallTable[[#This Row],[Year]]=0,0,MAX(0,WaterfallTable[[#This Row],[Cash Available]]-WaterfallTable[[#This Row],[Pref Paid]]-WaterfallTable[[#This Row],[A Capital Returned]]-WaterfallTable[[#This Row],[B Capital Returned]])*ClassBResidualShare)) -> 0 | M5: =IF(WaterfallTable[[#This Row],[Year]]>SaleExitYear,0,WaterfallTable[[#This Row],[B Capital Returned]]+WaterfallTable[[#This Row],[B Residual]]) -> 0 | N5: =IF(WaterfallTable[[#This Row],[Year]]>SaleExitYear,0,IF(WaterfallTable[[#This Row],[Year]]=0,SponsorPropertyPayment,0)) -> 0 | O5: =IF(WaterfallTable[[#This Row],[Year]]>SaleExitYear,0,IF(WaterfallTable[[#This Row],[Year]]=0,0,MAX(0,WaterfallTable[[#This Row],[Cash Available]]-WaterfallTable[[#This Row],[Pref Paid]]-WaterfallTable[[#This Row],[A Capital Returned]]-WaterfallTable[[#This Row],[B Capital Returned]])*SponsorResidualShare)) -> 0 | P5: =IF(WaterfallTable[[#This Row],[Year]]>SaleExitYear,0,WaterfallTable[[#This Row],[Property Payment]]+WaterfallTable[[#This Row],[Residual]]) -> 0
A6: 2 | B6: =IF(WaterfallTable[[#This Row],[Year]]>SaleExitYear,0,INDEX(AnnualModelTable[Cash Available Before Distributions],MATCH(WaterfallTable[[#This Row],[Year]],AnnualModelTable[Year],0))) -> 549686.64 | C6: =IF(WaterfallTable[[#This Row],[Year]]>SaleExitYear,0,WaterfallTable[[#This Row],[A Capital Balance]]*ClassAPreferredReturn) -> 24000 | D6: =IF(WaterfallTable[[#This Row],[Year]]>SaleExitYear,0,IF(WaterfallTable[[#This Row],[Year]]=0,0,MIN(WaterfallTable[[#This Row],[Cash Available]],INDEX(WaterfallTable[End of Year Pref Balance],2)+WaterfallTable[[#This Row],[Pref Accrued]]))) -> 54132 | E6: =IF(WaterfallTable[[#This Row],[Year]]>SaleExitYear,0,MAX(0,INDEX(WaterfallTable[End of Year Pref Balance],2)+WaterfallTable[[#This Row],[Pref Accrued]]-WaterfallTable[[#This Row],[Pref Paid]])) -> 0 | F6: =IF(WaterfallTable[[#This Row],[Year]]>SaleExitYear,0,MAX(0,INDEX(WaterfallTable[A Capital Balance],2)-INDEX(WaterfallTable[A Capital Returned],2))) -> 300000 | G6: =IF(WaterfallTable[[#This Row],[Year]]>SaleExitYear,0,IF(WaterfallTable[[#This Row],[Year]]=0,0,MIN(MAX(0,WaterfallTable[[#This Row],[Cash Available]]-WaterfallTable[[#This Row],[Pref Paid]]),WaterfallTable[[#This Row],[A Capital Balance]]))) -> 300000 | H6: =IF(WaterfallTable[[#This Row],[Year]]>SaleExitYear,0,IF(WaterfallTable[[#This Row],[Year]]=0,0,MAX(0,WaterfallTable[[#This Row],[Cash Available]]-WaterfallTable[[#This Row],[Pref Paid]]-WaterfallTable[[#This Row],[A Capital Returned]]-WaterfallTable[[#This Row],[B Capital Returned]])*ClassAResidualShare)) -> 0 | I6: =IF(WaterfallTable[[#This Row],[Year]]>SaleExitYear,0,WaterfallTable[[#This Row],[Pref Paid]]+WaterfallTable[[#This Row],[A Capital Returned]]+WaterfallTable[[#This Row],[A Residual]]) -> 354132 | J6: =IF(WaterfallTable[[#This Row],[Year]]>SaleExitYear,0,MAX(0,INDEX(WaterfallTable[B Capital Balance],2)-INDEX(WaterfallTable[B Capital Returned],2))) -> 597500 | K6: =IF(WaterfallTable[[#This Row],[Year]]>SaleExitYear,0,IF(WaterfallTable[[#This Row],[Year]]=0,0,IF(ClassBReturnPriority=1,MIN(MAX(0,WaterfallTable[[#This Row],[Cash Available]]-WaterfallTable[[#This Row],[Pref Paid]]-WaterfallTable[[#This Row],[A Capital Returned]]),WaterfallTable[[#This Row],[B Capital Balance]]),0))) -> 195554.64 | L6: =IF(WaterfallTable[[#This Row],[Year]]>SaleExitYear,0,IF(WaterfallTable[[#This Row],[Year]]=0,0,MAX(0,WaterfallTable[[#This Row],[Cash Available]]-WaterfallTable[[#This Row],[Pref Paid]]-WaterfallTable[[#This Row],[A Capital Returned]]-WaterfallTable[[#This Row],[B Capital Returned]])*ClassBResidualShare)) -> 0 | M6: =IF(WaterfallTable[[#This Row],[Year]]>SaleExitYear,0,WaterfallTable[[#This Row],[B Capital Returned]]+WaterfallTable[[#This Row],[B Residual]]) -> 195554.64 | N6: =IF(WaterfallTable[[#This Row],[Year]]>SaleExitYear,0,IF(WaterfallTable[[#This Row],[Year]]=0,SponsorPropertyPayment,0)) -> 0 | O6: =IF(WaterfallTable[[#This Row],[Year]]>SaleExitYear,0,IF(WaterfallTable[[#This Row],[Year]]=0,0,MAX(0,WaterfallTable[[#This Row],[Cash Available]]-WaterfallTable[[#This Row],[Pref Paid]]-WaterfallTable[[#This Row],[A Capital Returned]]-WaterfallTable[[#This Row],[B Capital Returned]])*SponsorResidualShare)) -> 0 | P6: =IF(WaterfallTable[[#This Row],[Year]]>SaleExitYear,0,WaterfallTable[[#This Row],[Property Payment]]+WaterfallTable[[#This Row],[Residual]]) -> 0
