Workbook
Name AnnualManagementFee: 'Operating Expense Budget'!$B$15
Name AssumedOperatingExpenseRatio: 'Operating Expense Budget'!$B$5
Name CalculatedOperatingExpenseRatio: 'Operating Expense Budget'!$B$6
Name ClassACapital: Assumptions!$B$39
Name ClassAPreferredReturn: Assumptions!$B$40
Name ClassAResidualShare: Assumptions!$B$44
Name ClassBCapital: Assumptions!$B$41
Name ClassBResidualShare: Assumptions!$B$45
Name ClassBReturnPriority: Assumptions!$B$42
Name CoLivingSuiteRent: Assumptions!$B$11
Name CoLivingSuiteRentHigh: Assumptions!$G$10
Name CoLivingSuiteRentLow: Assumptions!$E$10
Name CoLivingSuiteRentMedium: Assumptions!$F$10
Name CoLivingSuites: Assumptions!$B$10
Name ExistingDebtServiceAnnual: Assumptions!$B$28
Name ExistingFirstMortgage: Assumptions!$B$20
Name ExistingFirstMortgageAnnualPayment: Assumptions!$B$26
Name ExistingFirstMortgageMonthlyPI: Assumptions!$B$25
Name ExistingFirstMortgagePrincipal: Assumptions!$B$20
Name ExistingFirstMortgageRate: Assumptions!$B$21
Name ExitCapRate: Assumptions!$B$35
Name LeaseUpOccupancy: Assumptions!$B$14
Name ManagementFeeRate: 'Operating Expense Budget'!$D$15
Name NOIGrowth: Assumptions!$B$16
Name OperatingExpenseRatio: Assumptions!$B$15
Name OtherMonthlyIncome: Assumptions!$B$12
Name PermanentLoanAmortizationYears: Assumptions!$B$34
Name PermanentLoanAmount: Assumptions!$B$30
Name PermanentLoanRate: Assumptions!$B$33
Name PremiumSuiteRent: Assumptions!$B$9
Name PremiumSuiteRentHigh: Assumptions!$G$9
Name PremiumSuiteRentLow: Assumptions!$E$9
Name PremiumSuiteRentMedium: Assumptions!$F$9
Name PremiumSuites: Assumptions!$B$8
Name PrivateDebtAnnualInterestPayment: Assumptions!$B$27
Name PrivateDebtInterestRate: Assumptions!$B$23
Name PrivateDebtPrincipal: Assumptions!$B$22
Name ProjectDebtPayoffAtRefi: Assumptions!$B$24
Name RefinanceLoanAmortizationYears: Assumptions!$B$34
Name RefinanceLoanAmount: Assumptions!$B$30
Name RefinanceLoanRate: Assumptions!$B$33
Name RefinanceLoanToValueCap: Assumptions!$B$29
Name RefinanceProceedsAfterDebtAndClassA: Assumptions!$B$32
Name RefinanceProceedsAfterExistingDebt: Assumptions!$B$31
Name RentScenarioAverageMonthlyGross: Assumptions!$H$11
Name RentScenarioHighEffectiveYear: Assumptions!$G$12
Name RentScenarioHighMonthlyGross: Assumptions!$G$11
Name RentScenarioLowEffectiveYear: Assumptions!$E$12
Name RentScenarioLowMonthlyGross: Assumptions!$E$11
Name RentScenarioMediumEffectiveYear: Assumptions!$F$12
Name RentScenarioMediumMonthlyGross: Assumptions!$F$11
Name RepairsMaintenanceReserveTarget: 'Operating Expense Budget'!$B$20
Name SaleExitYear: Assumptions!$B$5
Name SelectedAnnualGrossRent: 'STR Scenarios'!$L$25:$L$34
Name SelectedCostCase: 'Cost Analysis'!$E$8
Name SelectedCostCaseId: 'Cost Analysis'!$D$11
Name SelectedOperatingExpenseRatio: 'Operating Expense Budget'!$B$7
Name SelectedOperatingScenario: 'STR Scenarios'!$D$4
Name SelectedOperatingScenarioId: 'STR Scenarios'!$H$4
Name SelectedProjectCost: 'Cost Analysis'!$G$10

Sheet STR Notes
A1: STR Experimental Workbook Notes
A3: This workbook is an experimental copy of the investor ROI model. The original workbook is not modified.
A5: The STR Scenarios tab lets the Annual Model switch between Base Co-Living / Medium-Term, One Floor STR + One Floor Co-Living, and Whole Building STR.
A7: STR outputs are modeled as annual gross rent after platform/lodging cost haircut and turnover cost allowance. Operating expenses still flow through the existing Operating Expense Budget unless separately revised.
A9: Use this copy for sensitivity testing. If the STR approach is abandoned, return to the original workbook.

Sheet STR Scenarios
A1: 3325 Banks Rd - STR Operating Scenarios
B2: Annual Model revenue pulls from this selected scenario.
A3: Scenario Selector | H3: Option #
A4: Selected Operating Scenario | D4: =IF(OR($H$4<1,$H$4>3),"",INDEX($B$7:$B$9,$H$4)) -> One Floor STR + One Floor Co-Living | H4: 2
A6: Select | B6: Operating Scenario | E6: Description
B7: Base Co-Living / Medium-Term | E7: Existing co-living rent schedule remains controlling.
B8: One Floor STR + One Floor Co-Living | E8: One full floor rents weekly as STR; other floor remains co-living/medium-term.
B9: Whole Building STR | E9: Entire building rents weekly as STR.
A12: STR Input Assumptions
A13: Input | D13: Low / Year 1 | E13: Medium / Year 2 | F13: High / Year 3+ | G13: Notes
A14: One-floor STR weekly rent | D14: 2500 | E14: 3250 | F14: 4000 | G14: Weekly gross rent for one full floor
A15: One-floor STR occupancy | D15: 0.4 | E15: 0.5 | F15: 0.6 | G15: Occupied week percentage
A16: Whole-building STR weekly rent | D16: 4500 | E16: 6000 | F16: 7500 | G16: Weekly gross rent for full building
A17: Whole-building STR occupancy | D17: 0.35 | E17: 0.45 | F17: 0.55 | G17: Occupied week percentage
A18: STR platform / lodging cost ratio | D18: 0.08 | E18: 0.09 | F18: 0.1 | G18: Gross-revenue haircut for STR platform/tax/admin stress
A19: STR turnover cost per occupied week | D19: 250 | E19: 300 | F19: 350 | G19: Cleaning, supplies, turnover allowance
A23: Annual Revenue Scenario Output
A24: Year | B24: Rent Case | C24: Base Monthly Gross Rent | D24: Base Annual Gross Rent | E24: One-Floor STR Weekly Rent | F24: One-Floor STR Occupancy | G24: Other Floor Annual Rent | H24: One-Floor STR Annual Gross | I24: Whole-Building STR Weekly Rent | J24: Whole-Building STR Occupancy | K24: Whole-Building STR Annual Gross | L24: Selected Annual Gross Rent
A25: 1 | B25: =IF(STRScenarioTable[[#This Row],[Year]]>=RentScenarioHighEffectiveYear,"High",IF(STRScenarioTable[[#This Row],[Year]]>=RentScenarioMediumEffectiveYear,"Medium",IF(STRScenarioTable[[#This Row],[Year]]>=RentScenarioLowEffectiveYear,"Low","None"))) -> Low | C25: =IF(STRScenarioTable[[#This Row],[Year]]>=RentScenarioHighEffectiveYear,RentScenarioHighMonthlyGross,IF(STRScenarioTable[[#This Row],[Year]]>=RentScenarioMediumEffectiveYear,RentScenarioMediumMonthlyGross,IF(STRScenarioTable[[#This Row],[Year]]>=RentScenarioLowEffectiveYear,RentScenarioLowMonthlyGross,0))) -> 8800 | D25: =STRScenarioTable[[#This Row],[Base Monthly Gross Rent]]*12 -> 105600 | E25: =IF(STRScenarioTable[[#This Row],[Year]]>=3,$F$14,IF(STRScenarioTable[[#This Row],[Year]]>=2,$E$14,$D$14)) -> 2500 | F25: =IF(STRScenarioTable[[#This Row],[Year]]>=3,$F$15,IF(STRScenarioTable[[#This Row],[Year]]>=2,$E$15,$D$15)) -> 0.4 | G25: =STRScenarioTable[[#This Row],[Base Annual Gross Rent]]/2 -> 52800 | H25: =(STRScenarioTable[[#This Row],[One-Floor STR Weekly Rent]]*52*STRScenarioTable[[#This Row],[One-Floor STR Occupancy]]*(1-IF(STRScenarioTable[[#This Row],[Year]]>=3,$F$18,IF(STRScenarioTable[[#This Row],[Year]]>=2,$E$18,$D$18))))-(STRScenarioTable[[#This Row],[One-Floor STR Occupancy]]*52*IF(STRScenarioTable[[#This Row],[Year]]>=3,$F$19,IF(STRScenarioTable[[#This Row],[Year]]>=2,$E$19,$D$19)))+STRScenarioTable[[#This Row],[Other Floor Annual Rent]] -> 95440 | I25: =IF(STRScenarioTable[[#This Row],[Year]]>=3,$F$16,IF(STRScenarioTable[[#This Row],[Year]]>=2,$E$16,$D$16)) -> 4500 | J25: =IF(STRScenarioTable[[#This Row],[Year]]>=3,$F$17,IF(STRScenarioTable[[#This Row],[Year]]>=2,$E$17,$D$17)) -> 0.35 | K25: =(STRScenarioTable[[#This Row],[Whole-Building STR Weekly Rent]]*52*STRScenarioTable[[#This Row],[Whole-Building STR Occupancy]]*(1-IF(STRScenarioTable[[#This Row],[Year]]>=3,$F$18,IF(STRScenarioTable[[#This Row],[Year]]>=2,$E$18,$D$18))))-(STRScenarioTable[[#This Row],[Whole-Building STR Occupancy]]*52*IF(STRScenarioTable[[#This Row],[Year]]>=3,$F$19,IF(STRScenarioTable[[#This Row],[Year]]>=2,$E$19,$D$19))) -> 70798 | L25: =CHOOSE(SelectedOperatingScenarioId,STRScenarioTable[[#This Row],[Base Annual Gross Rent]],STRScenarioTable[[#This Row],[One-Floor STR Annual Gross]],STRScenarioTable[[#This Row],[Whole-Building STR Annual Gross]]) -> 95440 | O25: =SUM(SelectedAnnualGrossRent) -> 1616535
A26: 2 | B26: =IF(STRScenarioTable[[#This Row],[Year]]>=RentScenarioHighEffectiveYear,"High",IF(STRScenarioTable[[#This Row],[Year]]>=RentScenarioMediumEffectiveYear,"Medium",IF(STRScenarioTable[[#This Row],[Year]]>=RentScenarioLowEffectiveYear,"Low","None"))) -> Medium | C26: =IF(STRScenarioTable[[#This Row],[Year]]>=RentScenarioHighEffectiveYear,RentScenarioHighMonthlyGross,IF(STRScenarioTable[[#This Row],[Year]]>=RentScenarioMediumEffectiveYear,RentScenarioMediumMonthlyGross,IF(STRScenarioTable[[#This Row],[Year]]>=RentScenarioLowEffectiveYear,RentScenarioLowMonthlyGross,0))) -> 10800 | D26: =STRScenarioTable[[#This Row],[Base Monthly Gross Rent]]*12 -> 129600 | E26: =IF(STRScenarioTable[[#This Row],[Year]]>=3,$F$14,IF(STRScenarioTable[[#This Row],[Year]]>=2,$E$14,$D$14)) -> 3250 | F26: =IF(STRScenarioTable[[#This Row],[Year]]>=3,$F$15,IF(STRScenarioTable[[#This Row],[Year]]>=2,$E$15,$D$15)) -> 0.5 | G26: =STRScenarioTable[[#This Row],[Base Annual Gross Rent]]/2 -> 64800 | H26: =(STRScenarioTable[[#This Row],[One-Floor STR Weekly Rent]]*52*STRScenarioTable[[#This Row],[One-Floor STR Occupancy]]*(1-IF(STRScenarioTable[[#This Row],[Year]]>=3,$F$18,IF(STRScenarioTable[[#This Row],[Year]]>=2,$E$18,$D$18))))-(STRScenarioTable[[#This Row],[One-Floor STR Occupancy]]*52*IF(STRScenarioTable[[#This Row],[Year]]>=3,$F$19,IF(STRScenarioTable[[#This Row],[Year]]>=2,$E$19,$D$19)))+STRScenarioTable[[#This Row],[Other Floor Annual Rent]] -> 133895 | I26: =IF(STRScenarioTable[[#This Row],[Year]]>=3,$F$16,IF(STRScenarioTable[[#This Row],[Year]]>=2,$E$16,$D$16)) -> 6000 | J26: =IF(STRScenarioTable[[#This Row],[Year]]>=3,$F$17,IF(STRScenarioTable[[#This Row],[Year]]>=2,$E$17,$D$17)) -> 0.45 | K26: =(STRScenarioTable[[#This Row],[Whole-Building STR Weekly Rent]]*52*STRScenarioTable[[#This Row],[Whole-Building STR Occupancy]]*(1-IF(STRScenarioTable[[#This Row],[Year]]>=3,$F$18,IF(STRScenarioTable[[#This Row],[Year]]>=2,$E$18,$D$18))))-(STRScenarioTable[[#This Row],[Whole-Building STR Occupancy]]*52*IF(STRScenarioTable[[#This Row],[Year]]>=3,$F$19,IF(STRScenarioTable[[#This Row],[Year]]>=2,$E$19,$D$19))) -> 120744 | L26: =CHOOSE(SelectedOperatingScenarioId,STRScenarioTable[[#This Row],[Base Annual Gross Rent]],STRScenarioTable[[#This Row],[One-Floor STR Annual Gross]],STRScenarioTable[[#This Row],[Whole-Building STR Annual Gross]]) -> 133895
A27: 3 | B27: =IF(STRScenarioTable[[#This Row],[Year]]>=RentScenarioHighEffectiveYear,"High",IF(STRScenarioTable[[#This Row],[Year]]>=RentScenarioMediumEffectiveYear,"Medium",IF(STRScenarioTable[[#This Row],[Year]]>=RentScenarioLowEffectiveYear,"Low","None"))) -> High | C27: =IF(STRScenarioTable[[#This Row],[Year]]>=RentScenarioHighEffectiveYear,RentScenarioHighMonthlyGross,IF(STRScenarioTable[[#This Row],[Year]]>=RentScenarioMediumEffectiveYear,RentScenarioMediumMonthlyGross,IF(STRScenarioTable[[#This Row],[Year]]>=RentScenarioLowEffectiveYear,RentScenarioLowMonthlyGross,0))) -> 12000 | D27: =STRScenarioTable[[#This Row],[Base Monthly Gross Rent]]*12 -> 144000 | E27: =IF(STRScenarioTable[[#This Row],[Year]]>=3,$F$14,IF(STRScenarioTable[[#This Row],[Year]]>=2,$E$14,$D$14)) -> 4000 | F27: =IF(STRScenarioTable[[#This Row],[Year]]>=3,$F$15,IF(STRScenarioTable[[#This Row],[Year]]>=2,$E$15,$D$15)) -> 0.6 | G27: =STRScenarioTable[[#This Row],[Base Annual Gross Rent]]/2 -> 72000 | H27: =(STRScenarioTable[[#This Row],[One-Floor STR Weekly Rent]]*52*STRScenarioTable[[#This Row],[One-Floor STR Occupancy]]*(1-IF(STRScenarioTable[[#This Row],[Year]]>=3,$F$18,IF(STRScenarioTable[[#This Row],[Year]]>=2,$E$18,$D$18))))-(STRScenarioTable[[#This Row],[One-Floor STR Occupancy]]*52*IF(STRScenarioTable[[#This Row],[Year]]>=3,$F$19,IF(STRScenarioTable[[#This Row],[Year]]>=2,$E$19,$D$19)))+STRScenarioTable[[#This Row],[Other Floor Annual Rent]] -> 173400 | I27: =IF(STRScenarioTable[[#This Row],[Year]]>=3,$F$16,IF(STRScenarioTable[[#This Row],[Year]]>=2,$E$16,$D$16)) -> 7500 | J27: =IF(STRScenarioTable[[#This Row],[Year]]>=3,$F$17,IF(STRScenarioTable[[#This Row],[Year]]>=2,$E$17,$D$17)) -> 0.55 | K27: =(STRScenarioTable[[#This Row],[Whole-Building STR Weekly Rent]]*52*STRScenarioTable[[#This Row],[Whole-Building STR Occupancy]]*(1-IF(STRScenarioTable[[#This Row],[Year]]>=3,$F$18,IF(STRScenarioTable[[#This Row],[Year]]>=2,$E$18,$D$18))))-(STRScenarioTable[[#This Row],[Whole-Building STR Occupancy]]*52*IF(STRScenarioTable[[#This Row],[Year]]>=3,$F$19,IF(STRScenarioTable[[#This Row],[Year]]>=2,$E$19,$D$19))) -> 183040 | L27: =CHOOSE(SelectedOperatingScenarioId,STRScenarioTable[[#This Row],[Base Annual Gross Rent]],STRScenarioTable[[#This Row],[One-Floor STR Annual Gross]],STRScenarioTable[[#This Row],[Whole-Building STR Annual Gross]]) -> 173400
A28: 4 | B28: =IF(STRScenarioTable[[#This Row],[Year]]>=RentScenarioHighEffectiveYear,"High",IF(STRScenarioTable[[#This Row],[Year]]>=RentScenarioMediumEffectiveYear,"Medium",IF(STRScenarioTable[[#This Row],[Year]]>=RentScenarioLowEffectiveYear,"Low","None"))) -> High | C28: =IF(STRScenarioTable[[#This Row],[Year]]>=RentScenarioHighEffectiveYear,RentScenarioHighMonthlyGross,IF(STRScenarioTable[[#This Row],[Year]]>=RentScenarioMediumEffectiveYear,RentScenarioMediumMonthlyGross,IF(STRScenarioTable[[#This Row],[Year]]>=RentScenarioLowEffectiveYear,RentScenarioLowMonthlyGross,0))) -> 12000 | D28: =STRScenarioTable[[#This Row],[Base Monthly Gross Rent]]*12 -> 144000 | E28: =IF(STRScenarioTable[[#This Row],[Year]]>=3,$F$14,IF(STRScenarioTable[[#This Row],[Year]]>=2,$E$14,$D$14)) -> 4000 | F28: =IF(STRScenarioTable[[#This Row],[Year]]>=3,$F$15,IF(STRScenarioTable[[#This Row],[Year]]>=2,$E$15,$D$15)) -> 0.6 | G28: =STRScenarioTable[[#This Row],[Base Annual Gross Rent]]/2 -> 72000 | H28: =(STRScenarioTable[[#This Row],[One-Floor STR Weekly Rent]]*52*STRScenarioTable[[#This Row],[One-Floor STR Occupancy]]*(1-IF(STRScenarioTable[[#This Row],[Year]]>=3,$F$18,IF(STRScenarioTable[[#This Row],[Year]]>=2,$E$18,$D$18))))-(STRScenarioTable[[#This Row],[One-Floor STR Occupancy]]*52*IF(STRScenarioTable[[#This Row],[Year]]>=3,$F$19,IF(STRScenarioTable[[#This Row],[Year]]>=2,$E$19,$D$19)))+STRScenarioTable[[#This Row],[Other Floor Annual Rent]] -> 173400 | I28: =IF(STRScenarioTable[[#This Row],[Year]]>=3,$F$16,IF(STRScenarioTable[[#This Row],[Year]]>=2,$E$16,$D$16)) -> 7500 | J28: =IF(STRScenarioTable[[#This Row],[Year]]>=3,$F$17,IF(STRScenarioTable[[#This Row],[Year]]>=2,$E$17,$D$17)) -> 0.55 | K28: =(STRScenarioTable[[#This Row],[Whole-Building STR Weekly Rent]]*52*STRScenarioTable[[#This Row],[Whole-Building STR Occupancy]]*(1-IF(STRScenarioTable[[#This Row],[Year]]>=3,$F$18,IF(STRScenarioTable[[#This Row],[Year]]>=2,$E$18,$D$18))))-(STRScenarioTable[[#This Row],[Whole-Building STR Occupancy]]*52*IF(STRScenarioTable[[#This Row],[Year]]>=3,$F$19,IF(STRScenarioTable[[#This Row],[Year]]>=2,$E$19,$D$19))) -> 183040 | L28: =CHOOSE(SelectedOperatingScenarioId,STRScenarioTable[[#This Row],[Base Annual Gross Rent]],STRScenarioTable[[#This Row],[One-Floor STR Annual Gross]],STRScenarioTable[[#This Row],[Whole-Building STR Annual Gross]]) -> 173400
A29: 5 | B29: =IF(STRScenarioTable[[#This Row],[Year]]>=RentScenarioHighEffectiveYear,"High",IF(STRScenarioTable[[#This Row],[Year]]>=RentScenarioMediumEffectiveYear,"Medium",IF(STRScenarioTable[[#This Row],[Year]]>=RentScenarioLowEffectiveYear,"Low","None"))) -> High | C29: =IF(STRScenarioTable[[#This Row],[Year]]>=RentScenarioHighEffectiveYear,RentScenarioHighMonthlyGross,IF(STRScenarioTable[[#This Row],[Year]]>=RentScenarioMediumEffectiveYear,RentScenarioMediumMonthlyGross,IF(STRScenarioTable[[#This Row],[Year]]>=RentScenarioLowEffectiveYear,RentScenarioLowMonthlyGross,0))) -> 12000 | D29: =STRScenarioTable[[#This Row],[Base Monthly Gross Rent]]*12 -> 144000 | E29: =IF(STRScenarioTable[[#This Row],[Year]]>=3,$F$14,IF(STRScenarioTable[[#This Row],[Year]]>=2,$E$14,$D$14)) -> 4000 | F29: =IF(STRScenarioTable[[#This Row],[Year]]>=3,$F$15,IF(STRScenarioTable[[#This Row],[Year]]>=2,$E$15,$D$15)) -> 0.6 | G29: =STRScenarioTable[[#This Row],[Base Annual Gross Rent]]/2 -> 72000 | H29: =(STRScenarioTable[[#This Row],[One-Floor STR Weekly Rent]]*52*STRScenarioTable[[#This Row],[One-Floor STR Occupancy]]*(1-IF(STRScenarioTable[[#This Row],[Year]]>=3,$F$18,IF(STRScenarioTable[[#This Row],[Year]]>=2,$E$18,$D$18))))-(STRScenarioTable[[#This Row],[One-Floor STR Occupancy]]*52*IF(STRScenarioTable[[#This Row],[Year]]>=3,$F$19,IF(STRScenarioTable[[#This Row],[Year]]>=2,$E$19,$D$19)))+STRScenarioTable[[#This Row],[Other Floor Annual Rent]] -> 173400 | I29: =IF(STRScenarioTable[[#This Row],[Year]]>=3,$F$16,IF(STRScenarioTable[[#This Row],[Year]]>=2,$E$16,$D$16)) -> 7500 | J29: =IF(STRScenarioTable[[#This Row],[Year]]>=3,$F$17,IF(STRScenarioTable[[#This Row],[Year]]>=2,$E$17,$D$17)) -> 0.55 | K29: =(STRScenarioTable[[#This Row],[Whole-Building STR Weekly Rent]]*52*STRScenarioTable[[#This Row],[Whole-Building STR Occupancy]]*(1-IF(STRScenarioTable[[#This Row],[Year]]>=3,$F$18,IF(STRScenarioTable[[#This Row],[Year]]>=2,$E$18,$D$18))))-(STRScenarioTable[[#This Row],[Whole-Building STR Occupancy]]*52*IF(STRScenarioTable[[#This Row],[Year]]>=3,$F$19,IF(STRScenarioTable[[#This Row],[Year]]>=2,$E$19,$D$19))) -> 183040 | L29: =CHOOSE(SelectedOperatingScenarioId,STRScenarioTable[[#This Row],[Base Annual Gross Rent]],STRScenarioTable[[#This Row],[One-Floor STR Annual Gross]],STRScenarioTable[[#This Row],[Whole-Building STR Annual Gross]]) -> 173400
A30: 6 | B30: =IF(STRScenarioTable[[#This Row],[Year]]>=RentScenarioHighEffectiveYear,"High",IF(STRScenarioTable[[#This Row],[Year]]>=RentScenarioMediumEffectiveYear,"Medium",IF(STRScenarioTable[[#This Row],[Year]]>=RentScenarioLowEffectiveYear,"Low","None"))) -> High | C30: =IF(STRScenarioTable[[#This Row],[Year]]>=RentScenarioHighEffectiveYear,RentScenarioHighMonthlyGross,IF(STRScenarioTable[[#This Row],[Year]]>=RentScenarioMediumEffectiveYear,RentScenarioMediumMonthlyGross,IF(STRScenarioTable[[#This Row],[Year]]>=RentScenarioLowEffectiveYear,RentScenarioLowMonthlyGross,0))) -> 12000 | D30: =STRScenarioTable[[#This Row],[Base Monthly Gross Rent]]*12 -> 144000 | E30: =IF(STRScenarioTable[[#This Row],[Year]]>=3,$F$14,IF(STRScenarioTable[[#This Row],[Year]]>=2,$E$14,$D$14)) -> 4000 | F30: =IF(STRScenarioTable[[#This Row],[Year]]>=3,$F$15,IF(STRScenarioTable[[#This Row],[Year]]>=2,$E$15,$D$15)) -> 0.6 | G30: =STRScenarioTable[[#This Row],[Base Annual Gross Rent]]/2 -> 72000 | H30: =(STRScenarioTable[[#This Row],[One-Floor STR Weekly Rent]]*52*STRScenarioTable[[#This Row],[One-Floor STR Occupancy]]*(1-IF(STRScenarioTable[[#This Row],[Year]]>=3,$F$18,IF(STRScenarioTable[[#This Row],[Year]]>=2,$E$18,$D$18))))-(STRScenarioTable[[#This Row],[One-Floor STR Occupancy]]*52*IF(STRScenarioTable[[#This Row],[Year]]>=3,$F$19,IF(STRScenarioTable[[#This Row],[Year]]>=2,$E$19,$D$19)))+STRScenarioTable[[#This Row],[Other Floor Annual Rent]] -> 173400 | I30: =IF(STRScenarioTable[[#This Row],[Year]]>=3,$F$16,IF(STRScenarioTable[[#This Row],[Year]]>=2,$E$16,$D$16)) -> 7500 | J30: =IF(STRScenarioTable[[#This Row],[Year]]>=3,$F$17,IF(STRScenarioTable[[#This Row],[Year]]>=2,$E$17,$D$17)) -> 0.55 | K30: =(STRScenarioTable[[#This Row],[Whole-Building STR Weekly Rent]]*52*STRScenarioTable[[#This Row],[Whole-Building STR Occupancy]]*(1-IF(STRScenarioTable[[#This Row],[Year]]>=3,$F$18,IF(STRScenarioTable[[#This Row],[Year]]>=2,$E$18,$D$18))))-(STRScenarioTable[[#This Row],[Whole-Building STR Occupancy]]*52*IF(STRScenarioTable[[#This Row],[Year]]>=3,$F$19,IF(STRScenarioTable[[#This Row],[Year]]>=2,$E$19,$D$19))) -> 183040 | L30: =CHOOSE(SelectedOperatingScenarioId,STRScenarioTable[[#This Row],[Base Annual Gross Rent]],STRScenarioTable[[#This Row],[One-Floor STR Annual Gross]],STRScenarioTable[[#This Row],[Whole-Building STR Annual Gross]]) -> 173400
A31: 7 | B31: =IF(STRScenarioTable[[#This Row],[Year]]>=RentScenarioHighEffectiveYear,"High",IF(STRScenarioTable[[#This Row],[Year]]>=RentScenarioMediumEffectiveYear,"Medium",IF(STRScenarioTable[[#This Row],[Year]]>=RentScenarioLowEffectiveYear,"Low","None"))) -> High | C31: =IF(STRScenarioTable[[#This Row],[Year]]>=RentScenarioHighEffectiveYear,RentScenarioHighMonthlyGross,IF(STRScenarioTable[[#This Row],[Year]]>=RentScenarioMediumEffectiveYear,RentScenarioMediumMonthlyGross,IF(STRScenarioTable[[#This Row],[Year]]>=RentScenarioLowEffectiveYear,RentScenarioLowMonthlyGross,0))) -> 12000 | D31: =STRScenarioTable[[#This Row],[Base Monthly Gross Rent]]*12 -> 144000 | E31: =IF(STRScenarioTable[[#This Row],[Year]]>=3,$F$14,IF(STRScenarioTable[[#This Row],[Year]]>=2,$E$14,$D$14)) -> 4000 | F31: =IF(STRScenarioTable[[#This Row],[Year]]>=3,$F$15,IF(STRScenarioTable[[#This Row],[Year]]>=2,$E$15,$D$15)) -> 0.6 | G31: =STRScenarioTable[[#This Row],[Base Annual Gross Rent]]/2 -> 72000 | H31: =(STRScenarioTable[[#This Row],[One-Floor STR Weekly Rent]]*52*STRScenarioTable[[#This Row],[One-Floor STR Occupancy]]*(1-IF(STRScenarioTable[[#This Row],[Year]]>=3,$F$18,IF(STRScenarioTable[[#This Row],[Year]]>=2,$E$18,$D$18))))-(STRScenarioTable[[#This Row],[One-Floor STR Occupancy]]*52*IF(STRScenarioTable[[#This Row],[Year]]>=3,$F$19,IF(STRScenarioTable[[#This Row],[Year]]>=2,$E$19,$D$19)))+STRScenarioTable[[#This Row],[Other Floor Annual Rent]] -> 173400 | I31: =IF(STRScenarioTable[[#This Row],[Year]]>=3,$F$16,IF(STRScenarioTable[[#This Row],[Year]]>=2,$E$16,$D$16)) -> 7500 | J31: =IF(STRScenarioTable[[#This Row],[Year]]>=3,$F$17,IF(STRScenarioTable[[#This Row],[Year]]>=2,$E$17,$D$17)) -> 0.55 | K31: =(STRScenarioTable[[#This Row],[Whole-Building STR Weekly Rent]]*52*STRScenarioTable[[#This Row],[Whole-Building STR Occupancy]]*(1-IF(STRScenarioTable[[#This Row],[Year]]>=3,$F$18,IF(STRScenarioTable[[#This Row],[Year]]>=2,$E$18,$D$18))))-(STRScenarioTable[[#This Row],[Whole-Building STR Occupancy]]*52*IF(STRScenarioTable[[#This Row],[Year]]>=3,$F$19,IF(STRScenarioTable[[#This Row],[Year]]>=2,$E$19,$D$19))) -> 183040 | L31: =CHOOSE(SelectedOperatingScenarioId,STRScenarioTable[[#This Row],[Base Annual Gross Rent]],STRScenarioTable[[#This Row],[One-Floor STR Annual Gross]],STRScenarioTable[[#This Row],[Whole-Building STR Annual Gross]]) -> 173400
A32: 8 | B32: =IF(STRScenarioTable[[#This Row],[Year]]>=RentScenarioHighEffectiveYear,"High",IF(STRScenarioTable[[#This Row],[Year]]>=RentScenarioMediumEffectiveYear,"Medium",IF(STRScenarioTable[[#This Row],[Year]]>=RentScenarioLowEffectiveYear,"Low","None"))) -> High | C32: =IF(STRScenarioTable[[#This Row],[Year]]>=RentScenarioHighEffectiveYear,RentScenarioHighMonthlyGross,IF(STRScenarioTable[[#This Row],[Year]]>=RentScenarioMediumEffectiveYear,RentScenarioMediumMonthlyGross,IF(STRScenarioTable[[#This Row],[Year]]>=RentScenarioLowEffectiveYear,RentScenarioLowMonthlyGross,0))) -> 12000 | D32: =STRScenarioTable[[#This Row],[Base Monthly Gross Rent]]*12 -> 144000 | E32: =IF(STRScenarioTable[[#This Row],[Year]]>=3,$F$14,IF(STRScenarioTable[[#This Row],[Year]]>=2,$E$14,$D$14)) -> 4000 | F32: =IF(STRScenarioTable[[#This Row],[Year]]>=3,$F$15,IF(STRScenarioTable[[#This Row],[Year]]>=2,$E$15,$D$15)) -> 0.6 | G32: =STRScenarioTable[[#This Row],[Base Annual Gross Rent]]/2 -> 72000 | H32: =(STRScenarioTable[[#This Row],[One-Floor STR Weekly Rent]]*52*STRScenarioTable[[#This Row],[One-Floor STR Occupancy]]*(1-IF(STRScenarioTable[[#This Row],[Year]]>=3,$F$18,IF(STRScenarioTable[[#This Row],[Year]]>=2,$E$18,$D$18))))-(STRScenarioTable[[#This Row],[One-Floor STR Occupancy]]*52*IF(STRScenarioTable[[#This Row],[Year]]>=3,$F$19,IF(STRScenarioTable[[#This Row],[Year]]>=2,$E$19,$D$19)))+STRScenarioTable[[#This Row],[Other Floor Annual Rent]] -> 173400 | I32: =IF(STRScenarioTable[[#This Row],[Year]]>=3,$F$16,IF(STRScenarioTable[[#This Row],[Year]]>=2,$E$16,$D$16)) -> 7500 | J32: =IF(STRScenarioTable[[#This Row],[Year]]>=3,$F$17,IF(STRScenarioTable[[#This Row],[Year]]>=2,$E$17,$D$17)) -> 0.55 | K32: =(STRScenarioTable[[#This Row],[Whole-Building STR Weekly Rent]]*52*STRScenarioTable[[#This Row],[Whole-Building STR Occupancy]]*(1-IF(STRScenarioTable[[#This Row],[Year]]>=3,$F$18,IF(STRScenarioTable[[#This Row],[Year]]>=2,$E$18,$D$18))))-(STRScenarioTable[[#This Row],[Whole-Building STR Occupancy]]*52*IF(STRScenarioTable[[#This Row],[Year]]>=3,$F$19,IF(STRScenarioTable[[#This Row],[Year]]>=2,$E$19,$D$19))) -> 183040 | L32: =CHOOSE(SelectedOperatingScenarioId,STRScenarioTable[[#This Row],[Base Annual Gross Rent]],STRScenarioTable[[#This Row],[One-Floor STR Annual Gross]],STRScenarioTable[[#This Row],[Whole-Building STR Annual Gross]]) -> 173400
A33: 9 | B33: =IF(STRScenarioTable[[#This Row],[Year]]>=RentScenarioHighEffectiveYear,"High",IF(STRScenarioTable[[#This Row],[Year]]>=RentScenarioMediumEffectiveYear,"Medium",IF(STRScenarioTable[[#This Row],[Year]]>=RentScenarioLowEffectiveYear,"Low","None"))) -> High | C33: =IF(STRScenarioTable[[#This Row],[Year]]>=RentScenarioHighEffectiveYear,RentScenarioHighMonthlyGross,IF(STRScenarioTable[[#This Row],[Year]]>=RentScenarioMediumEffectiveYear,RentScenarioMediumMonthlyGross,IF(STRScenarioTable[[#This Row],[Year]]>=RentScenarioLowEffectiveYear,RentScenarioLowMonthlyGross,0))) -> 12000 | D33: =STRScenarioTable[[#This Row],[Base Monthly Gross Rent]]*12 -> 144000 | E33: =IF(STRScenarioTable[[#This Row],[Year]]>=3,$F$14,IF(STRScenarioTable[[#This Row],[Year]]>=2,$E$14,$D$14)) -> 4000 | F33: =IF(STRScenarioTable[[#This Row],[Year]]>=3,$F$15,IF(STRScenarioTable[[#This Row],[Year]]>=2,$E$15,$D$15)) -> 0.6 | G33: =STRScenarioTable[[#This Row],[Base Annual Gross Rent]]/2 -> 72000 | H33: =(STRScenarioTable[[#This Row],[One-Floor STR Weekly Rent]]*52*STRScenarioTable[[#This Row],[One-Floor STR Occupancy]]*(1-IF(STRScenarioTable[[#This Row],[Year]]>=3,$F$18,IF(STRScenarioTable[[#This Row],[Year]]>=2,$E$18,$D$18))))-(STRScenarioTable[[#This Row],[One-Floor STR Occupancy]]*52*IF(STRScenarioTable[[#This Row],[Year]]>=3,$F$19,IF(STRScenarioTable[[#This Row],[Year]]>=2,$E$19,$D$19)))+STRScenarioTable[[#This Row],[Other Floor Annual Rent]] -> 173400 | I33: =IF(STRScenarioTable[[#This Row],[Year]]>=3,$F$16,IF(STRScenarioTable[[#This Row],[Year]]>=2,$E$16,$D$16)) -> 7500 | J33: =IF(STRScenarioTable[[#This Row],[Year]]>=3,$F$17,IF(STRScenarioTable[[#This Row],[Year]]>=2,$E$17,$D$17)) -> 0.55 | K33: =(STRScenarioTable[[#This Row],[Whole-Building STR Weekly Rent]]*52*STRScenarioTable[[#This Row],[Whole-Building STR Occupancy]]*(1-IF(STRScenarioTable[[#This Row],[Year]]>=3,$F$18,IF(STRScenarioTable[[#This Row],[Year]]>=2,$E$18,$D$18))))-(STRScenarioTable[[#This Row],[Whole-Building STR Occupancy]]*52*IF(STRScenarioTable[[#This Row],[Year]]>=3,$F$19,IF(STRScenarioTable[[#This Row],[Year]]>=2,$E$19,$D$19))) -> 183040 | L33: =CHOOSE(SelectedOperatingScenarioId,STRScenarioTable[[#This Row],[Base Annual Gross Rent]],STRScenarioTable[[#This Row],[One-Floor STR Annual Gross]],STRScenarioTable[[#This Row],[Whole-Building STR Annual Gross]]) -> 173400
A34: 10 | B34: =IF(STRScenarioTable[[#This Row],[Year]]>=RentScenarioHighEffectiveYear,"High",IF(STRScenarioTable[[#This Row],[Year]]>=RentScenarioMediumEffectiveYear,"Medium",IF(STRScenarioTable[[#This Row],[Year]]>=RentScenarioLowEffectiveYear,"Low","None"))) -> High | C34: =IF(STRScenarioTable[[#This Row],[Year]]>=RentScenarioHighEffectiveYear,RentScenarioHighMonthlyGross,IF(STRScenarioTable[[#This Row],[Year]]>=RentScenarioMediumEffectiveYear,RentScenarioMediumMonthlyGross,IF(STRScenarioTable[[#This Row],[Year]]>=RentScenarioLowEffectiveYear,RentScenarioLowMonthlyGross,0))) -> 12000 | D34: =STRScenarioTable[[#This Row],[Base Monthly Gross Rent]]*12 -> 144000 | E34: =IF(STRScenarioTable[[#This Row],[Year]]>=3,$F$14,IF(STRScenarioTable[[#This Row],[Year]]>=2,$E$14,$D$14)) -> 4000 | F34: =IF(STRScenarioTable[[#This Row],[Year]]>=3,$F$15,IF(STRScenarioTable[[#This Row],[Year]]>=2,$E$15,$D$15)) -> 0.6 | G34: =STRScenarioTable[[#This Row],[Base Annual Gross Rent]]/2 -> 72000 | H34: =(STRScenarioTable[[#This Row],[One-Floor STR Weekly Rent]]*52*STRScenarioTable[[#This Row],[One-Floor STR Occupancy]]*(1-IF(STRScenarioTable[[#This Row],[Year]]>=3,$F$18,IF(STRScenarioTable[[#This Row],[Year]]>=2,$E$18,$D$18))))-(STRScenarioTable[[#This Row],[One-Floor STR Occupancy]]*52*IF(STRScenarioTable[[#This Row],[Year]]>=3,$F$19,IF(STRScenarioTable[[#This Row],[Year]]>=2,$E$19,$D$19)))+STRScenarioTable[[#This Row],[Other Floor Annual Rent]] -> 173400 | I34: =IF(STRScenarioTable[[#This Row],[Year]]>=3,$F$16,IF(STRScenarioTable[[#This Row],[Year]]>=2,$E$16,$D$16)) -> 7500 | J34: =IF(STRScenarioTable[[#This Row],[Year]]>=3,$F$17,IF(STRScenarioTable[[#This Row],[Year]]>=2,$E$17,$D$17)) -> 0.55 | K34: =(STRScenarioTable[[#This Row],[Whole-Building STR Weekly Rent]]*52*STRScenarioTable[[#This Row],[Whole-Building STR Occupancy]]*(1-IF(STRScenarioTable[[#This Row],[Year]]>=3,$F$18,IF(STRScenarioTable[[#This Row],[Year]]>=2,$E$18,$D$18))))-(STRScenarioTable[[#This Row],[Whole-Building STR Occupancy]]*52*IF(STRScenarioTable[[#This Row],[Year]]>=3,$F$19,IF(STRScenarioTable[[#This Row],[Year]]>=2,$E$19,$D$19))) -> 183040 | L34: =CHOOSE(SelectedOperatingScenarioId,STRScenarioTable[[#This Row],[Base Annual Gross Rent]],STRScenarioTable[[#This Row],[One-Floor STR Annual Gross]],STRScenarioTable[[#This Row],[Whole-Building STR Annual Gross]]) -> 173400

Sheet Assumptions
A1: 3325 Banks Rd - Investor Return Model | C1: Editable inputs are in column B. Outputs update through formulas.
A3: Project Timing | L3: Experimental STR Scenario
A4: Stabilization / Refinance Year | B4: =MAX(1,MIN(10,SelectedWaterfallRefiOption)) -> 3 | C4: Model uses selected Waterfall refinance-year option button; helper cell Waterfall!R3; buttons shown for Years 1-10 only | L4: Selected Operating Scenario | M4: =SelectedOperatingScenario -> One Floor STR + One Floor Co-Living
A5: Sale / Exit Year | B5: =MAX(1,MIN(10,SelectedWaterfallExitOption)) -> 5 | C5: Model uses selected Waterfall exit-year option button; helper cell Waterfall!S3; buttons shown for Years 1-10 only | L5: Edit selector on STR Scenarios!B4
A7: Rental Program | D7: Rent Scenario Schedule
A8: First Floor Premium Suites | B8: 4 | C8: Private bed/bath/kitchenette suites | D8: Rent Input | E8: Low | F8: Medium | G8: High | H8: Average | I8: Current Use | J8: Notes
A9: Monthly Rent per Premium Suite | B9: 1600 | C9: Mid/base reference; Annual Model uses scenario schedule at right | D9: Premium Suite Rent | E9: 1350 | F9: 1600 | G9: 1750 | H9: =AVERAGE(E9:G9) -> 1566.6667 | I9: Rent levels increase left to right
A10: Second Floor Co-Living Suites | B10: 4 | C10: Private bed/bath with shared amenities | D10: Co-Living Suite Rent | E10: 850 | F10: 1100 | G10: 1250 | H10: =AVERAGE(E10:G10) -> 1066.6667 | I10: Rent levels increase left to right
A11: Monthly Rent per Co-Living Suite | B11: 1100 | C11: Mid/base reference; Annual Model uses scenario schedule at right | D11: Monthly Gross Rent | E11: =PremiumSuites*E9+CoLivingSuites*E10+OtherMonthlyIncome -> 8800 | F11: =PremiumSuites*F9+CoLivingSuites*F10+OtherMonthlyIncome -> 10800 | G11: =PremiumSuites*G9+CoLivingSuites*G10+OtherMonthlyIncome -> 12000 | H11: =AVERAGE(E11:G11) -> 10533.333 | I11: Average is reference only; model uses scenario schedule
A12: Other Monthly Income | B12: 0 | C12: Parking, utility fees, laundry, etc. | D12: Effective Year | E12: 1 | F12: 2 | G12: 3 | I12: Annual Model timing | J12: Low ends after Year 1 under current schedule
A13: Stabilized Occupancy | B13: 0.93 | C13: Before operating expense load
A14: Year 1 Lease-Up Occupancy | B14: 0.5 | C14: First partial operating year
A15: Selected Operating Expense Ratio | B15: =SelectedOperatingExpenseRatio -> 0.46912485 | C15: From Operating Expense Budget tab; toggle between assumed ratio and calculated budget ratio
A16: NOI Growth | B16: 0.03 | C16: Annual growth after stabilization
A17: Stabilized Monthly Gross Rent | B17: =IF(StabilizationRefiYear>=RentScenarioHighEffectiveYear,RentScenarioHighMonthlyGross,IF(StabilizationRefiYear>=RentScenarioMediumEffectiveYear,RentScenarioMediumMonthlyGross,IF(StabilizationRefiYear>=RentScenarioLowEffectiveYear,RentScenarioLowMonthlyGross,0))) -> 12000 | C17: Selected by Rent Scenario Schedule for the Stabilization / Refinance Year; average is reference only
A19: Debt / Refinance / Exit
A20: Existing First Mortgage Principal | B20: 119000 | C20: Existing first mortgage principal to be paid from refinance proceeds
A21: Existing First Mortgage Rate | B21: 0.0325 | C21: Interest rate on existing first mortgage
A22: Private Debt Principal | B22: 75000 | C22: Private debt principal; interest-only before payoff
A23: Private Debt Interest Rate | B23: 0.1 | C23: Interest-only private debt rate
A24: Total Existing Debt Payoff | B24: =_xlfn.SINGLE(ExistingFirstMortgagePrincipal)+PrivateDebtPrincipal -> 194000 | C24: Existing first mortgage principal plus private debt principal
A25: First Mortgage Monthly P&I Excl. Escrow | B25: 526 | C25: Actual monthly principal and interest payment; excludes escrow, taxes, and insurance
A26: First Mortgage Annual P&I Excl. Escrow | B26: =_xlfn.SINGLE(ExistingFirstMortgageMonthlyPI)*12 -> 6312 | C26: Annual principal and interest payment; excludes escrow, taxes, and insurance
A27: Private Debt Annual Interest Payment | B27: =PrivateDebtPrincipal*PrivateDebtInterestRate -> 7500 | C27: Interest-only payment on private debt
A28: Total Existing Annual Debt Service | B28: =ExistingFirstMortgageAnnualPayment+PrivateDebtAnnualInterestPayment -> 13812 | C28: Existing debt service before refinance; taxes and insurance remain in operating expenses
A29: Refinance Loan-to-Value Cap | B29: 0.7 | C29: Maximum refinance loan as % of stabilized value
A30: Refinance Loan Amount | B30: =MIN((StabilizedMonthlyGrossRent*12*StabilizedOccupancy*(1-OperatingExpenseRatio)*(1+NOIGrowth)/ExitCapRate)*RefinanceLoanToValueCap,TotalExistingDebt+ClassACapital+ClassBCapital) -> 732276.44 | C30: Only new loan; takeout/refinance proceeds, not development or construction debt
A31: Refi Proceeds After Existing Debt | B31: =MAX(0,RefinanceLoanAmount-TotalExistingDebt) -> 538276.44 | C31: Available to Class A first through waterfall
A32: Refi Remaining After Debt + Class A | B32: =MAX(0,RefinanceLoanAmount-TotalExistingDebt-ClassACapital) -> 238276.44 | C32: Indicative amount available to Class B before waterfall details
A33: Refinance Loan Interest Rate | B33: 0.065 | C33: Annual fixed rate on stabilization refinance loan
A34: Refinance Loan Amortization Years | B34: 30 | C34: Used for annual debt service after stabilization refinance
A35: Exit Cap Rate | B35: 0.07 | C35: Sale value = following year NOI / cap rate
A36: Selling Costs | B36: 0.02 | C36: Percent deducted from gross sale value
A38: Capital Stack / Waterfall
A39: Class A Capital | B39: 300000 | C39: Preferred capital raise
A40: Class A Preferred Return | B40: 0.08 | C40: Cumulative annual preferred return
A41: Class B Capital | B41: =MAX(0,SelectedProjectCost-ClassACapital) -> 547500 | C41: Subordinate beneficiary capital; dependent upon selected project cost in Cost Analysis
A42: Class B Capital Return Priority | B42: 1 | C42: 1 = return Class B capital before residual split
A43: Sponsor Residual Share | B43: 0.5 | C43: Editable sponsor share of residual after capital return priorities
A44: Class A Residual Share | B44: =(1-SponsorResidualShare)*(ClassACapital/(ClassACapital+ClassBCapital)) -> 0.17699115 | C44: Class A share of non-sponsor residual, proportional to Class A capital
...

Sheet Annual Model
A1: Annual Project Model
A3: Year | B3: Phase | C3: Gross Potential Rent | D3: Occupancy Effective Gross Income | E3: Operating Expenses | F3: NOI | G3: Debt Service | H3: Cash Before Refi/Sale | I3: Net Refi/Sale Proceeds | J3: Reserve Funding | K3: Reserve Balance | L3: Cash Available Before Distributions | M3: Waterfall Distributions | N3: Ending Cash Balance | O3: Loan Balance | P3: Property Value / Refi Value
A4: 0 | B4: Capitalization / Entitlement | C4: =IF(AnnualModelTable[[#This Row],[Year]]>SaleExitYear,0,IF(AnnualModelTable[[#This Row],[Year]]=0,0,INDEX(STRScenarioTable[Selected Annual Gross Rent],MATCH(AnnualModelTable[[#This Row],[Year]],STRScenarioTable[Year],0)))) -> 0 | D4: =IF(AnnualModelTable[[#This Row],[Year]]>SaleExitYear,0,IF(AnnualModelTable[[#This Row],[Year]]=0,0,AnnualModelTable[[#This Row],[Gross Potential Rent]]*IF(AnnualModelTable[[#This Row],[Year]]=1,LeaseUpOccupancy,StabilizedOccupancy))) -> 0 | E4: =IF(AnnualModelTable[[#This Row],[Year]]>SaleExitYear,0,AnnualModelTable[[#This Row],[Occupancy Effective Gross Income]]*OperatingExpenseRatio) -> 0 | F4: =IF(AnnualModelTable[[#This Row],[Year]]>SaleExitYear,0,AnnualModelTable[[#This Row],[Occupancy Effective Gross Income]]-AnnualModelTable[[#This Row],[Operating Expenses]]) -> 0 | G4: =IF(AnnualModelTable[[#This Row],[Year]]>SaleExitYear,0,IF(AND(AnnualModelTable[[#This Row],[Year]]>=1,AnnualModelTable[[#This Row],[Year]]<StabilizationRefiYear),ExistingDebtServiceAnnual,IF(AND(AnnualModelTable[[#This Row],[Year]]>=StabilizationRefiYear,AnnualModelTable[[#This Row],[Year]]<=SaleExitYear),-PMT(RefinanceLoanRate/12,RefinanceLoanAmortizationYears*12,RefinanceLoanAmount)*12,0))) -> 0 | H4: =IF(AnnualModelTable[[#This Row],[Year]]>SaleExitYear,0,AnnualModelTable[[#This Row],[NOI]]-AnnualModelTable[[#This Row],[Debt Service]]) -> 0 | I4: =IF(AnnualModelTable[[#This Row],[Year]]>SaleExitYear,0,IF(AnnualModelTable[[#This Row],[Year]]=0,SponsorPropertyPayment,IF(AnnualModelTable[[#This Row],[Year]]=StabilizationRefiYear,MAX(0,RefinanceLoanAmount-TotalExistingDebt),IF(AnnualModelTable[[#This Row],[Year]]=SaleExitYear,MAX(0,AnnualModelTable[[#This Row],[Property Value / Refi Value]]*(1-SellingCosts)-AnnualModelTable[[#This Row],[Loan Balance]]),0)))) -> 100000 | J4: =IF(AnnualModelTable[[#This Row],[Year]]>SaleExitYear,0,IF(AnnualModelTable[[#This Row],[Year]]=0,0,MIN(MAX(0,RepairsMaintenanceReserveTarget-IFERROR(INDEX(AnnualModelTable[Reserve Balance],MATCH(AnnualModelTable[[#This Row],[Year]]-1,AnnualModelTable[Year],0)),0)),MAX(0,IFERROR(INDEX(AnnualModelTable[Ending Cash Balance],MATCH(AnnualModelTable[[#This Row],[Year]]-1,AnnualModelTable[Year],0)),0)+AnnualModelTable[[#This Row],[Cash Before Refi/Sale]]+AnnualModelTable[[#This Row],[Net Refi/Sale Proceeds]])))) -> 0 | K4: =IF(AnnualModelTable[[#This Row],[Year]]>SaleExitYear,0,IF(AnnualModelTable[[#This Row],[Year]]=0,0,IFERROR(INDEX(AnnualModelTable[Reserve Balance],MATCH(AnnualModelTable[[#This Row],[Year]]-1,AnnualModelTable[Year],0)),0)+AnnualModelTable[[#This Row],[Reserve Funding]])) -> 0 | L4: =IF(AnnualModelTable[[#This Row],[Year]]>SaleExitYear,0,IF(AnnualModelTable[[#This Row],[Year]]=0,0,IFERROR(INDEX(AnnualModelTable[Ending Cash Balance],MATCH(AnnualModelTable[[#This Row],[Year]]-1,AnnualModelTable[Year],0)),0))+AnnualModelTable[[#This Row],[Cash Before Refi/Sale]]+AnnualModelTable[[#This Row],[Net Refi/Sale Proceeds]]-AnnualModelTable[[#This Row],[Reserve Funding]]) -> 100000 | M4: =IF(AnnualModelTable[[#This Row],[Year]]>SaleExitYear,0,SUM(INDEX(WaterfallTable[Total Dist A],MATCH(AnnualModelTable[[#This Row],[Year]],WaterfallTable[Year],0)),INDEX(WaterfallTable[Total Dist B],MATCH(AnnualModelTable[[#This Row],[Year]],WaterfallTable[Year],0)),INDEX(WaterfallTable[Total Dist2],MATCH(AnnualModelTable[[#This Row],[Year]],WaterfallTable[Year],0)))) -> 100000 | N4: =IF(AnnualModelTable[[#This Row],[Year]]>SaleExitYear,0,MAX(0,AnnualModelTable[[#This Row],[Cash Available Before Distributions]]-AnnualModelTable[[#This Row],[Waterfall Distributions]])) -> 0 | O4: =IF(AnnualModelTable[[#This Row],[Year]]>SaleExitYear,0,IF(AnnualModelTable[[#This Row],[Year]]<StabilizationRefiYear,0,IF(AnnualModelTable[[#This Row],[Year]]=SaleExitYear,0,-FV(RefinanceLoanRate/12,(AnnualModelTable[[#This Row],[Year]]-StabilizationRefiYear)*12,PMT(RefinanceLoanRate/12,RefinanceLoanAmortizationYears*12,RefinanceLoanAmount),RefinanceLoanAmount)))) -> 0 | P4: =IF(AnnualModelTable[[#This Row],[Year]]>SaleExitYear,0,IF(AnnualModelTable[[#This Row],[Year]]<StabilizationRefiYear,0,AnnualModelTable[[#This Row],[NOI]]*(1+NOIGrowth)/ExitCapRate)) -> 0
A5: 1 | B5: Lease-Up | C5: =IF(AnnualModelTable[[#This Row],[Year]]>SaleExitYear,0,IF(AnnualModelTable[[#This Row],[Year]]=0,0,INDEX(STRScenarioTable[Selected Annual Gross Rent],MATCH(AnnualModelTable[[#This Row],[Year]],STRScenarioTable[Year],0)))) -> 95440 | D5: =IF(AnnualModelTable[[#This Row],[Year]]>SaleExitYear,0,IF(AnnualModelTable[[#This Row],[Year]]=0,0,AnnualModelTable[[#This Row],[Gross Potential Rent]]*IF(AnnualModelTable[[#This Row],[Year]]=1,LeaseUpOccupancy,StabilizedOccupancy))) -> 47720 | E5: =IF(AnnualModelTable[[#This Row],[Year]]>SaleExitYear,0,AnnualModelTable[[#This Row],[Occupancy Effective Gross Income]]*OperatingExpenseRatio) -> 22386.638 | F5: =IF(AnnualModelTable[[#This Row],[Year]]>SaleExitYear,0,AnnualModelTable[[#This Row],[Occupancy Effective Gross Income]]-AnnualModelTable[[#This Row],[Operating Expenses]]) -> 25333.362 | G5: =IF(AnnualModelTable[[#This Row],[Year]]>SaleExitYear,0,IF(AND(AnnualModelTable[[#This Row],[Year]]>=1,AnnualModelTable[[#This Row],[Year]]<StabilizationRefiYear),ExistingDebtServiceAnnual,IF(AND(AnnualModelTable[[#This Row],[Year]]>=StabilizationRefiYear,AnnualModelTable[[#This Row],[Year]]<=SaleExitYear),-PMT(RefinanceLoanRate/12,RefinanceLoanAmortizationYears*12,RefinanceLoanAmount)*12,0))) -> 13812 | H5: =IF(AnnualModelTable[[#This Row],[Year]]>SaleExitYear,0,AnnualModelTable[[#This Row],[NOI]]-AnnualModelTable[[#This Row],[Debt Service]]) -> 11521.362 | I5: =IF(AnnualModelTable[[#This Row],[Year]]>SaleExitYear,0,IF(AnnualModelTable[[#This Row],[Year]]=0,SponsorPropertyPayment,IF(AnnualModelTable[[#This Row],[Year]]=StabilizationRefiYear,MAX(0,RefinanceLoanAmount-TotalExistingDebt),IF(AnnualModelTable[[#This Row],[Year]]=SaleExitYear,MAX(0,AnnualModelTable[[#This Row],[Property Value / Refi Value]]*(1-SellingCosts)-AnnualModelTable[[#This Row],[Loan Balance]]),0)))) -> 0 | J5: =IF(AnnualModelTable[[#This Row],[Year]]>SaleExitYear,0,IF(AnnualModelTable[[#This Row],[Year]]=0,0,MIN(MAX(0,RepairsMaintenanceReserveTarget-IFERROR(INDEX(AnnualModelTable[Reserve Balance],MATCH(AnnualModelTable[[#This Row],[Year]]-1,AnnualModelTable[Year],0)),0)),MAX(0,IFERROR(INDEX(AnnualModelTable[Ending Cash Balance],MATCH(AnnualModelTable[[#This Row],[Year]]-1,AnnualModelTable[Year],0)),0)+AnnualModelTable[[#This Row],[Cash Before Refi/Sale]]+AnnualModelTable[[#This Row],[Net Refi/Sale Proceeds]])))) -> 9000 | K5: =IF(AnnualModelTable[[#This Row],[Year]]>SaleExitYear,0,IF(AnnualModelTable[[#This Row],[Year]]=0,0,IFERROR(INDEX(AnnualModelTable[Reserve Balance],MATCH(AnnualModelTable[[#This Row],[Year]]-1,AnnualModelTable[Year],0)),0)+AnnualModelTable[[#This Row],[Reserve Funding]])) -> 9000 | L5: =IF(AnnualModelTable[[#This Row],[Year]]>SaleExitYear,0,IF(AnnualModelTable[[#This Row],[Year]]=0,0,IFERROR(INDEX(AnnualModelTable[Ending Cash Balance],MATCH(AnnualModelTable[[#This Row],[Year]]-1,AnnualModelTable[Year],0)),0))+AnnualModelTable[[#This Row],[Cash Before Refi/Sale]]+AnnualModelTable[[#This Row],[Net Refi/Sale Proceeds]]-AnnualModelTable[[#This Row],[Reserve Funding]]) -> 2521.3621 | M5: =IF(AnnualModelTable[[#This Row],[Year]]>SaleExitYear,0,SUM(INDEX(WaterfallTable[Total Dist A],MATCH(AnnualModelTable[[#This Row],[Year]],WaterfallTable[Year],0)),INDEX(WaterfallTable[Total Dist B],MATCH(AnnualModelTable[[#This Row],[Year]],WaterfallTable[Year],0)),INDEX(WaterfallTable[Total Dist2],MATCH(AnnualModelTable[[#This Row],[Year]],WaterfallTable[Year],0)))) -> 2521.3621 | N5: =IF(AnnualModelTable[[#This Row],[Year]]>SaleExitYear,0,MAX(0,AnnualModelTable[[#This Row],[Cash Available Before Distributions]]-AnnualModelTable[[#This Row],[Waterfall Distributions]])) -> 0 | O5: =IF(AnnualModelTable[[#This Row],[Year]]>SaleExitYear,0,IF(AnnualModelTable[[#This Row],[Year]]<StabilizationRefiYear,0,IF(AnnualModelTable[[#This Row],[Year]]=SaleExitYear,0,-FV(RefinanceLoanRate/12,(AnnualModelTable[[#This Row],[Year]]-StabilizationRefiYear)*12,PMT(RefinanceLoanRate/12,RefinanceLoanAmortizationYears*12,RefinanceLoanAmount),RefinanceLoanAmount)))) -> 0 | P5: =IF(AnnualModelTable[[#This Row],[Year]]>SaleExitYear,0,IF(AnnualModelTable[[#This Row],[Year]]<StabilizationRefiYear,0,AnnualModelTable[[#This Row],[NOI]]*(1+NOIGrowth)/ExitCapRate)) -> 0
A6: 2 | B6: Stabilization / Refi | C6: =IF(AnnualModelTable[[#This Row],[Year]]>SaleExitYear,0,IF(AnnualModelTable[[#This Row],[Year]]=0,0,INDEX(STRScenarioTable[Selected Annual Gross Rent],MATCH(AnnualModelTable[[#This Row],[Year]],STRScenarioTable[Year],0)))) -> 133895 | D6: =IF(AnnualModelTable[[#This Row],[Year]]>SaleExitYear,0,IF(AnnualModelTable[[#This Row],[Year]]=0,0,AnnualModelTable[[#This Row],[Gross Potential Rent]]*IF(AnnualModelTable[[#This Row],[Year]]=1,LeaseUpOccupancy,StabilizedOccupancy))) -> 124522.35 | E6: =IF(AnnualModelTable[[#This Row],[Year]]>SaleExitYear,0,AnnualModelTable[[#This Row],[Occupancy Effective Gross Income]]*OperatingExpenseRatio) -> 58416.529 | F6: =IF(AnnualModelTable[[#This Row],[Year]]>SaleExitYear,0,AnnualModelTable[[#This Row],[Occupancy Effective Gross Income]]-AnnualModelTable[[#This Row],[Operating Expenses]]) -> 66105.821 | G6: =IF(AnnualModelTable[[#This Row],[Year]]>SaleExitYear,0,IF(AND(AnnualModelTable[[#This Row],[Year]]>=1,AnnualModelTable[[#This Row],[Year]]<StabilizationRefiYear),ExistingDebtServiceAnnual,IF(AND(AnnualModelTable[[#This Row],[Year]]>=StabilizationRefiYear,AnnualModelTable[[#This Row],[Year]]<=SaleExitYear),-PMT(RefinanceLoanRate/12,RefinanceLoanAmortizationYears*12,RefinanceLoanAmount)*12,0))) -> 13812 | H6: =IF(AnnualModelTable[[#This Row],[Year]]>SaleExitYear,0,AnnualModelTable[[#This Row],[NOI]]-AnnualModelTable[[#This Row],[Debt Service]]) -> 52293.821 | I6: =IF(AnnualModelTable[[#This Row],[Year]]>SaleExitYear,0,IF(AnnualModelTable[[#This Row],[Year]]=0,SponsorPropertyPayment,IF(AnnualModelTable[[#This Row],[Year]]=StabilizationRefiYear,MAX(0,RefinanceLoanAmount-TotalExistingDebt),IF(AnnualModelTable[[#This Row],[Year]]=SaleExitYear,MAX(0,AnnualModelTable[[#This Row],[Property Value / Refi Value]]*(1-SellingCosts)-AnnualModelTable[[#This Row],[Loan Balance]]),0)))) -> 0 | J6: =IF(AnnualModelTable[[#This Row],[Year]]>SaleExitYear,0,IF(AnnualModelTable[[#This Row],[Year]]=0,0,MIN(MAX(0,RepairsMaintenanceReserveTarget-IFERROR(INDEX(AnnualModelTable[Reserve Balance],MATCH(AnnualModelTable[[#This Row],[Year]]-1,AnnualModelTable[Year],0)),0)),MAX(0,IFERROR(INDEX(AnnualModelTable[Ending Cash Balance],MATCH(AnnualModelTable[[#This Row],[Year]]-1,AnnualModelTable[Year],0)),0)+AnnualModelTable[[#This Row],[Cash Before Refi/Sale]]+AnnualModelTable[[#This Row],[Net Refi/Sale Proceeds]])))) -> 0 | K6: =IF(AnnualModelTable[[#This Row],[Year]]>SaleExitYear,0,IF(AnnualModelTable[[#This Row],[Year]]=0,0,IFERROR(INDEX(AnnualModelTable[Reserve Balance],MATCH(AnnualModelTable[[#This Row],[Year]]-1,AnnualModelTable[Year],0)),0)+AnnualModelTable[[#This Row],[Reserve Funding]])) -> 9000 | L6: =IF(AnnualModelTable[[#This Row],[Year]]>SaleExitYear,0,IF(AnnualModelTable[[#This Row],[Year]]=0,0,IFERROR(INDEX(AnnualModelTable[Ending Cash Balance],MATCH(AnnualModelTable[[#This Row],[Year]]-1,AnnualModelTable[Year],0)),0))+AnnualModelTable[[#This Row],[Cash Before Refi/Sale]]+AnnualModelTable[[#This Row],[Net Refi/Sale Proceeds]]-AnnualModelTable[[#This Row],[Reserve Funding]]) -> 52293.821 | M6: =IF(AnnualModelTable[[#This Row],[Year]]>SaleExitYear,0,SUM(INDEX(WaterfallTable[Total Dist A],MATCH(AnnualModelTable[[#This Row],[Year]],WaterfallTable[Year],0)),INDEX(WaterfallTable[Total Dist B],MATCH(AnnualModelTable[[#This Row],[Year]],WaterfallTable[Year],0)),INDEX(WaterfallTable[Total Dist2],MATCH(AnnualModelTable[[#This Row],[Year]],WaterfallTable[Year],0)))) -> 52293.821 | N6: =IF(AnnualModelTable[[#This Row],[Year]]>SaleExitYear,0,MAX(0,AnnualModelTable[[#This Row],[Cash Available Before Distributions]]-AnnualModelTable[[#This Row],[Waterfall Distributions]])) -> 0 | O6: =IF(AnnualModelTable[[#This Row],[Year]]>SaleExitYear,0,IF(AnnualModelTable[[#This Row],[Year]]<StabilizationRefiYear,0,IF(AnnualModelTable[[#This Row],[Year]]=SaleExitYear,0,-FV(RefinanceLoanRate/12,(AnnualModelTable[[#This Row],[Year]]-StabilizationRefiYear)*12,PMT(RefinanceLoanRate/12,RefinanceLoanAmortizationYears*12,RefinanceLoanAmount),RefinanceLoanAmount)))) -> 0 | P6: =IF(AnnualModelTable[[#This Row],[Year]]>SaleExitYear,0,IF(AnnualModelTable[[#This Row],[Year]]<StabilizationRefiYear,0,AnnualModelTable[[#This Row],[NOI]]*(1+NOIGrowth)/ExitCapRate)) -> 0
A7: 3 | B7: Operations | C7: =IF(AnnualModelTable[[#This Row],[Year]]>SaleExitYear,0,IF(AnnualModelTable[[#This Row],[Year]]=0,0,INDEX(STRScenarioTable[Selected Annual Gross Rent],MATCH(AnnualModelTable[[#This Row],[Year]],STRScenarioTable[Year],0)))) -> 173400 | D7: =IF(AnnualModelTable[[#This Row],[Year]]>SaleExitYear,0,IF(AnnualModelTable[[#This Row],[Year]]=0,0,AnnualModelTable[[#This Row],[Gross Potential Rent]]*IF(AnnualModelTable[[#This Row],[Year]]=1,LeaseUpOccupancy,StabilizedOccupancy))) -> 161262 | E7: =IF(AnnualModelTable[[#This Row],[Year]]>SaleExitYear,0,AnnualModelTable[[#This Row],[Occupancy Effective Gross Income]]*OperatingExpenseRatio) -> 75652.012 | F7: =IF(AnnualModelTable[[#This Row],[Year]]>SaleExitYear,0,AnnualModelTable[[#This Row],[Occupancy Effective Gross Income]]-AnnualModelTable[[#This Row],[Operating Expenses]]) -> 85609.988 | G7: =IF(AnnualModelTable[[#This Row],[Year]]>SaleExitYear,0,IF(AND(AnnualModelTable[[#This Row],[Year]]>=1,AnnualModelTable[[#This Row],[Year]]<StabilizationRefiYear),ExistingDebtServiceAnnual,IF(AND(AnnualModelTable[[#This Row],[Year]]>=StabilizationRefiYear,AnnualModelTable[[#This Row],[Year]]<=SaleExitYear),-PMT(RefinanceLoanRate/12,RefinanceLoanAmortizationYears*12,RefinanceLoanAmount)*12,0))) -> 55541.823 | H7: =IF(AnnualModelTable[[#This Row],[Year]]>SaleExitYear,0,AnnualModelTable[[#This Row],[NOI]]-AnnualModelTable[[#This Row],[Debt Service]]) -> 30068.166 | I7: =IF(AnnualModelTable[[#This Row],[Year]]>SaleExitYear,0,IF(AnnualModelTable[[#This Row],[Year]]=0,SponsorPropertyPayment,IF(AnnualModelTable[[#This Row],[Year]]=StabilizationRefiYear,MAX(0,RefinanceLoanAmount-TotalExistingDebt),IF(AnnualModelTable[[#This Row],[Year]]=SaleExitYear,MAX(0,AnnualModelTable[[#This Row],[Property Value / Refi Value]]*(1-SellingCosts)-AnnualModelTable[[#This Row],[Loan Balance]]),0)))) -> 538276.44 | J7: =IF(AnnualModelTable[[#This Row],[Year]]>SaleExitYear,0,IF(AnnualModelTable[[#This Row],[Year]]=0,0,MIN(MAX(0,RepairsMaintenanceReserveTarget-IFERROR(INDEX(AnnualModelTable[Reserve Balance],MATCH(AnnualModelTable[[#This Row],[Year]]-1,AnnualModelTable[Year],0)),0)),MAX(0,IFERROR(INDEX(AnnualModelTable[Ending Cash Balance],MATCH(AnnualModelTable[[#This Row],[Year]]-1,AnnualModelTable[Year],0)),0)+AnnualModelTable[[#This Row],[Cash Before Refi/Sale]]+AnnualModelTable[[#This Row],[Net Refi/Sale Proceeds]])))) -> 0 | K7: =IF(AnnualModelTable[[#This Row],[Year]]>SaleExitYear,0,IF(AnnualModelTable[[#This Row],[Year]]=0,0,IFERROR(INDEX(AnnualModelTable[Reserve Balance],MATCH(AnnualModelTable[[#This Row],[Year]]-1,AnnualModelTable[Year],0)),0)+AnnualModelTable[[#This Row],[Reserve Funding]])) -> 9000 | L7: =IF(AnnualModelTable[[#This Row],[Year]]>SaleExitYear,0,IF(AnnualModelTable[[#This Row],[Year]]=0,0,IFERROR(INDEX(AnnualModelTable[Ending Cash Balance],MATCH(AnnualModelTable[[#This Row],[Year]]-1,AnnualModelTable[Year],0)),0))+AnnualModelTable[[#This Row],[Cash Before Refi/Sale]]+AnnualModelTable[[#This Row],[Net Refi/Sale Proceeds]]-AnnualModelTable[[#This Row],[Reserve Funding]]) -> 568344.61 | M7: =IF(AnnualModelTable[[#This Row],[Year]]>SaleExitYear,0,SUM(INDEX(WaterfallTable[Total Dist A],MATCH(AnnualModelTable[[#This Row],[Year]],WaterfallTable[Year],0)),INDEX(WaterfallTable[Total Dist B],MATCH(AnnualModelTable[[#This Row],[Year]],WaterfallTable[Year],0)),INDEX(WaterfallTable[Total Dist2],MATCH(AnnualModelTable[[#This Row],[Year]],WaterfallTable[Year],0)))) -> 568344.61 | N7: =IF(AnnualModelTable[[#This Row],[Year]]>SaleExitYear,0,MAX(0,AnnualModelTable[[#This Row],[Cash Available Before Distributions]]-AnnualModelTable[[#This Row],[Waterfall Distributions]])) -> 0 | O7: =IF(AnnualModelTable[[#This Row],[Year]]>SaleExitYear,0,IF(AnnualModelTable[[#This Row],[Year]]<StabilizationRefiYear,0,IF(AnnualModelTable[[#This Row],[Year]]=SaleExitYear,0,-FV(RefinanceLoanRate/12,(AnnualModelTable[[#This Row],[Year]]-StabilizationRefiYear)*12,PMT(RefinanceLoanRate/12,RefinanceLoanAmortizationYears*12,RefinanceLoanAmount),RefinanceLoanAmount)))) -> 732276.44 | P7: =IF(AnnualModelTable[[#This Row],[Year]]>SaleExitYear,0,IF(AnnualModelTable[[#This Row],[Year]]<StabilizationRefiYear,0,AnnualModelTable[[#This Row],[NOI]]*(1+NOIGrowth)/ExitCapRate)) -> 1259689.8
A8: 4 | B8: Operations | C8: =IF(AnnualModelTable[[#This Row],[Year]]>SaleExitYear,0,IF(AnnualModelTable[[#This Row],[Year]]=0,0,INDEX(STRScenarioTable[Selected Annual Gross Rent],MATCH(AnnualModelTable[[#This Row],[Year]],STRScenarioTable[Year],0)))) -> 173400 | D8: =IF(AnnualModelTable[[#This Row],[Year]]>SaleExitYear,0,IF(AnnualModelTable[[#This Row],[Year]]=0,0,AnnualModelTable[[#This Row],[Gross Potential Rent]]*IF(AnnualModelTable[[#This Row],[Year]]=1,LeaseUpOccupancy,StabilizedOccupancy))) -> 161262 | E8: =IF(AnnualModelTable[[#This Row],[Year]]>SaleExitYear,0,AnnualModelTable[[#This Row],[Occupancy Effective Gross Income]]*OperatingExpenseRatio) -> 75652.012 | F8: =IF(AnnualModelTable[[#This Row],[Year]]>SaleExitYear,0,AnnualModelTable[[#This Row],[Occupancy Effective Gross Income]]-AnnualModelTable[[#This Row],[Operating Expenses]]) -> 85609.988 | G8: =IF(AnnualModelTable[[#This Row],[Year]]>SaleExitYear,0,IF(AND(AnnualModelTable[[#This Row],[Year]]>=1,AnnualModelTable[[#This Row],[Year]]<StabilizationRefiYear),ExistingDebtServiceAnnual,IF(AND(AnnualModelTable[[#This Row],[Year]]>=StabilizationRefiYear,AnnualModelTable[[#This Row],[Year]]<=SaleExitYear),-PMT(RefinanceLoanRate/12,RefinanceLoanAmortizationYears*12,RefinanceLoanAmount)*12,0))) -> 55541.823 | H8: =IF(AnnualModelTable[[#This Row],[Year]]>SaleExitYear,0,AnnualModelTable[[#This Row],[NOI]]-AnnualModelTable[[#This Row],[Debt Service]]) -> 30068.166 | I8: =IF(AnnualModelTable[[#This Row],[Year]]>SaleExitYear,0,IF(AnnualModelTable[[#This Row],[Year]]=0,SponsorPropertyPayment,IF(AnnualModelTable[[#This Row],[Year]]=StabilizationRefiYear,MAX(0,RefinanceLoanAmount-TotalExistingDebt),IF(AnnualModelTable[[#This Row],[Year]]=SaleExitYear,MAX(0,AnnualModelTable[[#This Row],[Property Value / Refi Value]]*(1-SellingCosts)-AnnualModelTable[[#This Row],[Loan Balance]]),0)))) -> 0 | J8: =IF(AnnualModelTable[[#This Row],[Year]]>SaleExitYear,0,IF(AnnualModelTable[[#This Row],[Year]]=0,0,MIN(MAX(0,RepairsMaintenanceReserveTarget-IFERROR(INDEX(AnnualModelTable[Reserve Balance],MATCH(AnnualModelTable[[#This Row],[Year]]-1,AnnualModelTable[Year],0)),0)),MAX(0,IFERROR(INDEX(AnnualModelTable[Ending Cash Balance],MATCH(AnnualModelTable[[#This Row],[Year]]-1,AnnualModelTable[Year],0)),0)+AnnualModelTable[[#This Row],[Cash Before Refi/Sale]]+AnnualModelTable[[#This Row],[Net Refi/Sale Proceeds]])))) -> 0 | K8: =IF(AnnualModelTable[[#This Row],[Year]]>SaleExitYear,0,IF(AnnualModelTable[[#This Row],[Year]]=0,0,IFERROR(INDEX(AnnualModelTable[Reserve Balance],MATCH(AnnualModelTable[[#This Row],[Year]]-1,AnnualModelTable[Year],0)),0)+AnnualModelTable[[#This Row],[Reserve Funding]])) -> 9000 | L8: =IF(AnnualModelTable[[#This Row],[Year]]>SaleExitYear,0,IF(AnnualModelTable[[#This Row],[Year]]=0,0,IFERROR(INDEX(AnnualModelTable[Ending Cash Balance],MATCH(AnnualModelTable[[#This Row],[Year]]-1,AnnualModelTable[Year],0)),0))+AnnualModelTable[[#This Row],[Cash Before Refi/Sale]]+AnnualModelTable[[#This Row],[Net Refi/Sale Proceeds]]-AnnualModelTable[[#This Row],[Reserve Funding]]) -> 30068.166 | M8: =IF(AnnualModelTable[[#This Row],[Year]]>SaleExitYear,0,SUM(INDEX(WaterfallTable[Total Dist A],MATCH(AnnualModelTable[[#This Row],[Year]],WaterfallTable[Year],0)),INDEX(WaterfallTable[Total Dist B],MATCH(AnnualModelTable[[#This Row],[Year]],WaterfallTable[Year],0)),INDEX(WaterfallTable[Total Dist2],MATCH(AnnualModelTable[[#This Row],[Year]],WaterfallTable[Year],0)))) -> 30068.166 | N8: =IF(AnnualModelTable[[#This Row],[Year]]>SaleExitYear,0,MAX(0,AnnualModelTable[[#This Row],[Cash Available Before Distributions]]-AnnualModelTable[[#This Row],[Waterfall Distributions]])) -> 0 | O8: =IF(AnnualModelTable[[#This Row],[Year]]>SaleExitYear,0,IF(AnnualModelTable[[#This Row],[Year]]<StabilizationRefiYear,0,IF(AnnualModelTable[[#This Row],[Year]]=SaleExitYear,0,-FV(RefinanceLoanRate/12,(AnnualModelTable[[#This Row],[Year]]-StabilizationRefiYear)*12,PMT(RefinanceLoanRate/12,RefinanceLoanAmortizationYears*12,RefinanceLoanAmount),RefinanceLoanAmount)))) -> 724091.6 | P8: =IF(AnnualModelTable[[#This Row],[Year]]>SaleExitYear,0,IF(AnnualModelTable[[#This Row],[Year]]<StabilizationRefiYear,0,AnnualModelTable[[#This Row],[NOI]]*(1+NOIGrowth)/ExitCapRate)) -> 1259689.8
