Workbook
Name baseCost: #REF!
Name BaseFlagOf: _xlfn.LAMBDA(_xlpm.i,_xlpm.baseIdxTxt,_xlpm.baseCost, --ISNUMBER(SEARCH("BASE PARENT", UPPER(_xlfn.XLOOKUP(TEXT(_xlpm.i,"0"), _xlpm.baseIdxTxt, _xlpm.baseCost, "")))) )
Name baseIdxTxt: TEXT(#REF!,"0")
Name cfdContractDate: [1]Amortization!$J$13
Name cfdContractMonths: [1]Amortization!$P$14
Name cfdEndDate: [1]Amortization!$S$14
Name cfdFirstRateMonths: [1]Amortization!$P$13
Name cfdRate1: [1]Amortization!$O$8
Name cfdRate1Payment: [1]Amortization!$V$8
Name cfdRate2: [1]Amortization!$O$11
Name cfdRate2Payment: [1]Amortization!$V$11
Name cfdRateChangeDate: [1]Amortization!$S$13
Name DepTitlesUsed: _xlfn.ANCHORARRAY(#REF!)
Name downPaymentRefinancedFirstMortgage: [1]Amortization!$AH$5
Name editsIdxTxt: TEXT(#REF!,"0")
Name editsParentKeyTxt: TEXT(#REF!,"0")
Name Milestone_Marker: '[1]Gnatt Chart'!$G$4
Name Milestone_Marker: 'Gnatt Chart'!$G$4
Name Project_Start: '[1]Gnatt Chart'!$F$2
Name Project_Start: 'Gnatt Chart'!$F$2
Name Scrolling_Increment: '[1]Gnatt Chart'!$AB$24
Name Scrolling_Increment: 'Gnatt Chart'!$AB$26
Name subjectInterestRate: [1]Amortization!$D$4
Name subjectKnownBalance: [1]Amortization!$D$3
Name subjectKnownBalanceDate: [1]Amortization!$D$7
Name subjectMortgageEndDate: [1]Amortization!$D$8
Name subjectPayment: [1]Amortization!$D$6
Name subjectRemainingMonths: [1]Amortization!$E$5
Name Today: TODAY()
Name tradeMonthlyNetSpread: 'Trade Properties'!$T$13
Name tradeNetCreditIncluded: 'Trade Properties'!$T$10
Name tradePropertyConditionsForDocs: 'Trade Properties'!$T$21
Name tradePropertyListForDocs: 'Trade Properties'!$T$20

Sheet Profit
A1: Flip, Hold or Wholetale: | B1: flip | E1: Buy | F1: Your Home LLC
B2: 3325 Banks Rd, Raleigh, NC 27603 | H2: Monthly Cash Flow | J2: Hearing Date:
A3: Income | D3: Immediate | F3: Upon Sale
A4: CMA: | B4: 439000 | J4: Finalized: | K4: No | O4: Todays' date: | P4: =NOW() -> 46203.546
A5: % Above/Below Market Sale: | B5: -0.15 | C5: 0.1 | N5: Zillow | O5: 45161 | P5: 276600
A6: Sale Price: | B6: =+B4 + IF(B1="Hold",B4*C5,0) + IF(B1="wholetale",B4*B5,0) -> 439000 | G6: =IF($B$1="hold",$B$4,$B$6) -> 439000 | J6: Anuual Growth: | K6: 0.1
A7: NonRefundable Deposit: | D7: =+B7 -> 0 | F7: =-B7 -> 0 | G7: =+IF($B$1="hold",$K$6,0)*$C$35/12*B4 -> 0 | H7: =+IF($B$1="hold","<-- Apprication -----------","")
A8: Rent: | B8: 2000 | I8: =IF(B1="Hold",+B8,"") | J8: Sq Footage | K8: 1899
C9: Net Income: | D9: Net Income: | E9: =SUM(D4:D8) -> 0 | F9: =+SUM(F4:G8) -> 439000 | H9: =SUM(H4:I8) -> 0
A11: Expenses
A12: Reinstatment Cost 1st: | B12: 12645 | D12: =-B12 -> -12645 | G12: =IF(K4="Yes",0.3*B12,"") | H12: <-- Approx Pay-Down | J12: If the Subject To Value is finalized, zero-out the Pay-Down savings
A13: Subject To 1st:Truist | B13: 0.03125 | C13: 125037.73 | F13: =-C13 -> -125037.73
A14: Reinstatment Cost 2st: | F14: =-+(120-C34)*(C14/120) -> 0 | H14: =-(C14*B14/12) -> 0
A15: Subject To 2st:Notes | B15: 0.1 | F15: =-C15 -> 0 | H15: =-C15/120-(C15*B15/12) -> 0
A16: Liens - IRS & HOA | D16: =-C16 -> 0
A17: Partners Share % | B17: 0
A18: or Seller Payout: | B18: 10000 | D18: =-B18 -> -10000 | J18: Yellow cells can be edited
A19: HOA Fees(Catch Up) | C19: 0 | D19: =-B19 -> 0
A20: Months Carried | B20: =+F57/30 -> 60.4 | J20: Do not edit Green cells. They are highlighted only to show profit
A21: Mortgage Payment: | B21: =+Carrying!H$88/$B$20 -> 1154.8924 | H21: =IF(B1="Hold",-B21,"")
A22: Mortgage Payment - 2nd: | H22: =IF(B1="Hold",-B22,"")
A23: Property Insurance | B23: =+Carrying!L$88/$B$20 -> 85.609437 | H23: =IF(B1="Hold",-B23,"")
A24: HOA Fees (monthly) | H24: =IF(B1="Hold",-B24,"")
A25: Electric | B25: =+Carrying!D$88/$B$20 -> 12.588576
A26: water | O26: 1st Mortgage | P26: =+C13 -> 125037.73
A27: Carrying Cost | B27: =+B20*SUM(B21:B26) -> 75686.66 | D27: =-B27 -> -75686.66 | J27: Purchase Cost | K27: =+SUM(B12:C16)+B18 -> 147682.86 | N27: Private Lender | O27: Neal Issacs | P27: 75000
A28: Private Lender Rate: | B28: 0.1 | C28: yes
A29: 75%ARV-Debt: | B29: =IF(C28="NO",0,+(B6*0.75)-(C13+C14+C15)) -> 204212.27 | E29: 75000 | F29: =IF(C28="No","",-E29-(B20*E29*B28/12)) -> -112750 | H29: =-IF($B$1="Hold",E29*B28/12,0) -> 0 | J29: Out of Pocket | K29: =+B12+C14+C16+B18+B30 -> 54069.184
A30: Rehab: | B30: =-D51 -> 31424.184 | D30: =-B30 -> -31424.184 | M30: =+K27+B30 -> 179107.05
A31: Marketing: | B31: 600 | D31: =-B31 -> -600 | J31: PL Balance +Interest | Q31: =SUM(P26:P30) -> 200037.73
A32: Seller Realtor's Flat Fee | B32: 1 | C32: =+B32*399 -> 399 | F32: =-C32 -> -399
A33: Seller Realtor's Fee Percent: | B33: 0 | C33: 0.026 | F33: =-B33*C33*$F$9 -> 0
A34: Buyers Realtors Fee Percent: | B34: 1 | C34: 0.024 | F34: =-B34*C34*$F$9 -> -10536
A35: Number of Rent Payments : | C35: 12
A36: Buyer Assistance | F36: =-C36 -> 0
A37: Buying Closing Cost: | B37: =+D71 -> 5998 | D37: =-B37 -> -5998
A38: Selling Closing Cost: | B38: =+D82 -> 290 | F38: =-B38 -> -290
C39: Net Expenses: | E39: =+SUM(D12:D38) -> -136353.84 | F39: =+SUM(F12:F38) -> -249012.73 | H39: =+SUM(H9:I38) -> 0
B40: Immediate Profit: | E40: =+SUM(E9:E39) -> -61353.844 | F40: =+SUM(F9:G38) -> 189987.27
E41: Long Term Profit: | G41: =+E40+F40 -> 128633.43 | J41: Partners Profit Share | K41: Our Profit Share
...

Sheet Trade Properties
A2: Property | B2: Home Type | C2: Est. Property Value | D2: Lot Rent / Mo | E2: Tenant Payment / Mo | F2: Property Tax / Mo | G2: Insurance / Mo | H2: Monthly Net Spread | I2: Annual Net Spread | J2: Expense % of Payment | K2: Net Spread Margin | L2: Net Yield on Value | M2: Max Value @ 10% | N2: Max Value @ 12% | O2: Max Value @ 15% | P2: Notes | R2: Summary / Document Outputs
H3: =IF(OR(D3="",E3=""),"",E3-SUM(D3,F3:G3)) | I3: =IF(H3="","",H3*12) | J3: =IFERROR(SUM(D3,F3:G3)/E3,"") | K3: =IFERROR(H3/E3,"") | L3: =IFERROR(I3/C3,"") | M3: =IF(I3="","",I3/10%) | N3: =IF(I3="","",I3/12%) | O3: =IF(I3="","",I3/15%) | R3: Total Trade Property Value Proposed | S3: =SUM(I14:I16) -> 0
H4: =IF(OR(D4="",E4=""),"",E4-SUM(D4,F4:G4)) | I4: =IF(H4="","",H4*12) | J4: =IFERROR(SUM(D4,F4:G4)/E4,"") | K4: =IFERROR(H4/E4,"") | L4: =IFERROR(I4/C4,"") | M4: =IF(I4="","",I4/10%) | N4: =IF(I4="","",I4/12%) | O4: =IF(I4="","",I4/15%) | R4: Total Liens or Deductions | S4: =SUM(J14:J16) -> 0
H5: =IF(OR(D5="",E5=""),"",E5-SUM(D5,F5:G5)) | I5: =IF(H5="","",H5*12) | J5: =IFERROR(SUM(D5,F5:G5)/E5,"") | K5: =IFERROR(H5/E5,"") | L5: =IFERROR(I5/C5,"") | M5: =IF(I5="","",I5/10%) | N5: =IF(I5="","",I5/12%) | O5: =IF(I5="","",I5/15%) | R5: Total Net Trade Credit Included | S5: =K17 -> 0
A6: Total | C6: =SUM(C3:C5) -> 0 | D6: =SUM(D3:D5) -> 0 | E6: =SUM(E3:E5) -> 0 | F6: =SUM(F3:F5) -> 0 | G6: =SUM(G3:G5) -> 0 | H6: =SUM(H3:H5) -> 0 | I6: =SUM(I3:I5) -> 0 | J6: =IFERROR(SUM(D6,F6:G6)/E6,"") | K6: =IFERROR(H6/E6,"") | L6: =IFERROR(I6/C6,"") | M6: =IF(I6="","",I6/10%) -> 0 | N6: =IF(I6="","",I6/12%) -> 0 | O6: =IF(I6="","",I6/15%) -> 0 | R6: Total Tenant Rent | S6: =D17 -> 0
R7: Total Monthly Expenses | S7: =C17 -> 0
A8: Trade Properties - Manufactured Home Credit Analysis | R8: Total Monthly Net Spread: | S8: =E17 -> 0
A9: Use this tab for valuation and support detail only. Contract generators should read only the final document fields exposed on Replacement Docs. Proposed values are analysis inputs until titles/bills of sale, lien releases, possession/keys, tenant/rent information, and park/lot approvals are delivered and accepted. | R9: Total Annual Net Spread: | S9: =F17 -> 0
I11: 0.1 | J11: 2 | R11: Implied Value at 10% Yield | S11: =S9/10% -> 0
C12: Expected monthly net spread from future Contract for Deed/resale payments after lot rent, property tax, and insurance | R12: Implied Value at 12% Yield | S12: =S9/12% -> 0
A13: Property Address | B13: Home Type | C13: Monthly Expenses | D13: Tenant Rent | E13: Monthly Net Spread | F13: Annual Net Spread | G13: Cap Based Value | H13: CMA Based Value | I13: Proposed Value / Agreed Credit | J13: Liens or Deductions | K13: Net Trade Credit | L13: Include in Contract? | M13: Title/Bill-of-Sale Status | N13: Park/Lot Approval Status | O13: Tenant/Lease Verification Status | R13: Implied Value at 15% Yield | S13: =S9/15% -> 0
A14: =+A3 -> 0 | B14: =+B3 -> 0 | C14: =SUM(D3,F3:G3) -> 0 | D14: =E3 -> 0 | E14: =D14-C14 -> 0 | F14: =E14*12 -> 0 | G14: =+O3 | H14: =C3 -> 0 | I14: =IF($J$11=2,H14,G14)*(1-$I$11) -> 0 | J14: 0 | K14: =IF($L14,MAX(0,I14-J14),0) -> 0 | L14: FALSE
A15: =+A4 -> 0 | B15: =+B4 -> 0 | C15: =SUM(D4,F4:G4) -> 0 | D15: =E4 -> 0 | E15: =D15-C15 -> 0 | F15: =E15*12 -> 0 | G15: =+O4 | H15: =C4 -> 0 | I15: =IF($J$11=2,H15,G15)*(1-$I$11) -> 0 | J15: 0 | K15: =IF($L15,MAX(0,I15-J15),0) -> 0 | L15: FALSE | R15: Trade Property List for Docs | S15: =_xlfn.TEXTJOIN("; ",TRUE,IF($L$14,$A$14&" - "&$B$14,""),IF($L$15,$A$15&" - "&$B$15,""),IF($L$16,$A$16&" - "&$B$16,""))
A16: =+A5 -> 0 | B16: =+B5 -> 0 | C16: =SUM(D5,F5:G5) -> 0 | D16: =E5 -> 0 | E16: =D16-C16 -> 0 | F16: =E16*12 -> 0 | G16: =+O5 | H16: =C5 -> 0 | I16: =IF($J$11=2,H16,G16)*(1-$I$11) -> 0 | J16: 0 | K16: =IF($L16,MAX(0,I16-J16),0) -> 0 | L16: FALSE | R16: Trade Property Conditions for Docs | S16: Trade credit is not final until titles/bills of sale, lien releases or payoff documentation, possession/keys, tenant and rent information, and park/lot approvals are delivered and accepted.
A17: Totals / Included Credit | C17: =SUMPRODUCT(--($L$14:$L$16=TRUE),C14:C16) -> 0 | D17: =SUMPRODUCT(--($L$14:$L$16=TRUE),D14:D16) -> 0 | E17: =SUMPRODUCT(--($L$14:$L$16=TRUE),E14:E16) -> 0 | F17: =SUMPRODUCT(--($L$14:$L$16=TRUE),F14:F16) -> 0 | G17: =SUMPRODUCT(--($L$14:$L$16=TRUE),G14:G16) -> 0 | H17: =SUMPRODUCT(--($L$14:$L$16=TRUE),H14:H16) -> 0 | I17: =SUMPRODUCT(--($L$14:$L$16=TRUE),I14:I16) -> 0 | J17: =SUM(J14:J16) -> 0 | K17: =SUM(K14:K16) -> 0
R18: Addendum Requirement | S18: A trade-property addendum should control title, possession, park approval, liens, tenant rents, verification, condition, and remedies if conditions are not met.
T20: =_xlfn.TEXTJOIN("; ",TRUE,IF(AND($L$14,$A$14<>""),$A$14&" - "&$B$14,""),IF(AND($L$15,$A$15<>""),$A$15&" - "&$B$15,""),IF(AND($L$16,$A$16<>""),$A$16&" - "&$B$16,""))

Sheet MOG
C1: Multiple Offer Generator | I1: ="Hi "&B3 & IF(B4 ="",""," and ") &B4&", Thank you for the opportunity to make an offer on your property at "&Profit!B2&". I have several options I would like for you to consider. I also want to give you several very good reasons for you to work with us here at Buy Your Home LLC. "&REPT(" ",6)&"1. If you sell your home to us, you will incur no expense from the transaction. We will pay all: "&REPT(" ",20)&"Closing Cost "&REPT(" ",20)&"Attorney's Fees "&REPT(" ",20)&"Realtor Commissions "&REPT(" ",6) &" 2. We can close fast. It will be a matter of days, probably less than two weeks, when we can "&REPT(" ",11) &"close at our attorney's office and get you your cash. "&REPT(" ",6) &"3. We cover the cost, time, and effort of paying any money due to any lender or HOA "&REPT(" ",11) &"involved." -> Hi Nikki, Thank you for the opportunity to make an offer on your property at 3325 Banks Rd, Raleigh, NC 27603. I have several options I would like for you to consider. I also want to give you several very good reasons for you to work with us here at Buy Your Home LLC. 1. If you sell your home to us, you will incur no expense from the transaction. We will pay all: Closing Cost Attorney's Fees Realtor Commissions 2. We can close fast. It will be a matter of days, probably less than two weeks, when we can close at our attorney's office and get you your cash. 3. We cover the cost, time, and effort of paying any money due to any lender or HOA involved. | J1: Buyers Copy | K1: =+I1&IF(N14="X",O14,"")&" "& IF(H15="X",I15,"") &" "& IF(H16="X",I16,"") &" "& IF(H20="X",I20,"") &" "& IF(H26="X",I26,"") &" "& IF(H33="X",I33,"") & " "& IF(H42="X",I42,"") & " "& IF(H52="X",I52,"") & " "& IF(H61="X",I61,"") & " "& IF(H74="X",I74,"") & " "& IF(H81="X",I81,"") & " "& IF(H82="X",I82,"") & " "& "" -> Hi Nikki, Thank you for the opportunity to make an offer on your property at 3325 Banks Rd, Raleigh, NC 27603. I have several options I would like for you to consider. I also want to give you several very good reasons for you to work with us here at Buy Your Home LLC. 1. If you sell your home to us, you will incur no expense from the transaction. We will pay all: Closing Cost Attorney's Fees Realtor Commissions 2. We can close fast. It will be a matter of days, probably less than two weeks, when we can close at our attorney's office and get you your cash. 3. We cover the cost, time, and effort of paying any money due to any lender or HOA involved. Here are some purchase options for your consideration. They are presented in summary form and I am sure you will have some questions that I will be happy to take time needed to answer. Each option below will have more value than the one above it. Option 1: Cash plus Assumption of Mortgage This is a cash payment, at closing. We will take responsibility for the existing mortgage, HOA fees, and any liens that may be discovered until we are able to resell the property. This offer is: Cash: $10,000.00 Total Value: $10,000.00 Option 2: Cash plus Promissory Note The explanation for the cash component is the same as for option 1. However, 20.% of the value of the offer will be cash and 80.% will be in the form of a promissory note, complete with a Deed of Trust. The note will have a 24-month term that will pay simple interest at the rate of 4% per year. Cash: $2,000.00 12 Month Note: $28,000.00 Interest Earned: $2,240.00 $93.33 per month Total Value: $32,240.00 Option 3: Cash plus Beneficial Interest in Trust The explanation for the cash component is the same as for option 2. Instead of a note as in Option 2, you will share in the profit earned when the property is resold. The property will be placed into a trust that you will share a beneficial interest in. The advantage here is you will benefit from the appreciated value of the property, over time. You will receive quarterly reports on the financial status of the property. Cash: $10,000.00 Interest in Trust: 70.% Expected Sellers Profit: $120,773.40 * Expected 10% appreciation per year Expected Value: $130,773.40 ** After 24 months. Nikki, this offer is contingent upon a normal due diligence period. The values of each option are predicated on some assumptions that may need to be altered upon further discovery. The more we can learn from you, in advance, the more reliable these options may be considered. When you decide which offer you prefer, I will email you a contract along with an earnest money payment. We are ready to be of service in any way we can. This offer is based on Zillow's Zestimate of $439,000.00. We will clean and prepare the property for a quick resale. There is also an assumption that the property will need no rehab. If that turns out to not be true, an allowance will need to be made. In any case, that will be decided in the due diligence period of the contract. Sincerely, Wes Browning (919) 899-2104
A3: Seller 1: | B3: Nikki | C3: Kulas | J3: no
A4: Seller 2:
A5: email:
A6: Phone #:
A9: Offer 1 | B9: Traditional, All Cash
B10: This is an all cash payment, at closing with no other allowances considered. Seller pays all Mortgages, liens, HOA expenses out of closings proceedings.
F12: Seller's Equity
B13: Sales Price | C13: ARV | D13: Debt | G13: BYH's Profit
B14: =+D14+F14 -> 146682.86 | C14: =+Profit!B4 -> 439000 | D14: =+Profit!K27-Profit!B18 -> 137682.86 | F14: =+B24-(B24*F16) -> 9000 | G14: =+C14-D14-F14+Profit!E39+Profit!B18 -> 165963.29
D15: BYH Out of Pocket: | E15: =+Profit!$K$29 -> 54069.184
D16: BYH Profit/Out of Pocket: | E16: =+G14/E15 -> 3.0694618 | F16: 0.1 | H16: X | I16: ="Here are some purchase options for your consideration. They are presented in summary form and I am sure you will have some questions that I will be happy to take time needed to answer. Each option below will have more value than the one above it." -> Here are some purchase options for your consideration. They are presented in summary form and I am sure you will have some questions that I will be happy to take time needed to answer. Each option below will have more value than the one above it.
D17: Buy Your Home's % of Profit: | E17: =+G14/(F14+G14) -> 0.94856064 | F17: less than Opt 2
A19: Offer 2 | B19: Cash plus Assumption of Mortgage | D19: *This is the default values from the Profit Sheet. | H19: =IF(H20="X",1,0) -> 0
B20: Cash payment in conjunction with taking the existing mortgage subject to: | I20: ="Option "&H19&": "&""&B9&" "&REPT(" ",6)&"This is a, traditional, all cash purchase, at closing with no other allowances considered. Seller "&REPT(" ",6)&"pays all mortgages, liens, HOA expenses, etc., out of closings disbursements. This option has " & REPT(" ",6) & "the smallest value for the seller. Our cash offer is: "&REPT(" ",43) &"Cash:"&REPT(" ",21)&+TEXT(B14,"$#,##0.00") & IF(J3="yes",REPT(" ",10) & "Profit = "& TEXT(G14,"$#,##0.00"),"" )& " "&REPT(" ",32) & "Total Value:"&REPT(" ",21)&TEXT(F14,"$#,##0.00") -> Option 0: Traditional, All Cash This is a, traditional, all cash purchase, at closing with no other allowances considered. Seller pays all mortgages, liens, HOA expenses, etc., out of closings disbursements. This option has the smallest value for the seller. Our cash offer is: Cash: $146,682.86 Total Value: $9,000.00
B21: After reinstating existing loans and HOA fees
F22: Seller's Total Value
B23: Cash | G23: BYH's Profit
B24: =+Profit!B18 -> 10000 | C24: <- The default value form profit sheet | F24: =+B24 -> 10000 | G24: =+Profit!K45+Profit!B18-B24 -> 128633.43
D25: BYH Out of Pocket: | E25: =+Profit!$K$29 -> 54069.184 | H25: =IF(H26="X",1+H19,H19) -> 1
D26: BYH Profit/Out of Pocket: | E26: =+G24/E25 -> 2.3790525 | H26: x | I26: ="Option " & H25 & ": "&""&B19&" "&REPT(" ",6) & "This is a cash payment, at closing. We will take responsibility for the existing mortgage, HOA "&REPT(" ",6) & "fees, and any liens that may be discovered until we are able to resell the property. This offer is: "&REPT(" ",43)&"Cash:"&REPT(" ",22) & TEXT(F24,"$#,##0.00") & IF(J3="yes",REPT(" ",10) & "Profit = "& TEXT(G24,"$#,##0.00"),"" ) & " "&REPT(" ",32)&"Total Value:"&REPT(" ",22) & TEXT(F24,"$#,##0.00") -> Option 1: Cash plus Assumption of Mortgage This is a cash payment, at closing. We will take responsibility for the existing mortgage, HOA fees, and any liens that may be discovered until we are able to resell the property. This offer is: Cash: $10,000.00 Total Value: $10,000.00
D27: Buy Your Home's % of Profit: | E27: =+G24/(F24+G24) -> 0.92786732
A30: Offer 3 | B30: Cash plus Promissory Note | D30: - this is the one to stear seller to:
B31: Cash payment in conjunction with taking the existing mortgage subject to: | I31: ="This is a cash payment, at closing, in conjunction with reinstating the existing mortgage taking responsibility for those payments, HOA fees and other liens that may be discovered. Our cash offer is:" -> This is a cash payment, at closing, in conjunction with reinstating the existing mortgage taking responsibility for those payments, HOA fees and other liens that may be discovered. Our cash offer is:
B32: After reinstating existing loans and HOA fees | H32: =IF(H33="X",H25+1,H25) -> 2
H33: x | I33: ="Option " & H32 & ": " &""&B30&" "&REPT(" ",6)&"The explanation for the cash component is the same as for option "& H25 & ". However, "&TEXT(B38,"##.#%") &" of the " & REPT(" ",6) & "value of the offer will be cash and "& TEXT(C38,"##.#%") &" will be in the form of a promissory note, complete " & REPT(" ",6) & "with a Deed of Trust. The note will have a " & D35 & "-month term that will pay simple interest at " & REPT(" ",6) & "the rate of "&E37*100&"% per year. "& REPT(" ",43) & "Cash:" & REPT(" ",23) & TEXT(B37,"$#,##0.00") & IF(J3="yes",REPT(" ",10) & "Profit = "& TEXT(G37,"$#,##0.00"),"" ) &" "& REPT(" ",24) & "12 Month Note:" & REPT(" ",24) & TEXT(C37,"$#,##0.00")&" "& REPT(" ",25) & "Interest Earned:" & REPT(" ",25) & TEXT(D37,"$#,##0.00") &REPT(" ",12)&+TEXT(D37/D35,"$#,##0.00") & " per month" & " "& REPT(" ",32) & "Total Value:" & REPT(" ",20) & TEXT(F37,"$#,##0.00") -> Option 2: Cash plus Promissory Note The explanation for the cash component is the same as for option 1. However, 20.% of the value of the offer will be cash and 80.% will be in the form of a promissory note, complete with a Deed of Trust. The note will have a 24-month term that will pay simple interest at the rate of 4% per year. Cash: $2,000.00 12 Month Note: $28,000.00 Interest Earned: $2,240.00 $93.33 per month Total Value: $32,240.00
C34: Note is a simple interest note for: | D34: Months | F34: (Based on Current Valuation)
B35: Value added to Note: | C35: 20000 | D35: 24 | F35: Seller's Total Value
B36: Cash | C36: Note | D36: Interest Earned | E36: Interest Rate | G36: BYH's Profit
B37: =+(Profit!$B$18)*B38 -> 2000 | C37: =+(Profit!$B$18)-B37+C35 -> 28000 | D37: =+C37*D35/12*E37 -> 2240 | E37: 0.04 | F37: =+SUM(B37:D37) -> 32240 | G37: =+Profit!$K$45-D37-C35 -> 106393.43
B38: 0.2 | C38: =1-B38 -> 0.8
D39: BYH Out of Pocket: | E39: =+Profit!$K$29-C37+C35 -> 46069.184
D40: BYH Profit/Out of Pocket: | E40: =+G37/E39 -> 2.3094272
D41: Buy Your Home's % of Profit: | E41: =+G37/(F37+G37) -> 0.76744425 | H41: =IF(H42="X",H32+1,H32) -> 3
A42: Offer 4 | B42: Cash plus Beneficial Interest in Trust | H42: x | I42: ="Option " & H41 & ": " & B42&" "&REPT(" ",6)&"The explanation for the cash component is the same as for option "& H32 & ". Instead of a note as in " & REPT(" ",6) & "Option "& H32 & ", you will share in the profit earned when the property is resold." &" The property will " & REPT(" ",6) & "be placed into a trust that you will share a beneficial interest in. The advantage here is you will " & REPT(" ",6) & "benefit from the appreciated value of the property, over time." &" You will receive quarterly " & REPT(" ",6) & "reports on the financial status of the property. "& REPT(" ",43) & "Cash:" & REPT(" ",23) & TEXT(B50,"$#,##0.00") & IF(J3="yes",REPT(" ",10) & "Profit = "& TEXT(G50,"$#,##0.00"),"" ) &" "& REPT(" ",24) & "Interest in Trust:" & REPT(" ",33) & TEXT(D50,"#.#%")&" "& REPT(" ",13) & "Expected Sellers Profit:" & REPT(" ",23) & TEXT(E50,"$#,##0.00") &" * Expected "&Profit!$K$6*100&"% appreciation per year" & " "& REPT(" ",26) & "Expected Value:" & REPT(" ",20) & TEXT(F50,"$#,##0.00") & " ** After " & D35 &" months." -> Option 3: Cash plus Beneficial Interest in Trust The explanation for the cash component is the same as for option 2. Instead of a note as in Option 2, you will share in the profit earned when the property is resold. The property will be placed into a trust that you will share a beneficial interest in. The advantage here is you will benefit from the appreciated value of the property, over time. You will receive quarterly reports on the financial status of the property. Cash: $10,000.00 Interest in Trust: 70.% Expected Sellers Profit: $120,773.40 * Expected 10% appreciation per year Expected Value: $130,773.40 ** After 24 months.
B43: Cash payment in conjunction with taking the existing mortgage subject to:
B44: After reinstating existing loans and HOA fees
B45: Profit split is a split of the profits upon the eventual sale of the pproperty.
B46: Profits will be calculated after deducting all expenses incurred from the sales price
F47: (Based on Future Valuation)
...

Sheet Todo
B1: =+Profit!B2 -> 3325 Banks Rd, Raleigh, NC 27603 | D1: Notes | G1: 6004 Sandy Run | H1: Larchmont | I1: 2608 Alton | J1: 202 Avery | K1: 1900 Red Quartz | L1: 120 Keith | M1: 3007 Eric | N1: 2153 Haig Point | O1: 178 Patricia | P1: 1201 Hazelnut | Q1: 1223 Roffler | R1: 2025 Metacomet | S1: 5619 Marthonna
A2: New Seller
B3: Purchase & Sale Agreement | C3: Yes | H3: Yes
B4: Letter of Authorization | C4: Yes | H4: Yes (2)
B5: Reinstatement Quote | C5: Yes | H5: Yes (2)
B6: Bank Acknowledgement | C6: Yes | H6: yes
B7: On-Line Bank Access | C7: yes | H7: yes
B8: Change Mail | C8: yes | H8: yes
B9: Bank Attorney letter of dismisal | C9: na | H9: yes
B10: Get (orignal) Property Authorization | C10: na | H10: yes
H11: 0
A12: After Purchase | H12: 0
B13: Insurance Claim for Roof | C13: na | H13: yes
B14: Locks Changed | C14: na | H14: yes
B15: Gas Service | C15: na | H15: yes
B16: Electrical & Water Service | C16: yes | H16: yes
B17: Rehab bids | D17: In progress | H17: yes
B18: Order Dumpster | C18: yes | H18: n/a
B19: A/C service | C19: na | H19: yes
B20: Establish Mortgage payment | C20: yes | H20: yes
B21: Remove PMI | C21: na | H21: yes
B22: Claim Property on Zillow | C22: yes | H22: yes
B23: Add property to Our Website | C23: yes | H23: yes
B24: Make sure deed and agreement are done | C24: yes | H24: yes
B25: Change Insurance | C25: yes | H25: yes
B26: Get Insurance payments installed | C26: na | H26: yes
B27: Add Private Lender to Insurance | D27: In progess Add Scott Moore | H27: yes
B28: Probate letters - Notice to Creditors | C28: na | H28: yes
H29: 0
A30: Upon Sales Contract | B30: Send Clay contract | H30: 0
B31: Get Payoff Letter from Mortgage | H31: 0
B32: Respond to Closing Attorney | H32: 0
B33: Turn off utilities | H33: 0
B34: Alert Private Lenders | H34: 0
H35: 0
H36: 0
H37: 0
A38: Upon Closing | B38: Documents to send to Clay | H38: 0
B39: Alert Private Lenders | H39: 0
B40: Send Clay CD/Alta signed by all | H40: 0
...

Sheet Contact
A1: Vendor | B1: Phone Number | C1: Contact | D1: Acct/Policy | E1: Email | F1: Purpose
C2: Zola Turner | D2: SS#: 404-54-1686
C3: Karen Reilly | D3: SS#: 244-23-5473 | E3: Could be SS#: 244-23-5173
A5: Scooby Steve Power Wash | B5: 919-714-9713 | C5: Steve Simeus | F5: Power Wash | O5: Mortgagee | P5: Additional Insured | Q5: Loss Payee | R5: Lenders Loss Payee | S5: Certificate
A6: Braswell Realty | B6: 919-262-6828 | C6: Brantley Baker | E6: brantley@eldridgeandfranklin.com | F6: RE Investor - contacts | N6: Rushmore Loan Services | O6: X | P6: X | R6: X
B7: 919 579 8743 | E7: LaLogallazo@gmail.com | F7: Painter | N7: Neal Issacs | P7: X
A8: Handyman of Hedingham | B8: 919-819-6201 | C8: Tim Fleming | F8: Handyman | I8: Hedingham | N8: LoLa Turner | P8: X
A9: The Raleigh Handyman | B9: 919-210-1525 | C9: Alan C Thompson | E9: ac63yhompson@gmail.com | F9: Handyman | I9: Hedingham | N9: Scott Moore | P9: X
A10: Caliber Flooring, Inc | B10: 919-977-1153 | C10: Jennifer Lynn | F10: Flooring | I10: 1239 Wicker Drive | J10: Referral Sarah Huffman | N10: Rushmore Loan Services | O10: X | P10: X | R10: X
A11: Andy Carlson | B11: (213) 293-7539 | E11: andycarlson27@yahoo.com | N11: Neal Issacs | P11: X
N12: LoLa Turner | P12: X
A13: True Service Heating and AC | B13: 919 794 1804 | C13: Matt Truelove | E13: Matt@trueserviceinc.com | N13: Scott Moore | P13: X
A14: Walter Brothers | B14: 919 228 9107 | E14: Walter@GlasgowDB.com | N14: Rushmore Loan Services | S14: X
N15: Neal Issacs | S15: X
N16: LoLa Turner | S16: X
N17: Scott Moore | S17: X
A18: Rushmore Loan Mangement | B18: 888 504 6700
B19: 888 504 7200 | E19: User:WesWill@BuyYourHomeLLC.com | F19: PW:w3638B0@
A20: New Mortage Info: | B20: 877 888 4606 | D20: Loan #708108824 | E20: https://www.rushmoreservicing.com
E21: Rushmore Servicing
E22: Att: Payment Processing
E23: PO BOX 650783
E24: Dallas, TX 75265-0783
A26: 3rd party authorization | B26: Fax 949 341 2242 | C26: sent on 9/21/21 | E26: PW:W3638B0@
A27: Zola Turner | D27: SS# 404 54 1686
A28: Karen Reilly | D28: SS# 244 23 5473
A30: NREIG | B30: 770 734 1523 | C30: Jennifer Knight | D30: NRE8120320 | E30: https://nreig.com/contact/
A31: Insurance National Real Estate Insurance Group LLC | E31: Morgagee Clause: Truest Bank ISAOA/ATIMA, PO Box 47047,Atlanta GA, 30362
A33: juriscition | B33: Wake County
A34: Zoning | B34: R-30
A35: Acres | B35: 1.12

Sheet Carrying
A1: All Utilities | E1: Mortgage Payment paid after Reinstatement | J1: Insurance Payments | N1: Aqua America (Water)
A3: Utility | B3: Date | C3: Tax | F3: Date | G3: payment | J3: Date | K3: payment | N3: Date | O3: payment
A5: Duke | B5: 44482 | C5: 114.72 | F5: 44405 | G5: 724.38 | J5: 44565 | K5: 149.79
B6: =+B5+30 -> 44512 | C6: 30.06 | F6: 44440 | G6: 748.17 | J6: 44599 | K6: 149.79
B7: 44571 | C7: 30.21 | F7: 44461 | G7: 748.17 | J7: 44627 | K7: 149.79
B8: =+B7+30 -> 44601 | C8: 30.21 | F8: 44504 | G8: 748.17 | J8: 44656 | K8: 149.79
B9: =+B8+30 -> 44631 | C9: 30.39 | F9: 44524 | G9: 748.17 | J9: =+J8+30 -> 44686 | K9: 149.79
B10: 44648 | C10: 30.31 | F10: 44546 | G10: 748.17 | J10: 44713 | K10: 149.79
B11: 44712 | C11: 60.81 | F11: 44573 | G11: 748.17 | J11: =+J10+30 -> 44743 | K11: 149.79
B12: 44740 | C12: 30.39 | F12: 44588 | G12: 748.17 | J12: =+J11+30 -> 44773 | K12: 149.79
B13: 44776 | C13: 30.39 | F13: 44648 | G13: 748.17 | J13: 44809 | K13: 149.79
B14: 45041 | C14: 33.24 | F14: 44649 | G14: 748.17 | J14: =+J13+30 -> 44839 | K14: 149.79
B15: 45083 | C15: 30.61 | F15: =+F16-30 -> 44667 | G15: 749.94 | J15: =+J14+30 -> 44869 | K15: 149.79
B16: 45135 | C16: 7.74 | F16: 44697 | G16: 749.94 | J16: =+J15+30 -> 44899 | K16: 149.79
B17: 45166 | C17: 25.86 | F17: =+F18-30 -> 44745 | G17: 748.17 | J17: =+J16+30 -> 44929 | K17: 149.79
B18: 45195 | C18: 31.48 | F18: =+F19-30 -> 44775 | G18: 748.17 | J18: =+J17+30 -> 44959 | K18: 149.79
B19: =+B18+30 -> 45225 | C19: 32.12 | F19: 44805 | G19: 748.17 | J19: =+J18+30 -> 44989 | K19: 149.79
B20: 45329 | C20: 18.74 | F20: =+F5+30 -> 44435 | G20: 751.63 | J20: =+J19+30 -> 45019 | K20: 149.79
B21: 45364 | C21: 32.34 | F21: =+F20+30 -> 44465 | G21: =+G20 -> 751.63 | J21: =+J20+30 -> 45049 | K21: 149.79
B22: 45379 | C22: 32.34 | F22: 44896 | G22: =+G21 -> 751.63 | J22: 45078 | K22: 149.79
B23: 45400 | C23: 32.34 | F23: 44927 | G23: =+G22 -> 751.63 | J23: 45117 | K23: 222.97
B24: 45433 | C24: 32.34 | F24: =+F23+30 -> 44957 | G24: =+G23 -> 751.63 | J24: 45142 | K24: 222.97
B25: 45462 | C25: 32.34 | F25: =+F24+30 -> 44987 | G25: =+G24 -> 751.63 | J25: 45182 | K25: 222.97
B26: =+B25+30 -> 45492 | C26: 32.34 | F26: =+F25+30 -> 45017 | G26: =+G25 -> 751.63 | J26: 45202 | K26: 222.97
B27: 45524 | C27: -115.05 | F27: 45019 | G27: =+G26 -> 751.63 | J27: 45231 | K27: 222.97
B28: 45554 | C28: -115.05 | F28: =+F27+30 -> 45049 | G28: =+G27 -> 751.63 | J28: =+J27+30 -> 45261 | K28: 222.97
B29: 45586 | C29: -82.71 | F29: =+F28+30 -> 45079 | G29: =+G28 -> 751.63 | J29: 45292 | K29: 222.97
B30: 45615 | C30: -50.37 | F30: =+F29+30 -> 45109 | G30: =+G29 -> 751.63 | J30: 45323 | K30: 182.76
B31: 45644 | C31: -17.05 | F31: =+F30+30 -> 45139 | G31: =+G30 -> 751.63 | J31: =+J30+30 -> 45353 | K31: 182.76
B32: 45678 | C32: 16.39 | F32: =+F31+30 -> 45169 | G32: =+G31 -> 751.63 | J32: =+J31+30 -> 45383 | K32: 182.76
B33: 45708 | C33: -69.17 | F33: =+F32+30 -> 45199 | G33: =+G32 -> 751.63 | J33: =+J32+30 -> 45413 | K33: 182.76
B34: 45736 | C34: -36.46 | F34: =+F33+30 -> 45229 | G34: =+G33 -> 751.63 | K34: 182.76
B35: 45768 | C35: -3.75 | F35: =+F34+30 -> 45259 | G35: =+G34 -> 751.63
B36: 45797 | C36: 28.96 | F36: 45292 | G36: =+G35 -> 751.63
B37: 45827 | C37: 33.29 | F37: =+F36+30 -> 45322 | G37: =+G36 -> 751.63
B38: 45859 | C38: 32.71 | F38: =+F37+30 -> 45352 | G38: =+G37 -> 751.63
B39: 45889 | C39: 32.71 | F39: =+F38+30 -> 45382 | G39: =+G38 -> 751.63
B40: 45919 | C40: 32.71 | F40: =+F39+30 -> 45412 | G40: =+G39 -> 751.63
B41: 45951 | C41: 32.71 | F41: =+F40+30 -> 45442 | G41: =+G40 -> 751.63
B42: 45980 | C42: 32.71 | F42: =+F41+30 -> 45472 | G42: 782.96
...

Sheet Proposal
B2: ="Preassigned Rows Indicating Payment or Scheduling by " &Profit!E1&" Your Home" -> Preassigned Rows Indicating Payment or Scheduling by Buy Your Home
B4: Preassigned Rows Cordination of Glasgow with Contrtactors
B6: Pasted rows from Builder's Trend Proposal
B8: Notes: Only add rows to the bottom of the table
A11: Cost Code | B11: Title | C11: Description | D11: Qty | E11: Unit Price
A12: Deposit | B12: Deposit | C12: Initial Deposit to Start Job | D12: 0
A13: Draw | B13: Draw 1 | C13: Draw 1 | D13: 0
A14: Draw | B14: Draw 2 | C14: Draw 2 | D14: 0
B15: Sell | C15: List with MLS | D15: 6
A16: HVAC | B16: Cordinate Sub | C16: HVAC | D16: 0 | E16: 0
A17: Floor Coverings | B17: Cordinate Sub | C17: Flooring Contractor | D17: 0 | E17: 200
A18: Supervision | B18: Cordinate Sub | C18: Termite Treatment | D18: 0 | E18: 200
A19: Cabinets & Vanities | B19: Cordinate Sub | C19: Cabinet Delivery | D19: 0 | E19: 200
A20: Countertops | B20: Cordinate Sub | C20: Manage installion of granite countertops by others in kitchen | D20: 0 | E20: 135
C21: Clean out House | D21: 1 | E21: 0
C22: Contract | D22: 0 | E22: 0
A23: Deck labor
A24: Deck labor
A25: Deck material
A26: ... Demo
A27: ... Demo
A28: ... Demo
A29: ... Demo
A30: Demo labor
A31: 20 Millwork & Trim
A32: 20 Millwork & Trim
A33: 20 Millwork & Trim
A34: 22 Specialty
... A37: Bath Accessories
A38: Building Permits | G38: 1160
A39: Cabinets & Vanities
A40: Electrical & Lighting
A41: Frame labor
A42: Frame labor
A43: Frame labor
A44: Frame labor
A45: Frame materials
A46: Frame materials
A47: Frame materials
A48: HVAC
...

Sheet ProposalUpdate
A1: These Cells are updated from the Proposal tab and are protected here. | I1: These cells are updated here and carried over to the Gnatt Chart | P1: Contracted Task | Q1: 1 | R1: Payment | S1: 4
P2: Change Order | Q2: 2 | R2: Not Used | S2: 0
P3: Manage Vendor | Q3: 3 | R3: Post Contract | S3: 5
A4: Party | B4: Item | C4: Cost Code | D4: Title | E4: Description | F4: Qty | G4: Unit Price | H4: Price | I4: Done | J4: Group Order | K4: Start Date | L4: Days | M4: Paid | N4: Notes
A5: =+IF(FromProposal[[#This Row],[Cost Code]]<>0,"Glasgow","") -> Glasgow | B5: 1 | C5: Deposit | D5: Deposit | E5: Initial Deposit to Start Job | F5: 0
A6: =+IF(FromProposal[[#This Row],[Cost Code]]<>0,"Glasgow","") -> Glasgow | B6: 2 | C6: Draw | D6: Draw 1 | E6: Draw 1 | F6: 0
A7: =+IF(FromProposal[[#This Row],[Cost Code]]<>0,"Glasgow","") -> Glasgow | B7: 3 | C7: Draw | D7: Draw 2 | E7: Draw 2 | F7: 0
A8: =+IF(FromProposal[[#This Row],[Cost Code]]<>0,"Glasgow","") | B8: 4 | D8: Sell | E8: List with MLS | F8: 6
A9: =+IF(FromProposal[[#This Row],[Cost Code]]<>0,"Glasgow","") -> Glasgow | B9: 5 | C9: HVAC | D9: Cordinate Sub | E9: HVAC | F9: 0 | G9: 0 | H9: 0
A10: =+IF(FromProposal[[#This Row],[Cost Code]]<>0,"Glasgow","") -> Glasgow | B10: 6 | C10: Floor Coverings | D10: Cordinate Sub | E10: Flooring Contractor | F10: 0 | G10: 200 | H10: 0
A11: =+IF(FromProposal[[#This Row],[Cost Code]]<>0,"Glasgow","") -> Glasgow | B11: 7 | C11: Supervision | D11: Cordinate Sub | E11: Termite Treatment | F11: 0 | G11: 200 | H11: 0
A12: =+IF(FromProposal[[#This Row],[Cost Code]]<>0,"Glasgow","") -> Glasgow | B12: 8 | C12: Cabinets & Vanities | D12: Cordinate Sub | E12: Cabinet Delivery | F12: 0 | G12: 200 | H12: 0
A13: =+IF(FromProposal[[#This Row],[Cost Code]]<>0,"Glasgow","") -> Glasgow | B13: 9 | C13: Countertops | D13: Cordinate Sub | E13: Manage installion of granite countertops by others in kitchen | F13: 0 | G13: 135 | H13: 0
A14: =+IF(FromProposal[[#This Row],[Cost Code]]<>0,"Glasgow","") | B14: 10 | E14: Clean out House | F14: 1 | G14: 0 | H14: 0
A15: =+IF(FromProposal[[#This Row],[Cost Code]]<>0,"Glasgow","") | B15: 11 | E15: Contract | F15: 0 | G15: 0 | H15: 0
A16: =+IF(FromProposal[[#This Row],[Cost Code]]<>0,"Glasgow","") -> Glasgow | B16: 12 | C16: Deck labor
A17: =+IF(FromProposal[[#This Row],[Cost Code]]<>0,"Glasgow","") -> Glasgow | B17: 13 | C17: Deck labor
A18: =+IF(FromProposal[[#This Row],[Cost Code]]<>0,"Glasgow","") -> Glasgow | B18: 14 | C18: Deck material
A19: =+IF(FromProposal[[#This Row],[Cost Code]]<>0,"Glasgow","") -> Glasgow | B19: 15 | C19: ... Demo
A20: =+IF(FromProposal[[#This Row],[Cost Code]]<>0,"Glasgow","") -> Glasgow | B20: 16 | C20: ... Demo

Sheet Gnatt Chart
J1: Expense | N1: Due:
A2: ="Glasgow Design Build for "&Profit!E1& " Your Home" -> Glasgow Design Build for Buy Your Home | E2: Project Start Date: | F2: =+MIN(ProposalToGnatt[Start Date]) -> 0 | H2: Company Paid Materials Total: | J2: =+SUM(H8:H22) -> 27817.44 | M2: =+SUM(O8:O22)-SUM(M8:M22) -> 1070
A3: Jonathan Brothers | B3: Jonathan Brothers | H3: Contractors Total: | J3: =SUM(H24:H27) -> 750 | M3: =+J3-SUM(M24:M27) -> 0
A4: =+Profit!B2 -> 3325 Banks Rd, Raleigh, NC 27603 | B4: =+Profit!B2 -> 3325 Banks Rd, Raleigh, NC 27603 | E4: Milestone Marker: | G4: 1 | H4: Glasgow Total: | J4: =SUM(ProposalToGnatt[Price]) -> 0 | M4: {=+SUM(ProposalToGnatt[Due]-ProposalToGnatt[Paid])} -> 0
B5: Cells H5 through BK5 contain the day number of the month for the Month represented in the cell block above each date cell and are auto calculated. Do not modify these cells. Dates leading up to Today are shaded. | E5: Milestone Marker 2: | G5: 2 | H5: Grand Total | J5: =+SUM(J2:K4) -> 28567.44 | M5: =+SUM(M2:N4) -> 1070
E6: =Profit!E1&" Your Home Supplied Materials" -> Buy Your Home Supplied Materials
A7: Assigned | B7: Item # | C7: Cost Code | D7: Title | E7: Description | F7: Qty | G7: Unit Price | H7: Price | I7: Done | J7: Group Order | K7: Start Date | L7: Days | M7: Paid | N7: Notes | O7: Due | AO7: =IFERROR(IF(LEN(#REF!)=0,"",IF(AND(#REF!=#REF!,#REF!=1),Milestone_Marker_Old,"")),"")
A8: =Profit!$E$1&" Your Home" -> Buy Your Home | B8: 1 | E8: Cleanup (from Demo & Trash Haul Tab) | F8: 1 | G8: =+'Demo & Trash Haul'!G21 -> 5322.49 | H8: =+F8*G8 -> 5322.49 | I8: Yes | M8: 4672.49 | O8: =IF(I8="Yes",H8,0) -> 5322.49
A9: =Profit!$E$1&" Your Home" -> Buy Your Home | B9: =+B8+1 -> 2 | E9: Taxes - outside of closing (from Taxes tab) | F9: 0 | G9: =+Taxes!E19 -> 0 | H9: =+F9*G9 -> 0 | O9: =IF(I9="Yes",H9,0) -> 0
A10: =Profit!$E$1&" Your Home" -> Buy Your Home | B10: =+B8+1 -> 2 | E10: Appliances (from Appliances Tab) | F10: 0 | G10: =+Appliances!F21 -> 1269.16 | H10: =+F10*G10 -> 0 | O10: =IF(I10="Yes",H10,0) -> 0
A11: =Profit!$E$1&" Your Home" -> Buy Your Home | B11: =+B10+1 -> 3 | E11: Plubing Fixtures | F11: 0 | G11: =+'Plumbing Fixtures'!F23 -> 433.46 | H11: =+F11*G11 -> 0 | O11: =IF(I11="Yes",H11,0) -> 0
A12: =Profit!$E$1&" Your Home" -> Buy Your Home | B12: =+B11+1 -> 4 | E12: Windows & Doors | F12: 0 | G12: =+'Windows & Doors'!F30 -> 749.65 | H12: =+F12*G12 -> 0 | O12: =IF(I12="Yes",H12,0) -> 0
A13: =Profit!$E$1&" Your Home" -> Buy Your Home | B13: =+B12+1 -> 5 | E13: Cabinets (from Cabinets Tab) | F13: 0 | G13: =+Cabinets!G44 -> 4165.4 | H13: =+F13*G13 -> 0 | O13: =IF(I13="Yes",H13,0) -> 0
A14: =Profit!$E$1&" Your Home" -> Buy Your Home | B14: =+B13+1 -> 6 | E14: Paint (from Paint Tab) | F14: 0 | G14: =+Paint!G28 -> 1332.94 | H14: =+F14*G14 -> 0 | O14: =IF(I14="Yes",H14,0) -> 0
A15: =Profit!$E$1&" Your Home" -> Buy Your Home | B15: =+B14+1 -> 7 | E15: Flooring | F15: 0 | G15: =+Flooring!G7 -> 5098.8 | H15: =+F15*G15 -> 0 | O15: =IF(I15="Yes",H15,0) -> 0 | AP15: =IFERROR(IF(LEN(#REF!)=0,"",IF(P$29=#REF!,Milestone_Marker_Old,"")),"") | AQ15: =IFERROR(IF(LEN(#REF!)=0,"",IF(Q$29=#REF!,Milestone_Marker_Old,"")),"") | AR15: =IFERROR(IF(LEN(#REF!)=0,"",IF(R$29=#REF!,Milestone_Marker_Old,"")),"") | AS15: =IFERROR(IF(LEN(#REF!)=0,"",IF(S$29=#REF!,Milestone_Marker_Old,"")),"") | AT15: =IFERROR(IF(LEN(#REF!)=0,"",IF(T$29=#REF!,Milestone_Marker_Old,"")),"") | AU15: =IFERROR(IF(LEN(#REF!)=0,"",IF(U$29=#REF!,Milestone_Marker_Old,"")),"") | AV15: =IFERROR(IF(LEN(#REF!)=0,"",IF(V$29=#REF!,Milestone_Marker_Old,"")),"") | AW15: =IFERROR(IF(LEN(#REF!)=0,"",IF(W$29=#REF!,Milestone_Marker_Old,"")),"") | ... DU15: =IFERROR(IF(LEN(#REF!)=0,"",IF(CU$29=#REF!,Milestone_Marker_Old,"")),"")
A16: =Profit!$E$1&" Your Home" -> Buy Your Home | B16: =+B15+1 -> 8 | E16: Electrical fixtures (from Misc Tab) | F16: 0 | G16: =+'Electrical Fixtures'!F23 -> 1357.2 | H16: =+F16*G16 -> 0 | O16: =IF(I16="Yes",H16,0) -> 0 | AP16: =IFERROR(IF(LEN(#REF!)=0,"",IF(P$29=#REF!,Milestone_Marker_Old,"")),"") | AQ16: =IFERROR(IF(LEN(#REF!)=0,"",IF(Q$29=#REF!,Milestone_Marker_Old,"")),"") | AR16: =IFERROR(IF(LEN(#REF!)=0,"",IF(R$29=#REF!,Milestone_Marker_Old,"")),"") | AS16: =IFERROR(IF(LEN(#REF!)=0,"",IF(S$29=#REF!,Milestone_Marker_Old,"")),"") | AT16: =IFERROR(IF(LEN(#REF!)=0,"",IF(T$29=#REF!,Milestone_Marker_Old,"")),"") | AU16: =IFERROR(IF(LEN(#REF!)=0,"",IF(U$29=#REF!,Milestone_Marker_Old,"")),"") | AV16: =IFERROR(IF(LEN(#REF!)=0,"",IF(V$29=#REF!,Milestone_Marker_Old,"")),"") | AW16: =IFERROR(IF(LEN(#REF!)=0,"",IF(W$29=#REF!,Milestone_Marker_Old,"")),"") | ... DU16: =IFERROR(IF(LEN(#REF!)=0,"",IF(CU$29=#REF!,Milestone_Marker_Old,"")),"")
A17: =Profit!$E$1&" Your Home" -> Buy Your Home | B17: =+B16+1 -> 9 | E17: Exterior Tab | F17: 1 | G17: =+Exterior!D16 -> 19189.95 | H17: =+F17*G17 -> 19189.95 | I17: Yes | M17: 19189.95 | O17: =IF(I17="Yes",H17,0) -> 19189.95
A18: =Profit!$E$1&" Your Home" -> Buy Your Home | B18: =+B17+1 -> 10 | E18: Landscaping Tab | F18: 1 | G18: =+Landscape!H17 -> 3305 | H18: =+F18*G18 -> 3305 | I18: Yes | M18: 2885 | O18: =IF(I18="Yes",H18,0) -> 3305
A19: =Profit!$E$1&" Your Home" -> Buy Your Home | B19: =+B18+1 -> 11 | E19: HVAC Contractor | F19: 0 | G19: =+'Demo & Trash Haul'!F33 -> 0 | H19: =+F19*G19 -> 0 | O19: =IF(I19="Yes",H19,0) -> 0 | AP19: =IFERROR(IF(LEN(#REF!)=0,"",IF(P$29=#REF!,Milestone_Marker_Old,"")),"") | AQ19: =IFERROR(IF(LEN(#REF!)=0,"",IF(Q$29=#REF!,Milestone_Marker_Old,"")),"") | AR19: =IFERROR(IF(LEN(#REF!)=0,"",IF(R$29=#REF!,Milestone_Marker_Old,"")),"") | AS19: =IFERROR(IF(LEN(#REF!)=0,"",IF(S$29=#REF!,Milestone_Marker_Old,"")),"") | AT19: =IFERROR(IF(LEN(#REF!)=0,"",IF(T$29=#REF!,Milestone_Marker_Old,"")),"") | AU19: =IFERROR(IF(LEN(#REF!)=0,"",IF(U$29=#REF!,Milestone_Marker_Old,"")),"") | AV19: =IFERROR(IF(LEN(#REF!)=0,"",IF(V$29=#REF!,Milestone_Marker_Old,"")),"") | AW19: =IFERROR(IF(LEN(#REF!)=0,"",IF(W$29=#REF!,Milestone_Marker_Old,"")),"") | ... DU19: =IFERROR(IF(LEN(#REF!)=0,"",IF(CU$29=#REF!,Milestone_Marker_Old,"")),"")
A20: =Profit!$E$1&" Your Home" -> Buy Your Home | B20: =+B19+1 -> 12 | E20: Landscape | F20: 0 | G20: =+'Demo & Trash Haul'!F34 -> 0 | H20: =+F20*G20 -> 0 | O20: =IF(I20="Yes",H20,0) -> 0 | AP20: =IFERROR(IF(LEN(#REF!)=0,"",IF(P$29=#REF!,Milestone_Marker_Old,"")),"") | AQ20: =IFERROR(IF(LEN(#REF!)=0,"",IF(Q$29=#REF!,Milestone_Marker_Old,"")),"") | AR20: =IFERROR(IF(LEN(#REF!)=0,"",IF(R$29=#REF!,Milestone_Marker_Old,"")),"") | AS20: =IFERROR(IF(LEN(#REF!)=0,"",IF(S$29=#REF!,Milestone_Marker_Old,"")),"") | AT20: =IFERROR(IF(LEN(#REF!)=0,"",IF(T$29=#REF!,Milestone_Marker_Old,"")),"") | AU20: =IFERROR(IF(LEN(#REF!)=0,"",IF(U$29=#REF!,Milestone_Marker_Old,"")),"") | AV20: =IFERROR(IF(LEN(#REF!)=0,"",IF(V$29=#REF!,Milestone_Marker_Old,"")),"") | AW20: =IFERROR(IF(LEN(#REF!)=0,"",IF(W$29=#REF!,Milestone_Marker_Old,"")),"") | ... DU20: =IFERROR(IF(LEN(#REF!)=0,"",IF(CU$29=#REF!,Milestone_Marker_Old,"")),"")
A21: =Profit!$E$1&" Your Home" -> Buy Your Home | B21: =+B20+1 -> 13 | E21: Exterior- Termite | F21: 0 | G21: 0 | H21: =+F21*G21 -> 0 | O21: =IF(I21="Yes",H21,0) -> 0 | AP21: =IFERROR(IF(LEN(#REF!)=0,"",IF(P$29=#REF!,Milestone_Marker_Old,"")),"") | AQ21: =IFERROR(IF(LEN(#REF!)=0,"",IF(Q$29=#REF!,Milestone_Marker_Old,"")),"") | AR21: =IFERROR(IF(LEN(#REF!)=0,"",IF(R$29=#REF!,Milestone_Marker_Old,"")),"") | AS21: =IFERROR(IF(LEN(#REF!)=0,"",IF(S$29=#REF!,Milestone_Marker_Old,"")),"") | AT21: =IFERROR(IF(LEN(#REF!)=0,"",IF(T$29=#REF!,Milestone_Marker_Old,"")),"") | AU21: =IFERROR(IF(LEN(#REF!)=0,"",IF(U$29=#REF!,Milestone_Marker_Old,"")),"") | AV21: =IFERROR(IF(LEN(#REF!)=0,"",IF(V$29=#REF!,Milestone_Marker_Old,"")),"") | AW21: =IFERROR(IF(LEN(#REF!)=0,"",IF(W$29=#REF!,Milestone_Marker_Old,"")),"") | ... DU21: =IFERROR(IF(LEN(#REF!)=0,"",IF(CU$29=#REF!,Milestone_Marker_Old,"")),"")
A22: =Profit!$E$1&" Your Home" -> Buy Your Home | B22: =+B21+1 -> 14 | E22: Drainage | F22: 0 | G22: =+'Demo & Trash Haul'!F36 -> 0 | H22: =+F22*G22 -> 0 | O22: =IF(I22="Yes",H22,0) -> 0 | AP22: =IFERROR(IF(LEN(#REF!)=0,"",IF(P$29=#REF!,Milestone_Marker_Old,"")),"") | AQ22: =IFERROR(IF(LEN(#REF!)=0,"",IF(Q$29=#REF!,Milestone_Marker_Old,"")),"") | AR22: =IFERROR(IF(LEN(#REF!)=0,"",IF(R$29=#REF!,Milestone_Marker_Old,"")),"") | AS22: =IFERROR(IF(LEN(#REF!)=0,"",IF(S$29=#REF!,Milestone_Marker_Old,"")),"") | AT22: =IFERROR(IF(LEN(#REF!)=0,"",IF(T$29=#REF!,Milestone_Marker_Old,"")),"") | AU22: =IFERROR(IF(LEN(#REF!)=0,"",IF(U$29=#REF!,Milestone_Marker_Old,"")),"") | AV22: =IFERROR(IF(LEN(#REF!)=0,"",IF(V$29=#REF!,Milestone_Marker_Old,"")),"") | AW22: =IFERROR(IF(LEN(#REF!)=0,"",IF(W$29=#REF!,Milestone_Marker_Old,"")),"") | ... DU22: =IFERROR(IF(LEN(#REF!)=0,"",IF(CU$29=#REF!,Milestone_Marker_Old,"")),"")
E23: =Profit!E1&" Your Home's Paid Contractors" -> Buy Your Home's Paid Contractors | AP23: =IFERROR(IF(LEN(#REF!)=0,"",IF(P$29=#REF!,Milestone_Marker_Old,"")),"") | AQ23: =IFERROR(IF(LEN(#REF!)=0,"",IF(Q$29=#REF!,Milestone_Marker_Old,"")),"") | AR23: =IFERROR(IF(LEN(#REF!)=0,"",IF(R$29=#REF!,Milestone_Marker_Old,"")),"") | AS23: =IFERROR(IF(LEN(#REF!)=0,"",IF(S$29=#REF!,Milestone_Marker_Old,"")),"") | AT23: =IFERROR(IF(LEN(#REF!)=0,"",IF(T$29=#REF!,Milestone_Marker_Old,"")),"") | AU23: =IFERROR(IF(LEN(#REF!)=0,"",IF(U$29=#REF!,Milestone_Marker_Old,"")),"") | AV23: =IFERROR(IF(LEN(#REF!)=0,"",IF(V$29=#REF!,Milestone_Marker_Old,"")),"") | AW23: =IFERROR(IF(LEN(#REF!)=0,"",IF(W$29=#REF!,Milestone_Marker_Old,"")),"") | ... DU23: =IFERROR(IF(LEN(#REF!)=0,"",IF(CU$29=#REF!,Milestone_Marker_Old,"")),"")
A24: Mabrey Roofing | B24: =+B22+1 -> 15 | E24: Esitimate on new build | F24: 0 | G24: 300000 | H24: =+F24*G24 -> 0 | O24: =IF(I24="Yes",H24,0) -> 0 | AA24: Scrolling Increment: | AP24: =IFERROR(IF(LEN(#REF!)=0,"",IF(P$29=#REF!,Milestone_Marker_Old,"")),"") | AQ24: =IFERROR(IF(LEN(#REF!)=0,"",IF(Q$29=#REF!,Milestone_Marker_Old,"")),"") | AR24: =IFERROR(IF(LEN(#REF!)=0,"",IF(R$29=#REF!,Milestone_Marker_Old,"")),"") | AS24: =IFERROR(IF(LEN(#REF!)=0,"",IF(S$29=#REF!,Milestone_Marker_Old,"")),"") | AT24: =IFERROR(IF(LEN(#REF!)=0,"",IF(T$29=#REF!,Milestone_Marker_Old,"")),"") | AU24: =IFERROR(IF(LEN(#REF!)=0,"",IF(U$29=#REF!,Milestone_Marker_Old,"")),"") | AV24: =IFERROR(IF(LEN(#REF!)=0,"",IF(V$29=#REF!,Milestone_Marker_Old,"")),"") | AW24: =IFERROR(IF(LEN(#REF!)=0,"",IF(W$29=#REF!,Milestone_Marker_Old,"")),"") | ... DU24: =IFERROR(IF(LEN(#REF!)=0,"",IF(CU$29=#REF!,Milestone_Marker_Old,"")),"")
A25: Remodeling Solutions | B25: =+B24+1 -> 16 | E25: Design Plans | F25: 1 | G25: 750 | H25: =+F25*G25 -> 750 | I25: Yes | M25: 750 | O25: =IF(I25="Yes",H25,0) -> 750 | AP25: =IFERROR(IF(LEN(#REF!)=0,"",IF(P$29=#REF!,Milestone_Marker_Old,"")),"") | AQ25: =IFERROR(IF(LEN(#REF!)=0,"",IF(Q$29=#REF!,Milestone_Marker_Old,"")),"") | AR25: =IFERROR(IF(LEN(#REF!)=0,"",IF(R$29=#REF!,Milestone_Marker_Old,"")),"") | AS25: =IFERROR(IF(LEN(#REF!)=0,"",IF(S$29=#REF!,Milestone_Marker_Old,"")),"") | AT25: =IFERROR(IF(LEN(#REF!)=0,"",IF(T$29=#REF!,Milestone_Marker_Old,"")),"") | AU25: =IFERROR(IF(LEN(#REF!)=0,"",IF(U$29=#REF!,Milestone_Marker_Old,"")),"") | AV25: =IFERROR(IF(LEN(#REF!)=0,"",IF(V$29=#REF!,Milestone_Marker_Old,"")),"") | AW25: =IFERROR(IF(LEN(#REF!)=0,"",IF(W$29=#REF!,Milestone_Marker_Old,"")),"") | ... DU25: =IFERROR(IF(LEN(#REF!)=0,"",IF(CU$29=#REF!,Milestone_Marker_Old,"")),"")
A26: Love Services | B26: =+B25+1 -> 17 | E26: HVAC Contractor - Package Heat Pump | F26: 0 | G26: =+HVAC!F13 -> 13062 | H26: =+F26*G26 -> 0 | O26: =IF(I26="Yes",H26,0) -> 0 | AB26: 0
A27: Love Services | B27: =+B26+1 -> 18 | E27: HVAC Contractor - Duct Work | F27: 0 | G27: 4598 | H27: =+F27*G27 -> 0 | O27: =IF(I27="Yes",H27,0) -> 0
E28: Glasgow Design Items (all items should be updated from Proposal or ProposalUpdate tab) | P28: =IF(TEXT(Project_Start,"mmmm")=TEXT(P29,"mmmm"),"",TEXT(P29,"mmmm")) | Q28: =IF(TEXT(P29,"mmmm")=TEXT(Q29,"mmmm"),"",TEXT(Q29,"mmmm")) | R28: =IF(TEXT(Q29,"mmmm")=TEXT(R29,"mmmm"),"",TEXT(R29,"mmmm")) | S28: =IF(TEXT(R29,"mmmm")=TEXT(S29,"mmmm"),"",TEXT(S29,"mmmm")) | T28: =IF(TEXT(S29,"mmmm")=TEXT(T29,"mmmm"),"",TEXT(T29,"mmmm")) | U28: =IF(TEXT(T29,"mmmm")=TEXT(U29,"mmmm"),"",TEXT(U29,"mmmm")) | V28: =IF(TEXT(U29,"mmmm")=TEXT(V29,"mmmm"),"",TEXT(V29,"mmmm")) | W28: =IF(TEXT(V29,"mmmm")=TEXT(W29,"mmmm"),"",TEXT(W29,"mmmm")) | X28: =IF(TEXT(W29,"mmmm")=TEXT(X29,"mmmm"),"",TEXT(X29,"mmmm")) | ... CU28: =IF(TEXT(CT29,"mmmm")=TEXT(CU29,"mmmm"),"",TEXT(CU29,"mmmm"))
A29: Party | B29: Item | C29: Cost Code | D29: Title | E29: Description | F29: Qty | G29: Unit Price | H29: Price | I29: Done | J29: Group Order | K29: Start Date | L29: Days | M29: Paid | N29: Notes | O29: Due | P29: =IFERROR(Project_Start+Scrolling_Increment,TODAY()) -> 0 | Q29: =+P29+1 -> 1 | R29: =+Q29+1 -> 2 | S29: =+R29+1 -> 3 | T29: =+S29+1 -> 4 | U29: =+T29+1 -> 5 | V29: =+U29+1 -> 6 | W29: =+V29+1 -> 7 | X29: =+W29+1 -> 8 | ... CU29: =+CT29+1 -> 83
A30: Glasgow | B30: 1 | C30: Deposit | D30: Deposit | E30: Initial Deposit to Start Job | F30: 0 | P30: =IFERROR(+IF(P$29=ProposalToGnatt[[#This Row],[Start Date]],Milestone_Marker,IF(AND(P$29>ProposalToGnatt[[#This Row],[Start Date]],P$29<ProposalToGnatt[[#This Row],[Start Date]]+ProposalToGnatt[[#This Row],[Days]]),$G$5,"")),"") -> 1 | Q30: =IFERROR(+IF(Q$29=ProposalToGnatt[[#This Row],[Start Date]],Milestone_Marker,IF(AND(Q$29>ProposalToGnatt[[#This Row],[Start Date]],Q$29<ProposalToGnatt[[#This Row],[Start Date]]+ProposalToGnatt[[#This Row],[Days]]),$G$5,"")),"") | R30: =IFERROR(+IF(R$29=ProposalToGnatt[[#This Row],[Start Date]],Milestone_Marker,IF(AND(R$29>ProposalToGnatt[[#This Row],[Start Date]],R$29<ProposalToGnatt[[#This Row],[Start Date]]+ProposalToGnatt[[#This Row],[Days]]),$G$5,"")),"") | S30: =IFERROR(+IF(S$29=ProposalToGnatt[[#This Row],[Start Date]],Milestone_Marker,IF(AND(S$29>ProposalToGnatt[[#This Row],[Start Date]],S$29<ProposalToGnatt[[#This Row],[Start Date]]+ProposalToGnatt[[#This Row],[Days]]),$G$5,"")),"") | T30: =IFERROR(+IF(T$29=ProposalToGnatt[[#This Row],[Start Date]],Milestone_Marker,IF(AND(T$29>ProposalToGnatt[[#This Row],[Start Date]],T$29<ProposalToGnatt[[#This Row],[Start Date]]+ProposalToGnatt[[#This Row],[Days]]),$G$5,"")),"") | U30: =IFERROR(+IF(U$29=ProposalToGnatt[[#This Row],[Start Date]],Milestone_Marker,IF(AND(U$29>ProposalToGnatt[[#This Row],[Start Date]],U$29<ProposalToGnatt[[#This Row],[Start Date]]+ProposalToGnatt[[#This Row],[Days]]),$G$5,"")),"") | V30: =IFERROR(+IF(V$29=ProposalToGnatt[[#This Row],[Start Date]],Milestone_Marker,IF(AND(V$29>ProposalToGnatt[[#This Row],[Start Date]],V$29<ProposalToGnatt[[#This Row],[Start Date]]+ProposalToGnatt[[#This Row],[Days]]),$G$5,"")),"") | W30: =IFERROR(+IF(W$29=ProposalToGnatt[[#This Row],[Start Date]],Milestone_Marker,IF(AND(W$29>ProposalToGnatt[[#This Row],[Start Date]],W$29<ProposalToGnatt[[#This Row],[Start Date]]+ProposalToGnatt[[#This Row],[Days]]),$G$5,"")),"") | ... CU30: =IFERROR(+IF(CU$29=ProposalToGnatt[[#This Row],[Start Date]],Milestone_Marker,IF(AND(CU$29>ProposalToGnatt[[#This Row],[Start Date]],CU$29<ProposalToGnatt[[#This Row],[Start Date]]+ProposalToGnatt[[#This Row],[Days]]),$G$5,"")),"")
A31: Glasgow | B31: 2 | C31: Draw | D31: Draw 1 | E31: Draw 1 | F31: 0 | P31: =IFERROR(+IF(P$29=ProposalToGnatt[[#This Row],[Start Date]],Milestone_Marker,IF(AND(P$29>ProposalToGnatt[[#This Row],[Start Date]],P$29<ProposalToGnatt[[#This Row],[Start Date]]+ProposalToGnatt[[#This Row],[Days]]),$G$5,"")),"") -> 1 | Q31: =IFERROR(+IF(Q$29=ProposalToGnatt[[#This Row],[Start Date]],Milestone_Marker,IF(AND(Q$29>ProposalToGnatt[[#This Row],[Start Date]],Q$29<ProposalToGnatt[[#This Row],[Start Date]]+ProposalToGnatt[[#This Row],[Days]]),$G$5,"")),"") | R31: =IFERROR(+IF(R$29=ProposalToGnatt[[#This Row],[Start Date]],Milestone_Marker,IF(AND(R$29>ProposalToGnatt[[#This Row],[Start Date]],R$29<ProposalToGnatt[[#This Row],[Start Date]]+ProposalToGnatt[[#This Row],[Days]]),$G$5,"")),"") | S31: =IFERROR(+IF(S$29=ProposalToGnatt[[#This Row],[Start Date]],Milestone_Marker,IF(AND(S$29>ProposalToGnatt[[#This Row],[Start Date]],S$29<ProposalToGnatt[[#This Row],[Start Date]]+ProposalToGnatt[[#This Row],[Days]]),$G$5,"")),"") | T31: =IFERROR(+IF(T$29=ProposalToGnatt[[#This Row],[Start Date]],Milestone_Marker,IF(AND(T$29>ProposalToGnatt[[#This Row],[Start Date]],T$29<ProposalToGnatt[[#This Row],[Start Date]]+ProposalToGnatt[[#This Row],[Days]]),$G$5,"")),"") | U31: =IFERROR(+IF(U$29=ProposalToGnatt[[#This Row],[Start Date]],Milestone_Marker,IF(AND(U$29>ProposalToGnatt[[#This Row],[Start Date]],U$29<ProposalToGnatt[[#This Row],[Start Date]]+ProposalToGnatt[[#This Row],[Days]]),$G$5,"")),"") | V31: =IFERROR(+IF(V$29=ProposalToGnatt[[#This Row],[Start Date]],Milestone_Marker,IF(AND(V$29>ProposalToGnatt[[#This Row],[Start Date]],V$29<ProposalToGnatt[[#This Row],[Start Date]]+ProposalToGnatt[[#This Row],[Days]]),$G$5,"")),"") | W31: =IFERROR(+IF(W$29=ProposalToGnatt[[#This Row],[Start Date]],Milestone_Marker,IF(AND(W$29>ProposalToGnatt[[#This Row],[Start Date]],W$29<ProposalToGnatt[[#This Row],[Start Date]]+ProposalToGnatt[[#This Row],[Days]]),$G$5,"")),"") | ... CU31: =IFERROR(+IF(CU$29=ProposalToGnatt[[#This Row],[Start Date]],Milestone_Marker,IF(AND(CU$29>ProposalToGnatt[[#This Row],[Start Date]],CU$29<ProposalToGnatt[[#This Row],[Start Date]]+ProposalToGnatt[[#This Row],[Days]]),$G$5,"")),"")
A32: Glasgow | B32: 3 | C32: Draw | D32: Draw 2 | E32: Draw 2 | F32: 0 | P32: =IFERROR(+IF(P$29=ProposalToGnatt[[#This Row],[Start Date]],Milestone_Marker,IF(AND(P$29>ProposalToGnatt[[#This Row],[Start Date]],P$29<ProposalToGnatt[[#This Row],[Start Date]]+ProposalToGnatt[[#This Row],[Days]]),$G$5,"")),"") -> 1 | Q32: =IFERROR(+IF(Q$29=ProposalToGnatt[[#This Row],[Start Date]],Milestone_Marker,IF(AND(Q$29>ProposalToGnatt[[#This Row],[Start Date]],Q$29<ProposalToGnatt[[#This Row],[Start Date]]+ProposalToGnatt[[#This Row],[Days]]),$G$5,"")),"") | R32: =IFERROR(+IF(R$29=ProposalToGnatt[[#This Row],[Start Date]],Milestone_Marker,IF(AND(R$29>ProposalToGnatt[[#This Row],[Start Date]],R$29<ProposalToGnatt[[#This Row],[Start Date]]+ProposalToGnatt[[#This Row],[Days]]),$G$5,"")),"") | S32: =IFERROR(+IF(S$29=ProposalToGnatt[[#This Row],[Start Date]],Milestone_Marker,IF(AND(S$29>ProposalToGnatt[[#This Row],[Start Date]],S$29<ProposalToGnatt[[#This Row],[Start Date]]+ProposalToGnatt[[#This Row],[Days]]),$G$5,"")),"") | T32: =IFERROR(+IF(T$29=ProposalToGnatt[[#This Row],[Start Date]],Milestone_Marker,IF(AND(T$29>ProposalToGnatt[[#This Row],[Start Date]],T$29<ProposalToGnatt[[#This Row],[Start Date]]+ProposalToGnatt[[#This Row],[Days]]),$G$5,"")),"") | U32: =IFERROR(+IF(U$29=ProposalToGnatt[[#This Row],[Start Date]],Milestone_Marker,IF(AND(U$29>ProposalToGnatt[[#This Row],[Start Date]],U$29<ProposalToGnatt[[#This Row],[Start Date]]+ProposalToGnatt[[#This Row],[Days]]),$G$5,"")),"") | V32: =IFERROR(+IF(V$29=ProposalToGnatt[[#This Row],[Start Date]],Milestone_Marker,IF(AND(V$29>ProposalToGnatt[[#This Row],[Start Date]],V$29<ProposalToGnatt[[#This Row],[Start Date]]+ProposalToGnatt[[#This Row],[Days]]),$G$5,"")),"") | W32: =IFERROR(+IF(W$29=ProposalToGnatt[[#This Row],[Start Date]],Milestone_Marker,IF(AND(W$29>ProposalToGnatt[[#This Row],[Start Date]],W$29<ProposalToGnatt[[#This Row],[Start Date]]+ProposalToGnatt[[#This Row],[Days]]),$G$5,"")),"") | ... CU32: =IFERROR(+IF(CU$29=ProposalToGnatt[[#This Row],[Start Date]],Milestone_Marker,IF(AND(CU$29>ProposalToGnatt[[#This Row],[Start Date]],CU$29<ProposalToGnatt[[#This Row],[Start Date]]+ProposalToGnatt[[#This Row],[Days]]),$G$5,"")),"")
B33: 4 | D33: Sell | E33: List with MLS | F33: 6 | P33: =IFERROR(+IF(P$29=ProposalToGnatt[[#This Row],[Start Date]],Milestone_Marker,IF(AND(P$29>ProposalToGnatt[[#This Row],[Start Date]],P$29<ProposalToGnatt[[#This Row],[Start Date]]+ProposalToGnatt[[#This Row],[Days]]),$G$5,"")),"") -> 1 | Q33: =IFERROR(+IF(Q$29=ProposalToGnatt[[#This Row],[Start Date]],Milestone_Marker,IF(AND(Q$29>ProposalToGnatt[[#This Row],[Start Date]],Q$29<ProposalToGnatt[[#This Row],[Start Date]]+ProposalToGnatt[[#This Row],[Days]]),$G$5,"")),"") | R33: =IFERROR(+IF(R$29=ProposalToGnatt[[#This Row],[Start Date]],Milestone_Marker,IF(AND(R$29>ProposalToGnatt[[#This Row],[Start Date]],R$29<ProposalToGnatt[[#This Row],[Start Date]]+ProposalToGnatt[[#This Row],[Days]]),$G$5,"")),"") | S33: =IFERROR(+IF(S$29=ProposalToGnatt[[#This Row],[Start Date]],Milestone_Marker,IF(AND(S$29>ProposalToGnatt[[#This Row],[Start Date]],S$29<ProposalToGnatt[[#This Row],[Start Date]]+ProposalToGnatt[[#This Row],[Days]]),$G$5,"")),"") | T33: =IFERROR(+IF(T$29=ProposalToGnatt[[#This Row],[Start Date]],Milestone_Marker,IF(AND(T$29>ProposalToGnatt[[#This Row],[Start Date]],T$29<ProposalToGnatt[[#This Row],[Start Date]]+ProposalToGnatt[[#This Row],[Days]]),$G$5,"")),"") | U33: =IFERROR(+IF(U$29=ProposalToGnatt[[#This Row],[Start Date]],Milestone_Marker,IF(AND(U$29>ProposalToGnatt[[#This Row],[Start Date]],U$29<ProposalToGnatt[[#This Row],[Start Date]]+ProposalToGnatt[[#This Row],[Days]]),$G$5,"")),"") | V33: =IFERROR(+IF(V$29=ProposalToGnatt[[#This Row],[Start Date]],Milestone_Marker,IF(AND(V$29>ProposalToGnatt[[#This Row],[Start Date]],V$29<ProposalToGnatt[[#This Row],[Start Date]]+ProposalToGnatt[[#This Row],[Days]]),$G$5,"")),"") | W33: =IFERROR(+IF(W$29=ProposalToGnatt[[#This Row],[Start Date]],Milestone_Marker,IF(AND(W$29>ProposalToGnatt[[#This Row],[Start Date]],W$29<ProposalToGnatt[[#This Row],[Start Date]]+ProposalToGnatt[[#This Row],[Days]]),$G$5,"")),"") | ... CU33: =IFERROR(+IF(CU$29=ProposalToGnatt[[#This Row],[Start Date]],Milestone_Marker,IF(AND(CU$29>ProposalToGnatt[[#This Row],[Start Date]],CU$29<ProposalToGnatt[[#This Row],[Start Date]]+ProposalToGnatt[[#This Row],[Days]]),$G$5,"")),"")
A34: Glasgow | B34: 5 | C34: HVAC | D34: Cordinate Sub | E34: HVAC | F34: 0 | G34: 0 | H34: 0 | P34: =IFERROR(+IF(P$29=ProposalToGnatt[[#This Row],[Start Date]],Milestone_Marker,IF(AND(P$29>ProposalToGnatt[[#This Row],[Start Date]],P$29<ProposalToGnatt[[#This Row],[Start Date]]+ProposalToGnatt[[#This Row],[Days]]),$G$5,"")),"") -> 1 | Q34: =IFERROR(+IF(Q$29=ProposalToGnatt[[#This Row],[Start Date]],Milestone_Marker,IF(AND(Q$29>ProposalToGnatt[[#This Row],[Start Date]],Q$29<ProposalToGnatt[[#This Row],[Start Date]]+ProposalToGnatt[[#This Row],[Days]]),$G$5,"")),"") | R34: =IFERROR(+IF(R$29=ProposalToGnatt[[#This Row],[Start Date]],Milestone_Marker,IF(AND(R$29>ProposalToGnatt[[#This Row],[Start Date]],R$29<ProposalToGnatt[[#This Row],[Start Date]]+ProposalToGnatt[[#This Row],[Days]]),$G$5,"")),"") | S34: =IFERROR(+IF(S$29=ProposalToGnatt[[#This Row],[Start Date]],Milestone_Marker,IF(AND(S$29>ProposalToGnatt[[#This Row],[Start Date]],S$29<ProposalToGnatt[[#This Row],[Start Date]]+ProposalToGnatt[[#This Row],[Days]]),$G$5,"")),"") | T34: =IFERROR(+IF(T$29=ProposalToGnatt[[#This Row],[Start Date]],Milestone_Marker,IF(AND(T$29>ProposalToGnatt[[#This Row],[Start Date]],T$29<ProposalToGnatt[[#This Row],[Start Date]]+ProposalToGnatt[[#This Row],[Days]]),$G$5,"")),"") | U34: =IFERROR(+IF(U$29=ProposalToGnatt[[#This Row],[Start Date]],Milestone_Marker,IF(AND(U$29>ProposalToGnatt[[#This Row],[Start Date]],U$29<ProposalToGnatt[[#This Row],[Start Date]]+ProposalToGnatt[[#This Row],[Days]]),$G$5,"")),"") | V34: =IFERROR(+IF(V$29=ProposalToGnatt[[#This Row],[Start Date]],Milestone_Marker,IF(AND(V$29>ProposalToGnatt[[#This Row],[Start Date]],V$29<ProposalToGnatt[[#This Row],[Start Date]]+ProposalToGnatt[[#This Row],[Days]]),$G$5,"")),"") | W34: =IFERROR(+IF(W$29=ProposalToGnatt[[#This Row],[Start Date]],Milestone_Marker,IF(AND(W$29>ProposalToGnatt[[#This Row],[Start Date]],W$29<ProposalToGnatt[[#This Row],[Start Date]]+ProposalToGnatt[[#This Row],[Days]]),$G$5,"")),"") | ... CU34: =IFERROR(+IF(CU$29=ProposalToGnatt[[#This Row],[Start Date]],Milestone_Marker,IF(AND(CU$29>ProposalToGnatt[[#This Row],[Start Date]],CU$29<ProposalToGnatt[[#This Row],[Start Date]]+ProposalToGnatt[[#This Row],[Days]]),$G$5,"")),"")
