Workbook
Name baseCost: #REF!
Name BaseFlagOf: _xlfn.LAMBDA(_xlpm.i,_xlpm.baseIdxTxt,_xlpm.baseCost, --ISNUMBER(SEARCH("BASE PARENT", UPPER(_xlfn.XLOOKUP(TEXT(_xlpm.i,"0"), _xlpm.baseIdxTxt, _xlpm.baseCost, "")))) )
Name baseIdxTxt: TEXT(#REF!,"0")
Name cfdContractDate: [1]Amortization!$J$13
Name cfdContractMonths: [1]Amortization!$P$14
Name cfdEndDate: [1]Amortization!$S$14
Name cfdFirstRateMonths: [1]Amortization!$P$13
Name cfdRate1: [1]Amortization!$O$8
Name cfdRate1Payment: [1]Amortization!$V$8
Name cfdRate2: [1]Amortization!$O$11
Name cfdRate2Payment: [1]Amortization!$V$11
Name cfdRateChangeDate: [1]Amortization!$S$13
Name DepTitlesUsed: _xlfn.ANCHORARRAY(#REF!)
Name downPaymentRefinancedFirstMortgage: [1]Amortization!$AH$5
Name editsIdxTxt: TEXT(#REF!,"0")
Name editsParentKeyTxt: TEXT(#REF!,"0")
Name Milestone_Marker: '[1]Gnatt Chart'!$G$4
Name Milestone_Marker: 'Gnatt Chart'!$G$4
Name Project_Start: '[1]Gnatt Chart'!$F$2
Name Project_Start: 'Gnatt Chart'!$F$2
Name Scrolling_Increment: '[1]Gnatt Chart'!$AB$24
Name Scrolling_Increment: 'Gnatt Chart'!$AB$26
Name subjectInterestRate: [1]Amortization!$D$4
Name subjectKnownBalance: [1]Amortization!$D$3
Name subjectKnownBalanceDate: [1]Amortization!$D$7
Name subjectMortgageEndDate: [1]Amortization!$D$8
Name subjectPayment: [1]Amortization!$D$6
Name subjectRemainingMonths: [1]Amortization!$E$5
Name Today: TODAY()
Name tradeMonthlyNetSpread: 'Trade Properties'!$T$13
Name tradeNetCreditIncluded: 'Trade Properties'!$T$10
Name tradePropertyConditionsForDocs: 'Trade Properties'!$T$21
Name tradePropertyListForDocs: 'Trade Properties'!$T$20

Sheet Profit
A1: Flip, Hold or Wholetale: | B1: hold | E1: Buy | F1: Your Home LLC
B2: 115 Rosebrooks Dr, Cary, NC 27513 | H2: Monthly Cash Flow | J2: Hearing Date: | N2: Use Template Estimate | O2: Yes
A3: Income | D3: Immediate | F3: Upon Sale
A4: CMA: | B4: 289000 | J4: Finalized: | K4: No
A5: % Above/Below Market Sale: | B5: -0.15 | C5: 0.1 | N5: Zillow: | O5: 45194 | P5: 344600
A6: Sale Price: | B6: =+B4 + IF(B1="Hold",B4*C5,0) + IF(B1="wholetale",B4*B5,0) -> 317900 | G6: =IF($B$1="hold",$B$4,$B$6) -> 289000 | J6: Anuual Growth: | K6: 0.03 | O6: 45217 | P6: 342200
A7: NonRefundable Deposit: | D7: =+B7 -> 0 | F7: =-B7 -> 0 | G7: =+IF($B$1="hold",$K$6,0)*$C$49/12*B4 -> 23409 | H7: =+IF($B$1="hold","<-- Apprication -----------","") -> <-- Apprication ----------- | O7: 45820 | P7: 279400
A8: Rent: | B8: 0 | I8: =IF(B1="Hold",+B8,"") -> 0 | J8: Sq Footage | K8: 1200 | O8: 46174 | P8: 280600
C9: Net Income: | D9: Net Income: | E9: =SUM(D4:D8) -> 0 | F9: =+SUM(F4:G8) -> 312409 | H9: =SUM(H4:I8) -> 0
A11: Expenses
A12: Reinstatment Cost 1st: | B12: 6266.78 | D12: =-B12 -> -6266.78 | G12: =IF(K4="Yes",0.3*B12,"") | H12: <-- Approx Pay-Down | J12: If the Subject To Value is finalized, zero-out the Pay-Down savings
A13: Subject To 1st:Truist | B13: 0.03375 | C13: 22000 | D13: =-C13 -> -22000
A14: Reinstatment Cost 2st: | F14: =-+(120-C48)*(C14/120) -> 0 | H14: =-(C14*B14/12) -> 0
A15: Refinance | B15: 0.07075 | C15: 181057.16 | E15: =+C15 -> 181057.16 | F15: =-C15 -> -181057.16
A16: Liens - IRS & HOA | D16: =-C16 -> 0
A17: Partners Share % | B17: 0
A18: or Seller Payout: | B18: 0 | D18: =-B18 -> 0 | J18: Yellow cells can be edited
A19: HOA Fees(Catch Up) | C19: 0 | D19: =-B19 -> 0
A20: Months Carried | B20: =+J69 -> 32.4 | J20: Do not edit Green cells. They are highlighted only to show profit
A21: Mortgage Payment: | B21: =+Carrying!F$49/$H$56 -> 942.76389 | H21: =IF($B$1="Hold",-B21,"") -> -942.76389
A22: Private Money Interest: | B22: =+Carrying!I$49/$H$56 -> 192.90123 | H22: =IF($B$1="Hold",-B22,"") -> -192.90123
A23: Property Insurance | B23: =+Carrying!L$49/$H$56 -> 55.917901 | H23: =IF($B$1="Hold",-B23,"") -> -55.917901
A37: Property Tax: | B37: =+Carrying!X$49/$H$56 -> 126.30833 | H37: =IF($B$1="Hold",-B37,"") -> -126.30833
A38: HOA Fees (monthly) | B38: =+Carrying!U$49/$H$56 -> 162.96296 | H38: =IF($B$1="Hold",-B38,"") -> -162.96296
A39: Electric | B39: =+Carrying!C$49/$H$56 -> 0 | H39: =IF($B$1="Hold",-B39,"") -> 0
A40: water | B40: =+Carrying!O$49/$H$56 -> 0 | H40: =IF($B$1="Hold",-B40,"") -> 0
A41: Carrying Cost | B41: =+B20*SUM(B21:B40) -> 47979.68 | J41: Carrying Cost | K41: =+B41/B20 -> 1480.8543 | M41: 15 | N41: 100732.5
A42: Private Lender Rate: | B42: 0.1 | C42: yes | M42: 0.1 | N42: 67155
A43: 75%ARV-Debt: | B43: 75000 | D43: =-B43 -> -75000 | E43: =B43 -> 75000 | N43: =SUM(E43:F43) -> 75000
A44: Rehab: | B44: =-D65 -> 37573.025 | D44: =-B44 -> -37573.025 | J44: Total Debt: | K44: =+SUM(C15:C19) -> 181057.16
A45: Marketing: | B45: 600 | D45: =-B45 -> -600
A46: Seller Realtor's Flat Fee | B46: 1 | C46: 500 | F46: =-C46 -> -500
A47: Seller Realtor's Fee Percent: | B47: 0 | C47: 0.026 | F47: =-B47*C47*$F$9 -> 0 | J47: Purchase Cost | K47: =+B12+C15 -> 187323.94 | M47: =+K47+B44 -> 224896.97
A48: Buyers Realtors Fee Percent: | B48: 1 | C48: 0.024 | F48: =-B48*C48*$F$9 -> -7497.816
A49: Number of Rent Payments : | C49: =+B20 -> 32.4 | J49: Out of Pocket | K49: =+B12+C14+C16+B18+B44 -> 43839.805
A50: Buyer Assistance | F50: =-C50 -> 0
A51: Buying Closing Cost: | B51: =+D85 -> 940 | D51: =-B51 -> -940 | J51: PL Balance +Interest
A52: Selling Closing Cost: | B52: =+D96 -> 290 | F52: =-B52 -> -290
C53: Net Expenses: | E53: =+SUM(D12:D52) -> -142379.81 | F53: =+SUM(F12:F52) -> -189344.98 | H53: =+SUM(H9:I52) -> -1480.8543
B54: Immediate Profit: | E54: =+SUM(E9:E53) -> 113677.35 | F54: =+SUM(F9:G52) -> 123064.02
...

Sheet Trade Properties
A2: Property | B2: Home Type | C2: Est. Property Value | D2: Lot Rent / Mo | E2: Tenant Payment / Mo | F2: Property Tax / Mo | G2: Insurance / Mo | H2: Monthly Net Spread | I2: Annual Net Spread | J2: Expense % of Payment | K2: Net Spread Margin | L2: Net Yield on Value | M2: Max Value @ 10% | N2: Max Value @ 12% | O2: Max Value @ 15% | P2: Notes | R2: Summary / Document Outputs
H3: =IF(OR(D3="",E3=""),"",E3-SUM(D3,F3:G3)) | I3: =IF(H3="","",H3*12) | J3: =IFERROR(SUM(D3,F3:G3)/E3,"") | K3: =IFERROR(H3/E3,"") | L3: =IFERROR(I3/C3,"") | M3: =IF(I3="","",I3/10%) | N3: =IF(I3="","",I3/12%) | O3: =IF(I3="","",I3/15%) | R3: Total Trade Property Value Proposed | S3: =SUM(I14:I16) -> 0
H4: =IF(OR(D4="",E4=""),"",E4-SUM(D4,F4:G4)) | I4: =IF(H4="","",H4*12) | J4: =IFERROR(SUM(D4,F4:G4)/E4,"") | K4: =IFERROR(H4/E4,"") | L4: =IFERROR(I4/C4,"") | M4: =IF(I4="","",I4/10%) | N4: =IF(I4="","",I4/12%) | O4: =IF(I4="","",I4/15%) | R4: Total Liens or Deductions | S4: =SUM(J14:J16) -> 0
H5: =IF(OR(D5="",E5=""),"",E5-SUM(D5,F5:G5)) | I5: =IF(H5="","",H5*12) | J5: =IFERROR(SUM(D5,F5:G5)/E5,"") | K5: =IFERROR(H5/E5,"") | L5: =IFERROR(I5/C5,"") | M5: =IF(I5="","",I5/10%) | N5: =IF(I5="","",I5/12%) | O5: =IF(I5="","",I5/15%) | R5: Total Net Trade Credit Included | S5: =K17 -> 0
A6: Total | C6: =SUM(C3:C5) -> 0 | D6: =SUM(D3:D5) -> 0 | E6: =SUM(E3:E5) -> 0 | F6: =SUM(F3:F5) -> 0 | G6: =SUM(G3:G5) -> 0 | H6: =SUM(H3:H5) -> 0 | I6: =SUM(I3:I5) -> 0 | J6: =IFERROR(SUM(D6,F6:G6)/E6,"") | K6: =IFERROR(H6/E6,"") | L6: =IFERROR(I6/C6,"") | M6: =IF(I6="","",I6/10%) -> 0 | N6: =IF(I6="","",I6/12%) -> 0 | O6: =IF(I6="","",I6/15%) -> 0 | R6: Total Tenant Rent | S6: =D17 -> 0
R7: Total Monthly Expenses | S7: =C17 -> 0
A8: Trade Properties - Manufactured Home Credit Analysis | R8: Total Monthly Net Spread: | S8: =E17 -> 0
A9: Use this tab for valuation and support detail only. Contract generators should read only the final document fields exposed on Replacement Docs. Proposed values are analysis inputs until titles/bills of sale, lien releases, possession/keys, tenant/rent information, and park/lot approvals are delivered and accepted. | R9: Total Annual Net Spread: | S9: =F17 -> 0
I11: 0.1 | J11: 2 | R11: Implied Value at 10% Yield | S11: =S9/10% -> 0
C12: Expected monthly net spread from future Contract for Deed/resale payments after lot rent, property tax, and insurance | R12: Implied Value at 12% Yield | S12: =S9/12% -> 0
A13: Property Address | B13: Home Type | C13: Monthly Expenses | D13: Tenant Rent | E13: Monthly Net Spread | F13: Annual Net Spread | G13: Cap Based Value | H13: CMA Based Value | I13: Proposed Value / Agreed Credit | J13: Liens or Deductions | K13: Net Trade Credit | L13: Include in Contract? | M13: Title/Bill-of-Sale Status | N13: Park/Lot Approval Status | O13: Tenant/Lease Verification Status | R13: Implied Value at 15% Yield | S13: =S9/15% -> 0
A14: =+A3 -> 0 | B14: =+B3 -> 0 | C14: =SUM(D3,F3:G3) -> 0 | D14: =E3 -> 0 | E14: =D14-C14 -> 0 | F14: =E14*12 -> 0 | G14: =+O3 | H14: =C3 -> 0 | I14: =IF($J$11=2,H14,G14)*(1-$I$11) -> 0 | J14: 0 | K14: =IF($L14,MAX(0,I14-J14),0) -> 0 | L14: FALSE
A15: =+A4 -> 0 | B15: =+B4 -> 0 | C15: =SUM(D4,F4:G4) -> 0 | D15: =E4 -> 0 | E15: =D15-C15 -> 0 | F15: =E15*12 -> 0 | G15: =+O4 | H15: =C4 -> 0 | I15: =IF($J$11=2,H15,G15)*(1-$I$11) -> 0 | J15: 0 | K15: =IF($L15,MAX(0,I15-J15),0) -> 0 | L15: FALSE | R15: Trade Property List for Docs | S15: =_xlfn.TEXTJOIN("; ",TRUE,IF($L$14,$A$14&" - "&$B$14,""),IF($L$15,$A$15&" - "&$B$15,""),IF($L$16,$A$16&" - "&$B$16,""))
A16: =+A5 -> 0 | B16: =+B5 -> 0 | C16: =SUM(D5,F5:G5) -> 0 | D16: =E5 -> 0 | E16: =D16-C16 -> 0 | F16: =E16*12 -> 0 | G16: =+O5 | H16: =C5 -> 0 | I16: =IF($J$11=2,H16,G16)*(1-$I$11) -> 0 | J16: 0 | K16: =IF($L16,MAX(0,I16-J16),0) -> 0 | L16: FALSE | R16: Trade Property Conditions for Docs | S16: Trade credit is not final until titles/bills of sale, lien releases or payoff documentation, possession/keys, tenant and rent information, and park/lot approvals are delivered and accepted.
A17: Totals / Included Credit | C17: =SUMPRODUCT(--($L$14:$L$16=TRUE),C14:C16) -> 0 | D17: =SUMPRODUCT(--($L$14:$L$16=TRUE),D14:D16) -> 0 | E17: =SUMPRODUCT(--($L$14:$L$16=TRUE),E14:E16) -> 0 | F17: =SUMPRODUCT(--($L$14:$L$16=TRUE),F14:F16) -> 0 | G17: =SUMPRODUCT(--($L$14:$L$16=TRUE),G14:G16) -> 0 | H17: =SUMPRODUCT(--($L$14:$L$16=TRUE),H14:H16) -> 0 | I17: =SUMPRODUCT(--($L$14:$L$16=TRUE),I14:I16) -> 0 | J17: =SUM(J14:J16) -> 0 | K17: =SUM(K14:K16) -> 0
R18: Addendum Requirement | S18: A trade-property addendum should control title, possession, park approval, liens, tenant rents, verification, condition, and remedies if conditions are not met.
T20: =_xlfn.TEXTJOIN("; ",TRUE,IF(AND($L$14,$A$14<>""),$A$14&" - "&$B$14,""),IF(AND($L$15,$A$15<>""),$A$15&" - "&$B$15,""),IF(AND($L$16,$A$16<>""),$A$16&" - "&$B$16,""))

Sheet MOG
C1: Multiple Offer Generator | I1: ="Hi "&B3 & IF(B4 ="",""," and ") &B4&", Thank you for the opportunity to make an offer on your property at "&Profit!B2&". I have several options I would like for you to consider. I also want to give you several very good reasons for you to work with us here at Buy Your Home LLC. "&REPT(" ",6)&"1. If you sell your home to us, you will incur no expense from the transaction. We will pay all: "&REPT(" ",20)&"Closing Cost "&REPT(" ",20)&"Attorney's Fees "&REPT(" ",20)&"Realtor Commissions "&REPT(" ",6) &" 2. We can close fast. It will be a matter of days, probably less than two weeks, when we can "&REPT(" ",11) &"close at our attorney's office and get you your cash. "&REPT(" ",6) &"3. We cover the cost, time, and effort of paying any money due to any lender or HOA "&REPT(" ",11) &"involved." -> Hi Nikki, Thank you for the opportunity to make an offer on your property at 115 Rosebrooks Dr, Cary, NC 27513. I have several options I would like for you to consider. I also want to give you several very good reasons for you to work with us here at Buy Your Home LLC. 1. If you sell your home to us, you will incur no expense from the transaction. We will pay all: Closing Cost Attorney's Fees Realtor Commissions 2. We can close fast. It will be a matter of days, probably less than two weeks, when we can close at our attorney's office and get you your cash. 3. We cover the cost, time, and effort of paying any money due to any lender or HOA involved. | J1: Buyers Copy | K1: =+I1&IF(N14="X",O14,"")&" "& IF(H15="X",I15,"") &" "& IF(H16="X",I16,"") &" "& IF(H20="X",I20,"") &" "& IF(H26="X",I26,"") &" "& IF(H33="X",I33,"") & " "& IF(H42="X",I42,"") & " "& IF(H52="X",I52,"") & " "& IF(H61="X",I61,"") & " "& IF(H74="X",I74,"") & " "& IF(H81="X",I81,"") & " "& IF(H82="X",I82,"") & " "& "" -> Hi Nikki, Thank you for the opportunity to make an offer on your property at 115 Rosebrooks Dr, Cary, NC 27513. I have several options I would like for you to consider. I also want to give you several very good reasons for you to work with us here at Buy Your Home LLC. 1. If you sell your home to us, you will incur no expense from the transaction. We will pay all: Closing Cost Attorney's Fees Realtor Commissions 2. We can close fast. It will be a matter of days, probably less than two weeks, when we can close at our attorney's office and get you your cash. 3. We cover the cost, time, and effort of paying any money due to any lender or HOA involved. Here are some purchase options for your consideration. They are presented in summary form and I am sure you will have some questions that I will be happy to take time needed to answer. Each option below will have more value than the one above it. Option 1: Cash plus Assumption of Mortgage This is a cash payment, at closing. We will take responsibility for the existing mortgage, HOA fees, and any liens that may be discovered until we are able to resell the property. This offer is: Cash: $0.00 Total Value: $0.00 Option 2: Cash plus Promissory Note The explanation for the cash component is the same as for option 1. However, 20.% of the value of the offer will be cash and 80.% will be in the form of a promissory note, complete with a Deed of Trust. The note will have a 24-month term that will pay simple interest at the rate of 4% per year. Cash: $0.00 12 Month Note: $20,000.00 Interest Earned: $1,600.00 $66.67 per month Total Value: $21,600.00 Option 3: Cash plus Beneficial Interest in Trust The explanation for the cash component is the same as for option 2. Instead of a note as in Option 2, you will share in the profit earned when the property is resold. The property will be placed into a trust that you will share a beneficial interest in. The advantage here is you will benefit from the appreciated value of the property, over time. You will receive quarterly reports on the financial status of the property. Cash: $10,000.00 Interest in Trust: 70.% Expected Sellers Profit: $141,519.49 * Expected 3% appreciation per year Expected Value: $151,519.49 ** After 24 months. Nikki, this offer is contingent upon a normal due diligence period. The values of each option are predicated on some assumptions that may need to be altered upon further discovery. The more we can learn from you, in advance, the more reliable these options may be considered. When you decide which offer you prefer, I will email you a contract along with an earnest money payment. We are ready to be of service in any way we can. This offer is based on Zillow's Zestimate of $289,000.00. We will clean and prepare the property for a quick resale. There is also an assumption that the property will need no rehab. If that turns out to not be true, an allowance will need to be made. In any case, that will be decided in the due diligence period of the contract. Sincerely, Wes Browning (919) 899-2104
A3: Seller 1: | B3: Nikki | C3: Kulas | J3: no
A4: Seller 2:
A5: email:
A6: Phone #:
A9: Offer 1 | B9: Traditional, All Cash
B10: This is an all cash payment, at closing with no other allowances considered. Seller pays all Mortgages, liens, HOA expenses out of closings proceedings.
F12: Seller's Equity
B13: Sales Price | C13: ARV | D13: Debt | G13: BYH's Profit
B14: =+D14+F14 -> 187323.94 | C14: =+Profit!B4 -> 289000 | D14: =+Profit!K47-Profit!B18 -> 187323.94 | F14: =+B24-(B24*F16) -> 0 | G14: =+C14-D14-F14+Profit!E53+Profit!B18 -> -40703.745
D15: BYH Out of Pocket: | E15: =+Profit!$K$49 -> 43839.805
D16: BYH Profit/Out of Pocket: | E16: =+G14/E15 -> -0.92846547 | F16: 0.1 | H16: X | I16: ="Here are some purchase options for your consideration. They are presented in summary form and I am sure you will have some questions that I will be happy to take time needed to answer. Each option below will have more value than the one above it." -> Here are some purchase options for your consideration. They are presented in summary form and I am sure you will have some questions that I will be happy to take time needed to answer. Each option below will have more value than the one above it.
D17: Buy Your Home's % of Profit: | E17: =+G14/(F14+G14) -> 1 | F17: less than Opt 2
A19: Offer 2 | B19: Cash plus Assumption of Mortgage | D19: *This is the default values from the Profit Sheet. | H19: =IF(H20="X",1,0) -> 0
B20: Cash payment in conjunction with taking the existing mortgage subject to: | I20: ="Option "&H19&": "&""&B9&" "&REPT(" ",6)&"This is a, traditional, all cash purchase, at closing with no other allowances considered. Seller "&REPT(" ",6)&"pays all mortgages, liens, HOA expenses, etc., out of closings disbursements. This option has " & REPT(" ",6) & "the smallest value for the seller. Our cash offer is: "&REPT(" ",43) &"Cash:"&REPT(" ",21)&+TEXT(B14,"$#,##0.00") & IF(J3="yes",REPT(" ",10) & "Profit = "& TEXT(G14,"$#,##0.00"),"" )& " "&REPT(" ",32) & "Total Value:"&REPT(" ",21)&TEXT(F14,"$#,##0.00") -> Option 0: Traditional, All Cash This is a, traditional, all cash purchase, at closing with no other allowances considered. Seller pays all mortgages, liens, HOA expenses, etc., out of closings disbursements. This option has the smallest value for the seller. Our cash offer is: Cash: $187,323.94 Total Value: $0.00
B21: After reinstating existing loans and HOA fees
F22: Seller's Total Value
B23: Cash | G23: BYH's Profit
B24: =+Profit!B18 -> 0 | C24: <- The default value form profit sheet | F24: =+B24 -> 0 | G24: =+Profit!K59+Profit!B18-B24 -> 188761.7
D25: BYH Out of Pocket: | E25: =+Profit!$K$49 -> 43839.805 | H25: =IF(H26="X",1+H19,H19) -> 1
D26: BYH Profit/Out of Pocket: | E26: =+G24/E25 -> 4.3057148 | H26: x | I26: ="Option " & H25 & ": "&""&B19&" "&REPT(" ",6) & "This is a cash payment, at closing. We will take responsibility for the existing mortgage, HOA "&REPT(" ",6) & "fees, and any liens that may be discovered until we are able to resell the property. This offer is: "&REPT(" ",43)&"Cash:"&REPT(" ",22) & TEXT(F24,"$#,##0.00") & IF(J3="yes",REPT(" ",10) & "Profit = "& TEXT(G24,"$#,##0.00"),"" ) & " "&REPT(" ",32)&"Total Value:"&REPT(" ",22) & TEXT(F24,"$#,##0.00") -> Option 1: Cash plus Assumption of Mortgage This is a cash payment, at closing. We will take responsibility for the existing mortgage, HOA fees, and any liens that may be discovered until we are able to resell the property. This offer is: Cash: $0.00 Total Value: $0.00
D27: Buy Your Home's % of Profit: | E27: =+G24/(F24+G24) -> 1
A30: Offer 3 | B30: Cash plus Promissory Note | D30: - this is the one to stear seller to:
B31: Cash payment in conjunction with taking the existing mortgage subject to: | I31: ="This is a cash payment, at closing, in conjunction with reinstating the existing mortgage taking responsibility for those payments, HOA fees and other liens that may be discovered. Our cash offer is:" -> This is a cash payment, at closing, in conjunction with reinstating the existing mortgage taking responsibility for those payments, HOA fees and other liens that may be discovered. Our cash offer is:
B32: After reinstating existing loans and HOA fees | H32: =IF(H33="X",H25+1,H25) -> 2
H33: x | I33: ="Option " & H32 & ": " &""&B30&" "&REPT(" ",6)&"The explanation for the cash component is the same as for option "& H25 & ". However, "&TEXT(B38,"##.#%") &" of the " & REPT(" ",6) & "value of the offer will be cash and "& TEXT(C38,"##.#%") &" will be in the form of a promissory note, complete " & REPT(" ",6) & "with a Deed of Trust. The note will have a " & D35 & "-month term that will pay simple interest at " & REPT(" ",6) & "the rate of "&E37*100&"% per year. "& REPT(" ",43) & "Cash:" & REPT(" ",23) & TEXT(B37,"$#,##0.00") & IF(J3="yes",REPT(" ",10) & "Profit = "& TEXT(G37,"$#,##0.00"),"" ) &" "& REPT(" ",24) & "12 Month Note:" & REPT(" ",24) & TEXT(C37,"$#,##0.00")&" "& REPT(" ",25) & "Interest Earned:" & REPT(" ",25) & TEXT(D37,"$#,##0.00") &REPT(" ",12)&+TEXT(D37/D35,"$#,##0.00") & " per month" & " "& REPT(" ",32) & "Total Value:" & REPT(" ",20) & TEXT(F37,"$#,##0.00") -> Option 2: Cash plus Promissory Note The explanation for the cash component is the same as for option 1. However, 20.% of the value of the offer will be cash and 80.% will be in the form of a promissory note, complete with a Deed of Trust. The note will have a 24-month term that will pay simple interest at the rate of 4% per year. Cash: $0.00 12 Month Note: $20,000.00 Interest Earned: $1,600.00 $66.67 per month Total Value: $21,600.00
C34: Note is a simple interest note for: | D34: Months | F34: (Based on Current Valuation)
B35: Value added to Note: | C35: 20000 | D35: 24 | F35: Seller's Total Value
B36: Cash | C36: Note | D36: Interest Earned | E36: Interest Rate | G36: BYH's Profit
B37: =+(Profit!$B$18)*B38 -> 0 | C37: =+(Profit!$B$18)-B37+C35 -> 20000 | D37: =+C37*D35/12*E37 -> 1600 | E37: 0.04 | F37: =+SUM(B37:D37) -> 21600 | G37: =+Profit!$K$59-D37-C35 -> 167161.7
B38: 0.2 | C38: =1-B38 -> 0.8
D39: BYH Out of Pocket: | E39: =+Profit!$K$49-C37+C35 -> 43839.805
D40: BYH Profit/Out of Pocket: | E40: =+G37/E39 -> 3.8130119
D41: Buy Your Home's % of Profit: | E41: =+G37/(F37+G37) -> 0.88557001 | H41: =IF(H42="X",H32+1,H32) -> 3
A42: Offer 4 | B42: Cash plus Beneficial Interest in Trust | H42: x | I42: ="Option " & H41 & ": " & B42&" "&REPT(" ",6)&"The explanation for the cash component is the same as for option "& H32 & ". Instead of a note as in " & REPT(" ",6) & "Option "& H32 & ", you will share in the profit earned when the property is resold." &" The property will " & REPT(" ",6) & "be placed into a trust that you will share a beneficial interest in. The advantage here is you will " & REPT(" ",6) & "benefit from the appreciated value of the property, over time." &" You will receive quarterly " & REPT(" ",6) & "reports on the financial status of the property. "& REPT(" ",43) & "Cash:" & REPT(" ",23) & TEXT(B50,"$#,##0.00") & IF(J3="yes",REPT(" ",10) & "Profit = "& TEXT(G50,"$#,##0.00"),"" ) &" "& REPT(" ",24) & "Interest in Trust:" & REPT(" ",33) & TEXT(D50,"#.#%")&" "& REPT(" ",13) & "Expected Sellers Profit:" & REPT(" ",23) & TEXT(E50,"$#,##0.00") &" * Expected "&Profit!$K$6*100&"% appreciation per year" & " "& REPT(" ",26) & "Expected Value:" & REPT(" ",20) & TEXT(F50,"$#,##0.00") & " ** After " & D35 &" months." -> Option 3: Cash plus Beneficial Interest in Trust The explanation for the cash component is the same as for option 2. Instead of a note as in Option 2, you will share in the profit earned when the property is resold. The property will be placed into a trust that you will share a beneficial interest in. The advantage here is you will benefit from the appreciated value of the property, over time. You will receive quarterly reports on the financial status of the property. Cash: $10,000.00 Interest in Trust: 70.% Expected Sellers Profit: $141,519.49 * Expected 3% appreciation per year Expected Value: $151,519.49 ** After 24 months.
B43: Cash payment in conjunction with taking the existing mortgage subject to:
B44: After reinstating existing loans and HOA fees
B45: Profit split is a split of the profits upon the eventual sale of the pproperty.
B46: Profits will be calculated after deducting all expenses incurred from the sales price
F47: (Based on Future Valuation)
...

Sheet Contact
A1: Vendor | B1: Phone Number | C1: Contact | D1: Acct/Policy | E1: Email | F1: Purpose
A2: Sellers
A3: Brenda Griffith | C3: 910 808 9147 | D3: SS#:244 66 8962 | E3: Birth: 11/16/1940
A4: Cheryl D Powell | D4: SS#: 246 84 4592
D5: 936 52 3090
A6: Mortgage | B6: 800 274 7025
A7: Bank of America | B7: 800 669 0102 | C7: 800 669 6607 | D7: 0401704000 | F7: sent on 09/27/2023
A8: Hutchens La w Firm: Liza Norris | B8: 910 864 3068 | E8: Liza.Norris@HutchensLawfirm.com | F8: emailed on 11/1/23
A9: Brock & Scott | B9: 910 392 4988 | F9: emaild on 6/17/24
A10: Taylors Pond HOA | B10: 919 362 1460 | C10: Tammy Finance
A12: Shellpoint | B12: Jenny@BuyYourHomeLLC.com | C12: w3638B0# | D12: https://signin.shellpointmtg.com/signin/myaccount
A13: Loan # | D13: 691805311
A14: NREIG | B14: 770 734 1523
U16: To | V16: Subject | W16: Sent | X16: Size | Y16: Categories
U17: DefaultCFC@Truist.com | V17: 5008 Larchmont Dr - Loan 9015 2144 11-5998 | W17: 0.44583333 | X17: 478 KB
A20: Insurance National Real Estate Insurance Group LLC
A21: Rani Walker | B21: 678 329 0123 | C21: RWalker@insurancehub.com
A22: Customer Care Specialist
A23: InsuranceHub Leavitt Agency
A24: Phone/SMS/Fax: 678.329.0123 | insurancehub.com
A25: Becki Miron | B25: 678.685.3277 | C25: BMiron@insurancehub.com
A26: Account Manager
A27: InsuranceHub Leavitt Agency
A28: Phone/SMS/Fax: 678.685.3277 | insurancehub.com

Sheet Carrying
A1: Duke Electric | E1: Mortgage Payments | H1: Neal Issac | K1: Insurance Payments | N1: City of Raleigh(Water) | Q1: Dominion Energy (gas) | T1: HOA | W1: Taxes
B2: Date | C2: payment | E2: Date | F2: payment | H2: Date | I2: payment | K2: Date | L2: payment | N2: Date | O2: payment | Q2: Date | R2: payment | T2: Date | U2: payment | W2: Date | X2: payment
E4: 45444 | H4: 45307 | I4: 625 | K4: 45231 | L4: 166.58 | T4: 45231 | U4: 120 | W4: 45170 | X4: 853.79
E5: =+E4+30 -> 45474 | H5: =+H4+30 -> 45337 | I5: =+I4 -> 625 | K5: =+K4+30 -> 45261 | L5: =IF(NOW()>K5,L4,0) -> 166.58 | T5: =+T4+30 -> 45261 | U5: =IF(Profit!$J$71>T5,U4,0) -> 120 | W5: =365+W4 -> 45535 | X5: =IF(Profit!$J$71>W5,X4,0) -> 853.79
E6: =+E5+30 -> 45504 | H6: =+H5+30 -> 45367 | I6: =+I5 -> 625 | K6: =+K5+30 -> 45291 | L6: =IF(NOW()>K6,L5,0) -> 166.58 | T6: =+T5+30 -> 45291 | U6: =IF(Profit!$J$71>T6,U5,0) -> 120 | W6: =365+W5 -> 45900 | X6: 2384.81
E7: =+E6+30 -> 45534 | H7: =+H6+30 -> 45397 | I7: =IF(Profit!$J$71>H7,I6,0) -> 625 | K7: =+K6+30 -> 45321 | L7: =IF(NOW()>K7,L6,0) -> 166.58 | T7: =+T6+30 -> 45321 | U7: =IF(Profit!$J$71>T7,U6,0) -> 120 | W7: =365+W6 -> 46265 | X7: =IF(Profit!$J$71>W7,X6,0) -> 0
E8: =+E7+30 -> 45564 | H8: =+H7+30 -> 45427 | I8: =IF(Profit!$J$71>H8,I7,0) -> 625 | K8: =+K7+30 -> 45351 | L8: =IF(NOW()>K8,L7,0) -> 166.58 | T8: =+T7+30 -> 45351 | U8: =IF(Profit!$J$71>T8,U7,0) -> 120 | W8: =365+W7 -> 46630 | X8: =IF(Profit!$J$71>W8,X7,0) -> 0
E9: =+E8+30 -> 45594 | F9: 1218.69 | H9: =+H8+30 -> 45457 | I9: =IF(Profit!$J$71>H9,I8,0) -> 625 | K9: =+K8+30 -> 45381 | L9: =IF(NOW()>K9,L8,0) -> 166.58 | T9: =+T8+30 -> 45381 | U9: =IF(Profit!$J$71>T9,U8,0) -> 120 | W9: =365+W8 -> 46995 | X9: =IF(Profit!$J$71>W9,X8,0) -> 0 | AA9: =+L8+U9+Profit!B23 -> 342.4979
E10: =+E9+30 -> 45624 | F10: =IF(Profit!$J$71>E10,F9,0) -> 1218.69 | H10: =+H9+30 -> 45487 | I10: =IF(Profit!$J$71>H10,I9,0) -> 625 | K10: =+K9+30 -> 45411 | L10: =IF(NOW()>K10,L9,0) -> 166.58 | T10: =+T9+30 -> 45411 | U10: =IF(Profit!$J$71>T10,U9,0) -> 120 | W10: =365+W9 -> 47360 | X10: =IF(Profit!$J$71>W10,X9,0) -> 0
E11: =+E10+30 -> 45654 | F11: =IF(Profit!$J$71>E11,F10,0) -> 1218.69 | H11: =+H10+30 -> 45517 | I11: =IF(Profit!$J$71>H11,I10,0) -> 625 | K11: 45456 | L11: 161.42 | T11: =+T10+30 -> 45441 | U11: =IF(Profit!$J$71>T11,U10,0) -> 120 | W11: =365+W10 -> 47725 | X11: =IF(Profit!$J$71>W11,X10,0) -> 0
E12: =+E11+30 -> 45684 | F12: 1493.86 | H12: =+H11+30 -> 45547 | I12: =IF(Profit!$J$71>H12,I11,0) -> 625 | K12: 45486 | L12: 80.71 | T12: =+T11+30 -> 45471 | U12: =IF(Profit!$J$71>T12,U11,0) -> 120 | W12: =365+W11 -> 48090 | X12: =IF(Profit!$J$71>W12,X11,0) -> 0
E13: =+E12+30 -> 45714 | F13: =IF(Profit!$J$71>E13,F12,0) -> 1493.86 | H13: =+H12+30 -> 45577 | I13: =IF(Profit!$J$71>H13,I12,0) -> 625 | K13: 45517 | L13: =IF(Profit!$J$71>K13,L12,0) -> 80.71 | T13: =+T12+30 -> 45501 | U13: =IF(Profit!$J$71>T13,U12,0) -> 120 | W13: =365+W12 -> 48455 | X13: =IF(Profit!$J$71>W13,X12,0) -> 0
E14: =+E13+30 -> 45744 | F14: =IF(Profit!$J$71>E14,F13,0) -> 1493.86 | H14: =+H13+30 -> 45607 | K14: =+K13+30 -> 45547 | L14: =IF(Profit!$J$71>K14,L13,0) -> 80.71 | T14: =+T13+30 -> 45531 | U14: =IF(Profit!$J$71>T14,U13,0) -> 120 | W14: =365+W13 -> 48820 | X14: =IF(Profit!$J$71>W14,X13,0) -> 0
E15: =+E14+30 -> 45774 | F15: =IF(Profit!$J$71>E15,F14,0) -> 1493.86 | H15: =+H14+30 -> 45637 | I15: =IF(Profit!$J$71>H15,I14,0) -> 0 | K15: =+K14+30 -> 45577 | L15: =IF(Profit!$J$71>K15,L14,0) -> 80.71 | T15: =+T14+30 -> 45561 | U15: =IF(Profit!$J$71>T15,U14,0) -> 120 | W15: =365+W14 -> 49185 | X15: =IF(Profit!$J$71>W15,X14,0) -> 0
E16: =+E15+30 -> 45804 | F16: 1493.86 | H16: =+H15+30 -> 45667 | I16: =IF(Profit!$J$71>H16,I15,0) -> 0 | K16: =+K15+30 -> 45607 | L16: =IF(Profit!$J$71>K16,L15,0) -> 80.71 | T16: =+T15+30 -> 45591 | U16: =IF(Profit!$J$71>T16,U15,0) -> 120 | W16: =365+W15 -> 49550 | X16: =IF(Profit!$J$71>W16,X15,0) -> 0
E17: =+E16+30 -> 45834 | F17: =IF(Profit!$J$71>E17,F16,0) -> 1493.86 | H17: =+H16+30 -> 45697 | I17: =IF(Profit!$J$71>H17,I16,0) -> 0 | K17: =+K16+30 -> 45637 | L17: =IF(Profit!$J$71>K17,L16,0) -> 80.71 | T17: =+T16+30 -> 45621 | U17: =IF(Profit!$J$71>T17,U16,0) -> 120 | W17: =365+W16 -> 49915 | X17: =IF(Profit!$J$71>W17,X16,0) -> 0
E18: =+E17+30 -> 45864 | F18: =IF(Profit!$J$71>E18,F17,0) -> 1493.86 | H18: =+H17+30 -> 45727 | I18: =IF(Profit!$J$71>H18,I17,0) -> 0 | K18: =+K17+30 -> 45667 | L18: 0 | T18: =+T17+30 -> 45651 | U18: =IF(Profit!$J$71>T18,U17,0) -> 120 | W18: =365+W17 -> 50280 | X18: =IF(Profit!$J$71>W18,X17,0) -> 0
E19: =+E18+30 -> 45894 | F19: =IF(Profit!$J$71>E19,F18,0) -> 1493.86 | H19: =+H18+30 -> 45757 | I19: =IF(Profit!$J$71>H19,I18,0) -> 0 | K19: =+K18+30 -> 45697 | L19: 0 | T19: =+T18+30 -> 45681 | U19: =IF(Profit!$J$71>T19,U18,0) -> 120 | W19: =365+W18 -> 50645 | X19: =IF(Profit!$J$71>W19,X18,0) -> 0
E20: =+E19+30 -> 45924 | F20: =IF(Profit!$J$71>E20,F19,0) -> 1493.86 | H20: =+H19+30 -> 45787 | I20: =IF(Profit!$J$71>H20,I19,0) -> 0 | K20: =+K19+30 -> 45727 | L20: 0 | T20: =+T19+30 -> 45711 | U20: =IF(Profit!$J$71>T20,U19,0) -> 120 | W20: =365+W19 -> 51010 | X20: =IF(Profit!$J$71>W20,X19,0) -> 0
E21: =+E20+30 -> 45954 | F21: =IF(Profit!$J$71>E21,F20,0) -> 1493.86 | H21: =+H20+30 -> 45817 | I21: =IF(Profit!$J$71>H21,I20,0) -> 0 | K21: =+K20+30 -> 45757 | L21: 0 | T21: =+T20+30 -> 45741 | U21: =IF(Profit!$J$71>T21,U20,0) -> 120 | W21: =365+W20 -> 51375 | X21: =IF(Profit!$J$71>W21,X20,0) -> 0
E22: =+E21+30 -> 45984 | F22: =IF(Profit!$J$71>E22,F21,0) -> 1493.86 | H22: =+H21+30 -> 45847 | I22: =IF(Profit!$J$71>H22,I21,0) -> 0 | K22: =+K21+30 -> 45787 | L22: 0 | T22: =+T21+30 -> 45771 | U22: =IF(Profit!$J$71>T22,U21,0) -> 120 | W22: =365+W21 -> 51740 | X22: =IF(Profit!$J$71>W22,X21,0) -> 0
E23: =+E22+30 -> 46014 | F23: =IF(Profit!$J$71>E23,F22,0) -> 1493.86 | H23: =+H22+30 -> 45877 | I23: =IF(Profit!$J$71>H23,I22,0) -> 0 | K23: =+K22+30 -> 45817 | L23: 0 | T23: =+T22+30 -> 45801 | U23: =IF(Profit!$J$71>T23,U22,0) -> 120 | W23: =365+W22 -> 52105 | X23: =IF(Profit!$J$71>W23,X22,0) -> 0
E24: =+E23+30 -> 46044 | F24: =IF(Profit!$J$71>E24,F23,0) -> 1493.86 | H24: =+H23+30 -> 45907 | I24: =IF(Profit!$J$71>H24,I23,0) -> 0 | K24: =+K23+30 -> 45847 | L24: 0 | T24: =+T23+30 -> 45831 | U24: =IF(Profit!$J$71>T24,U23,0) -> 120 | W24: =365+W23 -> 52470 | X24: =IF(Profit!$J$71>W24,X23,0) -> 0
E25: =+E24+30 -> 46074 | F25: =IF(Profit!$J$71>E25,F24,0) -> 1493.86 | H25: =+H24+30 -> 45937 | I25: =IF(Profit!$J$71>H25,I24,0) -> 0 | K25: =+K24+30 -> 45877 | L25: 0 | T25: =+T24+30 -> 45861 | U25: =IF(Profit!$J$71>T25,U24,0) -> 120 | W25: =365+W24 -> 52835 | X25: =IF(Profit!$J$71>W25,X24,0) -> 0
E26: =+E25+30 -> 46104 | F26: =IF(Profit!$J$71>E26,F25,0) -> 1493.86 | H26: =+H25+30 -> 45967 | I26: =IF(Profit!$J$71>H26,I25,0) -> 0 | K26: =+K25+30 -> 45907 | L26: 0 | T26: =+T25+30 -> 45891 | U26: =IF(Profit!$J$71>T26,U25,0) -> 120 | W26: =365+W25 -> 53200 | X26: =IF(Profit!$J$71>W26,X25,0) -> 0
E27: =+E26+30 -> 46134 | F27: =IF(Profit!$J$71>E27,F26,0) -> 1493.86 | H27: =+H26+30 -> 45997 | I27: =IF(Profit!$J$71>H27,I26,0) -> 0 | K27: =+K26+30 -> 45937 | L27: 0 | T27: =+T26+30 -> 45921 | U27: =IF(Profit!$J$71>T27,U26,0) -> 120 | W27: =365+W26 -> 53565 | X27: =IF(Profit!$J$71>W27,X26,0) -> 0
E28: =+E27+30 -> 46164 | F28: =IF(Profit!$J$71>E28,F27,0) -> 1493.86 | H28: =+H27+30 -> 46027 | I28: =IF(Profit!$J$71>H28,I27,0) -> 0 | K28: =+K27+30 -> 45967 | L28: 0 | T28: =+T27+30 -> 45951 | U28: =IF(Profit!$J$71>T28,U27,0) -> 120 | W28: =365+W27 -> 53930 | X28: =IF(Profit!$J$71>W28,X27,0) -> 0
E29: =+E28+30 -> 46194 | F29: =IF(Profit!$J$71>E29,F28,0) -> 1493.86 | H29: =+H28+30 -> 46057 | I29: =IF(Profit!$J$71>H29,I28,0) -> 0 | K29: =+K28+30 -> 45997 | L29: 0 | T29: =+T28+30 -> 45981 | U29: =IF(Profit!$J$71>T29,U28,0) -> 120 | W29: =365+W28 -> 54295 | X29: =IF(Profit!$J$71>W29,X28,0) -> 0
E30: =+E29+30 -> 46224 | F30: =IF(Profit!$J$71>E30,F29,0) -> 0 | H30: =+H29+30 -> 46087 | I30: =IF(Profit!$J$71>H30,I29,0) -> 0 | K30: =+K29+30 -> 46027 | L30: 0 | T30: =+T29+30 -> 46011 | U30: =IF(Profit!$J$71>T30,U29,0) -> 120 | W30: =365+W29 -> 54660 | X30: =IF(Profit!$J$71>W30,X29,0) -> 0
E31: =+E30+30 -> 46254 | F31: =IF(Profit!$J$71>E31,F30,0) -> 0 | H31: =+H30+30 -> 46117 | I31: =IF(Profit!$J$71>H31,I30,0) -> 0 | K31: =+K30+30 -> 46057 | L31: 0 | T31: 45662 | U31: =IF(Profit!$J$71>T31,U30,0) -> 120 | W31: =365+W30 -> 55025 | X31: =IF(Profit!$J$71>W31,X30,0) -> 0
E32: =+E31+30 -> 46284 | F32: =IF(Profit!$J$71>E32,F31,0) -> 0 | H32: =+H31+30 -> 46147 | I32: =IF(Profit!$J$71>H32,I31,0) -> 0 | K32: =+K31+30 -> 46087 | L32: 0 | T32: =+T31+30 -> 45692 | U32: =IF(Profit!$J$71>T32,U31,0) -> 120 | W32: =365+W31 -> 55390 | X32: =IF(Profit!$J$71>W32,X31,0) -> 0
E33: =+E32+30 -> 46314 | F33: =IF(Profit!$J$71>E33,F32,0) -> 0 | H33: =+H32+30 -> 46177 | I33: =IF(Profit!$J$71>H33,I32,0) -> 0 | K33: =+K32+30 -> 46117 | L33: 0 | T33: =+T32+30 -> 45722 | U33: =IF(Profit!$J$71>T33,U32,0) -> 120 | W33: =365+W32 -> 55755 | X33: =IF(Profit!$J$71>W33,X32,0) -> 0
E34: =+E33+30 -> 46344 | F34: =IF(Profit!$J$71>E34,F33,0) -> 0 | H34: =+H33+30 -> 46207 | I34: =IF(Profit!$J$71>H34,I33,0) -> 0 | K34: =+K33+30 -> 46147 | L34: 0 | T34: =+T33+30 -> 45752 | U34: =IF(Profit!$J$71>T34,U33,0) -> 120 | W34: =365+W33 -> 56120 | X34: =IF(Profit!$J$71>W34,X33,0) -> 0
E35: =+E34+30 -> 46374 | F35: =IF(Profit!$J$71>E35,F34,0) -> 0 | H35: =+H34+30 -> 46237 | I35: =IF(Profit!$J$71>H35,I34,0) -> 0 | K35: =+K34+30 -> 46177 | L35: 0 | T35: =+T34+30 -> 45782 | U35: =IF(Profit!$J$71>T35,U34,0) -> 120 | W35: =365+W34 -> 56485 | X35: =IF(Profit!$J$71>W35,X34,0) -> 0
E36: =+E35+30 -> 46404 | F36: =IF(Profit!$J$71>E36,F35,0) -> 0 | H36: =+H35+30 -> 46267 | I36: =IF(Profit!$J$71>H36,I35,0) -> 0 | K36: =+K35+30 -> 46207 | L36: 0 | T36: =+T35+30 -> 45812 | U36: =IF(Profit!$J$71>T36,U35,0) -> 120 | W36: =365+W35 -> 56850 | X36: =IF(Profit!$J$71>W36,X35,0) -> 0
E37: =+E36+30 -> 46434 | F37: =IF(Profit!$J$71>E37,F36,0) -> 0 | H37: =+H36+30 -> 46297 | I37: =IF(Profit!$J$71>H37,I36,0) -> 0 | K37: =+K36+30 -> 46237 | L37: 0 | T37: =+T36+30 -> 45842 | U37: =IF(Profit!$J$71>T37,U36,0) -> 120 | W37: =365+W36 -> 57215 | X37: =IF(Profit!$J$71>W37,X36,0) -> 0
E38: =+E37+30 -> 46464 | F38: =IF(Profit!$J$71>E38,F37,0) -> 0 | H38: =+H37+30 -> 46327 | I38: =IF(Profit!$J$71>H38,I37,0) -> 0 | K38: =+K37+30 -> 46267 | L38: 0 | T38: =+T37+30 -> 45872 | U38: =IF(Profit!$J$71>T38,U37,0) -> 120 | W38: =365+W37 -> 57580 | X38: =IF(Profit!$J$71>W38,X37,0) -> 0
E39: =+E38+30 -> 46494 | F39: =IF(Profit!$J$71>E39,F38,0) -> 0 | H39: =+H38+30 -> 46357 | I39: =IF(Profit!$J$71>H39,I38,0) -> 0 | K39: =+K38+30 -> 46297 | L39: 0 | T39: =+T38+30 -> 45902 | U39: =IF(Profit!$J$71>T39,U38,0) -> 120 | W39: =365+W38 -> 57945 | X39: =IF(Profit!$J$71>W39,X38,0) -> 0
E40: =+E39+30 -> 46524 | F40: =IF(Profit!$J$71>E40,F39,0) -> 0 | H40: =+H39+30 -> 46387 | I40: =IF(Profit!$J$71>H40,I39,0) -> 0 | K40: =+K39+30 -> 46327 | L40: 0 | T40: =+T39+30 -> 45932 | U40: =IF(Profit!$J$71>T40,U39,0) -> 120 | W40: =365+W39 -> 58310 | X40: =IF(Profit!$J$71>W40,X39,0) -> 0
E41: =+E40+30 -> 46554 | F41: =IF(Profit!$J$71>E41,F40,0) -> 0 | H41: =+H40+30 -> 46417 | I41: =IF(Profit!$J$71>H41,I40,0) -> 0 | K41: =+K40+30 -> 46357 | L41: 0 | T41: =+T40+30 -> 45962 | U41: =IF(Profit!$J$71>T41,U40,0) -> 120 | W41: =365+W40 -> 58675 | X41: =IF(Profit!$J$71>W41,X40,0) -> 0
...

Sheet Contract
B2: ="Preassigned Rows Indicating Payment or Scheduling by " &Profit!E1&" Your Home" -> Preassigned Rows Indicating Payment or Scheduling by Buy Your Home
B4: Preassigned Rows Cordination of Glasgow with Contrtactors
B6: Pasted rows from Builder's Trend Proposal
B8: Notes: Only add rows to the bottom of the table
A11: Cost Code | B11: Title | C11: Description | D11: Qty | E11: Unit Price
A12: Deposit | B12: Deposit | C12: Initial Deposit to Start Job | D12: 0 | E12: 7016
A13: Draw | B13: Draw 1 | C13: Draw 1 | D13: 0 | E13: 10505.74
A14: Draw | B14: Draw 2 | C14: Draw 2 | D14: 0 | E14: 9940
B15: Sell | C15: List with MLS | D15: 6
A16: HVAC | B16: Cordinate Sub | C16: HVAC | D16: 0 | E16: 0
A17: Floor Coverings | B17: Cordinate Sub | C17: Flooring Contractor | D17: 0 | E17: 0
A18: Supervision | B18: Cordinate Sub | C18: Termite Treatment | D18: 0 | E18: 0
A19: Cabinets & Vanities | B19: Cordinate Sub | C19: Cabinet Delivery | D19: 0 | E19: 0
A20: Countertops | B20: Cordinate Sub | C20: Manage installion of granite countertops by others in kitchen | D20: 0 | E20: 0
A21: Demo | B21: r | C21: Kitchen countertops | D21: 1 | E21: 3800
A22: Demo | C22: Rug | D22: 0
A23: Demo | C23: Vinyl flooring | D23: 0
A24: Paint | C24: Paint Interior of houseCeiling, walls, doors, trim. Exterior2 Doors, 4 Shutters | D24: 1 | E24: 4950
A25: Power Wash | C25: Power wash exterior, House only | D25: 1 | E25: 590
A26: Floor Coverings | B26: LVP | C26: Install LVP | D26: 1 | E26: 3790
A27: Floor Coverings | C27: All of first floor including baths and laundry room in 2nd floor. Labor and shoe mold included.
A28: Floor Coverings | C28: Note- Client will purchase flooring materials. Estimated- 850 sqft, Please include 10% for waste
A29: Floor Coverings | B29: Carpet | C29: Install Carpet Estimated-884 sqft General Use Carpet and padding Labor | D29: 1 | E29: 1200
A30: Countertops | B30: Quartz | C30: Level 1 Quartz $3,190 | D30: 1 | E30: 3190
A31: Countertops | B31: Quartz | C31: Level 2 Quartz $3,850 | D31: 0
A32: Countertops | B32: change order #9 | C32: Level 3 Granet $4,620 | D32: 1 | E32: 4345
A33: Installations | B33: Labor and supplies | C33: Installations | D33: 1 | E33: 4252.5
A34: Installations | B34: Labor and supplies | C34: 3-Toilets | D34: 1
A35: Installations | B35: Labor and supplies | C35: 1-Kitchen Sink | D35: 1
A36: Installations | B36: Labor and supplies | C36: 1-Shower doors | D36: 1
A37: Installations | B37: Labor and supplies | C37: 2- Mirrors | D37: 1
A38: Installations | B38: Labor and supplies | C38: 1- Stove, | D38: 1
A39: Installations | B39: Labor and supplies | C39: DW, | D39: 1
A40: Installations | B40: Labor and supplies | C40: Microwave | D40: 1
A41: Installations | B41: Labor and supplies | C41: 2- TP Holders | D41: 1
A42: Installations | B42: Labor and supplies | C42: 2- Ceiling Fans | D42: 1
A43: Installations | B43: Labor and supplies | C43: 2- Kitchen light fixtures | D43: 1
A44: Installations | B44: Labor and supplies | C44: 1- Pantry Light | D44: 1
A45: Installations | B45: Labor and supplies | C45: 2- Shower heads | D45: 1
A46: Installations | B46: Labor and supplies | C46: Drywall Repair in garage Labor and supplies included | D46: 1
...

Sheet UpdateContract
A1: These Cells are updated from the Proposal tab and are protected here. | I1: These cells are updated here and carried over to the Gnatt Chart | P1: Contracted Task | Q1: 1 | R1: Payment | S1: 4
P2: Change Order | Q2: 2 | R2: Not Used | S2: 0
P3: Manage Vendor | Q3: 3 | R3: Post Contract | S3: 5
A4: Party | B4: Item | C4: Cost Code | D4: Title | E4: Description | F4: Qty | G4: Unit Price | H4: Price | I4: Done | J4: Group Order | K4: Start Date | L4: Days | M4: Paid | N4: Notes
A5: =+IF(FromProposal[[#This Row],[Cost Code]]<>0,+'Gnatt Chart'!$A$2,"") -> AvilaCRI | B5: 1 | C5: Deposit | D5: Deposit | E5: Initial Deposit to Start Job | F5: 0 | G5: 7016 | H5: 0 | I5: Yes | J5: 4 | K5: 10/13 | M5: 7016
A6: =+IF(FromProposal[[#This Row],[Cost Code]]<>0,+'Gnatt Chart'!$A$2,"") -> AvilaCRI | B6: 2 | C6: Draw | D6: Draw 1 | E6: Draw 1 | F6: 0 | G6: 10505.74 | H6: 0 | I6: yes | J6: 4 | K6: 45218 | M6: 10505.74
A7: =+IF(FromProposal[[#This Row],[Cost Code]]<>0,+'Gnatt Chart'!$A$2,"") -> AvilaCRI | B7: 3 | C7: Draw | D7: Draw 2 | E7: Draw 2 | F7: 0 | G7: 9940 | H7: 0 | J7: 4 | K7: 45226 | M7: 9940
A8: =+IF(FromProposal[[#This Row],[Cost Code]]<>0,+'Gnatt Chart'!$A$2,"") | B8: 4 | D8: Sell | E8: List with MLS | F8: 6 | J8: 5
A9: =+IF(FromProposal[[#This Row],[Cost Code]]<>0,+'Gnatt Chart'!$A$2,"") -> AvilaCRI | B9: 5 | C9: HVAC | D9: Cordinate Sub | E9: HVAC | F9: 0 | G9: 0 | H9: 0 | J9: 0
A10: =+IF(FromProposal[[#This Row],[Cost Code]]<>0,+'Gnatt Chart'!$A$2,"") -> AvilaCRI | B10: 6 | C10: Floor Coverings | D10: Cordinate Sub | E10: Flooring Contractor | F10: 0 | G10: 0 | H10: 0 | J10: 0 | L10: 5
A11: =+IF(FromProposal[[#This Row],[Cost Code]]<>0,+'Gnatt Chart'!$A$2,"") -> AvilaCRI | B11: 7 | C11: Supervision | D11: Cordinate Sub | E11: Termite Treatment | F11: 0 | G11: 0 | H11: 0 | J11: 0
A12: =+IF(FromProposal[[#This Row],[Cost Code]]<>0,+'Gnatt Chart'!$A$2,"") -> AvilaCRI | B12: 8 | C12: Cabinets & Vanities | D12: Cordinate Sub | E12: Cabinet Delivery | F12: 0 | G12: 0 | H12: 0 | J12: 0
A13: =+IF(FromProposal[[#This Row],[Cost Code]]<>0,+'Gnatt Chart'!$A$2,"") -> AvilaCRI | B13: 9 | C13: Countertops | D13: Cordinate Sub | E13: Manage installion of granite countertops by others in kitchen | F13: 0 | G13: 0 | H13: 0 | I13: yes | J13: 0
A14: =+IF(FromProposal[[#This Row],[Cost Code]]<>0,+'Gnatt Chart'!$A$2,"") -> AvilaCRI | B14: 10 | C14: Demo | D14: r | E14: Kitchen countertops | F14: 1 | G14: 3800 | H14: 3800 | I14: yes | J14: 1 | K14: 45213 | L14: 1
A15: =+IF(FromProposal[[#This Row],[Cost Code]]<>0,+'Gnatt Chart'!$A$2,"") -> AvilaCRI | B15: 11 | C15: Demo | E15: Rug | F15: 0 | I15: yes | J15: 1 | K15: 45213 | L15: 1
A16: =+IF(FromProposal[[#This Row],[Cost Code]]<>0,+'Gnatt Chart'!$A$2,"") -> AvilaCRI | B16: 12 | C16: Demo | E16: Vinyl flooring | F16: 0 | I16: yes | J16: 1 | K16: 45213 | L16: 1
A17: =+IF(FromProposal[[#This Row],[Cost Code]]<>0,+'Gnatt Chart'!$A$2,"") -> AvilaCRI | B17: 13 | C17: Paint | E17: Paint Interior of houseCeiling, walls, doors, trim. Exterior2 Doors, 4 Shutters | F17: 1 | G17: 4950 | H17: 4950 | I17: yes | J17: 1 | K17: 45216 | L17: 7
A18: =+IF(FromProposal[[#This Row],[Cost Code]]<>0,+'Gnatt Chart'!$A$2,"") -> AvilaCRI | B18: 14 | C18: Power Wash | E18: Power wash exterior, House only | F18: 1 | G18: 590 | H18: 590 | J18: 1 | L18: 1
A19: =+IF(FromProposal[[#This Row],[Cost Code]]<>0,+'Gnatt Chart'!$A$2,"") -> AvilaCRI | B19: 15 | C19: Floor Coverings | D19: LVP | E19: Install LVP | F19: 1 | G19: 3790 | H19: 3790 | I19: Yes | J19: 1 | K19: 45226 | L19: 2
A20: =+IF(FromProposal[[#This Row],[Cost Code]]<>0,+'Gnatt Chart'!$A$2,"") -> AvilaCRI | B20: 16 | C20: Floor Coverings | E20: All of first floor including baths and laundry room in 2nd floor. Labor and shoe mold included. | J20: 1
A21: =+IF(FromProposal[[#This Row],[Cost Code]]<>0,+'Gnatt Chart'!$A$2,"") -> AvilaCRI | B21: 17 | C21: Floor Coverings | E21: Note- Client will purchase flooring materials. Estimated- 850 sqft, Please include 10% for waste | J21: 1
A22: =+IF(FromProposal[[#This Row],[Cost Code]]<>0,+'Gnatt Chart'!$A$2,"") -> AvilaCRI | B22: 18 | C22: Floor Coverings | D22: Carpet | E22: Install Carpet Estimated-884 sqft General Use Carpet and padding Labor | F22: 1 | G22: 1200 | H22: 1200 | I22: yes | J22: 1 | K22: 45225 | L22: 1
A23: =+IF(FromProposal[[#This Row],[Cost Code]]<>0,+'Gnatt Chart'!$A$2,"") -> AvilaCRI | B23: 19 | C23: Countertops | D23: Quartz | E23: Level 1 Quartz $3,190 | F23: 1 | G23: 3190 | H23: 3190 | I23: yes | J23: 1 | K23: 45219 | L23: 1 | N23: credit via CO#9
A24: =+IF(FromProposal[[#This Row],[Cost Code]]<>0,+'Gnatt Chart'!$A$2,"") -> AvilaCRI | B24: 20 | C24: Countertops | D24: Quartz | E24: Level 2 Quartz $3,850 | F24: 0 | J24: 1
A25: =+IF(FromProposal[[#This Row],[Cost Code]]<>0,+'Gnatt Chart'!$A$2,"") -> AvilaCRI | B25: 21 | C25: Countertops | D25: change order #9 | E25: Level 3 Granet $4,620 | F25: 1 | G25: 4345 | H25: 4345 | I25: yes | J25: 2 | K25: 45219
A26: =+IF(FromProposal[[#This Row],[Cost Code]]<>0,+'Gnatt Chart'!$A$2,"") -> AvilaCRI | B26: 22 | C26: Installations | D26: Labor and supplies | E26: Installations | F26: 1 | G26: 4252.5 | H26: 4252.5 | I26: yes | J26: 1 | K26: 45229 | L26: 7
A27: =+IF(FromProposal[[#This Row],[Cost Code]]<>0,+'Gnatt Chart'!$A$2,"") -> AvilaCRI | B27: 23 | C27: Installations | D27: Labor and supplies | E27: 3-Toilets | F27: 1 | J27: 1 | K27: 45229
A28: =+IF(FromProposal[[#This Row],[Cost Code]]<>0,+'Gnatt Chart'!$A$2,"") -> AvilaCRI | B28: 24 | C28: Installations | D28: Labor and supplies | E28: 1-Kitchen Sink | F28: 1 | J28: 1 | K28: 45229
A29: =+IF(FromProposal[[#This Row],[Cost Code]]<>0,+'Gnatt Chart'!$A$2,"") -> AvilaCRI | B29: 25 | C29: Installations | D29: Labor and supplies | E29: 1-Shower doors | F29: 1 | J29: 1 | K29: 45229
A30: =+IF(FromProposal[[#This Row],[Cost Code]]<>0,+'Gnatt Chart'!$A$2,"") -> AvilaCRI | B30: 26 | C30: Installations | D30: Labor and supplies | E30: 2- Mirrors | F30: 1 | J30: 1 | K30: 45229
A31: =+IF(FromProposal[[#This Row],[Cost Code]]<>0,+'Gnatt Chart'!$A$2,"") -> AvilaCRI | B31: 27 | C31: Installations | D31: Labor and supplies | E31: 1- Stove, | F31: 1 | J31: 1 | K31: 45229
A32: =+IF(FromProposal[[#This Row],[Cost Code]]<>0,+'Gnatt Chart'!$A$2,"") -> AvilaCRI | B32: 28 | C32: Installations | D32: Labor and supplies | E32: DW, | F32: 1 | J32: 1 | K32: 45229
A33: =+IF(FromProposal[[#This Row],[Cost Code]]<>0,+'Gnatt Chart'!$A$2,"") -> AvilaCRI | B33: 29 | C33: Installations | D33: Labor and supplies | E33: Microwave | F33: 1 | J33: 1 | K33: 45229
A34: =+IF(FromProposal[[#This Row],[Cost Code]]<>0,+'Gnatt Chart'!$A$2,"") -> AvilaCRI | B34: 30 | C34: Installations | D34: Labor and supplies | E34: 2- TP Holders | F34: 1 | J34: 1 | K34: 45229
A35: =+IF(FromProposal[[#This Row],[Cost Code]]<>0,+'Gnatt Chart'!$A$2,"") -> AvilaCRI | B35: 31 | C35: Installations | D35: Labor and supplies | E35: 2- Ceiling Fans | F35: 1 | J35: 1 | K35: 45229
A36: =+IF(FromProposal[[#This Row],[Cost Code]]<>0,+'Gnatt Chart'!$A$2,"") -> AvilaCRI | B36: 32 | C36: Installations | D36: Labor and supplies | E36: 2- Kitchen light fixtures | F36: 1 | J36: 1 | K36: 45229
A37: =+IF(FromProposal[[#This Row],[Cost Code]]<>0,+'Gnatt Chart'!$A$2,"") -> AvilaCRI | B37: 33 | C37: Installations | D37: Labor and supplies | E37: 1- Pantry Light | F37: 1 | J37: 1 | K37: 45229
A38: =+IF(FromProposal[[#This Row],[Cost Code]]<>0,+'Gnatt Chart'!$A$2,"") -> AvilaCRI | B38: 34 | C38: Installations | D38: Labor and supplies | E38: 2- Shower heads | F38: 1 | J38: 1 | K38: 45229
A39: =+IF(FromProposal[[#This Row],[Cost Code]]<>0,+'Gnatt Chart'!$A$2,"") -> AvilaCRI | B39: 35 | C39: Installations | D39: Labor and supplies | E39: Drywall Repair in garage Labor and supplies included | F39: 1 | J39: 1 | K39: 45216 | L39: 1
A40: =+IF(FromProposal[[#This Row],[Cost Code]]<>0,+'Gnatt Chart'!$A$2,"") -> AvilaCRI | B40: 36 | C40: Installations | D40: change order #1 | E40: Fix Screens | F40: 1 | G40: 600 | H40: 600 | J40: 2
...

Sheet Gnatt Chart
J1: Expense | M1: Due | O1: ToDo
A2: AvilaCRI | C2: =Profit!E1& " Your Home" -> Buy Your Home | E2: Project Start Date: | F2: =+MIN(ProposalToGnatt[Start Date]) -> 45212 | H2: Company Paid Materials Total: | J2: =+SUM(H8:H22) -> 5405.5556 | M2: =+SUM(N8:N22)-SUM(M8:M22) -> -2293.24 | O2: =+SUM(H8:H22)-SUM(M8:M22) -> 1912.3156
H3: Contractors Total: | J3: =SUM(H24:H27) -> 0 | M3: =+J3-SUM(M24:M27) -> 0 | O3: =+SUM(H24:H27)-SUM(M24:M27) -> 0
A4: =+Profit!B2 -> 115 Rosebrooks Dr, Cary, NC 27513 | B4: =+Profit!B2 -> 115 Rosebrooks Dr, Cary, NC 27513 | E4: Milestone Marker: | G4: 1 | H4: =+A2 & "Total:" -> AvilaCRI Total: | J4: =SUM(ProposalToGnatt[Price]) -> 28751.74 | M4: {=+SUM(ProposalToGnatt[Due]-ProposalToGnatt[Paid])} -> -1.8189894e-12 | O4: =+SUM(ProposalToGnatt[Price])-SUM(ProposalToGnatt[Paid]) -> 1290
B5: Cells H5 through BK5 contain the day number of the month for the Month represented in the cell block above each date cell and are auto calculated. Do not modify these cells. Dates leading up to Today are shaded. | E5: Milestone Marker 2: | G5: 2 | H5: Grand Total | J5: =+SUM(J2:K4) -> 34157.296 | M5: =+SUM(M2:M4) -> -2293.24 | O5: =+SUM(O2:Q4) -> 3202.3156
E6: =Profit!E1&" Your Home Supplied Materials" -> Buy Your Home Supplied Materials
A7: Assigned | B7: Item # | C7: Cost Code | D7: Title | E7: Description | F7: Qty | G7: Unit Price | H7: Price | I7: Done | J7: Group Order | K7: Start Date | L7: Days | M7: Paid | N7: Due | O7: Notes | AO7: =IFERROR(IF(LEN(#REF!)=0,"",IF(AND(#REF!=#REF!,#REF!=1),Milestone_Marker_Old,"")),"")
A8: =Profit!$E$1&" Your Home" -> Buy Your Home | B8: 1 | E8: Cleanup (from Demo & Trash Haul Tab) | F8: 1 | G8: =+'Demo & Trash Haul'!G17 -> 1200 | H8: =+F8*G8 -> 1200 | I8: yes | M8: 800 | N8: =IF(I8="Yes",H8,0) -> 1200
A9: =Profit!$E$1&" Your Home" -> Buy Your Home | B9: =+B8+1 -> 2 | E9: Taxes - outside of closing (from Taxes tab) | F9: 1 | G9: =+Taxes!E19 -> 2559 | H9: =+F9*G9 -> 2559 | N9: =IF(I9="Yes",H9,0) -> 0
A10: =Profit!$E$1&" Your Home" -> Buy Your Home | B10: =+B8+1 -> 2 | E10: Appliances (from Appliances Tab) | F10: 1 | G10: =+Appliances!G20 -> 1646.5556 | H10: =+F10*G10 -> 1646.5556 | N10: =IF(I10="Yes",H10,0) -> 0
A11: =Profit!$E$1&" Your Home" -> Buy Your Home | B11: =+B10+1 -> 3 | E11: Plubing Fixtures | F11: 1 | G11: =+'Plumbing Fixtures'!G22 -> 0 | H11: =+F11*G11 -> 0 | I11: yes | M11: 706.39 | N11: =IF(I11="Yes",H11,0) -> 0
A12: =Profit!$E$1&" Your Home" -> Buy Your Home | B12: =+B11+1 -> 4 | E12: Windows & Doors | F12: 0 | G12: =+'Windows & Doors'!F34 -> 0 | H12: =+F12*G12 -> 0 | N12: =IF(I12="Yes",H12,0) -> 0
A13: =Profit!$E$1&" Your Home" -> Buy Your Home | B13: =+B12+1 -> 5 | E13: Cabinets (from Cabinets Tab) | F13: 0 | G13: =+Cabinets!H44 -> 0 | H13: =+F13*G13 -> 0 | N13: =IF(I13="Yes",H13,0) -> 0
A14: =Profit!$E$1&" Your Home" -> Buy Your Home | B14: =+B13+1 -> 6 | E14: Paint (from Paint Tab) | F14: 1 | G14: =+Paint!I31 -> 0 | H14: =+F14*G14 -> 0 | I14: yes | M14: 1519.41 | N14: =IF(I14="Yes",H14,0) -> 0
A15: =Profit!$E$1&" Your Home" -> Buy Your Home | B15: =+B14+1 -> 7 | E15: Flooring | F15: 1 | G15: =+Flooring!G10 -> 0 | H15: =+F15*G15 -> 0 | N15: =IF(I15="Yes",H15,0) -> 0 | AP15: =IFERROR(IF(LEN(#REF!)=0,"",IF(P$29=#REF!,Milestone_Marker_Old,"")),"") | AQ15: =IFERROR(IF(LEN(#REF!)=0,"",IF(Q$29=#REF!,Milestone_Marker_Old,"")),"") | AR15: =IFERROR(IF(LEN(#REF!)=0,"",IF(R$29=#REF!,Milestone_Marker_Old,"")),"") | AS15: =IFERROR(IF(LEN(#REF!)=0,"",IF(S$29=#REF!,Milestone_Marker_Old,"")),"") | AT15: =IFERROR(IF(LEN(#REF!)=0,"",IF(T$29=#REF!,Milestone_Marker_Old,"")),"") | AU15: =IFERROR(IF(LEN(#REF!)=0,"",IF(U$29=#REF!,Milestone_Marker_Old,"")),"") | AV15: =IFERROR(IF(LEN(#REF!)=0,"",IF(V$29=#REF!,Milestone_Marker_Old,"")),"") | AW15: =IFERROR(IF(LEN(#REF!)=0,"",IF(W$29=#REF!,Milestone_Marker_Old,"")),"") | ... DU15: =IFERROR(IF(LEN(#REF!)=0,"",IF(CU$29=#REF!,Milestone_Marker_Old,"")),"")
A16: =Profit!$E$1&" Your Home" -> Buy Your Home | B16: =+B15+1 -> 8 | E16: Electrical fixtures (from Misc Tab) | F16: 1 | G16: =+'Electrical Fixtures'!F28 -> 0 | H16: =+F16*G16 -> 0 | I16: yes | M16: 417.69 | N16: =IF(I16="Yes",H16,0) -> 0 | AP16: =IFERROR(IF(LEN(#REF!)=0,"",IF(P$29=#REF!,Milestone_Marker_Old,"")),"") | AQ16: =IFERROR(IF(LEN(#REF!)=0,"",IF(Q$29=#REF!,Milestone_Marker_Old,"")),"") | AR16: =IFERROR(IF(LEN(#REF!)=0,"",IF(R$29=#REF!,Milestone_Marker_Old,"")),"") | AS16: =IFERROR(IF(LEN(#REF!)=0,"",IF(S$29=#REF!,Milestone_Marker_Old,"")),"") | AT16: =IFERROR(IF(LEN(#REF!)=0,"",IF(T$29=#REF!,Milestone_Marker_Old,"")),"") | AU16: =IFERROR(IF(LEN(#REF!)=0,"",IF(U$29=#REF!,Milestone_Marker_Old,"")),"") | AV16: =IFERROR(IF(LEN(#REF!)=0,"",IF(V$29=#REF!,Milestone_Marker_Old,"")),"") | AW16: =IFERROR(IF(LEN(#REF!)=0,"",IF(W$29=#REF!,Milestone_Marker_Old,"")),"") | ... DU16: =IFERROR(IF(LEN(#REF!)=0,"",IF(CU$29=#REF!,Milestone_Marker_Old,"")),"")
A17: =Profit!$E$1&" Your Home" -> Buy Your Home | B17: =+B16+1 -> 9 | E17: Exterior Tab | F17: 1 | G17: =+Exterior!H19 -> 0 | H17: =+F17*G17 -> 0 | I17: yes | M17: 49.75 | N17: =IF(I17="Yes",H17,0) -> 0
A18: =Profit!$E$1&" Your Home" -> Buy Your Home | B18: =+B17+1 -> 10 | E18: Landscaping Tab | F18: 1 | G18: =+Landscape!G17 -> 0 | H18: =+F18*G18 -> 0 | N18: =IF(I18="Yes",H18,0) -> 0
A19: =Profit!$E$1&" Your Home" -> Buy Your Home | B19: =+B18+1 -> 11 | E19: HVAC Contractor | F19: 0 | G19: =+'Demo & Trash Haul'!F29 -> 0 | H19: =+F19*G19 -> 0 | N19: =IF(I19="Yes",H19,0) -> 0 | AP19: =IFERROR(IF(LEN(#REF!)=0,"",IF(P$29=#REF!,Milestone_Marker_Old,"")),"") | AQ19: =IFERROR(IF(LEN(#REF!)=0,"",IF(Q$29=#REF!,Milestone_Marker_Old,"")),"") | AR19: =IFERROR(IF(LEN(#REF!)=0,"",IF(R$29=#REF!,Milestone_Marker_Old,"")),"") | AS19: =IFERROR(IF(LEN(#REF!)=0,"",IF(S$29=#REF!,Milestone_Marker_Old,"")),"") | AT19: =IFERROR(IF(LEN(#REF!)=0,"",IF(T$29=#REF!,Milestone_Marker_Old,"")),"") | AU19: =IFERROR(IF(LEN(#REF!)=0,"",IF(U$29=#REF!,Milestone_Marker_Old,"")),"") | AV19: =IFERROR(IF(LEN(#REF!)=0,"",IF(V$29=#REF!,Milestone_Marker_Old,"")),"") | AW19: =IFERROR(IF(LEN(#REF!)=0,"",IF(W$29=#REF!,Milestone_Marker_Old,"")),"") | ... DU19: =IFERROR(IF(LEN(#REF!)=0,"",IF(CU$29=#REF!,Milestone_Marker_Old,"")),"")
A20: =Profit!$E$1&" Your Home" -> Buy Your Home | B20: =+B19+1 -> 12 | E20: Landscape | F20: 0 | G20: =+'Demo & Trash Haul'!F30 -> 0 | H20: =+F20*G20 -> 0 | N20: =IF(I20="Yes",H20,0) -> 0 | AP20: =IFERROR(IF(LEN(#REF!)=0,"",IF(P$29=#REF!,Milestone_Marker_Old,"")),"") | AQ20: =IFERROR(IF(LEN(#REF!)=0,"",IF(Q$29=#REF!,Milestone_Marker_Old,"")),"") | AR20: =IFERROR(IF(LEN(#REF!)=0,"",IF(R$29=#REF!,Milestone_Marker_Old,"")),"") | AS20: =IFERROR(IF(LEN(#REF!)=0,"",IF(S$29=#REF!,Milestone_Marker_Old,"")),"") | AT20: =IFERROR(IF(LEN(#REF!)=0,"",IF(T$29=#REF!,Milestone_Marker_Old,"")),"") | AU20: =IFERROR(IF(LEN(#REF!)=0,"",IF(U$29=#REF!,Milestone_Marker_Old,"")),"") | AV20: =IFERROR(IF(LEN(#REF!)=0,"",IF(V$29=#REF!,Milestone_Marker_Old,"")),"") | AW20: =IFERROR(IF(LEN(#REF!)=0,"",IF(W$29=#REF!,Milestone_Marker_Old,"")),"") | ... DU20: =IFERROR(IF(LEN(#REF!)=0,"",IF(CU$29=#REF!,Milestone_Marker_Old,"")),"")
A21: =Profit!$E$1&" Your Home" -> Buy Your Home | B21: =+B20+1 -> 13 | E21: Exterior- Termite | F21: 0 | G21: 0 | H21: =+F21*G21 -> 0 | N21: =IF(I21="Yes",H21,0) -> 0 | AP21: =IFERROR(IF(LEN(#REF!)=0,"",IF(P$29=#REF!,Milestone_Marker_Old,"")),"") | AQ21: =IFERROR(IF(LEN(#REF!)=0,"",IF(Q$29=#REF!,Milestone_Marker_Old,"")),"") | AR21: =IFERROR(IF(LEN(#REF!)=0,"",IF(R$29=#REF!,Milestone_Marker_Old,"")),"") | AS21: =IFERROR(IF(LEN(#REF!)=0,"",IF(S$29=#REF!,Milestone_Marker_Old,"")),"") | AT21: =IFERROR(IF(LEN(#REF!)=0,"",IF(T$29=#REF!,Milestone_Marker_Old,"")),"") | AU21: =IFERROR(IF(LEN(#REF!)=0,"",IF(U$29=#REF!,Milestone_Marker_Old,"")),"") | AV21: =IFERROR(IF(LEN(#REF!)=0,"",IF(V$29=#REF!,Milestone_Marker_Old,"")),"") | AW21: =IFERROR(IF(LEN(#REF!)=0,"",IF(W$29=#REF!,Milestone_Marker_Old,"")),"") | ... DU21: =IFERROR(IF(LEN(#REF!)=0,"",IF(CU$29=#REF!,Milestone_Marker_Old,"")),"")
A22: =Profit!$E$1&" Your Home" -> Buy Your Home | B22: =+B21+1 -> 14 | E22: Drainage | F22: 0 | G22: =+'Demo & Trash Haul'!F32 -> 0 | H22: =+F22*G22 -> 0 | N22: =IF(I22="Yes",H22,0) -> 0 | AP22: =IFERROR(IF(LEN(#REF!)=0,"",IF(P$29=#REF!,Milestone_Marker_Old,"")),"") | AQ22: =IFERROR(IF(LEN(#REF!)=0,"",IF(Q$29=#REF!,Milestone_Marker_Old,"")),"") | AR22: =IFERROR(IF(LEN(#REF!)=0,"",IF(R$29=#REF!,Milestone_Marker_Old,"")),"") | AS22: =IFERROR(IF(LEN(#REF!)=0,"",IF(S$29=#REF!,Milestone_Marker_Old,"")),"") | AT22: =IFERROR(IF(LEN(#REF!)=0,"",IF(T$29=#REF!,Milestone_Marker_Old,"")),"") | AU22: =IFERROR(IF(LEN(#REF!)=0,"",IF(U$29=#REF!,Milestone_Marker_Old,"")),"") | AV22: =IFERROR(IF(LEN(#REF!)=0,"",IF(V$29=#REF!,Milestone_Marker_Old,"")),"") | AW22: =IFERROR(IF(LEN(#REF!)=0,"",IF(W$29=#REF!,Milestone_Marker_Old,"")),"") | ... DU22: =IFERROR(IF(LEN(#REF!)=0,"",IF(CU$29=#REF!,Milestone_Marker_Old,"")),"")
E23: =Profit!E1&" Your Home's Paid Contractors" -> Buy Your Home's Paid Contractors | AP23: =IFERROR(IF(LEN(#REF!)=0,"",IF(P$29=#REF!,Milestone_Marker_Old,"")),"") | AQ23: =IFERROR(IF(LEN(#REF!)=0,"",IF(Q$29=#REF!,Milestone_Marker_Old,"")),"") | AR23: =IFERROR(IF(LEN(#REF!)=0,"",IF(R$29=#REF!,Milestone_Marker_Old,"")),"") | AS23: =IFERROR(IF(LEN(#REF!)=0,"",IF(S$29=#REF!,Milestone_Marker_Old,"")),"") | AT23: =IFERROR(IF(LEN(#REF!)=0,"",IF(T$29=#REF!,Milestone_Marker_Old,"")),"") | AU23: =IFERROR(IF(LEN(#REF!)=0,"",IF(U$29=#REF!,Milestone_Marker_Old,"")),"") | AV23: =IFERROR(IF(LEN(#REF!)=0,"",IF(V$29=#REF!,Milestone_Marker_Old,"")),"") | AW23: =IFERROR(IF(LEN(#REF!)=0,"",IF(W$29=#REF!,Milestone_Marker_Old,"")),"") | ... DU23: =IFERROR(IF(LEN(#REF!)=0,"",IF(CU$29=#REF!,Milestone_Marker_Old,"")),"")
A24: Mabrey Roofing | B24: =+B22+1 -> 15 | E24: Roof Contractor | F24: 1 | G24: 0 | H24: =+F24*G24 -> 0 | N24: =IF(I24="Yes",H24,0) -> 0 | AA24: Scrolling Increment: | AP24: =IFERROR(IF(LEN(#REF!)=0,"",IF(P$29=#REF!,Milestone_Marker_Old,"")),"") | AQ24: =IFERROR(IF(LEN(#REF!)=0,"",IF(Q$29=#REF!,Milestone_Marker_Old,"")),"") | AR24: =IFERROR(IF(LEN(#REF!)=0,"",IF(R$29=#REF!,Milestone_Marker_Old,"")),"") | AS24: =IFERROR(IF(LEN(#REF!)=0,"",IF(S$29=#REF!,Milestone_Marker_Old,"")),"") | AT24: =IFERROR(IF(LEN(#REF!)=0,"",IF(T$29=#REF!,Milestone_Marker_Old,"")),"") | AU24: =IFERROR(IF(LEN(#REF!)=0,"",IF(U$29=#REF!,Milestone_Marker_Old,"")),"") | AV24: =IFERROR(IF(LEN(#REF!)=0,"",IF(V$29=#REF!,Milestone_Marker_Old,"")),"") | AW24: =IFERROR(IF(LEN(#REF!)=0,"",IF(W$29=#REF!,Milestone_Marker_Old,"")),"") | ... DU24: =IFERROR(IF(LEN(#REF!)=0,"",IF(CU$29=#REF!,Milestone_Marker_Old,"")),"")
A25: Mabrey Roofing | B25: =+B24+1 -> 16 | E25: Roof Contractor | F25: 0 | G25: 400 | H25: =+F25*G25 -> 0 | N25: =IF(I25="Yes",H25,0) -> 0 | AP25: =IFERROR(IF(LEN(#REF!)=0,"",IF(P$29=#REF!,Milestone_Marker_Old,"")),"") | AQ25: =IFERROR(IF(LEN(#REF!)=0,"",IF(Q$29=#REF!,Milestone_Marker_Old,"")),"") | AR25: =IFERROR(IF(LEN(#REF!)=0,"",IF(R$29=#REF!,Milestone_Marker_Old,"")),"") | AS25: =IFERROR(IF(LEN(#REF!)=0,"",IF(S$29=#REF!,Milestone_Marker_Old,"")),"") | AT25: =IFERROR(IF(LEN(#REF!)=0,"",IF(T$29=#REF!,Milestone_Marker_Old,"")),"") | AU25: =IFERROR(IF(LEN(#REF!)=0,"",IF(U$29=#REF!,Milestone_Marker_Old,"")),"") | AV25: =IFERROR(IF(LEN(#REF!)=0,"",IF(V$29=#REF!,Milestone_Marker_Old,"")),"") | AW25: =IFERROR(IF(LEN(#REF!)=0,"",IF(W$29=#REF!,Milestone_Marker_Old,"")),"") | ... DU25: =IFERROR(IF(LEN(#REF!)=0,"",IF(CU$29=#REF!,Milestone_Marker_Old,"")),"")
A26: Love Services | B26: =+B25+1 -> 17 | E26: HVAC Contractor - Package Heat Pump | F26: 0 | G26: =+HVAC!F13 -> 0 | H26: =+F26*G26 -> 0 | N26: =IF(I26="Yes",H26,0) -> 0 | AB26: 0
A27: Love Services | B27: =+B26+1 -> 18 | E27: HVAC Contractor - Duct Work | F27: 0 | G27: 4598 | H27: =+F27*G27 -> 0 | N27: =IF(I27="Yes",H27,0) -> 0
