Workbook
Name AssumedOperatingExpenseRatio: 'Operating Expense Budget'!$B$5
Name CalculatedOperatingExpenseRatio: 'Operating Expense Budget'!$B$6
Name ClassACapital: Assumptions!$B$28
Name ClassAPreferredReturn: Assumptions!$B$29
Name ClassBCapital: Assumptions!$B$30
Name ClassBResidualShare: Assumptions!$B$32
Name ClassBReturnPriority: Assumptions!$B$31
Name CoLivingSuiteRent: Assumptions!$B$11
Name CoLivingSuites: Assumptions!$B$10
Name ExitCapRate: Assumptions!$B$24
Name LeaseUpOccupancy: Assumptions!$B$14
Name NOIGrowth: Assumptions!$B$16
Name OperatingExpenseRatio: Assumptions!$B$15
Name OtherMonthlyIncome: Assumptions!$B$12
Name PermanentLoanAmortizationYears: Assumptions!$B$23
Name PermanentLoanAmount: Assumptions!$B$21
Name PermanentLoanRate: Assumptions!$B$22
Name PremiumSuiteRent: Assumptions!$B$9
Name PremiumSuites: Assumptions!$B$8
Name ProjectDebtPayoffAtRefi: Assumptions!$B$20
Name SaleExitYear: Assumptions!$B$5
Name SelectedOperatingExpenseRatio: 'Operating Expense Budget'!$B$7
Name SellingCosts: Assumptions!$B$25
Name SponsorBasis: Assumptions!$B$34
Name SponsorResidualShare: Assumptions!$B$33
Name StabilizationRefiYear: Assumptions!$B$4
Name StabilizedEffectiveGrossIncome: 'Operating Expense Budget'!$B$10
Name StabilizedMonthlyGrossRent: Assumptions!$B$17
Name StabilizedOccupancy: Assumptions!$B$13
Name TotalAnnualOperatingExpenseBudget: 'Operating Expense Budget'!$B$36
Name UseCalculatedOperatingExpenseRatio: 'Operating Expense Budget'!$B$4

Sheet Assumptions
A1: 3325 Banks Rd - Investor Return Model | C1: Editable inputs are in column B. Outputs update through formulas.
A3: Project Timing
A4: Stabilization / Refinance Year | B4: 2 | C4: Year when refinance proceeds are modeled
A5: Sale / Exit Year | B5: 4 | C5: Model uses annual periods 0 through this year
A7: Rental Program
A8: First Floor Premium Suites | B8: 4 | C8: Private bed/bath/kitchenette suites
A9: Monthly Rent per Premium Suite | B9: 1600 | C9: Editable rent assumption
A10: Second Floor Co-Living Suites | B10: 4 | C10: Private bed/bath with shared amenities
A11: Monthly Rent per Co-Living Suite | B11: 1100 | C11: Editable rent assumption
A12: Other Monthly Income | B12: 0 | C12: Parking, utility fees, laundry, etc.
A13: Stabilized Occupancy | B13: 0.93 | C13: Before operating expense load
A14: Year 1 Lease-Up Occupancy | B14: 0.5 | C14: First partial operating year
A15: Selected Operating Expense Ratio | B15: =SelectedOperatingExpenseRatio -> 0.77741272 | C15: From Operating Expense Budget tab; toggle between assumed ratio and calculated budget ratio
A16: NOI Growth | B16: 0.03 | C16: Annual growth after stabilization
A17: Stabilized Monthly Gross Rent | B17: =PremiumSuites*PremiumSuiteRent+CoLivingSuites*CoLivingSuiteRent+OtherMonthlyIncome -> 10800 | C17: Calculated
A19: Debt / Refinance / Exit
A20: Project Debt Payoff at Refi | B20: =MIN(INDEX('Annual Model'!$L$4:$L$14,MATCH(StabilizationRefiYear,'Annual Model'!$A$4:$A$14,0))*70%,ClassACapital+ClassBCapital) -> 276328.4 | C20: Construction/existing debt repaid from refinance
A21: Permanent Loan Amount | B21: 650000 | C21: New loan proceeds at refinance
A22: Permanent Loan Interest Rate | B22: 0.065 | C22: Annual fixed rate
A23: Permanent Loan Amortization Years | B23: 30 | C23: Used for annual debt service
A24: Exit Cap Rate | B24: 0.07 | C24: Sale value = following year NOI / cap rate
A25: Selling Costs | B25: 0.02 | C25: Percent deducted from gross sale value
A27: Capital Stack / Waterfall
A28: Class A Capital | B28: 300000 | C28: Preferred capital raise
A29: Class A Preferred Return | B29: 0.08 | C29: Cumulative annual preferred return
A30: Class B Capital | B30: =MAX(0,'Cost Analysis'!$C$17-ClassACapital) -> 1200000 | C30: Subordinate beneficiary capital; edit as needed
A31: Class B Capital Return Priority | B31: 1 | C31: 1 = return Class B capital before residual split
A32: Class B Residual Share | B32: 0.4 | C32: Residual cash flow / sale proceeds after priority payments
A33: Sponsor Residual Share | B33: =1-ClassBResidualShare -> 0.6 | C33: Default aligns with ~60% sponsor residual participation
A34: Sponsor Basis / Deemed Investment | B34: 150000 | C34: Land/control/origination value used for sponsor ROI
A36: Model Note | B36: This is a planning model, not tax, legal, securities, or investment advice.

Sheet Annual Model
A1: Annual Project Model
A3: Year | B3: Phase | C3: Gross Potential Rent | D3: Effective Gross Income | E3: Operating Expenses | F3: NOI | G3: Debt Service | H3: Cash Before Refi/Sale | I3: Net Refi/Sale Proceeds | J3: Total Cash Available | K3: Loan Balance | L3: Property Value / Refi Value
A4: 0 | B4: Capitalization / Entitlement | C4: =IF(A4=0,0,StabilizedMonthlyGrossRent*12*(1+NOIGrowth)^MAX(0,A4-StabilizationRefiYear)) -> 0 | D4: =IF(A4=0,0,C4*IF(A4=1,LeaseUpOccupancy,StabilizedOccupancy)) -> 0 | E4: =D4*OperatingExpenseRatio -> 0 | F4: =D4-E4 -> 0 | G4: =IF(AND(A4>=StabilizationRefiYear,A4<=SaleExitYear),-PMT(PermanentLoanRate/12,PermanentLoanAmortizationYears*12,PermanentLoanAmount)*12,0) -> 0 | H4: =F4-G4 -> 0 | I4: =IF(A4=StabilizationRefiYear,MAX(0,PermanentLoanAmount-ProjectDebtPayoffAtRefi),IF(A4=SaleExitYear,MAX(0,L4*(1-SellingCosts)-K4),0)) -> 0 | J4: =H4+I4 -> 0 | K4: =IF(A4<StabilizationRefiYear,0,IF(A4=SaleExitYear,0,-FV(PermanentLoanRate/12,(A4-StabilizationRefiYear)*12,PMT(PermanentLoanRate/12,PermanentLoanAmortizationYears*12,PermanentLoanAmount),PermanentLoanAmount))) -> 0 | L4: =IF(A4<StabilizationRefiYear,0,F4*(1+NOIGrowth)/ExitCapRate) -> 0
A5: 1 | B5: Lease-Up | C5: =IF(A5=0,0,StabilizedMonthlyGrossRent*12*(1+NOIGrowth)^MAX(0,A5-StabilizationRefiYear)) -> 129600 | D5: =IF(A5=0,0,C5*IF(A5=1,LeaseUpOccupancy,StabilizedOccupancy)) -> 64800 | E5: =D5*OperatingExpenseRatio -> 50376.344 | F5: =D5-E5 -> 14423.656 | G5: =IF(AND(A5>=StabilizationRefiYear,A5<=SaleExitYear),-PMT(PermanentLoanRate/12,PermanentLoanAmortizationYears*12,PermanentLoanAmount)*12,0) -> 0 | H5: =F5-G5 -> 14423.656 | I5: =IF(A5=StabilizationRefiYear,MAX(0,PermanentLoanAmount-ProjectDebtPayoffAtRefi),IF(A5=SaleExitYear,MAX(0,L5*(1-SellingCosts)-K5),0)) -> 0 | J5: =H5+I5 -> 14423.656 | K5: =IF(A5<StabilizationRefiYear,0,IF(A5=SaleExitYear,0,-FV(PermanentLoanRate/12,(A5-StabilizationRefiYear)*12,PMT(PermanentLoanRate/12,PermanentLoanAmortizationYears*12,PermanentLoanAmount),PermanentLoanAmount))) -> 0 | L5: =IF(A5<StabilizationRefiYear,0,F5*(1+NOIGrowth)/ExitCapRate) -> 0
A6: 2 | B6: Stabilization / Refi | C6: =IF(A6=0,0,StabilizedMonthlyGrossRent*12*(1+NOIGrowth)^MAX(0,A6-StabilizationRefiYear)) -> 129600 | D6: =IF(A6=0,0,C6*IF(A6=1,LeaseUpOccupancy,StabilizedOccupancy)) -> 120528 | E6: =D6*OperatingExpenseRatio -> 93700 | F6: =D6-E6 -> 26828 | G6: =IF(AND(A6>=StabilizationRefiYear,A6<=SaleExitYear),-PMT(PermanentLoanRate/12,PermanentLoanAmortizationYears*12,PermanentLoanAmount)*12,0) -> 49301.306 | H6: =F6-G6 -> -22473.306 | I6: =IF(A6=StabilizationRefiYear,MAX(0,PermanentLoanAmount-ProjectDebtPayoffAtRefi),IF(A6=SaleExitYear,MAX(0,L6*(1-SellingCosts)-K6),0)) -> 373671.6 | J6: =H6+I6 -> 351198.29 | K6: =IF(A6<StabilizationRefiYear,0,IF(A6=SaleExitYear,0,-FV(PermanentLoanRate/12,(A6-StabilizationRefiYear)*12,PMT(PermanentLoanRate/12,PermanentLoanAmortizationYears*12,PermanentLoanAmount),PermanentLoanAmount))) -> 650000 | L6: =IF(A6<StabilizationRefiYear,0,F6*(1+NOIGrowth)/ExitCapRate) -> 394754.86
A7: 3 | B7: Operations | C7: =IF(A7=0,0,StabilizedMonthlyGrossRent*12*(1+NOIGrowth)^MAX(0,A7-StabilizationRefiYear)) -> 133488 | D7: =IF(A7=0,0,C7*IF(A7=1,LeaseUpOccupancy,StabilizedOccupancy)) -> 124143.84 | E7: =D7*OperatingExpenseRatio -> 96511 | F7: =D7-E7 -> 27632.84 | G7: =IF(AND(A7>=StabilizationRefiYear,A7<=SaleExitYear),-PMT(PermanentLoanRate/12,PermanentLoanAmortizationYears*12,PermanentLoanAmount)*12,0) -> 49301.306 | H7: =F7-G7 -> -21668.466 | I7: =IF(A7=StabilizationRefiYear,MAX(0,PermanentLoanAmount-ProjectDebtPayoffAtRefi),IF(A7=SaleExitYear,MAX(0,L7*(1-SellingCosts)-K7),0)) -> 0 | J7: =H7+I7 -> -21668.466 | K7: =IF(A7<StabilizationRefiYear,0,IF(A7=SaleExitYear,0,-FV(PermanentLoanRate/12,(A7-StabilizationRefiYear)*12,PMT(PermanentLoanRate/12,PermanentLoanAmortizationYears*12,PermanentLoanAmount),PermanentLoanAmount))) -> 642734.78 | L7: =IF(A7<StabilizationRefiYear,0,F7*(1+NOIGrowth)/ExitCapRate) -> 406597.5
A8: 4 | B8: Operations | C8: =IF(A8=0,0,StabilizedMonthlyGrossRent*12*(1+NOIGrowth)^MAX(0,A8-StabilizationRefiYear)) -> 137492.64 | D8: =IF(A8=0,0,C8*IF(A8=1,LeaseUpOccupancy,StabilizedOccupancy)) -> 127868.16 | E8: =D8*OperatingExpenseRatio -> 99406.33 | F8: =D8-E8 -> 28461.825 | G8: =IF(AND(A8>=StabilizationRefiYear,A8<=SaleExitYear),-PMT(PermanentLoanRate/12,PermanentLoanAmortizationYears*12,PermanentLoanAmount)*12,0) -> 49301.306 | H8: =F8-G8 -> -20839.481 | I8: =IF(A8=StabilizationRefiYear,MAX(0,PermanentLoanAmount-ProjectDebtPayoffAtRefi),IF(A8=SaleExitYear,MAX(0,L8*(1-SellingCosts)-K8),0)) -> 410419.52 | J8: =H8+I8 -> 389580.04 | K8: =IF(A8<StabilizationRefiYear,0,IF(A8=SaleExitYear,0,-FV(PermanentLoanRate/12,(A8-StabilizationRefiYear)*12,PMT(PermanentLoanRate/12,PermanentLoanAmortizationYears*12,PermanentLoanAmount),PermanentLoanAmount))) -> 0 | L8: =IF(A8<StabilizationRefiYear,0,F8*(1+NOIGrowth)/ExitCapRate) -> 418795.43
A9: 5 | B9: Operations | C9: =IF(A9=0,0,StabilizedMonthlyGrossRent*12*(1+NOIGrowth)^MAX(0,A9-StabilizationRefiYear)) -> 141617.42 | D9: =IF(A9=0,0,C9*IF(A9=1,LeaseUpOccupancy,StabilizedOccupancy)) -> 131704.2 | E9: =D9*OperatingExpenseRatio -> 102388.52 | F9: =D9-E9 -> 29315.68 | G9: =IF(AND(A9>=StabilizationRefiYear,A9<=SaleExitYear),-PMT(PermanentLoanRate/12,PermanentLoanAmortizationYears*12,PermanentLoanAmount)*12,0) -> 0 | H9: =F9-G9 -> 29315.68 | I9: =IF(A9=StabilizationRefiYear,MAX(0,PermanentLoanAmount-ProjectDebtPayoffAtRefi),IF(A9=SaleExitYear,MAX(0,L9*(1-SellingCosts)-K9),0)) -> 0 | J9: =H9+I9 -> 29315.68 | K9: =IF(A9<StabilizationRefiYear,0,IF(A9=SaleExitYear,0,-FV(PermanentLoanRate/12,(A9-StabilizationRefiYear)*12,PMT(PermanentLoanRate/12,PermanentLoanAmortizationYears*12,PermanentLoanAmount),PermanentLoanAmount))) -> 626712.07 | L9: =IF(A9<StabilizationRefiYear,0,F9*(1+NOIGrowth)/ExitCapRate) -> 431359.29
A10: 6 | B10: Operations | C10: =IF(A10=0,0,StabilizedMonthlyGrossRent*12*(1+NOIGrowth)^MAX(0,A10-StabilizationRefiYear)) -> 145865.94 | D10: =IF(A10=0,0,C10*IF(A10=1,LeaseUpOccupancy,StabilizedOccupancy)) -> 135655.33 | E10: =D10*OperatingExpenseRatio -> 105460.18 | F10: =D10-E10 -> 30195.15 | G10: =IF(AND(A10>=StabilizationRefiYear,A10<=SaleExitYear),-PMT(PermanentLoanRate/12,PermanentLoanAmortizationYears*12,PermanentLoanAmount)*12,0) -> 0 | H10: =F10-G10 -> 30195.15 | I10: =IF(A10=StabilizationRefiYear,MAX(0,PermanentLoanAmount-ProjectDebtPayoffAtRefi),IF(A10=SaleExitYear,MAX(0,L10*(1-SellingCosts)-K10),0)) -> 0 | J10: =H10+I10 -> 30195.15 | K10: =IF(A10<StabilizationRefiYear,0,IF(A10=SaleExitYear,0,-FV(PermanentLoanRate/12,(A10-StabilizationRefiYear)*12,PMT(PermanentLoanRate/12,PermanentLoanAmortizationYears*12,PermanentLoanAmount),PermanentLoanAmount))) -> 617887.22 | L10: =IF(A10<StabilizationRefiYear,0,F10*(1+NOIGrowth)/ExitCapRate) -> 444300.07
A11: 7 | B11: Operations | C11: =IF(A11=0,0,StabilizedMonthlyGrossRent*12*(1+NOIGrowth)^MAX(0,A11-StabilizationRefiYear)) -> 150241.92 | D11: =IF(A11=0,0,C11*IF(A11=1,LeaseUpOccupancy,StabilizedOccupancy)) -> 139724.99 | E11: =D11*OperatingExpenseRatio -> 108623.98 | F11: =D11-E11 -> 31101.005 | G11: =IF(AND(A11>=StabilizationRefiYear,A11<=SaleExitYear),-PMT(PermanentLoanRate/12,PermanentLoanAmortizationYears*12,PermanentLoanAmount)*12,0) -> 0 | H11: =F11-G11 -> 31101.005 | I11: =IF(A11=StabilizationRefiYear,MAX(0,PermanentLoanAmount-ProjectDebtPayoffAtRefi),IF(A11=SaleExitYear,MAX(0,L11*(1-SellingCosts)-K11),0)) -> 0 | J11: =H11+I11 -> 31101.005 | K11: =IF(A11<StabilizationRefiYear,0,IF(A11=SaleExitYear,0,-FV(PermanentLoanRate/12,(A11-StabilizationRefiYear)*12,PMT(PermanentLoanRate/12,PermanentLoanAmortizationYears*12,PermanentLoanAmount),PermanentLoanAmount))) -> 608471.35 | L11: =IF(A11<StabilizationRefiYear,0,F11*(1+NOIGrowth)/ExitCapRate) -> 457629.07
A12: 8 | B12: Operations | C12: =IF(A12=0,0,StabilizedMonthlyGrossRent*12*(1+NOIGrowth)^MAX(0,A12-StabilizationRefiYear)) -> 154749.18 | D12: =IF(A12=0,0,C12*IF(A12=1,LeaseUpOccupancy,StabilizedOccupancy)) -> 143916.74 | E12: =D12*OperatingExpenseRatio -> 111882.7 | F12: =D12-E12 -> 32034.035 | G12: =IF(AND(A12>=StabilizationRefiYear,A12<=SaleExitYear),-PMT(PermanentLoanRate/12,PermanentLoanAmortizationYears*12,PermanentLoanAmount)*12,0) -> 0 | H12: =F12-G12 -> 32034.035 | I12: =IF(A12=StabilizationRefiYear,MAX(0,PermanentLoanAmount-ProjectDebtPayoffAtRefi),IF(A12=SaleExitYear,MAX(0,L12*(1-SellingCosts)-K12),0)) -> 0 | J12: =H12+I12 -> 32034.035 | K12: =IF(A12<StabilizationRefiYear,0,IF(A12=SaleExitYear,0,-FV(PermanentLoanRate/12,(A12-StabilizationRefiYear)*12,PMT(PermanentLoanRate/12,PermanentLoanAmortizationYears*12,PermanentLoanAmount),PermanentLoanAmount))) -> 598424.89 | L12: =IF(A12<StabilizationRefiYear,0,F12*(1+NOIGrowth)/ExitCapRate) -> 471357.94
A13: 9 | B13: Operations | C13: =IF(A13=0,0,StabilizedMonthlyGrossRent*12*(1+NOIGrowth)^MAX(0,A13-StabilizationRefiYear)) -> 159391.65 | D13: =IF(A13=0,0,C13*IF(A13=1,LeaseUpOccupancy,StabilizedOccupancy)) -> 148234.24 | E13: =D13*OperatingExpenseRatio -> 115239.18 | F13: =D13-E13 -> 32995.056 | G13: =IF(AND(A13>=StabilizationRefiYear,A13<=SaleExitYear),-PMT(PermanentLoanRate/12,PermanentLoanAmortizationYears*12,PermanentLoanAmount)*12,0) -> 0 | H13: =F13-G13 -> 32995.056 | I13: =IF(A13=StabilizationRefiYear,MAX(0,PermanentLoanAmount-ProjectDebtPayoffAtRefi),IF(A13=SaleExitYear,MAX(0,L13*(1-SellingCosts)-K13),0)) -> 0 | J13: =H13+I13 -> 32995.056 | K13: =IF(A13<StabilizationRefiYear,0,IF(A13=SaleExitYear,0,-FV(PermanentLoanRate/12,(A13-StabilizationRefiYear)*12,PMT(PermanentLoanRate/12,PermanentLoanAmortizationYears*12,PermanentLoanAmount),PermanentLoanAmount))) -> 587705.59 | L13: =IF(A13<StabilizationRefiYear,0,F13*(1+NOIGrowth)/ExitCapRate) -> 485498.68
A14: 10 | B14: Exit | C14: =IF(A14=0,0,StabilizedMonthlyGrossRent*12*(1+NOIGrowth)^MAX(0,A14-StabilizationRefiYear)) -> 164173.4 | D14: =IF(A14=0,0,C14*IF(A14=1,LeaseUpOccupancy,StabilizedOccupancy)) -> 152681.26 | E14: =D14*OperatingExpenseRatio -> 118696.36 | F14: =D14-E14 -> 33984.908 | G14: =IF(AND(A14>=StabilizationRefiYear,A14<=SaleExitYear),-PMT(PermanentLoanRate/12,PermanentLoanAmortizationYears*12,PermanentLoanAmount)*12,0) -> 0 | H14: =F14-G14 -> 33984.908 | I14: =IF(A14=StabilizationRefiYear,MAX(0,PermanentLoanAmount-ProjectDebtPayoffAtRefi),IF(A14=SaleExitYear,MAX(0,L14*(1-SellingCosts)-K14),0)) -> 0 | J14: =H14+I14 -> 33984.908 | K14: =IF(A14<StabilizationRefiYear,0,IF(A14=SaleExitYear,0,-FV(PermanentLoanRate/12,(A14-StabilizationRefiYear)*12,PMT(PermanentLoanRate/12,PermanentLoanAmortizationYears*12,PermanentLoanAmount),PermanentLoanAmount))) -> 576268.4 | L14: =IF(A14<StabilizationRefiYear,0,F14*(1+NOIGrowth)/ExitCapRate) -> 500063.64

Sheet Waterfall
A1: Annual Waterfall
A3: Year | B3: Cash Available | C3: Class A Beg. Accrued Pref | D3: Class A Pref Accrued | E3: Class A Pref Paid | F3: Class A Beg. Capital | G3: Class A Capital Returned | H3: Class A End Accrued Pref | I3: Class A End Capital | J3: Cash After Class A | K3: Class B Beg. Capital | L3: Class B Capital Returned | M3: Class B End Capital | N3: Residual to Class B | O3: Residual to Sponsor | P3: Total Class A Dist. | Q3: Total Class B Dist. | R3: Total Sponsor Dist.
A4: 0 | B4: ='Annual Model'!J4 -> 0 | C4: =0 -> 0 | D4: =F4*ClassAPreferredReturn -> 24000 | E4: =MIN(B4,C4+D4) -> 0 | F4: =ClassACapital -> 300000 | G4: =MIN(MAX(0,B4-E4),F4) -> 0 | H4: =C4+D4-E4 -> 24000 | I4: =F4-G4 -> 300000 | J4: =MAX(0,B4-E4-G4) -> 0 | K4: =ClassBCapital -> 1200000 | L4: =IF(ClassBReturnPriority=1,MIN(J4,K4),0) -> 0 | M4: =K4-L4 -> 1200000 | N4: =MAX(0,J4-L4)*ClassBResidualShare -> 0 | O4: =MAX(0,J4-L4)*SponsorResidualShare -> 0 | P4: =E4+G4 -> 0 | Q4: =L4+N4 -> 0 | R4: =O4 -> 0
A5: 1 | B5: ='Annual Model'!J5 -> 14423.656 | C5: =H4 -> 24000 | D5: =F5*ClassAPreferredReturn -> 24000 | E5: =MIN(B5,C5+D5) -> 14423.656 | F5: =I4 -> 300000 | G5: =MIN(MAX(0,B5-E5),F5) -> 0 | H5: =C5+D5-E5 -> 33576.344 | I5: =F5-G5 -> 300000 | J5: =MAX(0,B5-E5-G5) -> 0 | K5: =M4 -> 1200000 | L5: =IF(ClassBReturnPriority=1,MIN(J5,K5),0) -> 0 | M5: =K5-L5 -> 1200000 | N5: =MAX(0,J5-L5)*ClassBResidualShare -> 0 | O5: =MAX(0,J5-L5)*SponsorResidualShare -> 0 | P5: =E5+G5 -> 14423.656 | Q5: =L5+N5 -> 0 | R5: =O5 -> 0
A6: 2 | B6: ='Annual Model'!J6 -> 351198.29 | C6: =H5 -> 33576.344 | D6: =F6*ClassAPreferredReturn -> 24000 | E6: =MIN(B6,C6+D6) -> 57576.344 | F6: =I5 -> 300000 | G6: =MIN(MAX(0,B6-E6),F6) -> 293621.95 | H6: =C6+D6-E6 -> 0 | I6: =F6-G6 -> 6378.0499 | J6: =MAX(0,B6-E6-G6) -> 0 | K6: =M5 -> 1200000 | L6: =IF(ClassBReturnPriority=1,MIN(J6,K6),0) -> 0 | M6: =K6-L6 -> 1200000 | N6: =MAX(0,J6-L6)*ClassBResidualShare -> 0 | O6: =MAX(0,J6-L6)*SponsorResidualShare -> 0 | P6: =E6+G6 -> 351198.29 | Q6: =L6+N6 -> 0 | R6: =O6 -> 0
A7: 3 | B7: ='Annual Model'!J7 -> -21668.466 | C7: =H6 -> 0 | D7: =F7*ClassAPreferredReturn -> 510.24399 | E7: =MIN(B7,C7+D7) -> -21668.466 | F7: =I6 -> 6378.0499 | G7: =MIN(MAX(0,B7-E7),F7) -> 0 | H7: =C7+D7-E7 -> 22178.71 | I7: =F7-G7 -> 6378.0499 | J7: =MAX(0,B7-E7-G7) -> 0 | K7: =M6 -> 1200000 | L7: =IF(ClassBReturnPriority=1,MIN(J7,K7),0) -> 0 | M7: =K7-L7 -> 1200000 | N7: =MAX(0,J7-L7)*ClassBResidualShare -> 0 | O7: =MAX(0,J7-L7)*SponsorResidualShare -> 0 | P7: =E7+G7 -> -21668.466 | Q7: =L7+N7 -> 0 | R7: =O7 -> 0
A8: 4 | B8: ='Annual Model'!J8 -> 389580.04 | C8: =H7 -> 22178.71 | D8: =F8*ClassAPreferredReturn -> 510.24399 | E8: =MIN(B8,C8+D8) -> 22688.954 | F8: =I7 -> 6378.0499 | G8: =MIN(MAX(0,B8-E8),F8) -> 6378.0499 | H8: =C8+D8-E8 -> 0 | I8: =F8-G8 -> 0 | J8: =MAX(0,B8-E8-G8) -> 360513.04 | K8: =M7 -> 1200000 | L8: =IF(ClassBReturnPriority=1,MIN(J8,K8),0) -> 360513.04 | M8: =K8-L8 -> 839486.96 | N8: =MAX(0,J8-L8)*ClassBResidualShare -> 0 | O8: =MAX(0,J8-L8)*SponsorResidualShare -> 0 | P8: =E8+G8 -> 29067.004 | Q8: =L8+N8 -> 360513.04 | R8: =O8 -> 0
A9: 5 | B9: ='Annual Model'!J9 -> 29315.68 | C9: =H8 -> 0 | D9: =F9*ClassAPreferredReturn -> 0 | E9: =MIN(B9,C9+D9) -> 0 | F9: =I8 -> 0 | G9: =MIN(MAX(0,B9-E9),F9) -> 0 | H9: =C9+D9-E9 -> 0 | I9: =F9-G9 -> 0 | J9: =MAX(0,B9-E9-G9) -> 29315.68 | K9: =M8 -> 839486.96 | L9: =IF(ClassBReturnPriority=1,MIN(J9,K9),0) -> 29315.68 | M9: =K9-L9 -> 810171.29 | N9: =MAX(0,J9-L9)*ClassBResidualShare -> 0 | O9: =MAX(0,J9-L9)*SponsorResidualShare -> 0 | P9: =E9+G9 -> 0 | Q9: =L9+N9 -> 29315.68 | R9: =O9 -> 0
A10: 6 | B10: ='Annual Model'!J10 -> 30195.15 | C10: =H9 -> 0 | D10: =F10*ClassAPreferredReturn -> 0 | E10: =MIN(B10,C10+D10) -> 0 | F10: =I9 -> 0 | G10: =MIN(MAX(0,B10-E10),F10) -> 0 | H10: =C10+D10-E10 -> 0 | I10: =F10-G10 -> 0 | J10: =MAX(0,B10-E10-G10) -> 30195.15 | K10: =M9 -> 810171.29 | L10: =IF(ClassBReturnPriority=1,MIN(J10,K10),0) -> 30195.15 | M10: =K10-L10 -> 779976.13 | N10: =MAX(0,J10-L10)*ClassBResidualShare -> 0 | O10: =MAX(0,J10-L10)*SponsorResidualShare -> 0 | P10: =E10+G10 -> 0 | Q10: =L10+N10 -> 30195.15 | R10: =O10 -> 0
A11: 7 | B11: ='Annual Model'!J11 -> 31101.005 | C11: =H10 -> 0 | D11: =F11*ClassAPreferredReturn -> 0 | E11: =MIN(B11,C11+D11) -> 0 | F11: =I10 -> 0 | G11: =MIN(MAX(0,B11-E11),F11) -> 0 | H11: =C11+D11-E11 -> 0 | I11: =F11-G11 -> 0 | J11: =MAX(0,B11-E11-G11) -> 31101.005 | K11: =M10 -> 779976.13 | L11: =IF(ClassBReturnPriority=1,MIN(J11,K11),0) -> 31101.005 | M11: =K11-L11 -> 748875.13 | N11: =MAX(0,J11-L11)*ClassBResidualShare -> 0 | O11: =MAX(0,J11-L11)*SponsorResidualShare -> 0 | P11: =E11+G11 -> 0 | Q11: =L11+N11 -> 31101.005 | R11: =O11 -> 0
A12: 8 | B12: ='Annual Model'!J12 -> 32034.035 | C12: =H11 -> 0 | D12: =F12*ClassAPreferredReturn -> 0 | E12: =MIN(B12,C12+D12) -> 0 | F12: =I11 -> 0 | G12: =MIN(MAX(0,B12-E12),F12) -> 0 | H12: =C12+D12-E12 -> 0 | I12: =F12-G12 -> 0 | J12: =MAX(0,B12-E12-G12) -> 32034.035 | K12: =M11 -> 748875.13 | L12: =IF(ClassBReturnPriority=1,MIN(J12,K12),0) -> 32034.035 | M12: =K12-L12 -> 716841.09 | N12: =MAX(0,J12-L12)*ClassBResidualShare -> 0 | O12: =MAX(0,J12-L12)*SponsorResidualShare -> 0 | P12: =E12+G12 -> 0 | Q12: =L12+N12 -> 32034.035 | R12: =O12 -> 0
A13: 9 | B13: ='Annual Model'!J13 -> 32995.056 | C13: =H12 -> 0 | D13: =F13*ClassAPreferredReturn -> 0 | E13: =MIN(B13,C13+D13) -> 0 | F13: =I12 -> 0 | G13: =MIN(MAX(0,B13-E13),F13) -> 0 | H13: =C13+D13-E13 -> 0 | I13: =F13-G13 -> 0 | J13: =MAX(0,B13-E13-G13) -> 32995.056 | K13: =M12 -> 716841.09 | L13: =IF(ClassBReturnPriority=1,MIN(J13,K13),0) -> 32995.056 | M13: =K13-L13 -> 683846.04 | N13: =MAX(0,J13-L13)*ClassBResidualShare -> 0 | O13: =MAX(0,J13-L13)*SponsorResidualShare -> 0 | P13: =E13+G13 -> 0 | Q13: =L13+N13 -> 32995.056 | R13: =O13 -> 0
A14: 10 | B14: ='Annual Model'!J14 -> 33984.908 | C14: =H13 -> 0 | D14: =F14*ClassAPreferredReturn -> 0 | E14: =MIN(B14,C14+D14) -> 0 | F14: =I13 -> 0 | G14: =MIN(MAX(0,B14-E14),F14) -> 0 | H14: =C14+D14-E14 -> 0 | I14: =F14-G14 -> 0 | J14: =MAX(0,B14-E14-G14) -> 33984.908 | K14: =M13 -> 683846.04 | L14: =IF(ClassBReturnPriority=1,MIN(J14,K14),0) -> 33984.908 | M14: =K14-L14 -> 649861.13 | N14: =MAX(0,J14-L14)*ClassBResidualShare -> 0 | O14: =MAX(0,J14-L14)*SponsorResidualShare -> 0 | P14: =E14+G14 -> 0 | Q14: =L14+N14 -> 33984.908 | R14: =O14 -> 0

Sheet Returns
A1: Investor / Sponsor Return Summary
A3: Participant | B3: Capital / Basis | C3: Total Distributions | D3: Net Profit | E3: Equity Multiple | F3: ROI % | G3: IRR | H3: Year 0 | I3: Year 1 | J3: Year 2 | K3: Year 3 | L3: Year 4 | M3: Year 5 | N3: Year 6 | O3: Year 7 | P3: Year 8 | Q3: Year 9 | R3: Year 10
A4: Class A | B4: =ClassACapital -> 300000 | C4: =SUM(Waterfall!P4:P14) -> 373020.49 | D4: =C4-B4 -> 73020.488 | E4: =C4/B4 -> 1.2434016 | F4: =D4/B4 -> 0.24340163 | G4: =IRR(H4:R4) -> 0.11243506 | H4: =-B4 -> -300000 | I4: =Waterfall!P5 -> 14423.656 | J4: =Waterfall!P6 -> 351198.29 | K4: =Waterfall!P7 -> -21668.466 | L4: =Waterfall!P8 -> 29067.004 | M4: =Waterfall!P9 -> 0 | N4: =Waterfall!P10 -> 0 | O4: =Waterfall!P11 -> 0 | P4: =Waterfall!P12 -> 0 | Q4: =Waterfall!P13 -> 0 | R4: =Waterfall!P14 -> 0
A5: Class B | B5: =ClassBCapital -> 1200000 | C5: =SUM(Waterfall!Q4:Q14) -> 550138.87 | D5: =C5-B5 -> -649861.13 | E5: =IFERROR(C5/B5,0) -> 0.45844906 | F5: =IFERROR(D5/B5,0) -> -0.54155094 | G5: =IFERROR(IRR(H5:R5),0) -> -0.13122126 | H5: =-B5 -> -1200000 | I5: =Waterfall!Q5 -> 0 | J5: =Waterfall!Q6 -> 0 | K5: =Waterfall!Q7 -> 0 | L5: =Waterfall!Q8 -> 360513.04 | M5: =Waterfall!Q9 -> 29315.68 | N5: =Waterfall!Q10 -> 30195.15 | O5: =Waterfall!Q11 -> 31101.005 | P5: =Waterfall!Q12 -> 32034.035 | Q5: =Waterfall!Q13 -> 32995.056 | R5: =Waterfall!Q14 -> 33984.908
A6: Sponsor | B6: =SponsorBasis -> 150000 | C6: =SUM(Waterfall!R4:R14) -> 0 | D6: =C6-B6 -> -150000 | E6: =IFERROR(C6/B6,0) -> 0 | F6: =IFERROR(D6/B6,0) -> -1 | G6: =IFERROR(IRR(H6:R6),0) -> 0 | H6: =-B6 -> -150000 | I6: =Waterfall!R5 -> 0 | J6: =Waterfall!R6 -> 0 | K6: =Waterfall!R7 -> 0 | L6: =Waterfall!R8 -> 0 | M6: =Waterfall!R9 -> 0 | N6: =Waterfall!R10 -> 0 | O6: =Waterfall!R11 -> 0 | P6: =Waterfall!R12 -> 0 | Q6: =Waterfall!R13 -> 0 | R6: =Waterfall!R14 -> 0
A9: Important | B9: Class A preferred return is modeled as cumulative simple annual accrual on unrecovered Class A capital. Class B capital is returned before residual splits when the Assumptions toggle is set to 1.

Sheet Notes
A1: Model Notes
A3: Purpose | B3: Calculates project-level cash available, then allocates distributions to Class A, Class B, and Sponsor through a simplified waterfall.
A4: Key editable cells | B4: Use the Assumptions tab, column B.
A5: Class A | B5: Modeled with 8% cumulative annual preferred return by default, then return of capital, then no residual share unless you revise the waterfall.
A6: Class B | B6: Modeled as subordinate capital that can receive capital back before residual distributions, plus residual participation.
A7: Sponsor | B7: Modeled using sponsor basis / deemed investment as the return denominator and sponsor residual share as the distribution source.
A8: Caution | B8: This workbook is for planning and discussion only. It is not legal, tax, securities, appraisal, or investment advice. Have counsel and CPA review before investor use.

Sheet Cost Analysis
A1: 3325 Banks Rd - Design, Development & Build Cost Analysis
A2: Status | B2: Planning estimate added 2026-05-11
A3: Source Markdown | B3: 04_Design_Development_and_Build_Cost_Analysis.md
A5: Workbook-Backed Capital Assumptions | B5: Amount | C5: Notes
A6: Project debt payoff at refinance | B6: =ProjectDebtPayoffAtRefi -> 276328.4 | C6: Existing assumption
A7: Permanent loan amount | B7: =PermanentLoanAmount -> 650000 | C7: Existing assumption
A8: Class A capital | B8: =ClassACapital -> 300000 | C8: Existing assumption
A9: Class B capital | B9: =ClassBCapital -> 1200000 | C9: Existing assumption
A10: Sponsor basis / deemed investment | B10: =SponsorBasis -> 150000 | C10: Existing assumption
A11: Total Class A + Class B capitalization | B11: =B8+B9 -> 1500000 | C11: Completion capital
A13: Project Cost Case Summary | B13: Low | C13: High
A14: Sponsor-Controlled Case (from controlling bridge below) | B14: =B32 -> 750000 | C14: =C32 -> 1500000
A15: Outside-Market Benchmark (from outside-market subtotals below) | B15: =B46+B55+B64 -> 1880000 | C15: =C46+C55+C64 -> 4160000
A16: Selected Underwriting Case For Capitalization | B16: Sponsor-Controlled | C16: Sponsor-Controlled
A17: Selected Total Project Cost | B17: =B14 -> 750000 | C17: =C14 -> 1500000
A19: Sponsor-Controlled Metrics | B19: Low Case | C19: High Case
A20: Total project cost - risk adjusted | B20: 750000 | C20: 1500000
A21: Cost per SF at 5,000 SF | B21: 150 | C21: 300
A22: Cost per SF at 6,000 SF | B22: 125 | C22: 250
A24: Controlling Sponsor-Controlled Line-Item Bridge | B24: Low | C24: High
A25: Design, entitlement, permits, and professional services | B25: 75000 | C25: 175000
A26: Development, financing, insurance, carrying, and administration | B26: 50000 | C26: 125000
A27: Post-frame building shell and interior buildout | B27: 390000 | C27: 610000
A28: Sitework, access, grading, drainage, and parking | B28: 55000 | C28: 110000
A29: Private utilities, well, wastewater, and related infrastructure | B29: 90000 | C29: 225000
A30: Furnishings, fixtures, equipment, and turnover | B30: 30000 | C30: 100000
A31: Contingency and owner reserve | B31: 60000 | C31: 155000
A32: Sponsor-Controlled Total Package | B32: =SUM(B25:B31) -> 750000 | C32: =SUM(C25:C31) -> 1500000
A33: Funding Gap Analysis | B33: Low | C33: High
A34: Estimated total project cost | B34: =B17 -> 750000 | C34: =C17 -> 1500000
A35: Class A + Class B capitalization | B35: =B11 -> 1500000 | C35: =B11 -> 1500000
A36: Potential unfunded development gap | B36: =MAX(0,B34-B35) -> 0 | C36: =MAX(0,C34-C35) -> 0
A38: Outside Market - Design & Entitlement Detail | B38: Low | C38: High
A39: Architecture and building design | B39: 35000 | C39: 90000
A40: Civil engineering and site planning | B40: 20000 | C40: 60000
A41: Septic, soil, and wastewater engineering | B41: 20000 | C41: 90000
A42: Survey, testing, environmental, and due diligence | B42: 10000 | C42: 30000
A43: Permitting, review, and municipal/county coordination | B43: 15000 | C43: 50000
A44: Legal, accounting, and trust structuring | B44: 15000 | C44: 40000
A45: Design/entitlement contingency | B45: 15000 | C45: 45000
...

Sheet Operating Expense Budget
A1: 3325 Banks Rd - Operating Expense Budget
A3: Toggle / Selection
A4: Use Calculated Budget Ratio? | B4: TRUE | C4: FALSE = use assumed ratio; TRUE = use calculated budget ratio
A5: Assumed Operating Expense Ratio | B5: 0.4 | C5: Current planning assumption reflected in Assumptions tab when toggle is FALSE
A6: Calculated Operating Expense Ratio | B6: =IFERROR(B36/B10,0) -> 0.77741272 | C6: Total annual operating expense budget / effective gross income
A7: Selected Operating Expense Ratio | B7: =IF(B4,B6,B5) -> 0.77741272 | C7: Feeds Assumptions!B15
A9: Revenue Basis
A10: Stabilized Effective Gross Income | B10: =StabilizedMonthlyGrossRent*12*StabilizedOccupancy -> 120528 | C10: Annual stabilized EGI after occupancy
A12: Expense Category | B12: Annual Amount | C12: Basis / Notes
A13: Property taxes | B13: 12000 | C13: Placeholder; replace with assessed value/tax estimate
A14: Property insurance | B14: 9000 | C14: Hazard/liability coverage estimate
A15: Property management / administration | B15: 7800 | C15: Approx. 6% of stabilized EGI
A16: Utilities - electric | B16: 7200 | C16: Owner-paid/common-area and vacancy exposure
A17: Utilities - water / well maintenance | B17: 1800 | C17: Well testing, maintenance, treatment allowance
A18: Utilities - internet | B18: 2400 | C18: Shared/furnished rental expectation
A19: Trash / recycling | B19: 1800 | C19: Recurring service
A20: Repairs and maintenance | B20: 9000 | C20: Routine R&M reserve
A21: Turnover, cleaning, and supplies | B21: 6000 | C21: Co-living/furnished turnover allowance
A22: Landscaping / grounds | B22: 3600 | C22: Mowing, upkeep, seasonal cleanup
A23: Pest control | B23: 1200 | C23: Recurring service
A24: Septic / wastewater maintenance | B24: 3000 | C24: Inspection, pump, service contracts
... A35: Miscellaneous / operating contingency | B35: 4000 | C35: Catch-all reserve
A36: Total Annual Operating Expense Budget | B36: =SUM(B13:B35) -> 93700 | C36: Calculated from line items
