Workbook

Sheet Cards
A1: Lender | B1: Entity ID | C1: Corp/ Pers | D1: Name | E1: Used By | F1: Paid By | G1: Last 4 | H1: Card Number | I1: Bal Xfer | J1: CVV Code | K1: Expire Date | L1: St Date | M1: Points | N1: Current Balance | O1: Credit Limit | P1: Available Credit | Q1: Free Interest | R1: Interest Rate | S1: PIN | T1: Monthly Payment | U1: Interest Paid | V1: 0.35 | W1: 0.5 | X1: paydown for 35% | Y1: paydown for 50% | Z1: Paydown | AA1: User | AB1: Password | AC1: URL
A2: First Bank | B2: 3 | C2: C | D2: Buy Your Home | E2: BYH | F2: Truist-BYH | G2: 3901 | H2: 3901, 5592 222 0652 7750 | J2: 633 | K2: 11324 | L2: 30 | N2: 11769 | O2: 25000 | P2: =+O2-N2 -> 13231 | R2: 0.199 | T2: 355 | V2: =+O2*0.35 -> 8750 | W2: =+O2*0.5 -> 12500 | X2: =+(N2-V2)*IF(C2="P",1,0) -> 0 | Y2: =+(N2-W2)*IF(C2="C",1,0) -> -731 | Z2: =+X2+Y2 -> -731 | AA2: WesWill@BuyYourHomeLLC.com | AB2: w3638B0@Wes | AC2: https://spendtrack.fiservapp.com/first-bank/signOut
A3: Fundbox | B3: 7 | C3: LoC | D3: Buy Your Home-LoC | E3: BYH | F3: Truist-BYH | G3: 7867 | N3: 10354.13 | O3: 39000 | P3: =+O3-N3 -> 28645.87 | R3: 0.195 | T3: =1725.67*4.33333333333333 -> 7477.9033 | U3: =IF(Q3="",+N3*R3/12,0) -> 168.25461 | V3: =+O3*0.35 -> 13650 | W3: =+O3*0.5 -> 19500 | X3: =+(N3-V3)*IF(C3="P",1,0) -> 0 | Y3: =+(N3-W3)*IF(C3="C",1,0) -> 0 | Z3: =+X3+Y3 -> 0 | AA3: HeritageManagement1 | AB3: w3638B0!Wesley | AC3: https://www.mycardstatement.com/
A4: Dogwood State Bank | B4: 7 | C4: C | D4: Heritage Mangement | E4: BYH | F4: Truist-BYH | G4: =RIGHT(H4,4) -> 0030 | H4: 40017942 3500 0030 | I4: Yes | J4: 664 | K4: 46813 | N4: =2730+5842 -> 8572 | O4: 12500 | P4: =+O4-N4 -> 3928 | Q4: 46096 | R4: 0 | T4: 178 | U4: =IF(Q4="",+N4*R4/12,0) -> 0 | V4: =+O4*0.35 -> 4375 | W4: =+O4*0.5 -> 6250 | X4: =+(N4-V4)*IF(C4="P",1,0) -> 0 | Y4: =+(N4-W4)*IF(C4="C",1,0) -> 2322 | Z4: =+X4+Y4 -> 2322 | AA4: HeritageManagement1 | AB4: w3638B0!Wesley | AC4: https://www.mycardstatement.com/
A5: Chase (new) | B5: 7 | C5: C | D5: Heritage Mangement | E5: HM | F5: Truist-BYH | G5: =RIGHT(H5,4) -> 0030 | H5: 0779,4246 3154 7243 0030 | I5: No | J5: 718 | K5: 11355 | L5: 15 | N5: 23286 | O5: 23000 | P5: =+O5-N5 -> -286 | R5: 0 | T5: 233 | U5: =IF(Q5="",+N5*R5/12,0) -> 0 | V5: =+O5*0.35 -> 8050 | W5: =+O5*0.5 -> 11500 | X5: =+(N5-V5)*IF(C5="P",1,0) -> 0 | Y5: =+(N5-W5)*IF(C5="C",1,0) -> 11786 | Z5: =+X5+Y5 -> 11786 | AA5: HeritageManagementLLC2 | AB5: w3638B0# | AC5: https://secure.chase.com/web/auth/dashboard#/dashboard/overview
A6: AmEx | B6: 7 | C6: C | D6: Heritage Mangement | E6: BYH | F6: Truist-BYH | G6: =RIGHT(H6,4) -> 1000 | H6: 3729 822518 61000 | J6: 6 | K6: 10990 | L6: 4 | N6: 8218 | O6: 16300 | P6: =+O6-N6 -> 8082 | Q6: 46109 | R6: 0 | T6: 292 | U6: =IF(Q6="",+N6*R6/12,0) -> 0 | V6: =+O6*0.35 -> 5705 | W6: =+O6*0.5 -> 8150 | X6: =+(N6-V6)*IF(C6="P",1,0) -> 0 | Y6: =+(N6-W6)*IF(C6="C",1,0) -> 68 | Z6: =+X6+Y6 -> 68 | AA6: wesbrowning1 | AB6: w3638B0& | AC6: https://global.americanexpress.com/dashboard
A7: AmEx | B7: 2 | C7: P | D7: Wes | E7: BYH | F7: Truist-BYH | G7: =RIGHT(H7,4) -> 1000 | H7: 3792 965024 01000 | J7: 3862 | K7: 11202 | L7: 14 | N7: 909 | O7: 1000 | P7: =+O7-N7 -> 91 | R7: 0.1399 | T7: 43 | U7: =IF(Q7="",+N7*R7/12,0) -> 10.597425 | V7: =+O7*0.35 -> 350 | W7: =+O7*0.5 -> 500 | X7: =+(N7-V7)*IF(C7="P",1,0) -> 559 | Y7: =+(N7-W7)*IF(C7="C",1,0) -> 0 | Z7: =+X7+Y7 -> 559 | AA7: wesbrowning1 | AB7: w3638B0& | AC7: https://global.americanexpress.com/dashboard
A8: AmEx (Delta SkyMiles) | B8: 3 | C8: P | D8: Jenny | E8: BYH | F8: Truist-BYH | G8: =RIGHT(H8,4) -> 1002 | H8: 3797 883673 01002 | J8: 9101 | K8: 46631 | L8: 14 | N8: 5824 | O8: 17200 | P8: =+O8-N8 -> 11376 | R8: 0.2249 | T8: 175 | U8: =IF(Q8="",+N8*R8/12,0) -> 109.15147 | V8: =+O8*0.35 -> 6020 | W8: =+O8*0.5 -> 8600 | X8: =+(N8-V8)*IF(C8="P",1,0) -> -196 | Y8: =+(N8-W8)*IF(C8="C",1,0) -> 0 | Z8: =+X8+Y8 -> -196 | AA8: Jenny3638 | AB8: BuyYourHome1 | AC8: https://global.americanexpress.com/dashboard?inav=MYCA_Home
A9: AmEx(closed) | B9: 4 | C9: P | D9: Wes | E9: BYH | F9: Truist-BYH | G9: =RIGHT(H9,4) -> 1003 | H9: 3716 972512 11003 | J9: 0864 | K9: 44922 | N9: 0 | O9: 2000 | P9: =+O9-N9 -> 2000 | R9: 0.1624 | U9: =IF(Q9="",+N9*R9/12,0) -> 0 | V9: =+O9*0.35 -> 700 | W9: =+O9*0.5 -> 1000 | X9: =+(N9-V9)*IF(C9="P",1,0) -> -700 | Y9: =+(N9-W9)*IF(C9="C",1,0) -> 0 | Z9: =+X9+Y9 -> -700 | AA9: wesbrowning1 | AB9: w3638B0& | AC9: https://global.americanexpress.com/dashboard
A10: AmEx | B10: 3 | C10: C | D10: Buy Your Home | E10: BYH | F10: Truist-BYH | G10: =RIGHT(H10,4) -> 1007 | H10: 3767 418424 02013-3767 418424 01007 | J10: 7288 | K10: 46204 | L10: 12 | N10: 2357 | O10: 4000 | P10: =+O10-N10 -> 1643 | R10: 0 | T10: 381 | U10: =IF(Q10="",+N10*R10/12,0) -> 0 | V10: =+O10*0.35 -> 1400 | W10: =+O10*0.5 -> 2000 | X10: =+(N10-V10)*IF(C10="P",1,0) -> 0 | Y10: =+(N10-W10)*IF(C10="C",1,0) -> 357 | Z10: =+X10+Y10 -> 357 | AA10: Jenny3638 | AB10: BuyYourHome1 | AC10: https://global.americanexpress.com/dashboard?inav=MYCA_Home
A11: AmEx | B11: 1 | C11: C | D11: Hollinger Investments | E11: BYH | F11: Truist-BYH | G11: =RIGHT(H11,4) -> 1009 | H11: 3798 241742 11009 | J11: 4004 | K11: 47300 | L11: 27 | N11: 3364 | O11: 7000 | P11: =+O11-N11 -> 3636 | R11: 0.1624 | S11: 727 | T11: 111 | U11: =IF(Q11="",+N11*R11/12,0) -> 45.526133 | V11: =+O11*0.35 -> 2450 | W11: =+O11*0.5 -> 3500 | X11: =+(N11-V11)*IF(C11="P",1,0) -> 0 | Y11: =+(N11-W11)*IF(C11="C",1,0) -> -136 | Z11: =+X11+Y11 -> -136 | AA11: Jenny3638 | AB11: BuyYourHome1 | AC11: https://global.americanexpress.com/dashboard?inav=MYCA_Home
A12: AmEx (New) | B12: 7 | C12: C | D12: Heritage Mangement | E12: BYH | F12: Truist-BYH | G12: =RIGHT(H12,4) -> 1009 | H12: 3729 905291 11009 | J12: 2578 | K12: 11324 | L12: 4 | O12: 2000 | P12: =+O12-N12 -> 2000 | Q12: 46109 | R12: 0 | T12: 280 | U12: =T16=IF(Q12="",+N12*R12/12,0) -> FALSE | V12: =+O12*0.35 -> 700 | W12: =+O12*0.5 -> 1000 | X12: =+(N12-V12)*IF(C12="P",1,0) -> 0 | Y12: =+(N12-W12)*IF(C12="C",1,0) -> -1000 | Z12: =+X12+Y12 -> -1000 | AA12: wesbrowning1 | AB12: w3638B0& | AC12: https://global.americanexpress.com/dashboard
A13: Bank of America(new) | B13: 1 | C13: C | D13: Jenny | F13: Truist-BYH | G13: =RIGHT(H13,4) -> 1286 | H13: 4400 6696 3175 1286 | J13: 902 | K13: 11232 | O13: 8000 | P13: =+O13-N13 -> 8000 | R13: 0.1549 | T13: 149 | U13: =IF(Q13="",+N13*R13/12,0) -> 0 | V13: =+O13*0.35 -> 2800 | W13: =+O13*0.5 -> 4000 | X13: =+(N13-V13)*IF(C13="P",1,0) -> 0 | Y13: =+(N13-W13)*IF(C13="C",1,0) -> -4000 | Z13: =+X13+Y13 -> -4000 | AA13: Ilovevince1 | AC13: https://www.bankofamerica.com/business/
A14: Wells Fargo (closed) | B14: 4 | D14: Wes | E14: BYH | F14: Truist-BYH | G14: =RIGHT(H14,4) -> 1357 | H14: 4465 4205 9474 1357 | J14: 946 | K14: 44220 | N14: 0 | P14: =+O14-N14 -> 0 | R14: 0 | U14: =IF(Q14="",+N14*R14/12,0) -> 0 | V14: =+O14*0.35 -> 0 | W14: =+O14*0.5 -> 0 | X14: =+(N14-V14)*IF(C14="P",1,0) -> 0 | Y14: =+(N14-W14)*IF(C14="C",1,0) -> 0 | Z14: =+X14+Y14 -> 0 | AA14: WesBrowning1 | AB14: w3638B0@ | AC14: https://www.wellsfargo.com/
A15: First Citizens-401K-LoC | B15: 7 | C15: LoC | D15: BYH 401K-LoC | E15: HM | F15: FC-BYH 401K | G15: =RIGHT(H15,4) -> 1439 | H15: 910013291439 | N15: 1500 | O15: 10000 | P15: =+O15-N15 -> 8500 | R15: 0.1175 | T15: 13 | U15: =IF(Q15="",+N15*R15/12,0) -> 14.6875 | V15: =+O15*0.35 -> 3500 | W15: =+O15*0.5 -> 5000 | X15: =+(N15-V15)*IF(C15="P",1,0) -> 0 | Y15: =+(N15-W15)*IF(C15="C",1,0) -> 0 | Z15: =+X15+Y15 -> 0 | AA15: HeritageManagement1 | AB15: w3638B0!Wesley | AC15: https://www.mycardstatement.com/
A16: Bank of America | B16: 2 | C16: P | D16: Jenny | E16: BYH | F16: Truist-BYH | G16: =RIGHT(H16,4) -> 1450 | H16: 5524 3365 6660 1450 | J16: 196 | K16: 45591 | L16: 8 | N16: 4667 | O16: 13800 | P16: =+O16-N16 -> 9133 | Q16: 45627 | R16: 0.2224 | T16: 125 | U16: =IF(Q16="",+N16*R16/12,0) -> 0 | V16: =+O16*0.35 -> 4830 | W16: =+O16*0.5 -> 6900 | X16: =+(N16-V16)*IF(C16="P",1,0) -> -163 | Y16: =+(N16-W16)*IF(C16="C",1,0) -> 0 | Z16: =+X16+Y16 -> -163 | AA16: Ilovevince1 | AB16: w3638B0)
A17: M&F Bank | B17: 7 | C17: C | D17: Heritage Mangement | E17: BYH | F17: Truist-BYH | G17: =RIGHT(H17,4) -> 1651 | H17: 5594 9510 5590 1651 | J17: 870 | K17: 45745 | L17: 4 | N17: 3732 | O17: 10000 | P17: =+O17-N17 -> 6268 | Q17: 45901 | R17: 0.2049 | T17: 218 | U17: =IF(Q17="",+N17*R17/12,0) -> 0 | V17: =+O17*0.35 -> 3500 | W17: =+O17*0.5 -> 5000 | X17: =+(N17-V17)*IF(C17="P",1,0) -> 0 | Y17: =+(N17-W17)*IF(C17="C",1,0) -> -1268 | Z17: =+X17+Y17 -> -1268 | AA17: HeritageManagement | AB17: w3638B0& | AC17: https://www.24-7cardaccess.com/Login
A18: First Citizens | B18: 7 | C18: C | D18: Heritage Mangement | E18: HM | F18: Truist-BYH | G18: =RIGHT(H18,4) -> 1839 | H18: 4053 0133 0114 2866 - Master 4053 0134 5068 1839 | J18: 046 | K18: 47543 | L18: 5 | N18: =17093+4500 -> 21593 | O18: 25000 | P18: =+O18-N18 -> 3407 | R18: 0 | T18: 1076 | U18: =IF(Q18="",+N18*R18/12,0) -> 0 | V18: =+O18*0.35 -> 8750 | W18: =+O18*0.5 -> 12500 | X18: =+(N18-V18)*IF(C18="P",1,0) -> 0 | Y18: =+(N18-W18)*IF(C18="C",1,0) -> 9093 | Z18: =+X18+Y18 -> 9093 | AA18: HeritageManagement1 | AB18: w3638B0!Wesley
A19: Truist-SunTrust | B19: 3 | C19: C | D19: Buy Your Home | E19: BYH | F19: Truist-BYH | G19: =RIGHT(H19,4) -> 2202 | H19: 3793, 2043, 5589 6600 0191 2202 | J19: 792 | K19: 44098 | L19: 17 | N19: 7133 | O19: 9500 | P19: =+O19-N19 -> 2367 | R19: 0.2149 | T19: 204 | U19: =IF(Q19="",+N19*R19/12,0) -> 0 | V19: =+O19*0.35 -> 3325 | W19: =+O19*0.5 -> 4750 | X19: =+(N19-V19)*IF(C19="P",1,0) -> 0 | Y19: =+(N19-W19)*IF(C19="C",1,0) -> 2383 | Z19: =+X19+Y19 -> 2383
A20: Discover | B20: 2 | C20: P | D20: Jenny | E20: BYH | F20: Truist-BYH | G20: =RIGHT(H20,4) -> 3823 | H20: 3823 | N20: 0 | O20: 4000 | P20: =+O20-N20 -> 4000 | R20: 0 | U20: =IF(Q20="",+N20*R20/12,0) -> 0 | V20: =+O20*0.35 -> 1400 | W20: =+O20*0.5 -> 2000 | X20: =+(N20-V20)*IF(C20="P",1,0) -> -1400 | Y20: =+(N20-W20)*IF(C20="C",1,0) -> 0 | Z20: =+X20+Y20 -> -1400 | AA20: WesBrowning2 | AB20: w3638B0@
A21: SECU - Personal | B21: 5 | C21: LoC | D21: Personal Home | E21: BYH | F21: Truist-BYH | G21: =RIGHT(H21,4) -> 3-93 | H21: 53-93 | N21: 23169 | O21: 35000 | P21: =+O21-N21 -> 11831 | R21: 0.1075 | T21: 444 | U21: =IF(Q21="",+N21*R21/12,0) -> 207.55562 | V21: =+O21*0.35 -> 12250 | W21: =+O21*0.5 -> 17500 | X21: =+(N21-V21)*IF(C21="P",1,0) -> 0 | Y21: =+(N21-W21)*IF(C21="C",1,0) -> 0 | Z21: =+X21+Y21 -> 0
A22: Citi (Closed) | B22: 4 | C22: P | D22: Wes | E22: BYH | F22: Truist-BYH | G22: =RIGHT(H22,4) -> 3945 | H22: 3945 | N22: 0 | O22: 0 | P22: =+O22-N22 -> 0 | R22: 0 | U22: =IF(Q22="",+N22*R22/12,0) -> 0 | V22: =+O22*0.35 -> 0 | W22: =+O22*0.5 -> 0 | X22: =+(N22-V22)*IF(C22="P",1,0) -> 0 | Y22: =+(N22-W22)*IF(C22="C",1,0) -> 0 | Z22: =+X22+Y22 -> 0 | AA22: wesBrowning | AB22: w3638B0#
A23: SECU - Home Equity | B23: 5 | D23: Personal Home | E23: BYH | F23: Truist-BYH | G23: =RIGHT(H23,4) -> 3-96 | H23: 53-96 | N23: 30047 | O23: 37000 | P23: =+O23-N23 -> 6953 | R23: 0.06 | T23: 720 | U23: =IF(Q23="",+N23*R23/12,0) -> 150.235 | V23: =+O23*0.35 -> 12950 | W23: =+O23*0.5 -> 18500 | X23: =+(N23-V23)*IF(C23="P",1,0) -> 0 | Y23: =+(N23-W23)*IF(C23="C",1,0) -> 0 | Z23: =+X23+Y23 -> 0
A24: Bank of America | B24: 1 | C24: C | D24: Jenny | E24: BYH | F24: Truist-BYH | G24: =RIGHT(H24,4) -> 4126 | H24: 5589 6214 8047 6648, 4126 | J24: 773 | K24: 47300 | L24: 8 | N24: 7229 | O24: 15000 | P24: =+O24-N24 -> 7771 | R24: 0.1549 | T24: 177 | U24: =IF(Q24="",+N24*R24/12,0) -> 93.314342 | V24: =+O24*0.35 -> 5250 | W24: =+O24*0.5 -> 7500 | X24: =+(N24-V24)*IF(C24="P",1,0) -> 0 | Y24: =+(N24-W24)*IF(C24="C",1,0) -> -271 | Z24: =+X24+Y24 -> -271 | AA24: Ilovevince1
A25: Best Buy | B25: 4 | C25: P | D25: Wes | E25: BYH | F25: Truist-BYH | G25: =RIGHT(H25,4) -> 4127 | H25: 4269 3800 8114 4127 | J25: 569 | K25: 46327 | L25: 5 | N25: 1449 | O25: 5500 | P25: =+O25-N25 -> 4051 | Q25: 45992 | R25: 0 | T25: 30 | V25: =+O25*0.35 -> 1925 | W25: =+O25*0.5 -> 2750 | X25: =+(N25-V25)*IF(C25="P",1,0) -> -476 | Y25: =+(N25-W25)*IF(C25="C",1,0) -> 0 | Z25: =+X25+Y25 -> -476 | AA25: Wes@myBrowning.net | AB25: w3638B0@ | AC25: https://citiretailservices.citibankonline.com/RSnextgen/svc/launch/index.action?siteId=PLCN_BESTBUY#signon
A26: Truist (formally CP) | B26: 2 | C26: P | D26: Jenny | E26: BYH | F26: Truist-BYH | G26: =RIGHT(H26,4) -> 4528 | H26: 4616 0811 2120 7912- 4616 0820 0894 4528 | J26: 259 | K26: 46753 | L26: 5 | N26: 4040 | O26: 15000 | P26: =+O26-N26 -> 10960 | R26: 0.086 | T26: 82 | U26: =IF(Q26="",+N26*R26/12,0) -> 28.953333 | V26: =+O26*0.35 -> 5250 | W26: =+O26*0.5 -> 7500 | X26: =+(N26-V26)*IF(C26="P",1,0) -> -1210 | Y26: =+(N26-W26)*IF(C26="C",1,0) -> 0 | Z26: =+X26+Y26 -> -1210 | AA26: jennyincredible | AB26: gotojailnow9
A27: First Citizens | B27: 4 | C27: C | D27: BYH 401k | E27: BYH | F27: FC-BYH 401K | G27: =RIGHT(H27,4) -> 4696 | H27: 4053 0133 0116 4696 | J27: 887 | K27: 47270 | L27: 5 | N27: 4023 | O27: 10000 | P27: =+O27-N27 -> 5977 | R27: 0.075 | T27: 208 | U27: =A45=IF(Q27="",+N27*R27/12,0) -> FALSE | V27: =+O27*0.35 -> 3500 | W27: =+O27*0.5 -> 5000 | X27: =+(N27-V27)*IF(C27="P",1,0) -> 0 | Y27: =+(N27-W27)*IF(C27="C",1,0) -> -977 | Z27: =+X27+Y27 -> -977 | AA27: wesbrowning | AB27: w3638B0! | AC27: https://digitalbanking.firstcitizens.com/FCBTCOnline/uux.aspx#/landingPage
A28: First Citizens | B28: 7 | C28: C | D28: Sell Your Home | E28: SYH | F28: FC-SYH | G28: =RIGHT(H28,4) -> 4882 | H28: 4053 0133 0114 6222 - 4053 0134 5068 5103 - Master 4882 | J28: 256 | K28: 47362 | L28: 5 | N28: 15736 | O28: 25000 | P28: =+O28-N28 -> 9264 | R28: 0 | T28: 787 | U28: =IF(Q28="",+N28*R28/12,0) -> 0 | V28: =+O28*0.35 -> 8750 | W28: =+O28*0.5 -> 12500 | X28: =+(N28-V28)*IF(C28="P",1,0) -> 0 | Y28: =+(N28-W28)*IF(C28="C",1,0) -> 3236 | Z28: =+X28+Y28 -> 3236 | AA28: HeritageManagement1 | AB28: w3638B0!Wesley
A29: Chase Ink | B29: 1 | C29: C | D29: Hollinger Investments | E29: BYH | F29: Truist-BYH | G29: =RIGHT(H29,4) -> 5323 | H29: 4246 3152 8198 5323 | J29: 510 | K29: 46722 | L29: 17 | N29: 7669 | O29: 16000 | P29: =+O29-N29 -> 8331 | R29: 0.1699 | T29: 203 | U29: =IF(Q29="",+N29*R29/12,0) -> 108.58026 | V29: =+O29*0.35 -> 5600 | W29: =+O29*0.5 -> 8000 | X29: =+(N29-V29)*IF(C29="P",1,0) -> 0 | Y29: =+(N29-W29)*IF(C29="C",1,0) -> -331 | Z29: =+X29+Y29 -> -331 | AA29: JennyHollinger2 | AB29: Greatnewlife1! | AC29: https://www.chase.com/personal/credit-cards/verify-credit-card
A30: Truist | B30: 6 | C30: C | D30: Sell Your Home | E30: SYH | F30: Truist-BYH | G30: =RIGHT(H30,4) -> 5943 | H30: 4046 0112 0021 8522, 5943 | J30: 674 | K30: 47604 | L30: 22 | N30: 9279 | O30: 20000 | P30: =+O30-N30 -> 10721 | R30: 0.2599 | T30: 312 | U30: =IF(Q30="",+N30*R30/12,0) -> 200.96768 | V30: =+O30*0.35 -> 7000 | W30: =+O30*0.5 -> 10000 | X30: =+(N30-V30)*IF(C30="P",1,0) -> 0 | Y30: =+(N30-W30)*IF(C30="C",1,0) -> -721 | Z30: =+X30+Y30 -> -721
A31: US Bank (new) | D31: Heritage Mangement | E31: HM | F31: FC-HM | G31: =RIGHT(H31,4) -> 5991 | H31: 4798 5322 1337 5991 | J31: 013 | K31: 11324 | O31: 3000 | P31: =+O31-N31 -> 3000 | V31: =+O31*0.35 -> 1050 | W31: =+O31*0.5 -> 1500 | AA31: wesbrowning | AB31: w3638B0# | AC31: https://onlinebanking.usbank.com/auth/login/
A32: Lowes Pro | B32: 6 | C32: C | D32: Buy Your Home | E32: BYH | F32: Truist-BYH | G32: =RIGHT(H32,4) -> 5997 | H32: 821 313 4248 5997 | J32: 649 | K32: 11049 | L32: 17 | N32: 2878 | O32: 3300 | P32: =+O32-N32 -> 422 | R32: 0.1699 | T32: 126 | U32: =IF(Q32="",+N32*R32/12,0) -> 40.747683 | V32: =+O32*0.35 -> 1155 | W32: =+O32*0.5 -> 1650 | X32: =+(N32-V32)*IF(C32="P",1,0) -> 0 | Y32: =+(N32-W32)*IF(C32="C",1,0) -> 1228 | Z32: =+X32+Y32 -> 1228 | AA32: WesWill@BuyYourHomeRaleigh.com | AB32: w3638B0@ | AC32: https://lowes.syf.com/commercial/
A33: Truist | B33: 3 | C33: C | D33: Buy Your Home | E33: BYH | F33: Truist-BYH | G33: =RIGHT(H33,4) -> 6008 | H33: 4046 0112 0210 5081, 6008 | J33: 574 | K33: 46844 | L33: 16 | N33: 10564 | O33: 20000 | P33: =+O33-N33 -> 9436 | R33: 0.2599 | T33: 335 | U33: 0 | V33: =+O33*0.35 -> 7000 | W33: =+O33*0.5 -> 10000 | X33: =+(N33-V33)*IF(C33="P",1,0) -> 0 | Y33: =+(N33-W33)*IF(C33="C",1,0) -> 564 | Z33: =+X33+Y33 -> 564
A34: Lowes Pro | B34: 6 | C34: C | D34: Sell Your Home | E34: SYH | F34: FC-SYH | G34: =RIGHT(H34,4) -> 6140 | H34: 6140 | J34: 383 | K34: 12175 | N34: 8373 | O34: 12000 | P34: =+O34-N34 -> 3627 | R34: 0.1699 | T34: 350 | U34: =IF(Q34="",+N34*R34/12,0) -> 118.54772 | V34: =+O34*0.35 -> 4200 | W34: =+O34*0.5 -> 6000 | X34: =+(N34-V34)*IF(C34="P",1,0) -> 0 | Y34: =+(N34-W34)*IF(C34="C",1,0) -> 2373 | Z34: =+X34+Y34 -> 2373 | AA34: WesWill@BuyYourHomeRaleigh.com | AB34: w3638B0@ | AC34: https://lowes.syf.com/commercial/
A35: Chase Slate (closed) | B35: 2 | C35: P | D35: Jenny | E35: BYH | F35: Truist-BYH | G35: =RIGHT(H35,4) -> 6246 | H35: 4266 8415 1028 6246 | J35: 623 | K35: 43856 | N35: 0 | O35: 0 | P35: =+O35-N35 -> 0 | R35: 0.2074 | U35: =IF(Q35="",+N35*R35/12,0) -> 0 | V35: =+O35*0.35 -> 0 | W35: =+O35*0.5 -> 0 | X35: =+(N35-V35)*IF(C35="P",1,0) -> 0 | Y35: =+(N35-W35)*IF(C35="C",1,0) -> 0 | Z35: =+X35+Y35 -> 0 | AA35: JennyHollinger1 | AB35: Greatnewlife1!
A36: Chase Slate | B36: 4 | C36: P | D36: Wes | E36: BYH | F36: Truist-BYH | G36: =RIGHT(H36,4) -> 6281 | H36: 4266-8415-1032-6281 | J36: 466 | K36: 46023 | L36: 20 | N36: 1732 | O36: 6200 | P36: =+O36-N36 -> 4468 | R36: 0.2524 | T36: 56 | U36: =IF(Q36="",+N36*R36/12,0) -> 36.429733 | V36: =+O36*0.35 -> 2170 | W36: =+O36*0.5 -> 3100 | X36: =+(N36-V36)*IF(C36="P",1,0) -> -438 | Y36: =+(N36-W36)*IF(C36="C",1,0) -> 0 | Z36: =+X36+Y36 -> -438 | AA36: wesbrowning1 | AB36: w3638B0@
A37: Citi | B37: 2 | C37: P | D37: Jenny | E37: BYH | F37: Truist-BYH | G37: =RIGHT(H37,4) -> 6289 | H37: old 5285-4600-7127-3065 5189-4102-2469-6289 | J37: 359 | K37: 46539 | N37: 2671 | O37: 9210 | P37: =+O37-N37 -> 6539 | Q37: 45778 | R37: 0 | T37: 93 | U37: =IF(Q37="",+N37*R37/12,0) -> 0 | V37: =+O37*0.35 -> 3223.5 | W37: =+O37*0.5 -> 4605 | X37: =+(N37-V37)*IF(C37="P",1,0) -> -552.5 | Y37: =+(N37-W37)*IF(C37="C",1,0) -> 0 | Z37: =+X37+Y37 -> -552.5 | AA37: Jenny@BuyYourHomeLLC.com | AB37: w3638B0@
A38: Chase | B38: 7 | C38: C | D38: Heritage Mangement | E38: BYH | F38: Truist-BYH | G38: =RIGHT(H38,4) -> 6337 | H38: 4246 3154 3751 6337 | I38: No | J38: 124 | K38: 10990 | L38: 15 | N38: 17697 | O38: 31000 | P38: =+O38-N38 -> 13303 | R38: 0 | T38: 178 | U38: =IF(Q38="",+N38*R38/12,0) -> 0 | V38: =+O38*0.35 -> 10850 | W38: =+O38*0.5 -> 15500 | X38: =+(N38-V38)*IF(C38="P",1,0) -> 0 | Y38: =+(N38-W38)*IF(C38="C",1,0) -> 2197 | Z38: =+X38+Y38 -> 2197 | AA38: HeritageManagementLLC1 | AB38: w3638B0!Wes | AC38: https://secure.chase.com/web/auth/dashboard#/dashboard/overview
A39: Capital One | B39: 2 | C39: P | D39: Jenny | E39: BYH | F39: Truist-BYH | G39: =RIGHT(H39,4) -> 6426 | H39: 5156 7678 5579 6426 | J39: 067 | K39: 11140 | N39: 0 | O39: 1000 | P39: =+O39-N39 -> 1000 | Q39: free | R39: 0 | T39: 0 | U39: =IF(Q39="",+N39*R39/12,0) -> 0 | V39: =+O39*0.35 -> 350 | W39: =+O39*0.5 -> 500 | X39: =+(N39-V39)*IF(C39="P",1,0) -> -350 | Y39: =+(N39-W39)*IF(C39="C",1,0) -> 0 | Z39: =+X39+Y39 -> -350 | AA39: WesBrowning | AB39: w3638B0@
A40: Bank of America | B40: 3 | C40: C | D40: Buy Your Home | E40: BYH | F40: Truist-BYH | G40: =RIGHT(H40,4) -> 6525 | H40: 5474 1522 0807 7789, 5474 1517 2892 6525 | J40: 125 | K40: 11202 | N40: 2966 | O40: 7900 | P40: =+O40-N40 -> 4934 | R40: 0.1724 | T40: 85 | U40: =IF(Q40="",+N40*R40/12,0) -> 42.611533 | V40: =+O40*0.35 -> 2765 | W40: =+O40*0.5 -> 3950 | X40: =+(N40-V40)*IF(C40="P",1,0) -> 0 | Y40: =+(N40-W40)*IF(C40="C",1,0) -> -984 | Z40: =+X40+Y40 -> -984 | AA40: wesbrowning2 | AB40: w3638B0*
...

Sheet Balances
B1: Current Balnce | C1: Pay Down for 35% | D1: Pay Down for 50%
C3: =_xlfn.XLOOKUP($B$27,$A$11:$A$18,$C$11:$C$18) -> Jenny | D3: =_xlfn.XLOOKUP($B$24,$A$11:$A$18,$C$11:$C$18) -> Heritage Management
A4: Total Credit | B4: =+SUM(Cards!O5:O37) -> 385010 | C4: =+SUM(Cards!X5:X37) -> -4576.5 | D4: =+SUM(Cards!Y5:Y37) -> 22384
A5: Total Balance | B5: =+SUM(Cards!N4:N39) -> 237711
A6: Available | B6: =+B4-B5 -> 147299
A7: Interest Paid | B7: =+SUM(Cards!U5:U37) -> 1165.2939 | C7: 1132 | D7: 1091
A8: Annual Interest Paid | B8: =+B7*12 -> 13983.527 | C8: =+C7*12 -> 13584 | D8: 13096
A10: Intity Key | C10: Over Ratio:
A11: 1 | C11: Hollinger Investments or CP | D11: 12279
A12: 7 | C12: Heritage Management
A13: 3 | C13: Buy Your Home | D13: 11391
A14: 6 | C14: Sell Your Home | D14: 0
C15: Over Ratio: | E15: =+D14+D13+D11 -> 23670
A17: 4 | C17: Wes | D17: 37294
A18: 2 | C18: Jenny | D18: 9322
C19: Over Ratio: | E19: =+SUM(D17:D18) -> 46616
F20: =+E19+E15 -> 70286
A21: 5 | C21: Personal Home | D21: 30798 | E21: =+D21 -> 30798
A24: Business Entity ID = | B24: 7 | C24: =_xlfn.XLOOKUP($B$24,$A$11:$A$18,$C$11:$C$18) -> Heritage Management
A25: Paydown to get below 50% | C25: =+SUM(Cards!Y5:Y52) -> 23036
A27: Personal Entity ID = | B27: 2 | C27: =_xlfn.XLOOKUP(B27,$A$11:$A$18,$C$11:$C$18) -> Jenny
A28: Paydown to get below 35% | C28: =+SUM(Cards!X5:X52) -> -3909

Sheet Mega Success
B1: Paid | C1: Total
A2: Empire Builders | B2: 2000 | C2: 2000 | D2: 44883
A3: Cole Mastermind | B3: 5000 | C3: 15000 | D3: 44885 | E3: 2 installments
A4: The One Expeience Stage with Picture | B4: 2000 | C4: 25000 | D4: 44884 | E4: by 11/29
A6: Lender | B6: Entity ID | C6: Name | D6: Used By | E6: Card Number | F6: CVV Code | G6: Expire Date | H6: Current Balance | I6: Credit Limit | J6: Available Credit | K6: Free Interest | L6: Interest Rate | M6: PIN | N6: Interest Paid | O6: 0.35 | P6: 0.5 | Q6: paydown for 35% | R6: paydown for 50% | S6: User | T6: Password | U6: URL
A7: Truist | B7: 1 | C7: Cruise Planners | D7: CP | E7: 4616 0811 2120 7912 | F7: 361 | G7: 44585 | H7: -7177 | I7: 15000 | J7: =+I7-H7 -> 22177 | L7: 0.086 | N7: =IF(K7="",+H7*L7/12,0) -> -51.435167 | O7: =+I7*0.35 -> 5250 | P7: =+I7*0.5 -> 7500 | Q7: =+IF(H7-O7<0,0,(H7-O7)*IF(B7=Balances!$B$27,1,0)) -> 0 | R7: =IF(H7-P7<0,0,(H7-P7)*IF(B7=Balances!$B$24,1,0)) -> 0 | V7: 7182
A8: First Citizens - Wes | B8: 4 | C8: Wes | D8: BYH | E8: 4118 7096 5858 7867 | F8: 351 | G8: 44402 | H8: 0 | I8: 15000 | J8: =+I8-H8 -> 15000 | L8: 0.0325 | N8: =IF(K8="",+H8*L8/12,0) -> 0 | O8: =+I8*0.35 -> 5250 | P8: =+I8*0.5 -> 7500 | Q8: =+IF(H8-O8<0,0,(H8-O8)*IF(B8=Balances!$B$27,1,0)) -> 0 | R8: =IF(H8-P8<0,0,(H8-P8)*IF(B8=Balances!$B$24,1,0)) -> 0 | S8: wesbrowning | T8: w3638B0) | U8: https://digitalbanking.firstcitizens.com/FCBTCOnline/uux.aspx#/landingPage
C11: split 23,000 over these two | F11: =23000/2 -> 11500

Sheet Mortgages
A1: Number | B1: Property | C1: Benificial Interest | D1: Deed | E1: Lender | F1: loan# | G1: Payment | H1: Balance | I1: Int% | J1: Status | K1: Paid | L1: Checking | M1: Insurance | N1: Company | O1: Phone | P1: email | Q1: Premium | R1: New P | S1: Login | T1: UserName | U1: Password
A2: 27 | B2: 7001 Outrigger Rd | C2: Heritage Management | D2: 7001 Outrigger Drive Real Estate Trust date May 2, 2025 | E2: Village Capital | G2: 816.35 | H2: 78800 | I2: 0.045 | J2: Open | K2: Autopay | L2: FC HM | M2: Andrew Hamp | N2: State Farm | Q2: 2094 | R2: 674 | S2: https://loansphereservicingdigital.bkiconnect.com/villagecapital/#/login | T2: OutRigger | U2: w3638B0% | V2: Have to download statements
A3: 26 | B3: 612 Britton Ct | C3: BYH 401K | D3: The Tunnard Real Estate Trust on 612 Brittion ct dated March, 5 2025 | E3: Coastal Federal CU | F3: 185564-43201 | G3: 1344.14 | H3: 78400 | I3: 0.0475 | J3: Open | K3: Bill Pay | L3: FC 401K | M3: Andrew Hamp | N3: NCJUA | Q3: 3521 | R3: 1166 | S3: https://www.coastal24.com/ | T3: 185564LT | U3: Five927bek34$ | V3: https://www.coastal24.com/products/credit-cards-loans/insurance-coverage-verification
A4: 26 | B4: 908 Pond St | C4: Buy Your Home | D4: 908 Pond St Real Estate Trust dated March, 5 2025 | E4: Casa Lending | F4: 77278 | G4: 981 | H4: 150000 | I4: 0.1031 | J4: Open | K4: Autopay | L4: Truist BYH | M4: Allison Hasenbank | N4: NCJUA | O4: 888-741-8454 Ext.694 | P4: ahasenbank@nreig.com | Q4: =(368.38+67.36)*12 -> 5228.88 | R4: 2653 | S4: https://borrowers.constructionloanservices.com/ | T4: WesWill@BuyYourHomeLLC.com | U4: w3638B0@
A5: 24 | B5: 4121 Tensity Dr | C5: Heritage Management | D5: The Tensity Dr Real Estate Trust date Jan 22, 2025 | E5: Truist | F5: 60036258 | G5: 676.98 | H5: 78900 | I5: 0.0375 | J5: Open | K5: Bill Pay | L5: FC HM | M5: Andrew Hamp | N5: State Farm | Q5: 1677 | R5: 758 | S5: no login
A6: 23 | B6: 6316 Willowdell Dr | C6: Sell Your Home | D6: The 6316 Willowdell Drive Real Estate Trust date January 13, 2025 | E6: SECU | G6: 1662.42 | J6: Closed | K6: Bill Pay | L6: FC SYH | S6: no login
A7: 22 | B7: 2325 Cool Springs Rd | C7: Heritage Management | D7: The Cool Springs Rd Real Estate Trust date Sep, 05,2024 | E7: Planet Home Lending | F7: 5200096877 | G7: 1269.34 | H7: 168400 | I7: 0.03 | J7: Open | K7: AutoPay | L7: FC HM | M7: Andrew Hamp | N7: State Farm | O7: 888-741-8454 Ext.694 | P7: ahasenbank@nreig.com | Q7: =74.94*12 -> 899.28 | R7: 941 | S7: https://loansphereservicingdigital.bkiconnect.com/planetservicing/#/login | T7: CoolSprings | U7: w3638B0%
A8: 21 | B8: 1343 Old Buckhorn | C8: Sell Your Home | D8: The 1343 Old Buckhorn Real Estate Trust date April 10, 2024 | G8: 1120.77 | J8: Closed | K8: Autopay | L8: FC SYH | S8: myaccount.shellpointmtg.com. | T8: Wes@BYHLLC.com | U8: w3638B0@
A9: 19 | B9: 115 Rosebrooks Dr | C9: Buy Your Home | D9: Buy Your Home, LLC - need to go back into trust | F9: 691805311 | G9: 1504.55 | H9: 179300 | I9: 0.0707 | J9: Open | K9: AutoPay | L9: FC HM | M9: Allison Hasenbank | N9: NCJUA | O9: 888-741-8454 Ext.694 | P9: ahasenbank@nreig.com | Q9: =91.23*12 -> 1094.76 | R9: 724 | S9: https://signin.shellpointmtg.com/signin | T9: Jenny@BuyYourHomeLLC.com | U9: w3638B0#
A10: 18 | B10: 1426 Pleasant Garden Ln | C10: Buy Your Home | D10: Buy Your Home, LLC - need to go back into trust | E10: Wells Fargo | F10: 211198205 | G10: 980.87 | H10: 128717 | I10: 0.03375 | J10: Open | K10: Bill Pay | L10: FC HM | M10: Andrew Hamp | N10: State Farm | O10: ‪(919) 782-6666‬ | P10: jennifer.blankenship.vabhka@statefarm.com | Q10: 851 | R10: 851 | S10: no login
A11: 16 | B11: 3413 Pinetree Ln | C11: Sell Your Home | D11: The 3413 Pinetree Lane Real Estate Trust dated August 22,2023 | E11: Mr Cooper | F11: 623844180 | G11: 992.77 | H11: 138964 | I11: 0.03125 | J11: Open | K11: Autopay | L11: FC SYH | M11: Andrew Hamp | N11: State Farm | Q11: 1606 | R11: 1081 | S11: https://rocket.com/mortgage/servicing | T11: wes@bycllc.com | U11: w3638B0@ | V11: https://rocket.com/mortgage/servicing/onboarding?loanNumber=623844180
A12: 13 | B12: 2325 Banks Rd | C12: Buy Your Home | D12: 3325 Banks Rd Trust dated July 1, 2021- BYH trustee | E12: Rushmore | F12: 708108824 | G12: 795.86 | H12: 119194 | I12: 0.0325 | J12: Open | K12: AutoPay | L12: FC HM | N12: NREIG | P12: Angela Saverino <angela@reinsurepro.com> | Q12: =175.23*12 -> 2102.76 | R12: 2102.76 | S12: https://www.rushmoreservicing.com | T12: WesWill@BuyYourHomeLLC.com | U12: w3638B0#
A13: 28 | B13: 320 Rose Pl | C13: Sell Your Home | D13: 320 Rose Pl Real Estate Trust dated June 17, 2025 | E13: Shellpoint | F13: 690297767 | G13: 1017.65 | H13: 122609.12 | I13: 0.045 | J13: Open | K13: Autopay | L13: FC SYH | M13: Andrew Hamp | N13: NCJUA | Q13: 1190 | R13: 618 | S13: myaccount.shellpointmtg.com. | T13: WesWill@BuyYourHomeLLC.com | U13: w3638B0#
Q15: savings | R15: =SUM(Q2:Q13)-SUM(R2:R13) -> 8695.92
H16: Total Balance: | I16: =SUM(H2:H13) -> 1243284.1
H17: Effective Interes Rate: | I17: =SUMPRODUCT(H1:H13,I1:I13)/SUM(H1:H13) -> 0.049466006
A24: =+A1 -> Number | B24: =+B1 -> Property | C24: =+C1 -> Benificial Interest | D24: Deed | E24: Holding Recorded Deed | G24: Recorded Trust Docs
A25: =+A2 -> 27 | B25: =+B2 -> 7001 Outrigger Rd | C25: =+C2 -> Heritage Management | D25: =+D2 -> 7001 Outrigger Drive Real Estate Trust date May 2, 2025 | E25: No | G25: No
A26: =+A3 -> 26 | B26: =+B3 -> 612 Britton Ct | C26: =+C3 -> BYH 401K | D26: =+D3 -> The Tunnard Real Estate Trust on 612 Brittion ct dated March, 5 2025 | E26: no | G26: No
A27: =+A4 -> 26 | B27: =+B4 -> 908 Pond St | C27: =+C4 -> Buy Your Home | D27: =+D4 -> 908 Pond St Real Estate Trust dated March, 5 2025 | E27: Yes | G27: No
A28: =+A5 -> 24 | B28: =+B5 -> 4121 Tensity Dr | C28: =+C5 -> Heritage Management | D28: =+D5 -> The Tensity Dr Real Estate Trust date Jan 22, 2025 | E28: Yes, QCD | G28: No
A29: =+A6 -> 23 | B29: =+B6 -> 6316 Willowdell Dr | C29: =+C6 -> Sell Your Home | D29: =+D6 -> The 6316 Willowdell Drive Real Estate Trust date January 13, 2025 | E29: No | G29: No
A30: =+A7 -> 22 | B30: =+B7 -> 2325 Cool Springs Rd | C30: =+C7 -> Heritage Management | D30: =+D7 -> The Cool Springs Rd Real Estate Trust date Sep, 05,2024 | E30: No | G30: No
A31: =+A8 -> 21 | B31: =+B8 -> 1343 Old Buckhorn | C31: =+C8 -> Sell Your Home | D31: =+D8 -> The 1343 Old Buckhorn Real Estate Trust date April 10, 2024 | E31: Yes | G31: No
A32: =+A9 -> 19 | B32: =+B9 -> 115 Rosebrooks Dr | C32: =+C9 -> Buy Your Home | D32: =+D9 -> Buy Your Home, LLC - need to go back into trust | E32: yes | G32: n/a
A33: =+A10 -> 18 | B33: =+B10 -> 1426 Pleasant Garden Ln | C33: =+C10 -> Buy Your Home | D33: =+D10 -> Buy Your Home, LLC - need to go back into trust | E33: Yes | G33: n/a
A34: =+A11 -> 16 | B34: =+B11 -> 3413 Pinetree Ln | C34: =+C11 -> Sell Your Home | D34: =+D11 -> The 3413 Pinetree Lane Real Estate Trust dated August 22,2023 | E34: No | G34: No
A35: =+A12 -> 13 | B35: =+B12 -> 2325 Banks Rd | C35: =+C12 -> Buy Your Home | D35: =+D12 -> 3325 Banks Rd Trust dated July 1, 2021- BYH trustee | E35: Yes | G35: No
A36: =+A13 -> 28 | B36: =+B13 -> 320 Rose Pl | C36: =+C13 -> Sell Your Home | D36: =+D13 -> 320 Rose Pl Real Estate Trust dated June 17, 2025 | E36: No | G36: No

Sheet Private Lenders
B1: Total Loans | C1: =+SUM(D4:D13) -> 672017.01
A3: Business | B3: Name | C3: Property | D3: Amount | E3: Int Rate | F3: Start date | G3: Paid Date | H3: Days | I3: Interest Earned | J3: Monthly Payments | K3: payments made | L3: Principal Paid | M3: Status | N3: Borrowed/Lent
B4: Janie Lanabarger | C4: 1201 Hazlenut Dr | D4: 30000 | E4: 0.1 | F4: 44013 | G4: 44281 | H4: =+_xlfn.DAYS(G4,F4) -> 268 | I4: =D4*DAYS360(F4,G4)*E4/365 -> 2178.0822 | M4: Closed
B5: Jim Monroe | C5: 178 Patricia Dr | D5: 42000 | E5: 0.1 | F5: 44197 | G5: 44334 | H5: =+_xlfn.DAYS(G5,F5) -> 137 | I5: 2100 | M5: closed
B6: Janie Lanabarger | C6: n/a | D6: 95000 | E6: 0.12 | F6: 44285 | G6: 44377 | H6: =+_xlfn.DAYS(G6,F6) -> 92 | I6: =D6*DAYS360(F6,G6)*E6/365 -> 2810.9589 | M6: Closed
B7: Janie Lanabarger | C7: 3325 Banks Rd | D7: 95000 | E7: 0.1 | F7: 44377 | G7: 44672 | H7: =+_xlfn.DAYS(G7,F7) -> 295 | I7: 7573.29 | M7: Closed
B8: Tim & Robin Maura | C8: 2153 Haig Point Way | D8: 65017.01 | E8: 0.01 | F8: 44236 | G8: 44438 | H8: =+_xlfn.DAYS(G8,F8) -> 202 | I8: =D8*DAYS360(F8,G8)*E8/365 -> 358.03888 | J8: 541.81 | K8: 6 | L8: =+(J8*K8)-I8 -> 2892.8211 | M8: Closed
B9: Bill & Chloa Romick | C9: 1900 Red Quartz | D9: 100000 | E9: 0.1 | F9: 44606 | G9: 44788 | H9: =+_xlfn.DAYS(G9,F9) -> 182 | I9: =D9*DAYS360(F9,G9)*E9/365 -> 4958.9041 | J9: =+I9/12 -> 413.24201 | K9: 6 | L9: =+(J9*K9)-I9 -> -2479.4521 | M9: Closed
A10: BYH | B10: Bill & Chloa Romick | D10: 100000 | E10: 0.12 | F10: 44697 | G10: 45062 | H10: =+_xlfn.DAYS(G10,F10) -> 365 | I10: =D10*H10*E10/365 -> 12000 | J10: =+I10/12 -> 1000 | K10: 8 | L10: =+(J10*K10)-I10 -> -4000 | M10: Closed
A11: SYH | B11: Scoot Moore | C11: 2608 Alton Pl | D11: 30000 | E11: 0.1 | F11: 44708 | G11: 45175 | H11: =+_xlfn.DAYS(G11,F11) -> 467 | I11: =D11*H11*E11/365 -> 3838.3562 | J11: =+D11*E11/12 -> 250 | K11: 16 | L11: =+(J11*K11)-I11 -> 161.64384 | M11: Closed
A12: BYH | B12: Ann Chellman | C12: 164 Churchill Downs Dr | D12: 15000 | E12: 0.1 | F12: 44795 | G12: 45034 | H12: =+_xlfn.DAYS(G12,F12) -> 239 | I12: =D12*H12*E12/365 -> 982.19178 | J12: =+D12*E12/12 -> 125 | L12: =+(J12*K12)-I12 -> -982.19178 | M12: Closed
A13: BYH | B13: Bill & Chloa Romick | C13: 164 Churchill Downs Dr | D13: 100000 | E13: 0.1 | F13: 44867 | G13: 45034 | H13: =+_xlfn.DAYS(G13,F13) -> 167 | I13: =D13*H13*E13/365 -> 4575.3425 | J13: =+D13*E13/12 -> 833.33333 | L13: =+(J13*K13)-I13 -> -4575.3425 | M13: Closed
A14: SYH | B14: Dave & Jana | C14: 2608 Allton Pl | D14: 36000 | E14: 0.1 | F14: 44956 | G14: 45175 | H14: =+_xlfn.DAYS(G14,F14) -> 219 | I14: =D14*H14*E14/365 -> 2160 | J14: =+D14*E14/12 -> 300 | K14: 6 | L14: =+(J14*K14)-I14 -> -360 | M14: Closed
A15: SYH | B15: Bill & Chloa Romick | C15: 2608 Allton Pl | D15: 75000 | E15: 0.1 | F15: 45034 | G15: 45175 | H15: =+_xlfn.DAYS(G15,F15) -> 141 | I15: =D15*H15*E15/365 -> 2897.2603 | J15: =+D15*E15/12 -> 625 | K15: 4 | L15: =+(J15*K15)-I15 -> -397.26027 | M15: Closed
A16: BYH | B16: Neal Isaacs | C16: 3325 Banks Rd | D16: 75000 | E16: 0.1 | F16: 44701 | G16: 45432 | H16: =+_xlfn.DAYS(G16,F16) -> 731 | I16: =D16*H16*E16/365 -> 15020.548 | J16: =+D16*E16/12 -> 625 | L16: =+(J16*K16)-I16 -> -15020.548 | M16: Open
A17: SYH | B17: John Fish | C17: 5008 Larchmont | D17: 85000 | E17: 0.03 | F17: 44722 | G17: 45087 | H17: =+_xlfn.DAYS(G17,F17) -> 365 | I17: =D17*H17*E17/365 -> 2550 | J17: =+I17/12 -> 212.5 | L17: =+(J17*K17)-I17 -> -2550 | M17: Closed | O17: amortized for 120 months. Payments of $920.83. ballon at 60 months
A18: SYH | B18: Dave & Jana | C18: 5008 Larchmont | D18: 100300 | E18: 0.1 | F18: 44841 | G18: 45291 | H18: =+_xlfn.DAYS(G18,F18) -> 450 | I18: =D18*H18*E18/365 -> 12365.753 | J18: =+D18*E18/12 -> 835.83333 | L18: =+(J18*K18)-I18 -> -12365.753 | M18: Closed | O18: =+D18+I18 -> 112665.75
A19: SYH | B19: Scoot Moore | C19: 3325 Banks Rd | D19: 30000 | E19: 0.1 | F19: 45194 | G19: 45626 | H19: =+_xlfn.DAYS(G19,F19) -> 432 | I19: =D19*H19*E19/365 -> 3550.6849 | J19: =+D19*E19/12 -> 250 | L19: =+(J19*K19)-I19 -> -3550.6849 | M19: Closed
A20: BYH | B20: Dave & Jana | C20: 1426 Pleasant Garden Ln | D20: 36000 | E20: 0.1 | F20: 45203 | G20: 45934 | H20: =+_xlfn.DAYS(G20,F20) -> 731 | I20: =D20*H20*E20/365 -> 7209.863 | J20: =+D20*E20/12 -> 300 | K20: 6 | L20: =+(J20*K20)-I20 -> -5409.863 | M20: Open
A21: BYH | B21: Neal Isaacs | C21: 1426 Pleasant Garden Ln | D21: 75000 | E21: 0.1 | F21: 45212 | G21: 45573 | H21: =+_xlfn.DAYS(G21,F21) -> 361 | I21: =D21*H21*E21/365 -> 7417.8082 | J21: =+D21*E21/12 -> 625 | K21: 6 | L21: =+(J21*K21)-I21 -> -3667.8082 | M21: Open
A22: BYH | B22: Neal Isaacs | C22: 115 Rosebrooks Dr | D22: 75000 | E22: 0.1 | F22: 45307 | G22: 45573 | H22: =+_xlfn.DAYS(G22,F22) -> 266 | I22: =D22*H22*E22/365 -> 5465.7534 | J22: =+D22*E22/12 -> 625 | K22: 9 | L22: =+(J22*K22)-I22 -> 159.24658 | M22: Closed
A23: BYH | B23: Michael Obrien | C23: 8225 Burgwyn Ln | D23: 35000 | E23: 0.03 | F23: 45248 | G23: 45327 | H23: =+_xlfn.DAYS(G23,F23) -> 79 | I23: =D23*H23*E23/365 -> 227.26027 | J23: =+D23*E23/12 -> 87.5 | M23: Closed | N23: Note
A24: BYH | B24: Michael Obrien | C24: 8225 Burgwyn Ln | D24: 20000 | E24: 0.03 | F24: 45327 | G24: 45327 | H24: =+_xlfn.DAYS(G24,F24) -> 0 | I24: =D24*H24*E24/365 -> 0 | J24: =+D24*E24/12 -> 50 | N24: Note
A25: SYH | B25: Dianne Lipman | C25: N/A | D25: 22000 | E25: 0.1 | F25: 45250 | G25: 45311 | H25: =+_xlfn.DAYS(G25,F25) -> 61 | I25: =D25*H25*E25/365 -> 367.67123 | J25: =+D25*E25/12 -> 183.33333 | M25: closed | N25: Borrowed
A26: SYH | B26: Dianne Lipman | C26: N/A | D26: 15000 | E26: 0.1 | F26: 45321 | G26: 45345 | H26: =+_xlfn.DAYS(G26,F26) -> 24 | I26: =D26*H26*E26/365 -> 98.630137 | J26: =+D26*E26/12 -> 125 | M26: closed | N26: Borrowed
A27: BYH | B27: Michael Obrien | C27: N/A | D27: 10000 | E27: 0.12 | F27: 45248 | H27: =+_xlfn.DAYS(G27,F27) -> -45248 | J27: =+D27*E27/12 -> 100 | M27: Closed | N27: Lent
A28: SYH | B28: Sampson Wodes | C28: N/A | D28: 11000 | E28: 0.12 | F28: 45330 | G28: 45363 | H28: =+_xlfn.DAYS(G28,F28) -> 33 | I28: =D28*H28*E28/365 -> 119.34247 | J28: =+D28*E28/12 -> 110 | M28: Closed | N28: Lent
A29: BYH | B29: Neal Isaacs | C29: 1343 Old BuckHorn Rd | D29: 75000 | E29: 0.1 | F29: 45573 | G29: 45968 | H29: =+_xlfn.DAYS(G29,F29) -> 395 | I29: =D29*H29*E29/365 -> 8116.4384 | J29: =+D29*E29/12 -> 625 | K29: 13 | L29: =+(J29*K29)-I29 -> 8.5616438 | M29: Closed
A30: BYH | B30: Neal Isaacs | C30: 908 Pond St | D30: 100000 | E30: 0.11 | F30: 45722 | G30: 45930 | H30: =+_xlfn.DAYS(G30,F30) -> 208 | I30: =D30*H30*E30/365 -> 6268.4932 | J30: =+D30*E30/12 -> 916.66667 | K30: 7 | L30: =+(J30*K30)-I30 -> 148.17352 | M30: Closed
A31: 401K | B31: Dave & Jana | C31: 612 Britton Ct | D31: 100300 | E31: 0.1 | F31: 45754 | G31: 46484 | H31: =+_xlfn.DAYS(G31,F31) -> 730 | I31: =D31*H31*E31/365 -> 20060 | J31: =+D31*E31/12 -> 835.83333 | L31: =+(J31*K31)-I31 -> -20060 | M31: open | O31: Jana Willers Roth | P31: 0.297 | Q31: =+$J$31*P31 -> 248.2425 | R31: David Willers Roth | S31: 0.453 | T31: =+$J$31*S31 -> 378.6325 | U31: David Willers Trad | V31: 0.25 | W31: =+$J$31*V31 -> 208.95833
A32: SYH | B32: Lola Williams | C32: 3413 Pinetree Ln | D32: 30000 | E32: 0.03 | F32: 45156 | G32: =NOW() -> 46188.334 | H32: =+_xlfn.DAYS(G32,F32) -> 1032 | I32: =D32*H32*E32/365 -> 2544.6575 | J32: 0 | L32: =+(J32*K32)-I32 -> -2544.6575 | M32: open | O32: Jana Willers Roth | P32: 0.297 | Q32: =+$I$31*P32 -> 5957.82 | R32: David Willers Roth | S32: 0.453 | T32: =+$I$31*S32 -> 9087.18 | U32: David Willers Trad | V32: 0.25 | W32: =+$I$31*V32 -> 5015
A33: BYH | B33: Neal Isaacs | C33: 4121 Tensity Dr | D33: 100000 | E33: 0.11 | F33: 45931 | G33: 46660 | H33: =+_xlfn.DAYS(G33,F33) -> 729 | I33: =D33*H33*E33/365 -> 21969.863 | J33: =+D33*E33/12 -> 916.66667 | K33: 0 | L33: =+(J33*K33)-I33 -> -21969.863 | M33: Closed
A34: SYH | B34: Neal Isaacs | C34: 1343 Old BuckHorn Rd | D34: 75000 | E34: 0.1 | F34: 45540 | G34: 45991 | H34: =+_xlfn.DAYS(G34,F34) -> 451 | I34: =D34*H34*E34/365 -> 9267.1233 | J34: =+D34*E34/12 -> 625 | K34: 13 | L34: =+(J34*K34)-I34 -> -1142.1233 | M34: Closed
A35: HM | B35: Neal Isaacs | C35: 7001 Outrigger Dr | D35: 75000 | E35: 0.1 | F35: 45992 | G35: 46751 | H35: =+_xlfn.DAYS(G35,F35) -> 759 | I35: =D35*H35*E35/365 -> 15595.89 | J35: =+D35*E35/12 -> 625 | K35: 13 | L35: =+(J35*K35)-I35 -> -7470.8904 | M35: open
A36: BYH | B36: Neal Isaacs | C36: 4121 Tensity Dr | D36: 100000 | E36: 0.11 | F36: 45931 | G36: 46690 | H36: =+_xlfn.DAYS(G36,F36) -> 759 | I36: =D36*H36*E36/365 -> 22873.973 | J36: =+D36*E36/12 -> 916.66667 | K36: 7 | L36: =+(J36*K36)-I36 -> -16457.306 | M36: Open

Sheet Projects
E1: 320 Rose Pl | F1: 7001 Outrigger | G1: 908 Pond St | H1: 612 Britton Ct | I1: 4121 Tensity Dr | J1: 6316 Willow Dell | K1: 2325 Cool Springs Rd | L1: 1343 Old Buckhorn Rd | M1: 115 Rosebrooks Dr | N1: 1426 Pleasant Garden | O1: 3413 Pinetree Ln | P1: 3325 Banks | R1: 2025 | S1: 2024 | T1: 2023 | U1: 2022 | V1: 2021 | W1: 2020
B2: =+"Project Totals for the Year - "& COUNT(E3:Q3) & " Active Projects" -> Project Totals for the Year - 12 Active Projects | E2: =+E1 -> 320 Rose Pl | F2: =+F1 -> 7001 Outrigger | G2: =+G1 -> 908 Pond St | H2: =+H1 -> 612 Britton Ct | I2: =+I1 -> 4121 Tensity Dr | J2: =+J1 -> 6316 Willow Dell | K2: =+K1 -> 2325 Cool Springs Rd | L2: =+L1 -> 1343 Old Buckhorn Rd | ... P2: =+P1 -> 3325 Banks | R2: =+COUNTIFS('Past Projects'!$E$73:$H$73,">0") -> 2 | S2: =+COUNTIFS('Past Projects'!$E$59:$G$59,">0") -> 2 | T2: =+COUNTIFS('Past Projects'!$E$45:$G$45,">0") -> 2 | U2: =+COUNTIFS('Past Projects'!$E$31:$H$31,">0") -> 4 | V2: =+COUNTIFS('Past Projects'!$E$17:$H$17,">0") -> 3 | W2: =+COUNTIFS('Past Projects'!$E$3:$H$3,">0") -> 3
B3: Total CMA: | C3: =+SUM(E3:P3) -> 4283800 | E3: =+[1]Profit!$B$4 -> 330000 | F3: =+[2]Profit!$B$4 -> 257300 | G3: =+[3]Profit!$B$4 -> 625000 | H3: =+[4]Profit!$B$4 -> 399000 | I3: =+[5]Profit!B4 -> 276800 | J3: =+[6]Profit!B4 -> 425000 | K3: =+[7]Profit!B4 -> 239000 | L3: =+[8]Profit!B4 -> 375000 | M3: =+[9]Profit!B4 -> 289000 | N3: =+[10]Profit!B4 -> 341700 | O3: =+[11]Todo!$E44 -> 287000 | P3: =+[12]Todo!$E44 -> 439000 | R3: =+'Past Projects'!$C73 -> 1100000 | S3: =+'Past Projects'!$C59 -> 335000 | T3: =+'Past Projects'!$C45 -> 750000 | U3: =+'Past Projects'!$C31 -> 1262529 | V3: =+'Past Projects'!$C17 -> 811800 | W3: =+'Past Projects'!$C3 -> 540000
B4: Total Purchase Cost: | C4: =+SUM(E4:P4) -> 1935961.3 | E4: =+[1]Profit!$K$47 -> 222245 | F4: =+[2]Profit!$K$47 -> 112039.66 | G4: =+[3]Profit!$K$47 -> 221572.01 | H4: =+[4]Profit!$K$47 -> 136402.79 | I4: =+[5]Profit!K47 -> 130291.26 | J4: =+[6]Profit!K48 -> 281338.38 | K4: =+[7]Profit!K47 -> 204823.02 | L4: =+[8]Profit!K48 -> 106750.1 | M4: =+[9]Profit!K47 -> 187323.94 | N4: =+[10]Profit!K41 -> 68.119459 | O4: =+[11]Todo!$E45 -> 185424.13 | P4: =+[12]Todo!$E45 -> 147682.86 | R4: =+'Past Projects'!$C74 -> 572564.34 | S4: =+'Past Projects'!$C60 -> 89099.278 | T4: =+'Past Projects'!$C46 -> 352369 | U4: =+'Past Projects'!$C32 -> 554594.92 | V4: =+'Past Projects'!$C18 -> 401770.9 | W4: =+'Past Projects'!$C4 -> 310642.71
B5: Total Rehab Expense: | C5: =+SUM(E5:P5) -> 906845.72 | E5: =-[1]Profit!$D$54 -> 278753.06 | F5: =-[2]Profit!$D$67 -> 18552.64 | G5: =-[3]Profit!$D$67 -> 322046.9 | H5: =-[4]Profit!$D$67 -> 9836.5426 | I5: =-[5]Profit!D67 -> 27991.342 | J5: =-[6]Profit!D67 -> 56164.766 | K5: =-[7]Profit!D67 -> 11744.259 | L5: =-[8]Profit!D68 -> 59670.686 | M5: =-[9]Profit!D65 -> 37573.025 | N5: =-[10]Profit!D63 -> 47412.056 | O5: =+[11]Todo!$E46 -> 5676.264 | P5: =+[12]Todo!$E46 -> 31424.184 | R5: =+'Past Projects'!$C75 -> 217103.43 | S5: =+'Past Projects'!$C61 -> 84974.5 | T5: =+'Past Projects'!$C47 -> 242267 | U5: =+'Past Projects'!$C33 -> 148708.11 | V5: =+'Past Projects'!$C19 -> 146350.08 | W5: =+'Past Projects'!$C5 -> 49980.701
B6: Total Debt | C6: =+SUM(E6:P6) -> 2205147.6 | E6: =+[1]Profit!$K$44 -> 197245 | F6: =+[2]Profit!$K$44 -> 158169.53 | G6: =+[3]Profit!$K$44 -> 25600 | H6: =+[4]Profit!$K$44 -> 223480.67 | I6: =+[5]Profit!K44 -> 174694 | J6: =+[6]Profit!K45 -> 256982.44 | K6: =+[7]Profit!K44 -> 174164 | L6: =+[8]Profit!K44 -> 197509.1 | M6: =+[9]Profit!K44 -> 181057.16 | N6: =+[10]Profit!K44 -> 273784 | O6: =+[11]Todo!$E47 -> 142424 | P6: =+[12]Todo!$E47 -> 200037.73
B7: Monthly Carrying Cost: | C7: =+SUM(E7:P7) -> 12865.227 | E7: =+[1]Profit!$K$41 -> 80.933166 | F7: =+[2]Profit!$K$41 -> 954.63203 | G7: =+[3]Profit!$K$41 -> 2537.3345 | H7: =+[4]Profit!$K$41 -> 1519.0177 | I7: =+[5]Profit!$K41 -> 1493.6556 | J7: =+[6]Profit!K42 -> 1885.255 | K7: =+[7]Profit!$K41 -> 18.343958 | L7: =+[8]Profit!K41 -> 665.33282 | M7: =+[9]Profit!K41 -> 1477.3036 | N7: =+[10]Profit!K41 -> 68.119459 | O7: =+[11]Todo!$E48 -> 890.28 | P7: =+[12]Todo!$E48 -> 1275.0192
B8: Monthly Income: | C8: =+SUM(E8:P8) -> -139596.5 | E8: =+[1]Profit!$I$54 -> 2025.4832 | F8: =+[2]Profit!$I$54 -> 1503.892 | G8: =+[3]Profit!$I$54 -> 0 | H8: =+[4]Profit!$I$54 -> 2 | I8: =+[5]Profit!I54 -> 1403.1378 | J8: 0 | K8: =+[7]Profit!I55 -> 429.6 | L8: =+[8]Profit!I55 -> 0 | M8: 0 | N8: =+[10]Profit!K57 -> -145850.91 | O8: =+[11]Todo!$E49 -> 890.3 | P8: =+[12]Todo!$E49 -> 0
B9: Total Expected Profit: | C9: =+SUM(E9:P9) -> #REF! | E9: =+[1]Profit!$K$62 -> 159927.32 | F9: =+[2]Profit!$K$62 -> 179458.24 | G9: =+[3]Profit!$K$62 -> 110005.26 | H9: =+[4]Profit!$K$62 -> 193865.4 | I9: =+[5]Profit!$K62 -> 149081.32 | J9: =+[6]Profit!K61 -> 39419.874 | K9: =+[7]Profit!$K62 -> 68361.077 | L9: =+[8]Profit!K62 -> 123695.07 | M9: =+#REF! -> #REF! | N9: =+[10]Profit!B4 -> 341700 | O9: =+[11]Todo!$E50 -> 104394.5 | P9: =+[12]Todo!$E50 -> 129335.61
B10: Total Realized Profit: | C10: =+SUM(R10:W10) -> 1221725.3 | E10: =+#REF! -> #REF! | F10: =+#REF! -> #REF! | G10: =+#REF! -> #REF! | H10: =+#REF! -> #REF! | I10: =+#REF! -> #REF! | J10: =+#REF! -> #REF! | K10: =+#REF! -> #REF! | L10: =+#REF! -> #REF! | M10: =+#REF! -> #REF! | O10: =+[11]Todo!$E51 -> 10439.45 | P10: =+[12]Todo!$E51 -> 12933.561 | R10: =+'Past Projects'!$C76 -> 130635.6 | S10: =+'Past Projects'!$C62 -> 91406.694 | T10: =+'Past Projects'!$C48 -> 155363.9 | U10: =+'Past Projects'!$C34 -> 471212.08 | V10: =+'Past Projects'!$C20 -> 257067.1 | W10: =+'Past Projects'!$C6 -> 116039.93
B11: Total Chartable Contribution: | C11: =+SUM(E11:P11) -> #REF! | E11: =+#REF! -> #REF! | F11: =+#REF! -> #REF! | G11: =+#REF! -> #REF! | H11: =+#REF! -> #REF! | I11: =+#REF! -> #REF! | J11: =+#REF! -> #REF! | K11: =+#REF! -> #REF! | L11: =+#REF! -> #REF! | M11: 0 | N11: =+#REF! -> #REF! | O11: =+[11]Todo!$E52 -> 0 | P11: =+[12]Todo!$E52 -> 0 | R11: =+[13]Past!$C$64 -> 0 | S11: =+[13]Past!$C$64 -> 0 | T11: =+[13]Past!$C$50 -> 0 | U11: =+[13]Past!$C$36 -> 15470.804 | V11: =+[13]Past!$C$22 -> 0 | W11: =+[13]Past!$C$8 -> 0
B12: Averages for Held Properties | E12: =+"Averages for all Years Across "& COUNT(E3:Q3)+SUM(R2:W2) & " Projects" -> Averages for all Years Across 28 Projects | N12: Total for all Years | R12: BYH 401K
B13: Average CMA: | C13: =+AVERAGE(E3:Q3) -> 356983.33 | E13: Average CMA: | F13: =+SUM(E3:X3)/(COUNT(E3:P3)+SUM($R$2:$X$2)) -> 324397.46 | N13: Total CMA: | P13: =+SUM(E3:W3) -> 9083129 | R13: Heritage Mangement
B14: Average Purchase Cost: | C14: =+AVERAGE(E4:Q4) -> 161330.11 | E14: Average Purchase Cost: | F14: =+SUM(E4:X4)/(COUNT(E4:P4)+SUM($R$2:$X$2)) -> 150607.23 | N14: Total Purchase Cost: | P14: =+SUM(E4:$W$4) -> 4217002.4 | R14: Sell Your Home
B15: Average Rehab Expense: | C15: =+AVERAGE(E5:Q5) -> 75570.477 | E15: Average Rehab Expense: | F15: =+SUM(E5:X5)/(COUNT(E5:P5)+SUM($R$2:$X$2)) -> 64151.055 | N15: Total Rehab Expense: | P15: =+SUM(E5:W5) -> 1796229.5 | R15: Buy Your Home
B16: Average Profit: | C16: =+AVERAGE(E9:P9) -> #REF! | E16: Average Profit: | F16: =+SUM(E9:X10)/(COUNT(E9:P9)+SUM($R$2:$X$2)) -> #REF! | N16: Total Profit: | P16: =+SUM($E$9:$W$10) -> #REF! | R16: Completed Previous Years
B18: =+B9 -> Total Expected Profit: | C18: =+C9 -> #REF!
B19: Cash Reserves: | C19: =+Cards!N84 -> 200000 | E19: =SUM(C18:D19) -> #REF!
B20: Monthly Cash Flow: | E20: =+C8-C7 -> -152461.73
B21: Credit Card Monthly Payments | E21: =-Cards!S79 -> -7997
B22: Line of Credit Monthly Payments | E22: =-Cards!S80 -> -10482.523
B23: Monthly Personal Loan Payments: | E23: =-Cards!S81 -> -1164
B24: Admin: | D24: -668
B25: Admin(SYH): | D25: -613
B26: Marketing: | D26: -1710
B27: Operations: | D27: -872
B28: Tech: | D28: -656
B29: Monthly Business Expense : | E29: =SUM(D24:D28) -> -4519
B30: Monthly Personal Dispersment: | E30: -500
B32: Business Cash Flow | D32: Runway (years)
B33: =SUM(E20:E30) -> -177124.25 | D33: =E19/-B33/12 -> #REF!

Sheet Past Projects
B2: Properties Completed in 2020 | D2: Notes | E2: 1223 Roffler | F2: 2025 Metacomet | G2: 5619 Marthonna | K2: Property | L2: Year | M2: Purchase Price | N2: Rehab | O2: Sale Price | P2: Repaid Loans | Q2: Total Borrowed
B3: Total CMA: | C3: =+SUM(E3:H3) -> 540000 | E3: 150000 | F3: 195000 | G3: 195000 | J3: 1 | K3: 5619 Marthonna | L3: 2020 | M3: =+G4 -> 128687.99 | N3: =+G5 -> 23252.602 | O3: =+G3 -> 195000 | P3: =+E7 -> 62037 | Q3: =+P3+Q4 -> 251875
B4: Total Purchase Cost: | C4: =+SUM(E4:$H$4) -> 310642.71 | E4: 71644.86 | F4: 110309.86 | G4: 128687.99 | J4: =+J3+1 -> 2 | K4: 2025 Metacomet | L4: 2020 | M4: =+F4 -> 110309.86 | N4: =+F5 -> 20425.14 | O4: =+F3 -> 195000 | P4: =+F7 -> 75240 | Q4: =+P4+Q5 -> 189838
B5: Total Rehab Expense: | C5: =+SUM(E5:H5) -> 49980.701 | E5: 6302.96 | F5: 20425.14 | G5: 23252.602 | J5: =+J4+1 -> 3 | K5: 1223 Roffler | L5: 2020 | M5: =+E4 -> 71644.86 | N5: =+E5 -> 6302.96 | O5: =+E3 -> 150000 | P5: =+G7 -> 114598 | Q5: =+P5 -> 114598
B6: Total Realized Profit: | C6: =+SUM($E$6:$H$6) -> 116039.93 | E6: 37694.072 | F6: 52771.49 | G6: 25574.364 | J6: =+J5+1 -> 4 | K6: =+G16 -> 1201 Hazelnut | L6: 2021 | M6: =+G18 -> 74709 | N6: =+G19 -> 71081.807 | O6: =+G17 -> 237900 | P6: =+G21 -> 96542 | Q6: =+P6+Q3 -> 348417
B7: Total Repaid Debt: | C7: =+SUM(E7:H7) -> 251875 | E7: 62037 | F7: 75240 | G7: 114598 | J7: =+J6+1 -> 5 | K7: =+F16 -> 178 Patricia | L7: 2021 | M7: =+F18 -> 107061.9 | N7: =+F19 -> 47760.57 | O7: =+F17 -> 210000 | P7: =+F21 -> 51700 | Q7: =+P7+Q6 -> 400117
B8: Total Chartable Contribution: | C8: =+SUM($E$8:$H$8) -> 0 | J8: =+J7+1 -> 6 | K8: =+E16 -> 2153 Haig Point | L8: 2021 | M8: =+E18 -> 220000 | N8: =+E19 -> 27507.698 | O8: =+E17 -> 363900 | P8: =+E21 -> 218000 | Q8: =+P8+Q7 -> 618117
B9: Average CMA: | C9: =+AVERAGE(E3:G3) -> 180000 | J9: =+J8+1 -> 7 | K9: =+H30 -> 3007 Eric | L9: 2022 | M9: =+H32 -> 167033.66 | N9: =+H33 -> 38679.38 | O9: =+H31 -> 299000 | P9: =+H35 -> 206590 | Q9: =+P9+Q8 -> 824707
B10: Average Purchase Cost: | C10: =+AVERAGE(E4:G4) -> 103547.57 | J10: =+J9+1 -> 8 | K10: =+G30 -> 120 Keith | L10: 2022 | M10: =+G32 -> 85975.79 | N10: =+G33 -> 82805.727 | O10: =+G31 -> 330000 | P10: =+G35 -> 59415 | Q10: =+P10+Q9 -> 884122
B11: Average Rehab Expense: | C11: =+AVERAGE(E5:G5) -> 16660.234 | E11: Completed for Sell Your Home | J11: =+J10+1 -> 9 | K11: =+F30 -> 1900 Red Quartz | L11: 2022 | M11: =+F32 -> 174585.47 | N11: =+F33 -> 12223 | O11: =+F31 -> 423529 | P11: =+F35 -> 230800 | Q11: =+P11+Q10 -> 1114922
B12: Average Profit: | C12: =+AVERAGE(E6:G6) -> 38679.975 | E12: Completed for Buy Your Home | J12: =+J11+1 -> 10 | K12: =+E30 -> 202 Avery | L12: 2022 | M12: =+E32 -> 127000 | N12: =+E33 -> 15000 | O12: =+E31 -> 210000 | P12: =+E35 -> 0 | Q12: =+P12+Q11 -> 1114922
J13: =+J12+1 -> 11 | K13: =+F44 -> 2608 Alton | L13: 2023 | M13: =+F46 -> 102500 | N13: =+F47 -> 144075 | O13: =+F45 -> 315000 | P13: =+F49 -> 231000 | Q13: =+P13+Q12 -> 1345922
J14: =+J13+1 -> 12 | K14: =+E44 -> 164 Churchill Dr | L14: 2023 | M14: =+E46 -> 249869 | N14: =+E47 -> 98192 | O14: =+E45 -> 435000 | P14: =+E49 -> 256000 | Q14: =+P14+Q13 -> 1601922
J15: =+J14+1 -> 13 | K15: =+F58 -> 6004 Sandy Run | L15: 2024 | M15: =+F60 -> 79099.139 | N15: =+F61 -> 84974.5 | O15: =+F59 -> 285000 | P15: =+F63 -> 65943 | Q15: =+P15+Q14 -> 1667865
B16: Properties Completed in 2021 | D16: Notes | E16: 2153 Haig Point | F16: 178 Patricia | G16: 1201 Hazelnut | J16: =+J15+1 -> 14 | K16: =+E58 -> 3021 Pearces Rd | L16: 2024 | M16: =+E60 -> 10000.139 | N16: =+E61 -> 0 | O16: =+E59 -> 50000 | P16: =+E63 -> 0 | Q16: =+P16+Q15 -> 1667865
B17: Total CMA: | C17: =+SUM(E17:H17) -> 811800 | E17: 363900 | F17: 210000 | G17: 237900 | J17: =+J16+1 -> 15 | K17: =+G72 -> 5008 Larchmont | L17: 2025 | M17: =+G74 -> 352162.49 | N17: =+G75 -> 159759.01 | O17: =+G73 -> 630000 | P17: =+G77 -> 554121.49 | Q17: =+P17+Q16 -> 2221986.5
B18: Total Purchase Cost: | C18: =+SUM(E18:$H$18) -> 401770.9 | E18: 220000 | F18: 107061.9 | G18: 74709 | J18: =+J17+1 -> 16 | K18: =+F72 -> 8225 Burgwyn Ln | L18: 2025 | M18: =+F74 -> 220401.85 | N18: =+F75 -> 57344.421 | O18: =+F73 -> 470000 | P18: =+F77 -> 196273.85 | Q18: =+P18+Q17 -> 2418260.3
B19: Total Rehab Expense: | C19: =+SUM(E19:H19) -> 146350.08 | E19: 27507.698 | F19: 47760.57 | G19: 71081.807
B20: Total Realized Profit: | C20: =+SUM($E$20:$H$20) -> 257067.1 | E20: 92658.782 | F20: 64240.53 | G20: 100167.79
B21: Total Repaid Debt: | C21: =+SUM(E21:H21) -> 366242 | E21: =152983+65017 -> 218000 | F21: =9700+42000 -> 51700 | G21: =47279+19263+30000 -> 96542
B22: Total Chartable Contribution: | C22: =+SUM($E$22:$H$22) -> 0
B23: Average CMA: | C23: =+AVERAGE(E17:G17) -> 270600
B24: Average Purchase Cost: | C24: =+AVERAGE(E18:G18) -> 133923.63
B25: Average Rehab Expense: | C25: =+AVERAGE(E19:G19) -> 48783.358 | E25: Completed for Sell Your Home
B26: Average Profit: | C26: =+AVERAGE(E20:G20) -> 85689.035 | E26: Completed for Buy Your Home
B30: Properties Completed in 2022 | D30: Notes | E30: 202 Avery | F30: 1900 Red Quartz | G30: 120 Keith | H30: 3007 Eric
B31: Total CMA: | C31: =+SUM(E31:I31) -> 1262529 | E31: 210000 | F31: 423529 | G31: 330000 | H31: 299000
B32: Total Purchase Cost: | C32: =+SUM(E32:$I$32) -> 554594.92 | E32: 127000 | F32: 174585.47 | G32: 85975.79 | H32: 167033.66
B33: Total Rehab Expense: | C33: =+SUM(E33:I33) -> 148708.11 | E33: 15000 | F33: 12223 | G33: 82805.727 | H33: 38679.38
B34: Total Realized Profit: | C34: =+SUM($E$34:$I$34) -> 471212.08 | E34: 67485.868 | F34: 154708.04 | G34: 154490.2 | H34: 94527.968
B35: Total Repaid Debt: | C35: =+SUM(E35:H35) -> 496805 | E35: 0 | F35: =130800+100000 -> 230800 | G35: 59415 | H35: =131590+75000 -> 206590
B36: Total Chartable Contribution: | C36: =+SUM($E$36:$I$36) -> 15470.804 | F36: 15470.804
B37: Average CMA: | C37: =+AVERAGE(E31:H31) -> 315632.25
B38: Average Purchase Cost: | C38: =+AVERAGE(E32:H32) -> 138648.73
B39: Average Rehab Expense: | C39: =+AVERAGE(E33:H33) -> 37177.027 | E39: Completed for Sell Your Home
B40: Average Profit: | C40: =+AVERAGE(E34:H34) -> 117803.02 | E40: Completed for Buy Your Home
B44: Properties Completed in 2023 | D44: Notes | E44: 164 Churchill Dr | F44: 2608 Alton
B45: Total CMA: | C45: =+SUM(E45:G45) -> 750000 | E45: 435000 | F45: 315000
B46: Total Purchase Cost: | C46: =+SUM(E46:$G$46) -> 352369 | E46: 249869 | F46: 102500
B47: Total Rehab Expense: | C47: =+SUM(E47:G47) -> 242267 | E47: 98192 | F47: =+F45+-F46-F48 -> 144075
...
