Workbook
Name Milestone_Marker: 'Gnatt Chart'!$G$4
Name Project_Start: 'Gnatt Chart'!$F$2
Name Scrolling_Increment: 'Gnatt Chart'!$AB$26
Name Today: TODAY()

Sheet Profit
A1: Flip, Hold or Wholetale: | B1: hold | E1: Buy | F1: Your Home LLC
B2: 3413 Pinetree Ln, Greenville, NC 27858 | H2: Monthly Cash Flow | J2: Hearing Date:
A3: Income | D3: Immediate | F3: Upon Sale
A4: CMA: | B4: 287000 | J4: Finalized: | K4: No
A5: % Above/Below Market Sale: | B5: -0.15 | C5: 0.1 | N5: Zillow | O5: 45161 | P5: 276600
A6: Sale Price: | B6: =+B4 + IF(B1="Hold",B4*C5,0) + IF(B1="wholetale",B4*B5,0) -> 315700 | G6: =IF($B$1="hold",$B$4,$B$6) -> 287000 | J6: Anuual Growth: | K6: 0.1 | O6: 45754 | P6: 303900
A7: NonRefundable Deposit: | D7: =+B7 -> 0 | F7: =-B7 -> 0 | G7: =+IF($B$1="hold",$K$6,0)*$C$35/12*B4 -> 28700 | H7: =+IF($B$1="hold","<-- Apprication -----------","") -> <-- Apprication -----------
A8: Rent: | B8: 890.3 | I8: =IF(B1="Hold",+B8,"") -> 890.3 | J8: Sq Footage | K8: 1899
C9: Net Income: | D9: Net Income: | E9: =SUM(D4:D8) -> 0 | F9: =+SUM(F4:G8) -> 315700 | H9: =SUM(H4:I8) -> 890.3
A11: Expenses
A12: Reinstatment Cost 1st: | B12: =12028-11056+12028 -> 13000 | D12: =-B12 -> -13000 | G12: =IF(K4="Yes",0.3*B12,"") | H12: <-- Approx Pay-Down | J12: If the Subject To Value is finalized, zero-out the Pay-Down savings
A13: Subject To 1st:Truist | B13: 0.03125 | C13: 142424 | F13: =-C13 -> -142424
A14: Reinstatment Cost 2st: | F14: =-+(120-C34)*(C14/120) -> 0 | H14: =-(C14*B14/12) -> 0
A15: Subject To 2st:Notes | B15: 0.1 | F15: =-C15 -> 0 | H15: =-C15/120-(C15*B15/12) -> 0
A16: Liens - IRS & HOA | D16: =-C16 -> 0
A17: Partners Share % | B17: 0
A18: or Seller Payout: | B18: 30000 | D18: =-B18 -> -30000 | J18: Yellow cells can be edited
A19: HOA Fees(Catch Up) | C19: 0 | D19: =-B19 -> 0 | N19: =SUM(B12:C18) -> 185424.13
A20: Months Carried | B20: 6 | J20: Do not edit Green cells. They are highlighted only to show profit
A21: Mortgage Payment: | B21: =262.98+392.24+235.06 -> 890.28 | H21: =IF(B1="Hold",-B21,"") -> -890.28
A22: Mortgage Payment - 2nd: | H22: =IF(B1="Hold",-B22,"") -> 0 | N22: =+N19+B30 -> 191100.4
A23: Property Insurance | B23: 0 | H23: =IF(B1="Hold",-B23,"") -> 0
A24: HOA Fees (monthly) | B24: 0 | H24: =IF(B1="Hold",-B24,"") -> 0
A25: Electric | B25: 0
A26: water | B26: 0
A27: Carrying Cost | B27: =+B20*SUM(B21:B26) -> 5341.68 | D27: =-B27 -> -5341.68 | J27: Purchase Cost | K27: =+SUM(B12:C16)+B18 -> 185424.13
A28: Private Lender Rate: | B28: 0.1 | C28: no
A29: 75%ARV-Debt: | B29: =IF(C28="NO",0,+(B6*0.75)-(C13+C14+C15)) -> 0 | E29: =IF(B29<0,0,B29) -> 0 | F29: =IF(C28="No","",-E29-(B20*E29*B28/12)) | H29: =-IF($B$1="Hold",E29*B28/12,0) -> 0 | J29: Out of Pocket | K29: =+B12+C14+C16+B18+B30 -> 48676.264
A30: Rehab: | B30: =-D51 -> 5676.264 | D30: =-B30 -> -5676.264
A31: Marketing: | B31: 600 | D31: =-B31 -> -600 | J31: PL Balance +Interest
A32: Seller Realtor's Flat Fee | B32: 1 | C32: =+B32*399 -> 399 | F32: =-C32 -> -399
A33: Seller Realtor's Fee Percent: | B33: 0 | C33: 0.026 | F33: =-B33*C33*$F$9 -> 0
A34: Buyers Realtors Fee Percent: | B34: 1 | C34: 0.024 | F34: =-B34*C34*$F$9 -> -7576.8
A35: Number of Rent Payments : | C35: 12
A36: Buyer Assistance | F36: =-C36 -> 0
A37: Buying Closing Cost: | B37: =+D71 -> 5998 | D37: =-B37 -> -5998
A38: Selling Closing Cost: | B38: =+D82 -> 290 | F38: =-B38 -> -290
C39: Net Expenses: | E39: =+SUM(D12:D38) -> -60615.944 | F39: =+SUM(F12:F38) -> -150689.8 | H39: =+SUM(H9:I38) -> 0.02
B40: Immediate Profit: | E40: =+SUM(E9:E39) -> -60615.944 | F40: =+SUM(F9:G38) -> 165010.2
E41: Long Term Profit: | G41: =+E40+F40 -> 104394.26 | J41: Partners Profit Share | K41: Our Profit Share
...

Sheet MOG
C1: Multiple Offer Generator | I1: ="Hi "&B3 & IF(B4 ="",""," and ") &B4&", Thank you for the opportunity to make an offer on your property at "&Profit!B2&". I have several options I would like for you to consider. I also want to give you several very good reasons for you to work with us here at Buy Your Home LLC. "&REPT(" ",6)&"1. If you sell your home to us, you will incur no expense from the transaction. We will pay all: "&REPT(" ",20)&"Closing Cost "&REPT(" ",20)&"Attorney's Fees "&REPT(" ",20)&"Realtor Commissions "&REPT(" ",6) &" 2. We can close fast. It will be a matter of days, probably less than two weeks, when we can "&REPT(" ",11) &"close at our attorney's office and get you your cash. "&REPT(" ",6) &"3. We cover the cost, time, and effort of paying any money due to any lender or HOA "&REPT(" ",11) &"involved." -> Hi Nikki, Thank you for the opportunity to make an offer on your property at 3413 Pinetree Ln, Greenville, NC 27858. I have several options I would like for you to consider. I also want to give you several very good reasons for you to work with us here at Buy Your Home LLC. 1. If you sell your home to us, you will incur no expense from the transaction. We will pay all: Closing Cost Attorney's Fees Realtor Commissions 2. We can close fast. It will be a matter of days, probably less than two weeks, when we can close at our attorney's office and get you your cash. 3. We cover the cost, time, and effort of paying any money due to any lender or HOA involved. | J1: Buyers Copy | K1: =+I1&IF(N14="X",O14,"")&" "& IF(H15="X",I15,"") &" "& IF(H16="X",I16,"") &" "& IF(H20="X",I20,"") &" "& IF(H26="X",I26,"") &" "& IF(H33="X",I33,"") & " "& IF(H42="X",I42,"") & " "& IF(H52="X",I52,"") & " "& IF(H61="X",I61,"") & " "& IF(H74="X",I74,"") & " "& IF(H81="X",I81,"") & " "& IF(H82="X",I82,"") & " "& "" -> Hi Nikki, Thank you for the opportunity to make an offer on your property at 3413 Pinetree Ln, Greenville, NC 27858. I have several options I would like for you to consider. I also want to give you several very good reasons for you to work with us here at Buy Your Home LLC. 1. If you sell your home to us, you will incur no expense from the transaction. We will pay all: Closing Cost Attorney's Fees Realtor Commissions 2. We can close fast. It will be a matter of days, probably less than two weeks, when we can close at our attorney's office and get you your cash. 3. We cover the cost, time, and effort of paying any money due to any lender or HOA involved. Here are some purchase options for your consideration. They are presented in summary form and I am sure you will have some questions that I will be happy to take time needed to answer. Each option below will have more value than the one above it. Option 1: Cash plus Assumption of Mortgage This is a cash payment, at closing. We will take responsibility for the existing mortgage, HOA fees, and any liens that may be discovered until we are able to resell the property. This offer is: Cash: $30,000.00 Total Value: $30,000.00 Option 2: Cash plus Promissory Note The explanation for the cash component is the same as for option 1. However, 20.% of the value of the offer will be cash and 80.% will be in the form of a promissory note, complete with a Deed of Trust. The note will have a 24-month term that will pay simple interest at the rate of 4% per year. Cash: $6,000.00 12 Month Note: $44,000.00 Interest Earned: $3,520.00 $146.67 per month Total Value: $53,520.00 Option 3: Cash plus Beneficial Interest in Trust The explanation for the cash component is the same as for option 2. Instead of a note as in Option 2, you will share in the profit earned when the property is resold. The property will be placed into a trust that you will share a beneficial interest in. The advantage here is you will benefit from the appreciated value of the property, over time. You will receive quarterly reports on the financial status of the property. Cash: $10,000.00 Interest in Trust: 70.% Expected Sellers Profit: $107,166.15 * Expected 10% appreciation per year Expected Value: $117,166.15 ** After 24 months. Nikki, this offer is contingent upon a normal due diligence period. The values of each option are predicated on some assumptions that may need to be altered upon further discovery. The more we can learn from you, in advance, the more reliable these options may be considered. When you decide which offer you prefer, I will email you a contract along with an earnest money payment. We are ready to be of service in any way we can. This offer is based on Zillow's Zestimate of $287,000.00. We will clean and prepare the property for a quick resale. There is also an assumption that the property will need no rehab. If that turns out to not be true, an allowance will need to be made. In any case, that will be decided in the due diligence period of the contract. Sincerely, Wes Browning (919) 899-2104
A3: Seller 1: | B3: Nikki | C3: Kulas | J3: no
A4: Seller 2:
A5: email:
A6: Phone #:
A9: Offer 1 | B9: Traditional, All Cash
B10: This is an all cash payment, at closing with no other allowances considered. Seller pays all Mortgages, liens, HOA expenses out of closings proceedings.
F12: Seller's Equity
B13: Sales Price | C13: ARV | D13: Debt | G13: BYH's Profit
B14: =+D14+F14 -> 182424.13 | C14: =+Profit!B4 -> 287000 | D14: =+Profit!K27-Profit!B18 -> 155424.13 | F14: =+B24-(B24*F16) -> 27000 | G14: =+C14-D14-F14+Profit!E39+Profit!B18 -> 73959.925
D15: BYH Out of Pocket: | E15: =+Profit!$K$29 -> 48676.264
D16: BYH Profit/Out of Pocket: | E16: =+G14/E15 -> 1.5194248 | F16: 0.1 | H16: X | I16: ="Here are some purchase options for your consideration. They are presented in summary form and I am sure you will have some questions that I will be happy to take time needed to answer. Each option below will have more value than the one above it." -> Here are some purchase options for your consideration. They are presented in summary form and I am sure you will have some questions that I will be happy to take time needed to answer. Each option below will have more value than the one above it.
D17: Buy Your Home's % of Profit: | E17: =+G14/(F14+G14) -> 0.73256715 | F17: less than Opt 2
A19: Offer 2 | B19: Cash plus Assumption of Mortgage | D19: *This is the default values from the Profit Sheet. | H19: =IF(H20="X",1,0) -> 0
B20: Cash payment in conjunction with taking the existing mortgage subject to: | I20: ="Option "&H19&": "&""&B9&" "&REPT(" ",6)&"This is a, traditional, all cash purchase, at closing with no other allowances considered. Seller "&REPT(" ",6)&"pays all mortgages, liens, HOA expenses, etc., out of closings disbursements. This option has " & REPT(" ",6) & "the smallest value for the seller. Our cash offer is: "&REPT(" ",43) &"Cash:"&REPT(" ",21)&+TEXT(B14,"$#,##0.00") & IF(J3="yes",REPT(" ",10) & "Profit = "& TEXT(G14,"$#,##0.00"),"" )& " "&REPT(" ",32) & "Total Value:"&REPT(" ",21)&TEXT(F14,"$#,##0.00") -> Option 0: Traditional, All Cash This is a, traditional, all cash purchase, at closing with no other allowances considered. Seller pays all mortgages, liens, HOA expenses, etc., out of closings disbursements. This option has the smallest value for the seller. Our cash offer is: Cash: $182,424.13 Total Value: $27,000.00
B21: After reinstating existing loans and HOA fees
F22: Seller's Total Value
B23: Cash | G23: BYH's Profit
B24: =+Profit!B18 -> 30000 | C24: <- The default value form profit sheet | F24: =+B24 -> 30000 | G24: =+Profit!K45+Profit!B18-B24 -> 104394.5
D25: BYH Out of Pocket: | E25: =+Profit!$K$29 -> 48676.264 | H25: =IF(H26="X",1+H19,H19) -> 1
D26: BYH Profit/Out of Pocket: | E26: =+G24/E25 -> 2.1446694 | H26: x | I26: ="Option " & H25 & ": "&""&B19&" "&REPT(" ",6) & "This is a cash payment, at closing. We will take responsibility for the existing mortgage, HOA "&REPT(" ",6) & "fees, and any liens that may be discovered until we are able to resell the property. This offer is: "&REPT(" ",43)&"Cash:"&REPT(" ",22) & TEXT(F24,"$#,##0.00") & IF(J3="yes",REPT(" ",10) & "Profit = "& TEXT(G24,"$#,##0.00"),"" ) & " "&REPT(" ",32)&"Total Value:"&REPT(" ",22) & TEXT(F24,"$#,##0.00") -> Option 1: Cash plus Assumption of Mortgage This is a cash payment, at closing. We will take responsibility for the existing mortgage, HOA fees, and any liens that may be discovered until we are able to resell the property. This offer is: Cash: $30,000.00 Total Value: $30,000.00
D27: Buy Your Home's % of Profit: | E27: =+G24/(F24+G24) -> 0.77677657
A30: Offer 3 | B30: Cash plus Promissory Note | D30: - this is the one to stear seller to:
B31: Cash payment in conjunction with taking the existing mortgage subject to: | I31: ="This is a cash payment, at closing, in conjunction with reinstating the existing mortgage taking responsibility for those payments, HOA fees and other liens that may be discovered. Our cash offer is:" -> This is a cash payment, at closing, in conjunction with reinstating the existing mortgage taking responsibility for those payments, HOA fees and other liens that may be discovered. Our cash offer is:
B32: After reinstating existing loans and HOA fees | H32: =IF(H33="X",H25+1,H25) -> 2
H33: x | I33: ="Option " & H32 & ": " &""&B30&" "&REPT(" ",6)&"The explanation for the cash component is the same as for option "& H25 & ". However, "&TEXT(B38,"##.#%") &" of the " & REPT(" ",6) & "value of the offer will be cash and "& TEXT(C38,"##.#%") &" will be in the form of a promissory note, complete " & REPT(" ",6) & "with a Deed of Trust. The note will have a " & D35 & "-month term that will pay simple interest at " & REPT(" ",6) & "the rate of "&E37*100&"% per year. "& REPT(" ",43) & "Cash:" & REPT(" ",23) & TEXT(B37,"$#,##0.00") & IF(J3="yes",REPT(" ",10) & "Profit = "& TEXT(G37,"$#,##0.00"),"" ) &" "& REPT(" ",24) & "12 Month Note:" & REPT(" ",24) & TEXT(C37,"$#,##0.00")&" "& REPT(" ",25) & "Interest Earned:" & REPT(" ",25) & TEXT(D37,"$#,##0.00") &REPT(" ",12)&+TEXT(D37/D35,"$#,##0.00") & " per month" & " "& REPT(" ",32) & "Total Value:" & REPT(" ",20) & TEXT(F37,"$#,##0.00") -> Option 2: Cash plus Promissory Note The explanation for the cash component is the same as for option 1. However, 20.% of the value of the offer will be cash and 80.% will be in the form of a promissory note, complete with a Deed of Trust. The note will have a 24-month term that will pay simple interest at the rate of 4% per year. Cash: $6,000.00 12 Month Note: $44,000.00 Interest Earned: $3,520.00 $146.67 per month Total Value: $53,520.00
C34: Note is a simple interest note for: | D34: Months | F34: (Based on Current Valuation)
B35: Value added to Note: | C35: 20000 | D35: 24 | F35: Seller's Total Value
B36: Cash | C36: Note | D36: Interest Earned | E36: Interest Rate | G36: BYH's Profit
B37: =+(Profit!$B$18)*B38 -> 6000 | C37: =+(Profit!$B$18)-B37+C35 -> 44000 | D37: =+C37*D35/12*E37 -> 3520 | E37: 0.04 | F37: =+SUM(B37:D37) -> 53520 | G37: =+Profit!$K$45-D37-C35 -> 80874.496
B38: 0.2 | C38: =1-B38 -> 0.8
D39: BYH Out of Pocket: | E39: =+Profit!$K$29-C37+C35 -> 24676.264
D40: BYH Profit/Out of Pocket: | E40: =+G37/E39 -> 3.2774206
D41: Buy Your Home's % of Profit: | E41: =+G37/(F37+G37) -> 0.60176941 | H41: =IF(H42="X",H32+1,H32) -> 3
A42: Offer 4 | B42: Cash plus Beneficial Interest in Trust | H42: x | I42: ="Option " & H41 & ": " & B42&" "&REPT(" ",6)&"The explanation for the cash component is the same as for option "& H32 & ". Instead of a note as in " & REPT(" ",6) & "Option "& H32 & ", you will share in the profit earned when the property is resold." &" The property will " & REPT(" ",6) & "be placed into a trust that you will share a beneficial interest in. The advantage here is you will " & REPT(" ",6) & "benefit from the appreciated value of the property, over time." &" You will receive quarterly " & REPT(" ",6) & "reports on the financial status of the property. "& REPT(" ",43) & "Cash:" & REPT(" ",23) & TEXT(B50,"$#,##0.00") & IF(J3="yes",REPT(" ",10) & "Profit = "& TEXT(G50,"$#,##0.00"),"" ) &" "& REPT(" ",24) & "Interest in Trust:" & REPT(" ",33) & TEXT(D50,"#.#%")&" "& REPT(" ",13) & "Expected Sellers Profit:" & REPT(" ",23) & TEXT(E50,"$#,##0.00") &" * Expected "&Profit!$K$6*100&"% appreciation per year" & " "& REPT(" ",26) & "Expected Value:" & REPT(" ",20) & TEXT(F50,"$#,##0.00") & " ** After " & D35 &" months." -> Option 3: Cash plus Beneficial Interest in Trust The explanation for the cash component is the same as for option 2. Instead of a note as in Option 2, you will share in the profit earned when the property is resold. The property will be placed into a trust that you will share a beneficial interest in. The advantage here is you will benefit from the appreciated value of the property, over time. You will receive quarterly reports on the financial status of the property. Cash: $10,000.00 Interest in Trust: 70.% Expected Sellers Profit: $107,166.15 * Expected 10% appreciation per year Expected Value: $117,166.15 ** After 24 months.
B43: Cash payment in conjunction with taking the existing mortgage subject to:
B44: After reinstating existing loans and HOA fees
B45: Profit split is a split of the profits upon the eventual sale of the pproperty.
B46: Profits will be calculated after deducting all expenses incurred from the sales price
F47: (Based on Future Valuation)
...

Sheet Todo
B1: =+Profit!B2 -> 3413 Pinetree Ln, Greenville, NC 27858 | D1: Notes | F1: 3021 Pearces Rd | G1: 6004 Sandy Run | H1: Larchmont | I1: 3325 Banks | J1: 2608 Alton | K1: 202 Avery | L1: 1900 Red Quartz | M1: 120 Keith | N1: 3007 Eric | O1: 2153 Haig Point | P1: 178 Patricia | Q1: 1201 Hazelnut | R1: 1223 Roffler | S1: 2025 Metacomet | T1: 5619 Marthonna
A2: New Seller
B3: Purchase & Sale Agreement | C3: Yes | F3: 0 | H3: Yes | I3: =+[1]Todo!$C3 -> Yes
B4: Letter of Authorization | C4: Yes | F4: 0 | H4: Yes (2) | I4: =+[1]Todo!$C4 -> Yes
B5: Reinstatement Quote | C5: Yes | F5: 0 | H5: Yes (2) | I5: =+[1]Todo!$C5 -> Yes
B6: Bank Acknowledgement | C6: Yes | F6: 0 | H6: yes | I6: =+[1]Todo!$C6 -> Yes
B7: On-Line Bank Access | C7: yes | F7: 0 | H7: yes | I7: =+[1]Todo!$C7 -> yes
B8: Change Mail | C8: yes | F8: 0 | H8: yes | I8: =+[1]Todo!$C8 -> yes
B9: Bank Attorney letter of dismisal | C9: na | F9: 0 | H9: yes | I9: =+[1]Todo!$C9 -> na
B10: Get (orignal) Property Authorization | C10: na | F10: 0 | H10: yes | I10: =+[1]Todo!$C10 -> na
F11: 0 | H11: 0 | I11: =+[1]Todo!$C11 -> 0
A12: After Purchase | F12: After Purchase | H12: 0 | I12: =+[1]Todo!$C12 -> 0
B13: Insurance Claim for Roof | F13: 0 | H13: yes | I13: =+[1]Todo!$C13 -> na
B14: Locks Changed | D14: na till vacant | F14: 0 | H14: yes | I14: =+[1]Todo!$C14 -> na
B15: Gas Service | D15: na till vacant | F15: 0 | H15: yes | I15: =+[1]Todo!$C15 -> na
B16: Electrical & Water Service | D16: na till vacant | F16: 0 | H16: yes | I16: =+[1]Todo!$C16 -> yes
B17: Rehab bids | D17: na till vacant | F17: 0 | H17: yes | I17: =+[1]Todo!$C17 -> 0
B18: Order Dumpster | D18: na till vacant | F18: 0 | H18: n/a | I18: =+[1]Todo!$C18 -> yes
B19: A/C service | D19: na till vacant | F19: 0 | H19: yes | I19: =+[1]Todo!$C19 -> na
B20: Establish Mortgage payment | C20: yes | F20: 0 | H20: yes | I20: =+[1]Todo!$C20 -> yes
B21: Remove PMI | F21: 0 | H21: yes | I21: =+[1]Todo!$C21 -> na
B22: Claim Property on Zillow | F22: 0 | H22: yes | I22: =+[1]Todo!$C22 -> yes
B23: Add property to Our Website | F23: 0 | H23: yes | I23: =+[1]Todo!$C23 -> yes
B24: Make sure deed and agreement are done | C24: yes | D24: waiting on recorded deed | F24: 0 | H24: yes | I24: =+[1]Todo!$C24 -> yes
B25: Change Insurance | F25: 0 | H25: yes | I25: =+[1]Todo!$C25 -> yes
B26: Get Insurance payments installed | F26: 0 | H26: yes | I26: =+[1]Todo!$C26 -> na
B27: Add Private Lender to Insurance | F27: 0 | H27: yes | I27: =+[1]Todo!$C27 -> 0
B28: Probate letters - Notice to Creditors | C28: na | F28: 0 | H28: yes | I28: =+[1]Todo!$C28 -> na
F29: 0 | H29: 0 | I29: =+[1]Todo!$C29 -> 0
A30: Upon Sales Contract | B30: Send list realtor contract | F30: Upon Sales Contract | H30: 0 | I30: =+[1]Todo!$C30 -> 0
B31: Get Payoff Letter from Mortgage | F31: 0 | H31: 0 | I31: =+[1]Todo!$C31 -> 0
B32: Respond to Closing Attorney | F32: 0 | H32: 0 | I32: =+[1]Todo!$C32 -> 0
B33: Turn off utilities | F33: 0 | H33: 0 | I33: =+[1]Todo!$C33 -> 0
B34: Alert Private Lenders | F34: 0 | H34: 0 | I34: =+[1]Todo!$C34 -> 0
F35: 0 | H35: 0
F36: 0 | H36: 0
F37: 0 | H37: 0
A38: Upon Closing | B38: Documents to send to list realtor | F38: Upon Closing | H38: 0 | I38: =+[1]Todo!$C38 -> 0
B39: Alert Private Lenders | F39: 0 | H39: 0 | I39: =+[1]Todo!$C39 -> 0
B40: Send list realtor CD/Alta signed by all | F40: 0 | H40: 0 | I40: =+[1]Todo!$C40 -> 0
...

Sheet Contact
A1: Vendor | B1: Phone Number | C1: Contact | D1: Acct/Policy | E1: Email | F1: Purpose
A2: Sellers
A4: Lola Williams | B4: 252 814 4221 | D4: SS 237 72 4905 | E4: username: Wes@BYHLLC.com PW:w3638B0# | G4: https://account.mrcooper.com/ed04d0f3-eba1-467f-91e7-52505132554c/oauth2/v2.0/authorize?p=B2C_1A_SignUpOrSignIn&client_id=2a694b91-5631-4fe1-9039-775a23b420c8&nonce=defaultNonce&redirect_uri=https://www.mrcooper.com/sessions/login&scope=openid&response_type=id_token&response_mode=form_post&pageName=&guid=&ga_client_id=&session_id=395071fa82d98b338e7ef9cf7a7320d9&&getCustomer=no&state={%22redirect%22:null}&x-client-SKU=apollo-accounts-mrcooper
A6: Mortgage | E6: Wiring Instructions: Acct: 46290000967540 Rt#: 021000021 Address: JP Morgan Chase Bank, 270 Park ave, New York, NY 10017
A7: Rocket Mortgage | B7: 866 316 2432 | D7: 0623844180 | E7: https://rocket.com/mortgage/servicing/onboarding?loanNumber=623844180 | F7: sent on 8/23/2023
D8: login: | E8: Wes@BYHLLC.com
D9: Pasword: | E9: w3638B0@
A14: NREIG | B14: 770 734 1523
U16: To | V16: Subject | W16: Sent | X16: Size | Y16: Categories
U17: DefaultCFC@Truist.com | V17: 5008 Larchmont Dr - Loan 9015 2144 11-5998 | W17: 0.44583333 | X17: 478 KB
A20: Insurance National Real Estate Insurance Group LLC
A21: Rani Walker | B21: 678 329 0123 | C21: RWalker@insurancehub.com
A22: Customer Care Specialist
A23: InsuranceHub Leavitt Agency
A24: Phone/SMS/Fax: 678.329.0123 | insurancehub.com
A25: Becki Miron | B25: 678.685.3277 | C25: BMiron@insurancehub.com
A26: Account Manager
A27: InsuranceHub Leavitt Agency
A28: Phone/SMS/Fax: 678.685.3277 | insurancehub.com

Sheet Example Proposal
A1: Building Permits | B1: Permits | C1: File for building, electrical, plumbing ad mechanical permits | D1: 1 | E1: 675
A2: Demo labor | B2: Demolition | C2: Remove two (2) bathroom vanities and toilets | D2: 4 | E2: 33.75
A3: Deck material | B3: Deck material | C3: Supply treated material to build new deck | D3: 144 | E3: 14.85
A4: Supevision | B4: Roof Install | C4: Supervise roof replacement | D4: 0 | E4: 100
A5: Deck labor | B5: Deck | C5: Remove existing deck and build new 12x12 deck and stain. Stain supplied by HO. | D5: 144 | E5: 13.5
A6: Frame | B6: Floor repair | C6: Demo and replace water damaged floor in living room, hallway, first bedroom and both bathrooms | D6: 1 | E6: 7020
A7: Frame | B7: Change Order No. 1 | C7: Repair termte damaged subfloor and joists | D7: 1 | E7: 7500
A8: Supevision | B8: HVAC Install | C8: Supervise HVAC replacement | D8: 3 | E8: 100
A9: Home Repairs | B9: Repair fiberglass tubs | C9: Repair two (2) fiberglass tubs | D9: 2 | E9: 270
A10: Home Repairs | B10: Sliding glass door | C10: Clean track and repair sliding glass door.. No door cost included. | D10: 1 | E10: 202.5
A11: Siding labor | B11: Shed | C11: Repair and paint 12x12 shed. HO to supply paint. | D11: 100 | E11: 6.75
A12: Siding material | B12: Shed repair material | C12: Supply material to replace doors, siding, and some floor on shed | D12: 1 | E12: 472.5
A13: Window labor | B13: Replace broken window glass | C13: Replace glass in laundry room window and master bath | D13: 2 | E13: 303.75
A14: Interest | B14: Draw 1 Interest Charge | C14: Credit Card interest fee
A15: Cleaning | B15: Shed and crawl | C15: Clean shed and crawl | D15: 1375 | E15: 1.0125
A16: Floor Coverings | B16: LVP Flooring | C16: Install 1375 sq. ft. of Presto Plus Weathered Barnboard LVP throughout the home with11/16 Primed Quarter Round shoe molding. GDB to supply the flooring and shoe molding. | D16: 1375 | E16: 6.453
A17: Paint | B17: Powerwash | C17: Powerwash exterior of home and shed. | D17: 1 | E17: 405
A18: Paint | B18: Laundry cabinets | C18: Sand, prime and paint laundry room cabinets HO supplied paint | D18: 1 | E18: 405
A19: Paint | B19: Exterior paint | C19: Paint rails, stain porches, paint shutters, and doors | D19: 500 | E19: 1.35
A20: Paint | B20: Interior paint | C20: Prime with KIlz and paint all interior walls, ceiling and trim/doors. Remove borders, repair drywall. HO to supply paint | D20: 1375 | E20: 4.725
A21: Paint | B21: Paint floors | C21: Paint all floors with Kilz HO to supply paint | D21: 1
A22: Paint | B22: Paint kitchen cabinets | C22: Sand, prime and paint 16 kitchen cabinets. HO supplies paint | D22: 16 | E22: 135
A23: Cabinets & Vanities | B23: Bath vanities | C23: Install two (2) HO supplied bath vanities. Atlantic to install countertops with integrated sinks.. | D23: 2 | E23: 202.5
A24: Cabinets & Vanities | B24: Cabinet hardware | C24: Install knobs bath cabinets HO to supply hardware | D24: 5 | E24: 6.75
A25: Cabinets & Vanities | B25: Kitchen cabinet hardware | C25: Install HO supplied hardware on 16 kitchen cabinets | D25: 16 | E25: 6.75
A26: Supervision | B26: Kitchen Countertops | C26: Supervise installation of kitchen countertops | D26: 3 | E26: 100
A27: Plumbing | B27: Ice Maker Walter Line | C27: Install water line for the refrigerator ice maker. | D27: 1 | E27: 255.15
A28: Plumbing | B28: Kitchen plumbing | C28: Install kitchen sink, faucet and dishwasher. HO to supply sink, dishwasher and faucets. | D28: 3 | E28: 214.65
A29: Plumbing | B29: Install toilets | C29: Install two (2) HO supplied toilets | D29: 2 | E29: 222.75
A30: Plumbing | B30: Bathroom plumbing | C30: Install three (3) HO supplied bathroom faucets. | D30: 3 | E30: 255.15
A31: Electrical & Lighting | B31: Ceiling fans bedrooms | C31: Install ceiling fans with lights in three (3) bedrooms. HO to supply fans and lights. | D31: 3 | E31: 101.25
A32: Electrical & Lighting | B32: Ceiling fan living room | C32: Install ceiling fans with lights in living room.. HO to supply fans and lights. | D32: 1 | E32: 101.25
A33: Electrical & Lighting | B33: Bath lighting | C33: Replace light fixtures in two (2) bathrooms. HO to supply fixtures. | D33: 3 | E33: 67.5
... A47: Home Repairs | B47: Change Order No. 8 | C47: install HO supplied maibox | D47: 1 | E47: 135

Sheet Proposal
B2: ="Preassigned Rows Indicating Payment or Scheduling by " &Profit!E1&" Your Home" -> Preassigned Rows Indicating Payment or Scheduling by Buy Your Home
B4: Preassigned Rows Cordination of Glasgow with Contrtactors
B6: Pasted rows from Builder's Trend Proposal
B8: Notes: Only add rows to the bottom of the table
A11: Cost Code | B11: Title | C11: Description | D11: Qty | E11: Unit Price
A12: Deposit | B12: Deposit | C12: Initial Deposit to Start Job | D12: 0
A13: Draw | B13: Draw 1 | C13: Draw 1 | D13: 0
A14: Draw | B14: Draw 2 | C14: Draw 2 | D14: 0
B15: Sell | C15: List with MLS | D15: 6
A16: HVAC | B16: Cordinate Sub | C16: HVAC | D16: 0 | E16: 0
A17: Floor Coverings | B17: Cordinate Sub | C17: Flooring Contractor | D17: 0 | E17: 200
A18: Supervision | B18: Cordinate Sub | C18: Termite Treatment | D18: 0 | E18: 200
A19: Cabinets & Vanities | B19: Cordinate Sub | C19: Cabinet Delivery | D19: 0 | E19: 200
A20: Countertops | B20: Cordinate Sub | C20: Manage installion of granite countertops by others in kitchen | D20: 0 | E20: 135
C21: Clean out House | D21: 1 | E21: 0
C22: Contract | D22: 0 | E22: 0
A23: Deck labor
A24: Deck labor
A25: Deck material
A26: ... Demo
A27: ... Demo
A28: ... Demo
A29: ... Demo
A30: Demo labor
A31: 20 Millwork & Trim
A32: 20 Millwork & Trim
A33: 20 Millwork & Trim
A34: 22 Specialty
... A37: Bath Accessories
A38: Building Permits | G38: 1160
A39: Cabinets & Vanities
A40: Electrical & Lighting
A41: Frame labor
A42: Frame labor
A43: Frame labor
A44: Frame labor
A45: Frame materials
A46: Frame materials
A47: Frame materials
A48: HVAC
...

Sheet ProposalUpdate
A1: These Cells are updated from the Proposal tab and are protected here. | I1: These cells are updated here and carried over to the Gnatt Chart | P1: Contracted Task | Q1: 1 | R1: Payment | S1: 4
P2: Change Order | Q2: 2 | R2: Not Used | S2: 0
P3: Manage Vendor | Q3: 3 | R3: Post Contract | S3: 5
A4: Party | B4: Item | C4: Cost Code | D4: Title | E4: Description | F4: Qty | G4: Unit Price | H4: Price | I4: Done | J4: Group Order | K4: Start Date | L4: Days | M4: Paid | N4: Notes
A5: =+IF(FromProposal[[#This Row],[Cost Code]]<>0,"Glasgow","") -> Glasgow | B5: 1 | C5: Deposit | D5: Deposit | E5: Initial Deposit to Start Job | F5: 0
A6: =+IF(FromProposal[[#This Row],[Cost Code]]<>0,"Glasgow","") -> Glasgow | B6: 2 | C6: Draw | D6: Draw 1 | E6: Draw 1 | F6: 0
A7: =+IF(FromProposal[[#This Row],[Cost Code]]<>0,"Glasgow","") -> Glasgow | B7: 3 | C7: Draw | D7: Draw 2 | E7: Draw 2 | F7: 0
A8: =+IF(FromProposal[[#This Row],[Cost Code]]<>0,"Glasgow","") | B8: 4 | D8: Sell | E8: List with MLS | F8: 6
A9: =+IF(FromProposal[[#This Row],[Cost Code]]<>0,"Glasgow","") -> Glasgow | B9: 5 | C9: HVAC | D9: Cordinate Sub | E9: HVAC | F9: 0 | G9: 0 | H9: 0
A10: =+IF(FromProposal[[#This Row],[Cost Code]]<>0,"Glasgow","") -> Glasgow | B10: 6 | C10: Floor Coverings | D10: Cordinate Sub | E10: Flooring Contractor | F10: 0 | G10: 200 | H10: 0
A11: =+IF(FromProposal[[#This Row],[Cost Code]]<>0,"Glasgow","") -> Glasgow | B11: 7 | C11: Supervision | D11: Cordinate Sub | E11: Termite Treatment | F11: 0 | G11: 200 | H11: 0
A12: =+IF(FromProposal[[#This Row],[Cost Code]]<>0,"Glasgow","") -> Glasgow | B12: 8 | C12: Cabinets & Vanities | D12: Cordinate Sub | E12: Cabinet Delivery | F12: 0 | G12: 200 | H12: 0
A13: =+IF(FromProposal[[#This Row],[Cost Code]]<>0,"Glasgow","") -> Glasgow | B13: 9 | C13: Countertops | D13: Cordinate Sub | E13: Manage installion of granite countertops by others in kitchen | F13: 0 | G13: 135 | H13: 0
A14: =+IF(FromProposal[[#This Row],[Cost Code]]<>0,"Glasgow","") | B14: 10 | E14: Clean out House | F14: 1 | G14: 0 | H14: 0
A15: =+IF(FromProposal[[#This Row],[Cost Code]]<>0,"Glasgow","") | B15: 11 | E15: Contract | F15: 0 | G15: 0 | H15: 0
A16: =+IF(FromProposal[[#This Row],[Cost Code]]<>0,"Glasgow","") -> Glasgow | B16: 12 | C16: Deck labor
A17: =+IF(FromProposal[[#This Row],[Cost Code]]<>0,"Glasgow","") -> Glasgow | B17: 13 | C17: Deck labor
A18: =+IF(FromProposal[[#This Row],[Cost Code]]<>0,"Glasgow","") -> Glasgow | B18: 14 | C18: Deck material
A19: =+IF(FromProposal[[#This Row],[Cost Code]]<>0,"Glasgow","") -> Glasgow | B19: 15 | C19: ... Demo
A20: =+IF(FromProposal[[#This Row],[Cost Code]]<>0,"Glasgow","") -> Glasgow | B20: 16 | C20: ... Demo

Sheet Gnatt Chart
J1: Expense | N1: Due:
A2: ="Glasgow Design Build for "&Profit!E1& " Your Home" -> Glasgow Design Build for Buy Your Home | E2: Project Start Date: | F2: =+MIN(ProposalToGnatt[Start Date]) -> 0 | H2: Company Paid Materials Total: | J2: =+SUM(H8:H22) -> 5160.24 | M2: =+SUM(O8:O22)-SUM(M8:M22) -> 0
A3: Jonathan Brothers | B3: Jonathan Brothers | H3: Contractors Total: | J3: =SUM(H24:H27) -> 0 | M3: =+J3-SUM(M24:M27) -> 0
A4: =+Profit!B2 -> 3413 Pinetree Ln, Greenville, NC 27858 | B4: =+Profit!B2 -> 3413 Pinetree Ln, Greenville, NC 27858 | E4: Milestone Marker: | G4: 1 | H4: Glasgow Total: | J4: =SUM(ProposalToGnatt[Price]) -> 0 | M4: {=+SUM(ProposalToGnatt[Due]-ProposalToGnatt[Paid])} -> 0
B5: Cells H5 through BK5 contain the day number of the month for the Month represented in the cell block above each date cell and are auto calculated. Do not modify these cells. Dates leading up to Today are shaded. | E5: Milestone Marker 2: | G5: 2 | H5: Grand Total | J5: =+SUM(J2:K4) -> 5160.24 | M5: =+SUM(M2:N4) -> 0
E6: =Profit!E1&" Your Home Supplied Materials" -> Buy Your Home Supplied Materials
A7: Assigned | B7: Item # | C7: Cost Code | D7: Title | E7: Description | F7: Qty | G7: Unit Price | H7: Price | I7: Done | J7: Group Order | K7: Start Date | L7: Days | M7: Paid | N7: Notes | O7: Due | AO7: =IFERROR(IF(LEN(#REF!)=0,"",IF(AND(#REF!=#REF!,#REF!=1),Milestone_Marker_Old,"")),"")
A8: =Profit!$E$1&" Your Home" -> Buy Your Home | B8: 1 | E8: Cleanup (from Demo & Trash Haul Tab) | F8: 1 | G8: =+'Demo & Trash Haul'!G17 -> 0 | H8: =+F8*G8 -> 0 | O8: =IF(I8="Yes",H8,0) -> 0
A9: =Profit!$E$1&" Your Home" -> Buy Your Home | B9: =+B8+1 -> 2 | E9: Taxes - outside of closing (from Taxes tab) | F9: 0 | G9: =+Taxes!E19 -> 2138.17 | H9: =+F9*G9 -> 0 | O9: =IF(I9="Yes",H9,0) -> 0
A10: =Profit!$E$1&" Your Home" -> Buy Your Home | B10: =+B8+1 -> 2 | E10: Appliances (from Appliances Tab) | F10: 1 | G10: =+Appliances!F21 -> 0 | H10: =+F10*G10 -> 0 | O10: =IF(I10="Yes",H10,0) -> 0
A11: =Profit!$E$1&" Your Home" -> Buy Your Home | B11: =+B10+1 -> 3 | E11: Plubing Fixtures | F11: 1 | G11: =+'Plumbing Fixtures'!F23 -> 0 | H11: =+F11*G11 -> 0 | O11: =IF(I11="Yes",H11,0) -> 0
A12: =Profit!$E$1&" Your Home" -> Buy Your Home | B12: =+B11+1 -> 4 | E12: Windows & Doors | F12: 0 | G12: =+'Windows & Doors'!F30 -> 235.81 | H12: =+F12*G12 -> 0 | O12: =IF(I12="Yes",H12,0) -> 0
A13: =Profit!$E$1&" Your Home" -> Buy Your Home | B13: =+B12+1 -> 5 | E13: Cabinets (from Cabinets Tab) | F13: 0 | G13: =+Cabinets!G44 -> 0 | H13: =+F13*G13 -> 0 | O13: =IF(I13="Yes",H13,0) -> 0
A14: =Profit!$E$1&" Your Home" -> Buy Your Home | B14: =+B13+1 -> 6 | E14: Paint (from Paint Tab) | F14: 1 | G14: =+Paint!G28 -> 0 | H14: =+F14*G14 -> 0 | O14: =IF(I14="Yes",H14,0) -> 0
A15: =Profit!$E$1&" Your Home" -> Buy Your Home | B15: =+B14+1 -> 7 | E15: Flooring | F15: 1 | G15: =+Flooring!G7 -> 5098.8 | H15: =+F15*G15 -> 5098.8 | O15: =IF(I15="Yes",H15,0) -> 0 | AP15: =IFERROR(IF(LEN(#REF!)=0,"",IF(P$29=#REF!,Milestone_Marker_Old,"")),"") | AQ15: =IFERROR(IF(LEN(#REF!)=0,"",IF(Q$29=#REF!,Milestone_Marker_Old,"")),"") | AR15: =IFERROR(IF(LEN(#REF!)=0,"",IF(R$29=#REF!,Milestone_Marker_Old,"")),"") | AS15: =IFERROR(IF(LEN(#REF!)=0,"",IF(S$29=#REF!,Milestone_Marker_Old,"")),"") | AT15: =IFERROR(IF(LEN(#REF!)=0,"",IF(T$29=#REF!,Milestone_Marker_Old,"")),"") | AU15: =IFERROR(IF(LEN(#REF!)=0,"",IF(U$29=#REF!,Milestone_Marker_Old,"")),"") | AV15: =IFERROR(IF(LEN(#REF!)=0,"",IF(V$29=#REF!,Milestone_Marker_Old,"")),"") | AW15: =IFERROR(IF(LEN(#REF!)=0,"",IF(W$29=#REF!,Milestone_Marker_Old,"")),"") | ... DU15: =IFERROR(IF(LEN(#REF!)=0,"",IF(CU$29=#REF!,Milestone_Marker_Old,"")),"")
A16: =Profit!$E$1&" Your Home" -> Buy Your Home | B16: =+B15+1 -> 8 | E16: Electrical fixtures (from Misc Tab) | F16: 0 | G16: =+'Electrical Fixtures'!F23 -> 0 | H16: =+F16*G16 -> 0 | O16: =IF(I16="Yes",H16,0) -> 0 | AP16: =IFERROR(IF(LEN(#REF!)=0,"",IF(P$29=#REF!,Milestone_Marker_Old,"")),"") | AQ16: =IFERROR(IF(LEN(#REF!)=0,"",IF(Q$29=#REF!,Milestone_Marker_Old,"")),"") | AR16: =IFERROR(IF(LEN(#REF!)=0,"",IF(R$29=#REF!,Milestone_Marker_Old,"")),"") | AS16: =IFERROR(IF(LEN(#REF!)=0,"",IF(S$29=#REF!,Milestone_Marker_Old,"")),"") | AT16: =IFERROR(IF(LEN(#REF!)=0,"",IF(T$29=#REF!,Milestone_Marker_Old,"")),"") | AU16: =IFERROR(IF(LEN(#REF!)=0,"",IF(U$29=#REF!,Milestone_Marker_Old,"")),"") | AV16: =IFERROR(IF(LEN(#REF!)=0,"",IF(V$29=#REF!,Milestone_Marker_Old,"")),"") | AW16: =IFERROR(IF(LEN(#REF!)=0,"",IF(W$29=#REF!,Milestone_Marker_Old,"")),"") | ... DU16: =IFERROR(IF(LEN(#REF!)=0,"",IF(CU$29=#REF!,Milestone_Marker_Old,"")),"")
A17: =Profit!$E$1&" Your Home" -> Buy Your Home | B17: =+B16+1 -> 9 | E17: Exterior Tab | F17: 1 | G17: =+Exterior!D16 -> 61.44 | H17: =+F17*G17 -> 61.44 | O17: =IF(I17="Yes",H17,0) -> 0
A18: =Profit!$E$1&" Your Home" -> Buy Your Home | B18: =+B17+1 -> 10 | E18: Landscaping Tab | F18: 0 | G18: =+Landscape!G17 -> 0 | H18: =+F18*G18 -> 0 | O18: =IF(I18="Yes",H18,0) -> 0
A19: =Profit!$E$1&" Your Home" -> Buy Your Home | B19: =+B18+1 -> 11 | E19: HVAC Contractor | F19: 0 | G19: =+'Demo & Trash Haul'!F29 -> 0 | H19: =+F19*G19 -> 0 | O19: =IF(I19="Yes",H19,0) -> 0 | AP19: =IFERROR(IF(LEN(#REF!)=0,"",IF(P$29=#REF!,Milestone_Marker_Old,"")),"") | AQ19: =IFERROR(IF(LEN(#REF!)=0,"",IF(Q$29=#REF!,Milestone_Marker_Old,"")),"") | AR19: =IFERROR(IF(LEN(#REF!)=0,"",IF(R$29=#REF!,Milestone_Marker_Old,"")),"") | AS19: =IFERROR(IF(LEN(#REF!)=0,"",IF(S$29=#REF!,Milestone_Marker_Old,"")),"") | AT19: =IFERROR(IF(LEN(#REF!)=0,"",IF(T$29=#REF!,Milestone_Marker_Old,"")),"") | AU19: =IFERROR(IF(LEN(#REF!)=0,"",IF(U$29=#REF!,Milestone_Marker_Old,"")),"") | AV19: =IFERROR(IF(LEN(#REF!)=0,"",IF(V$29=#REF!,Milestone_Marker_Old,"")),"") | AW19: =IFERROR(IF(LEN(#REF!)=0,"",IF(W$29=#REF!,Milestone_Marker_Old,"")),"") | ... DU19: =IFERROR(IF(LEN(#REF!)=0,"",IF(CU$29=#REF!,Milestone_Marker_Old,"")),"")
A20: =Profit!$E$1&" Your Home" -> Buy Your Home | B20: =+B19+1 -> 12 | E20: Landscape | F20: 0 | G20: =+'Demo & Trash Haul'!F30 -> 0 | H20: =+F20*G20 -> 0 | O20: =IF(I20="Yes",H20,0) -> 0 | AP20: =IFERROR(IF(LEN(#REF!)=0,"",IF(P$29=#REF!,Milestone_Marker_Old,"")),"") | AQ20: =IFERROR(IF(LEN(#REF!)=0,"",IF(Q$29=#REF!,Milestone_Marker_Old,"")),"") | AR20: =IFERROR(IF(LEN(#REF!)=0,"",IF(R$29=#REF!,Milestone_Marker_Old,"")),"") | AS20: =IFERROR(IF(LEN(#REF!)=0,"",IF(S$29=#REF!,Milestone_Marker_Old,"")),"") | AT20: =IFERROR(IF(LEN(#REF!)=0,"",IF(T$29=#REF!,Milestone_Marker_Old,"")),"") | AU20: =IFERROR(IF(LEN(#REF!)=0,"",IF(U$29=#REF!,Milestone_Marker_Old,"")),"") | AV20: =IFERROR(IF(LEN(#REF!)=0,"",IF(V$29=#REF!,Milestone_Marker_Old,"")),"") | AW20: =IFERROR(IF(LEN(#REF!)=0,"",IF(W$29=#REF!,Milestone_Marker_Old,"")),"") | ... DU20: =IFERROR(IF(LEN(#REF!)=0,"",IF(CU$29=#REF!,Milestone_Marker_Old,"")),"")
A21: =Profit!$E$1&" Your Home" -> Buy Your Home | B21: =+B20+1 -> 13 | E21: Exterior- Termite | F21: 0 | G21: 0 | H21: =+F21*G21 -> 0 | O21: =IF(I21="Yes",H21,0) -> 0 | AP21: =IFERROR(IF(LEN(#REF!)=0,"",IF(P$29=#REF!,Milestone_Marker_Old,"")),"") | AQ21: =IFERROR(IF(LEN(#REF!)=0,"",IF(Q$29=#REF!,Milestone_Marker_Old,"")),"") | AR21: =IFERROR(IF(LEN(#REF!)=0,"",IF(R$29=#REF!,Milestone_Marker_Old,"")),"") | AS21: =IFERROR(IF(LEN(#REF!)=0,"",IF(S$29=#REF!,Milestone_Marker_Old,"")),"") | AT21: =IFERROR(IF(LEN(#REF!)=0,"",IF(T$29=#REF!,Milestone_Marker_Old,"")),"") | AU21: =IFERROR(IF(LEN(#REF!)=0,"",IF(U$29=#REF!,Milestone_Marker_Old,"")),"") | AV21: =IFERROR(IF(LEN(#REF!)=0,"",IF(V$29=#REF!,Milestone_Marker_Old,"")),"") | AW21: =IFERROR(IF(LEN(#REF!)=0,"",IF(W$29=#REF!,Milestone_Marker_Old,"")),"") | ... DU21: =IFERROR(IF(LEN(#REF!)=0,"",IF(CU$29=#REF!,Milestone_Marker_Old,"")),"")
A22: =Profit!$E$1&" Your Home" -> Buy Your Home | B22: =+B21+1 -> 14 | E22: Drainage | F22: 0 | G22: =+'Demo & Trash Haul'!F32 -> 0 | H22: =+F22*G22 -> 0 | O22: =IF(I22="Yes",H22,0) -> 0 | AP22: =IFERROR(IF(LEN(#REF!)=0,"",IF(P$29=#REF!,Milestone_Marker_Old,"")),"") | AQ22: =IFERROR(IF(LEN(#REF!)=0,"",IF(Q$29=#REF!,Milestone_Marker_Old,"")),"") | AR22: =IFERROR(IF(LEN(#REF!)=0,"",IF(R$29=#REF!,Milestone_Marker_Old,"")),"") | AS22: =IFERROR(IF(LEN(#REF!)=0,"",IF(S$29=#REF!,Milestone_Marker_Old,"")),"") | AT22: =IFERROR(IF(LEN(#REF!)=0,"",IF(T$29=#REF!,Milestone_Marker_Old,"")),"") | AU22: =IFERROR(IF(LEN(#REF!)=0,"",IF(U$29=#REF!,Milestone_Marker_Old,"")),"") | AV22: =IFERROR(IF(LEN(#REF!)=0,"",IF(V$29=#REF!,Milestone_Marker_Old,"")),"") | AW22: =IFERROR(IF(LEN(#REF!)=0,"",IF(W$29=#REF!,Milestone_Marker_Old,"")),"") | ... DU22: =IFERROR(IF(LEN(#REF!)=0,"",IF(CU$29=#REF!,Milestone_Marker_Old,"")),"")
E23: =Profit!E1&" Your Home's Paid Contractors" -> Buy Your Home's Paid Contractors | AP23: =IFERROR(IF(LEN(#REF!)=0,"",IF(P$29=#REF!,Milestone_Marker_Old,"")),"") | AQ23: =IFERROR(IF(LEN(#REF!)=0,"",IF(Q$29=#REF!,Milestone_Marker_Old,"")),"") | AR23: =IFERROR(IF(LEN(#REF!)=0,"",IF(R$29=#REF!,Milestone_Marker_Old,"")),"") | AS23: =IFERROR(IF(LEN(#REF!)=0,"",IF(S$29=#REF!,Milestone_Marker_Old,"")),"") | AT23: =IFERROR(IF(LEN(#REF!)=0,"",IF(T$29=#REF!,Milestone_Marker_Old,"")),"") | AU23: =IFERROR(IF(LEN(#REF!)=0,"",IF(U$29=#REF!,Milestone_Marker_Old,"")),"") | AV23: =IFERROR(IF(LEN(#REF!)=0,"",IF(V$29=#REF!,Milestone_Marker_Old,"")),"") | AW23: =IFERROR(IF(LEN(#REF!)=0,"",IF(W$29=#REF!,Milestone_Marker_Old,"")),"") | ... DU23: =IFERROR(IF(LEN(#REF!)=0,"",IF(CU$29=#REF!,Milestone_Marker_Old,"")),"")
A24: Mabrey Roofing | B24: =+B22+1 -> 15 | E24: Roof Contractor | F24: 0 | G24: =3743.62*2 -> 7487.24 | H24: =+F24*G24 -> 0 | O24: =IF(I24="Yes",H24,0) -> 0 | AA24: Scrolling Increment: | AP24: =IFERROR(IF(LEN(#REF!)=0,"",IF(P$29=#REF!,Milestone_Marker_Old,"")),"") | AQ24: =IFERROR(IF(LEN(#REF!)=0,"",IF(Q$29=#REF!,Milestone_Marker_Old,"")),"") | AR24: =IFERROR(IF(LEN(#REF!)=0,"",IF(R$29=#REF!,Milestone_Marker_Old,"")),"") | AS24: =IFERROR(IF(LEN(#REF!)=0,"",IF(S$29=#REF!,Milestone_Marker_Old,"")),"") | AT24: =IFERROR(IF(LEN(#REF!)=0,"",IF(T$29=#REF!,Milestone_Marker_Old,"")),"") | AU24: =IFERROR(IF(LEN(#REF!)=0,"",IF(U$29=#REF!,Milestone_Marker_Old,"")),"") | AV24: =IFERROR(IF(LEN(#REF!)=0,"",IF(V$29=#REF!,Milestone_Marker_Old,"")),"") | AW24: =IFERROR(IF(LEN(#REF!)=0,"",IF(W$29=#REF!,Milestone_Marker_Old,"")),"") | ... DU24: =IFERROR(IF(LEN(#REF!)=0,"",IF(CU$29=#REF!,Milestone_Marker_Old,"")),"")
A25: Mabrey Roofing | B25: =+B24+1 -> 16 | E25: Roof Contractor | F25: 0 | G25: 400 | H25: =+F25*G25 -> 0 | O25: =IF(I25="Yes",H25,0) -> 0 | AP25: =IFERROR(IF(LEN(#REF!)=0,"",IF(P$29=#REF!,Milestone_Marker_Old,"")),"") | AQ25: =IFERROR(IF(LEN(#REF!)=0,"",IF(Q$29=#REF!,Milestone_Marker_Old,"")),"") | AR25: =IFERROR(IF(LEN(#REF!)=0,"",IF(R$29=#REF!,Milestone_Marker_Old,"")),"") | AS25: =IFERROR(IF(LEN(#REF!)=0,"",IF(S$29=#REF!,Milestone_Marker_Old,"")),"") | AT25: =IFERROR(IF(LEN(#REF!)=0,"",IF(T$29=#REF!,Milestone_Marker_Old,"")),"") | AU25: =IFERROR(IF(LEN(#REF!)=0,"",IF(U$29=#REF!,Milestone_Marker_Old,"")),"") | AV25: =IFERROR(IF(LEN(#REF!)=0,"",IF(V$29=#REF!,Milestone_Marker_Old,"")),"") | AW25: =IFERROR(IF(LEN(#REF!)=0,"",IF(W$29=#REF!,Milestone_Marker_Old,"")),"") | ... DU25: =IFERROR(IF(LEN(#REF!)=0,"",IF(CU$29=#REF!,Milestone_Marker_Old,"")),"")
A26: Love Services | B26: =+B25+1 -> 17 | E26: HVAC Contractor - Package Heat Pump | F26: 1 | G26: =+HVAC!F13 -> 0 | H26: =+F26*G26 -> 0 | O26: =IF(I26="Yes",H26,0) -> 0 | AB26: 0
A27: Love Services | B27: =+B26+1 -> 18 | E27: HVAC Contractor - Duct Work | F27: 0 | G27: 4598 | H27: =+F27*G27 -> 0 | O27: =IF(I27="Yes",H27,0) -> 0
E28: Glasgow Design Items (all items should be updated from Proposal or ProposalUpdate tab) | P28: =IF(TEXT(Project_Start,"mmmm")=TEXT(P29,"mmmm"),"",TEXT(P29,"mmmm")) | Q28: =IF(TEXT(P29,"mmmm")=TEXT(Q29,"mmmm"),"",TEXT(Q29,"mmmm")) | R28: =IF(TEXT(Q29,"mmmm")=TEXT(R29,"mmmm"),"",TEXT(R29,"mmmm")) | S28: =IF(TEXT(R29,"mmmm")=TEXT(S29,"mmmm"),"",TEXT(S29,"mmmm")) | T28: =IF(TEXT(S29,"mmmm")=TEXT(T29,"mmmm"),"",TEXT(T29,"mmmm")) | U28: =IF(TEXT(T29,"mmmm")=TEXT(U29,"mmmm"),"",TEXT(U29,"mmmm")) | V28: =IF(TEXT(U29,"mmmm")=TEXT(V29,"mmmm"),"",TEXT(V29,"mmmm")) | W28: =IF(TEXT(V29,"mmmm")=TEXT(W29,"mmmm"),"",TEXT(W29,"mmmm")) | X28: =IF(TEXT(W29,"mmmm")=TEXT(X29,"mmmm"),"",TEXT(X29,"mmmm")) | ... CU28: =IF(TEXT(CT29,"mmmm")=TEXT(CU29,"mmmm"),"",TEXT(CU29,"mmmm"))
A29: Party | B29: Item | C29: Cost Code | D29: Title | E29: Description | F29: Qty | G29: Unit Price | H29: Price | I29: Done | J29: Group Order | K29: Start Date | L29: Days | M29: Paid | N29: Notes | O29: Due | P29: =IFERROR(Project_Start+Scrolling_Increment,TODAY()) -> 0 | Q29: =+P29+1 -> 1 | R29: =+Q29+1 -> 2 | S29: =+R29+1 -> 3 | T29: =+S29+1 -> 4 | U29: =+T29+1 -> 5 | V29: =+U29+1 -> 6 | W29: =+V29+1 -> 7 | X29: =+W29+1 -> 8 | ... CU29: =+CT29+1 -> 83
A30: Glasgow | B30: 1 | C30: Deposit | D30: Deposit | E30: Initial Deposit to Start Job | F30: 0 | P30: =IFERROR(+IF(P$29=ProposalToGnatt[[#This Row],[Start Date]],Milestone_Marker,IF(AND(P$29>ProposalToGnatt[[#This Row],[Start Date]],P$29<ProposalToGnatt[[#This Row],[Start Date]]+ProposalToGnatt[[#This Row],[Days]]),$G$5,"")),"") -> 1 | Q30: =IFERROR(+IF(Q$29=ProposalToGnatt[[#This Row],[Start Date]],Milestone_Marker,IF(AND(Q$29>ProposalToGnatt[[#This Row],[Start Date]],Q$29<ProposalToGnatt[[#This Row],[Start Date]]+ProposalToGnatt[[#This Row],[Days]]),$G$5,"")),"") | R30: =IFERROR(+IF(R$29=ProposalToGnatt[[#This Row],[Start Date]],Milestone_Marker,IF(AND(R$29>ProposalToGnatt[[#This Row],[Start Date]],R$29<ProposalToGnatt[[#This Row],[Start Date]]+ProposalToGnatt[[#This Row],[Days]]),$G$5,"")),"") | S30: =IFERROR(+IF(S$29=ProposalToGnatt[[#This Row],[Start Date]],Milestone_Marker,IF(AND(S$29>ProposalToGnatt[[#This Row],[Start Date]],S$29<ProposalToGnatt[[#This Row],[Start Date]]+ProposalToGnatt[[#This Row],[Days]]),$G$5,"")),"") | T30: =IFERROR(+IF(T$29=ProposalToGnatt[[#This Row],[Start Date]],Milestone_Marker,IF(AND(T$29>ProposalToGnatt[[#This Row],[Start Date]],T$29<ProposalToGnatt[[#This Row],[Start Date]]+ProposalToGnatt[[#This Row],[Days]]),$G$5,"")),"") | U30: =IFERROR(+IF(U$29=ProposalToGnatt[[#This Row],[Start Date]],Milestone_Marker,IF(AND(U$29>ProposalToGnatt[[#This Row],[Start Date]],U$29<ProposalToGnatt[[#This Row],[Start Date]]+ProposalToGnatt[[#This Row],[Days]]),$G$5,"")),"") | V30: =IFERROR(+IF(V$29=ProposalToGnatt[[#This Row],[Start Date]],Milestone_Marker,IF(AND(V$29>ProposalToGnatt[[#This Row],[Start Date]],V$29<ProposalToGnatt[[#This Row],[Start Date]]+ProposalToGnatt[[#This Row],[Days]]),$G$5,"")),"") | W30: =IFERROR(+IF(W$29=ProposalToGnatt[[#This Row],[Start Date]],Milestone_Marker,IF(AND(W$29>ProposalToGnatt[[#This Row],[Start Date]],W$29<ProposalToGnatt[[#This Row],[Start Date]]+ProposalToGnatt[[#This Row],[Days]]),$G$5,"")),"") | ... CU30: =IFERROR(+IF(CU$29=ProposalToGnatt[[#This Row],[Start Date]],Milestone_Marker,IF(AND(CU$29>ProposalToGnatt[[#This Row],[Start Date]],CU$29<ProposalToGnatt[[#This Row],[Start Date]]+ProposalToGnatt[[#This Row],[Days]]),$G$5,"")),"")
A31: Glasgow | B31: 2 | C31: Draw | D31: Draw 1 | E31: Draw 1 | F31: 0 | P31: =IFERROR(+IF(P$29=ProposalToGnatt[[#This Row],[Start Date]],Milestone_Marker,IF(AND(P$29>ProposalToGnatt[[#This Row],[Start Date]],P$29<ProposalToGnatt[[#This Row],[Start Date]]+ProposalToGnatt[[#This Row],[Days]]),$G$5,"")),"") -> 1 | Q31: =IFERROR(+IF(Q$29=ProposalToGnatt[[#This Row],[Start Date]],Milestone_Marker,IF(AND(Q$29>ProposalToGnatt[[#This Row],[Start Date]],Q$29<ProposalToGnatt[[#This Row],[Start Date]]+ProposalToGnatt[[#This Row],[Days]]),$G$5,"")),"") | R31: =IFERROR(+IF(R$29=ProposalToGnatt[[#This Row],[Start Date]],Milestone_Marker,IF(AND(R$29>ProposalToGnatt[[#This Row],[Start Date]],R$29<ProposalToGnatt[[#This Row],[Start Date]]+ProposalToGnatt[[#This Row],[Days]]),$G$5,"")),"") | S31: =IFERROR(+IF(S$29=ProposalToGnatt[[#This Row],[Start Date]],Milestone_Marker,IF(AND(S$29>ProposalToGnatt[[#This Row],[Start Date]],S$29<ProposalToGnatt[[#This Row],[Start Date]]+ProposalToGnatt[[#This Row],[Days]]),$G$5,"")),"") | T31: =IFERROR(+IF(T$29=ProposalToGnatt[[#This Row],[Start Date]],Milestone_Marker,IF(AND(T$29>ProposalToGnatt[[#This Row],[Start Date]],T$29<ProposalToGnatt[[#This Row],[Start Date]]+ProposalToGnatt[[#This Row],[Days]]),$G$5,"")),"") | U31: =IFERROR(+IF(U$29=ProposalToGnatt[[#This Row],[Start Date]],Milestone_Marker,IF(AND(U$29>ProposalToGnatt[[#This Row],[Start Date]],U$29<ProposalToGnatt[[#This Row],[Start Date]]+ProposalToGnatt[[#This Row],[Days]]),$G$5,"")),"") | V31: =IFERROR(+IF(V$29=ProposalToGnatt[[#This Row],[Start Date]],Milestone_Marker,IF(AND(V$29>ProposalToGnatt[[#This Row],[Start Date]],V$29<ProposalToGnatt[[#This Row],[Start Date]]+ProposalToGnatt[[#This Row],[Days]]),$G$5,"")),"") | W31: =IFERROR(+IF(W$29=ProposalToGnatt[[#This Row],[Start Date]],Milestone_Marker,IF(AND(W$29>ProposalToGnatt[[#This Row],[Start Date]],W$29<ProposalToGnatt[[#This Row],[Start Date]]+ProposalToGnatt[[#This Row],[Days]]),$G$5,"")),"") | ... CU31: =IFERROR(+IF(CU$29=ProposalToGnatt[[#This Row],[Start Date]],Milestone_Marker,IF(AND(CU$29>ProposalToGnatt[[#This Row],[Start Date]],CU$29<ProposalToGnatt[[#This Row],[Start Date]]+ProposalToGnatt[[#This Row],[Days]]),$G$5,"")),"")
A32: Glasgow | B32: 3 | C32: Draw | D32: Draw 2 | E32: Draw 2 | F32: 0 | P32: =IFERROR(+IF(P$29=ProposalToGnatt[[#This Row],[Start Date]],Milestone_Marker,IF(AND(P$29>ProposalToGnatt[[#This Row],[Start Date]],P$29<ProposalToGnatt[[#This Row],[Start Date]]+ProposalToGnatt[[#This Row],[Days]]),$G$5,"")),"") -> 1 | Q32: =IFERROR(+IF(Q$29=ProposalToGnatt[[#This Row],[Start Date]],Milestone_Marker,IF(AND(Q$29>ProposalToGnatt[[#This Row],[Start Date]],Q$29<ProposalToGnatt[[#This Row],[Start Date]]+ProposalToGnatt[[#This Row],[Days]]),$G$5,"")),"") | R32: =IFERROR(+IF(R$29=ProposalToGnatt[[#This Row],[Start Date]],Milestone_Marker,IF(AND(R$29>ProposalToGnatt[[#This Row],[Start Date]],R$29<ProposalToGnatt[[#This Row],[Start Date]]+ProposalToGnatt[[#This Row],[Days]]),$G$5,"")),"") | S32: =IFERROR(+IF(S$29=ProposalToGnatt[[#This Row],[Start Date]],Milestone_Marker,IF(AND(S$29>ProposalToGnatt[[#This Row],[Start Date]],S$29<ProposalToGnatt[[#This Row],[Start Date]]+ProposalToGnatt[[#This Row],[Days]]),$G$5,"")),"") | T32: =IFERROR(+IF(T$29=ProposalToGnatt[[#This Row],[Start Date]],Milestone_Marker,IF(AND(T$29>ProposalToGnatt[[#This Row],[Start Date]],T$29<ProposalToGnatt[[#This Row],[Start Date]]+ProposalToGnatt[[#This Row],[Days]]),$G$5,"")),"") | U32: =IFERROR(+IF(U$29=ProposalToGnatt[[#This Row],[Start Date]],Milestone_Marker,IF(AND(U$29>ProposalToGnatt[[#This Row],[Start Date]],U$29<ProposalToGnatt[[#This Row],[Start Date]]+ProposalToGnatt[[#This Row],[Days]]),$G$5,"")),"") | V32: =IFERROR(+IF(V$29=ProposalToGnatt[[#This Row],[Start Date]],Milestone_Marker,IF(AND(V$29>ProposalToGnatt[[#This Row],[Start Date]],V$29<ProposalToGnatt[[#This Row],[Start Date]]+ProposalToGnatt[[#This Row],[Days]]),$G$5,"")),"") | W32: =IFERROR(+IF(W$29=ProposalToGnatt[[#This Row],[Start Date]],Milestone_Marker,IF(AND(W$29>ProposalToGnatt[[#This Row],[Start Date]],W$29<ProposalToGnatt[[#This Row],[Start Date]]+ProposalToGnatt[[#This Row],[Days]]),$G$5,"")),"") | ... CU32: =IFERROR(+IF(CU$29=ProposalToGnatt[[#This Row],[Start Date]],Milestone_Marker,IF(AND(CU$29>ProposalToGnatt[[#This Row],[Start Date]],CU$29<ProposalToGnatt[[#This Row],[Start Date]]+ProposalToGnatt[[#This Row],[Days]]),$G$5,"")),"")
B33: 4 | D33: Sell | E33: List with MLS | F33: 6 | P33: =IFERROR(+IF(P$29=ProposalToGnatt[[#This Row],[Start Date]],Milestone_Marker,IF(AND(P$29>ProposalToGnatt[[#This Row],[Start Date]],P$29<ProposalToGnatt[[#This Row],[Start Date]]+ProposalToGnatt[[#This Row],[Days]]),$G$5,"")),"") -> 1 | Q33: =IFERROR(+IF(Q$29=ProposalToGnatt[[#This Row],[Start Date]],Milestone_Marker,IF(AND(Q$29>ProposalToGnatt[[#This Row],[Start Date]],Q$29<ProposalToGnatt[[#This Row],[Start Date]]+ProposalToGnatt[[#This Row],[Days]]),$G$5,"")),"") | R33: =IFERROR(+IF(R$29=ProposalToGnatt[[#This Row],[Start Date]],Milestone_Marker,IF(AND(R$29>ProposalToGnatt[[#This Row],[Start Date]],R$29<ProposalToGnatt[[#This Row],[Start Date]]+ProposalToGnatt[[#This Row],[Days]]),$G$5,"")),"") | S33: =IFERROR(+IF(S$29=ProposalToGnatt[[#This Row],[Start Date]],Milestone_Marker,IF(AND(S$29>ProposalToGnatt[[#This Row],[Start Date]],S$29<ProposalToGnatt[[#This Row],[Start Date]]+ProposalToGnatt[[#This Row],[Days]]),$G$5,"")),"") | T33: =IFERROR(+IF(T$29=ProposalToGnatt[[#This Row],[Start Date]],Milestone_Marker,IF(AND(T$29>ProposalToGnatt[[#This Row],[Start Date]],T$29<ProposalToGnatt[[#This Row],[Start Date]]+ProposalToGnatt[[#This Row],[Days]]),$G$5,"")),"") | U33: =IFERROR(+IF(U$29=ProposalToGnatt[[#This Row],[Start Date]],Milestone_Marker,IF(AND(U$29>ProposalToGnatt[[#This Row],[Start Date]],U$29<ProposalToGnatt[[#This Row],[Start Date]]+ProposalToGnatt[[#This Row],[Days]]),$G$5,"")),"") | V33: =IFERROR(+IF(V$29=ProposalToGnatt[[#This Row],[Start Date]],Milestone_Marker,IF(AND(V$29>ProposalToGnatt[[#This Row],[Start Date]],V$29<ProposalToGnatt[[#This Row],[Start Date]]+ProposalToGnatt[[#This Row],[Days]]),$G$5,"")),"") | W33: =IFERROR(+IF(W$29=ProposalToGnatt[[#This Row],[Start Date]],Milestone_Marker,IF(AND(W$29>ProposalToGnatt[[#This Row],[Start Date]],W$29<ProposalToGnatt[[#This Row],[Start Date]]+ProposalToGnatt[[#This Row],[Days]]),$G$5,"")),"") | ... CU33: =IFERROR(+IF(CU$29=ProposalToGnatt[[#This Row],[Start Date]],Milestone_Marker,IF(AND(CU$29>ProposalToGnatt[[#This Row],[Start Date]],CU$29<ProposalToGnatt[[#This Row],[Start Date]]+ProposalToGnatt[[#This Row],[Days]]),$G$5,"")),"")
A34: Glasgow | B34: 5 | C34: HVAC | D34: Cordinate Sub | E34: HVAC | F34: 0 | G34: 0 | H34: 0 | P34: =IFERROR(+IF(P$29=ProposalToGnatt[[#This Row],[Start Date]],Milestone_Marker,IF(AND(P$29>ProposalToGnatt[[#This Row],[Start Date]],P$29<ProposalToGnatt[[#This Row],[Start Date]]+ProposalToGnatt[[#This Row],[Days]]),$G$5,"")),"") -> 1 | Q34: =IFERROR(+IF(Q$29=ProposalToGnatt[[#This Row],[Start Date]],Milestone_Marker,IF(AND(Q$29>ProposalToGnatt[[#This Row],[Start Date]],Q$29<ProposalToGnatt[[#This Row],[Start Date]]+ProposalToGnatt[[#This Row],[Days]]),$G$5,"")),"") | R34: =IFERROR(+IF(R$29=ProposalToGnatt[[#This Row],[Start Date]],Milestone_Marker,IF(AND(R$29>ProposalToGnatt[[#This Row],[Start Date]],R$29<ProposalToGnatt[[#This Row],[Start Date]]+ProposalToGnatt[[#This Row],[Days]]),$G$5,"")),"") | S34: =IFERROR(+IF(S$29=ProposalToGnatt[[#This Row],[Start Date]],Milestone_Marker,IF(AND(S$29>ProposalToGnatt[[#This Row],[Start Date]],S$29<ProposalToGnatt[[#This Row],[Start Date]]+ProposalToGnatt[[#This Row],[Days]]),$G$5,"")),"") | T34: =IFERROR(+IF(T$29=ProposalToGnatt[[#This Row],[Start Date]],Milestone_Marker,IF(AND(T$29>ProposalToGnatt[[#This Row],[Start Date]],T$29<ProposalToGnatt[[#This Row],[Start Date]]+ProposalToGnatt[[#This Row],[Days]]),$G$5,"")),"") | U34: =IFERROR(+IF(U$29=ProposalToGnatt[[#This Row],[Start Date]],Milestone_Marker,IF(AND(U$29>ProposalToGnatt[[#This Row],[Start Date]],U$29<ProposalToGnatt[[#This Row],[Start Date]]+ProposalToGnatt[[#This Row],[Days]]),$G$5,"")),"") | V34: =IFERROR(+IF(V$29=ProposalToGnatt[[#This Row],[Start Date]],Milestone_Marker,IF(AND(V$29>ProposalToGnatt[[#This Row],[Start Date]],V$29<ProposalToGnatt[[#This Row],[Start Date]]+ProposalToGnatt[[#This Row],[Days]]),$G$5,"")),"") | W34: =IFERROR(+IF(W$29=ProposalToGnatt[[#This Row],[Start Date]],Milestone_Marker,IF(AND(W$29>ProposalToGnatt[[#This Row],[Start Date]],W$29<ProposalToGnatt[[#This Row],[Start Date]]+ProposalToGnatt[[#This Row],[Days]]),$G$5,"")),"") | ... CU34: =IFERROR(+IF(CU$29=ProposalToGnatt[[#This Row],[Start Date]],Milestone_Marker,IF(AND(CU$29>ProposalToGnatt[[#This Row],[Start Date]],CU$29<ProposalToGnatt[[#This Row],[Start Date]]+ProposalToGnatt[[#This Row],[Days]]),$G$5,"")),"")
A35: Glasgow | B35: 6 | C35: Floor Coverings | D35: Cordinate Sub | E35: Flooring Contractor | F35: 0 | G35: 200 | H35: 0 | P35: =IFERROR(+IF(P$29=ProposalToGnatt[[#This Row],[Start Date]],Milestone_Marker,IF(AND(P$29>ProposalToGnatt[[#This Row],[Start Date]],P$29<ProposalToGnatt[[#This Row],[Start Date]]+ProposalToGnatt[[#This Row],[Days]]),$G$5,"")),"") -> 1 | Q35: =IFERROR(+IF(Q$29=ProposalToGnatt[[#This Row],[Start Date]],Milestone_Marker,IF(AND(Q$29>ProposalToGnatt[[#This Row],[Start Date]],Q$29<ProposalToGnatt[[#This Row],[Start Date]]+ProposalToGnatt[[#This Row],[Days]]),$G$5,"")),"") | R35: =IFERROR(+IF(R$29=ProposalToGnatt[[#This Row],[Start Date]],Milestone_Marker,IF(AND(R$29>ProposalToGnatt[[#This Row],[Start Date]],R$29<ProposalToGnatt[[#This Row],[Start Date]]+ProposalToGnatt[[#This Row],[Days]]),$G$5,"")),"") | S35: =IFERROR(+IF(S$29=ProposalToGnatt[[#This Row],[Start Date]],Milestone_Marker,IF(AND(S$29>ProposalToGnatt[[#This Row],[Start Date]],S$29<ProposalToGnatt[[#This Row],[Start Date]]+ProposalToGnatt[[#This Row],[Days]]),$G$5,"")),"") | T35: =IFERROR(+IF(T$29=ProposalToGnatt[[#This Row],[Start Date]],Milestone_Marker,IF(AND(T$29>ProposalToGnatt[[#This Row],[Start Date]],T$29<ProposalToGnatt[[#This Row],[Start Date]]+ProposalToGnatt[[#This Row],[Days]]),$G$5,"")),"") | U35: =IFERROR(+IF(U$29=ProposalToGnatt[[#This Row],[Start Date]],Milestone_Marker,IF(AND(U$29>ProposalToGnatt[[#This Row],[Start Date]],U$29<ProposalToGnatt[[#This Row],[Start Date]]+ProposalToGnatt[[#This Row],[Days]]),$G$5,"")),"") | V35: =IFERROR(+IF(V$29=ProposalToGnatt[[#This Row],[Start Date]],Milestone_Marker,IF(AND(V$29>ProposalToGnatt[[#This Row],[Start Date]],V$29<ProposalToGnatt[[#This Row],[Start Date]]+ProposalToGnatt[[#This Row],[Days]]),$G$5,"")),"") | W35: =IFERROR(+IF(W$29=ProposalToGnatt[[#This Row],[Start Date]],Milestone_Marker,IF(AND(W$29>ProposalToGnatt[[#This Row],[Start Date]],W$29<ProposalToGnatt[[#This Row],[Start Date]]+ProposalToGnatt[[#This Row],[Days]]),$G$5,"")),"") | ... CU35: =IFERROR(+IF(CU$29=ProposalToGnatt[[#This Row],[Start Date]],Milestone_Marker,IF(AND(CU$29>ProposalToGnatt[[#This Row],[Start Date]],CU$29<ProposalToGnatt[[#This Row],[Start Date]]+ProposalToGnatt[[#This Row],[Days]]),$G$5,"")),"")
A36: Glasgow | B36: 7 | C36: Supervision | D36: Cordinate Sub | E36: Termite Treatment | F36: 0 | G36: 200 | H36: 0 | P36: =IFERROR(+IF(P$29=ProposalToGnatt[[#This Row],[Start Date]],Milestone_Marker,IF(AND(P$29>ProposalToGnatt[[#This Row],[Start Date]],P$29<ProposalToGnatt[[#This Row],[Start Date]]+ProposalToGnatt[[#This Row],[Days]]),$G$5,"")),"") -> 1 | Q36: =IFERROR(+IF(Q$29=ProposalToGnatt[[#This Row],[Start Date]],Milestone_Marker,IF(AND(Q$29>ProposalToGnatt[[#This Row],[Start Date]],Q$29<ProposalToGnatt[[#This Row],[Start Date]]+ProposalToGnatt[[#This Row],[Days]]),$G$5,"")),"") | R36: =IFERROR(+IF(R$29=ProposalToGnatt[[#This Row],[Start Date]],Milestone_Marker,IF(AND(R$29>ProposalToGnatt[[#This Row],[Start Date]],R$29<ProposalToGnatt[[#This Row],[Start Date]]+ProposalToGnatt[[#This Row],[Days]]),$G$5,"")),"") | S36: =IFERROR(+IF(S$29=ProposalToGnatt[[#This Row],[Start Date]],Milestone_Marker,IF(AND(S$29>ProposalToGnatt[[#This Row],[Start Date]],S$29<ProposalToGnatt[[#This Row],[Start Date]]+ProposalToGnatt[[#This Row],[Days]]),$G$5,"")),"") | T36: =IFERROR(+IF(T$29=ProposalToGnatt[[#This Row],[Start Date]],Milestone_Marker,IF(AND(T$29>ProposalToGnatt[[#This Row],[Start Date]],T$29<ProposalToGnatt[[#This Row],[Start Date]]+ProposalToGnatt[[#This Row],[Days]]),$G$5,"")),"") | U36: =IFERROR(+IF(U$29=ProposalToGnatt[[#This Row],[Start Date]],Milestone_Marker,IF(AND(U$29>ProposalToGnatt[[#This Row],[Start Date]],U$29<ProposalToGnatt[[#This Row],[Start Date]]+ProposalToGnatt[[#This Row],[Days]]),$G$5,"")),"") | V36: =IFERROR(+IF(V$29=ProposalToGnatt[[#This Row],[Start Date]],Milestone_Marker,IF(AND(V$29>ProposalToGnatt[[#This Row],[Start Date]],V$29<ProposalToGnatt[[#This Row],[Start Date]]+ProposalToGnatt[[#This Row],[Days]]),$G$5,"")),"") | W36: =IFERROR(+IF(W$29=ProposalToGnatt[[#This Row],[Start Date]],Milestone_Marker,IF(AND(W$29>ProposalToGnatt[[#This Row],[Start Date]],W$29<ProposalToGnatt[[#This Row],[Start Date]]+ProposalToGnatt[[#This Row],[Days]]),$G$5,"")),"") | ... CU36: =IFERROR(+IF(CU$29=ProposalToGnatt[[#This Row],[Start Date]],Milestone_Marker,IF(AND(CU$29>ProposalToGnatt[[#This Row],[Start Date]],CU$29<ProposalToGnatt[[#This Row],[Start Date]]+ProposalToGnatt[[#This Row],[Days]]),$G$5,"")),"")
